ERROR:app:Exception on /raw-updates [GET]
Traceback (most recent call last):
  File "/home/tfb/FrameworkBenchmarks/installs/pypy/site-packages/Flask-0.10.1-py2.7.egg/flask/app.py", line 1817, in wsgi_app
    response = self.full_dispatch_request()
  File "/home/tfb/FrameworkBenchmarks/installs/pypy/site-packages/Flask-0.10.1-py2.7.egg/flask/app.py", line 1477, in full_dispatch_request
    rv = self.handle_user_exception(e)
  File "/home/tfb/FrameworkBenchmarks/installs/pypy/site-packages/Flask-0.10.1-py2.7.egg/flask/app.py", line 1381, in handle_user_exception
    reraise(exc_type, exc_value, tb)
  File "/home/tfb/FrameworkBenchmarks/installs/pypy/site-packages/Flask-0.10.1-py2.7.egg/flask/app.py", line 1475, in full_dispatch_request
    rv = self.dispatch_request()
  File "/home/tfb/FrameworkBenchmarks/installs/pypy/site-packages/Flask-0.10.1-py2.7.egg/flask/app.py", line 1461, in dispatch_request
    return self.view_functions[rule.endpoint](**req.view_args)
  File "/home/tfb/FrameworkBenchmarks/flask/app.py", line 152, in raw_updates
    (randomNumber, world['id']))
  File "/home/tfb/FrameworkBenchmarks/installs/pypy/site-packages/SQLAlchemy-0.8.3-py2.7.egg/sqlalchemy/engine/base.py", line 1613, in execute
    connection = self.contextual_connect(close_with_result=True)
  File "/home/tfb/FrameworkBenchmarks/installs/pypy/site-packages/SQLAlchemy-0.8.3-py2.7.egg/sqlalchemy/engine/base.py", line 1661, in contextual_connect
    self.pool.connect(),
  File "/home/tfb/FrameworkBenchmarks/installs/pypy/site-packages/SQLAlchemy-0.8.3-py2.7.egg/sqlalchemy/pool.py", line 272, in connect
    return _ConnectionFairy(self).checkout()
  File "/home/tfb/FrameworkBenchmarks/installs/pypy/site-packages/SQLAlchemy-0.8.3-py2.7.egg/sqlalchemy/pool.py", line 431, in __init__
    rec = self._connection_record = pool._do_get()
  File "/home/tfb/FrameworkBenchmarks/installs/pypy/site-packages/SQLAlchemy-0.8.3-py2.7.egg/sqlalchemy/pool.py", line 780, in _do_get
    (self.size(), self.overflow(), self._timeout))
TimeoutError: QueuePool limit of size 5 overflow 10 reached, connection timed out, timeout 30
ERROR:app:Exception on /raw-updates [GET]
Traceback (most recent call last):
  File "/home/tfb/FrameworkBenchmarks/installs/pypy/site-packages/Flask-0.10.1-py2.7.egg/flask/app.py", line 1817, in wsgi_app
    response = self.full_dispatch_request()
  File "/home/tfb/FrameworkBenchmarks/installs/pypy/site-packages/Flask-0.10.1-py2.7.egg/flask/app.py", line 1477, in full_dispatch_request
    rv = self.handle_user_exception(e)
  File "/home/tfb/FrameworkBenchmarks/installs/pypy/site-packages/Flask-0.10.1-py2.7.egg/flask/app.py", line 1381, in handle_user_exception
    reraise(exc_type, exc_value, tb)
  File "/home/tfb/FrameworkBenchmarks/installs/pypy/site-packages/Flask-0.10.1-py2.7.egg/flask/app.py", line 1475, in full_dispatch_request
    rv = self.dispatch_request()
  File "/home/tfb/FrameworkBenchmarks/installs/pypy/site-packages/Flask-0.10.1-py2.7.egg/flask/app.py", line 1461, in dispatch_request
    return self.view_functions[rule.endpoint](**req.view_args)
  File "/home/tfb/FrameworkBenchmarks/flask/app.py", line 152, in raw_updates
    (randomNumber, world['id']))
  File "/home/tfb/FrameworkBenchmarks/installs/pypy/site-packages/SQLAlchemy-0.8.3-py2.7.egg/sqlalchemy/engine/base.py", line 1613, in execute
    connection = self.contextual_connect(close_with_result=True)
  File "/home/tfb/FrameworkBenchmarks/installs/pypy/site-packages/SQLAlchemy-0.8.3-py2.7.egg/sqlalchemy/engine/base.py", line 1661, in contextual_connect
    self.pool.connect(),
  File "/home/tfb/FrameworkBenchmarks/installs/pypy/site-packages/SQLAlchemy-0.8.3-py2.7.egg/sqlalchemy/pool.py", line 272, in connect
    return _ConnectionFairy(self).checkout()
  File "/home/tfb/FrameworkBenchmarks/installs/pypy/site-packages/SQLAlchemy-0.8.3-py2.7.egg/sqlalchemy/pool.py", line 431, in __init__
    rec = self._connection_record = pool._do_get()
  File "/home/tfb/FrameworkBenchmarks/installs/pypy/site-packages/SQLAlchemy-0.8.3-py2.7.egg/sqlalchemy/pool.py", line 780, in _do_get
    (self.size(), self.overflow(), self._timeout))
TimeoutError: QueuePool limit of size 5 overflow 10 reached, connection timed out, timeout 30
ERROR:app:Exception on /raw-updates [GET]
Traceback (most recent call last):
  File "/home/tfb/FrameworkBenchmarks/installs/pypy/site-packages/Flask-0.10.1-py2.7.egg/flask/app.py", line 1817, in wsgi_app
    response = self.full_dispatch_request()
  File "/home/tfb/FrameworkBenchmarks/installs/pypy/site-packages/Flask-0.10.1-py2.7.egg/flask/app.py", line 1477, in full_dispatch_request
    rv = self.handle_user_exception(e)
  File "/home/tfb/FrameworkBenchmarks/installs/pypy/site-packages/Flask-0.10.1-py2.7.egg/flask/app.py", line 1381, in handle_user_exception
    reraise(exc_type, exc_value, tb)
  File "/home/tfb/FrameworkBenchmarks/installs/pypy/site-packages/Flask-0.10.1-py2.7.egg/flask/app.py", line 1475, in full_dispatch_request
    rv = self.dispatch_request()
  File "/home/tfb/FrameworkBenchmarks/installs/pypy/site-packages/Flask-0.10.1-py2.7.egg/flask/app.py", line 1461, in dispatch_request
    return self.view_functions[rule.endpoint](**req.view_args)
  File "/home/tfb/FrameworkBenchmarks/flask/app.py", line 152, in raw_updates
    (randomNumber, world['id']))
  File "/home/tfb/FrameworkBenchmarks/installs/pypy/site-packages/SQLAlchemy-0.8.3-py2.7.egg/sqlalchemy/engine/base.py", line 1613, in execute
    connection = self.contextual_connect(close_with_result=True)
  File "/home/tfb/FrameworkBenchmarks/installs/pypy/site-packages/SQLAlchemy-0.8.3-py2.7.egg/sqlalchemy/engine/base.py", line 1661, in contextual_connect
    self.pool.connect(),
  File "/home/tfb/FrameworkBenchmarks/installs/pypy/site-packages/SQLAlchemy-0.8.3-py2.7.egg/sqlalchemy/pool.py", line 272, in connect
    return _ConnectionFairy(self).checkout()
  File "/home/tfb/FrameworkBenchmarks/installs/pypy/site-packages/SQLAlchemy-0.8.3-py2.7.egg/sqlalchemy/pool.py", line 431, in __init__
    rec = self._connection_record = pool._do_get()
  File "/home/tfb/FrameworkBenchmarks/installs/pypy/site-packages/SQLAlchemy-0.8.3-py2.7.egg/sqlalchemy/pool.py", line 780, in _do_get
    (self.size(), self.overflow(), self._timeout))
TimeoutError: QueuePool limit of size 5 overflow 10 reached, connection timed out, timeout 30
ERROR:app:Exception on /raw-updates [GET]
Traceback (most recent call last):
  File "/home/tfb/FrameworkBenchmarks/installs/pypy/site-packages/Flask-0.10.1-py2.7.egg/flask/app.py", line 1817, in wsgi_app
    response = self.full_dispatch_request()
  File "/home/tfb/FrameworkBenchmarks/installs/pypy/site-packages/Flask-0.10.1-py2.7.egg/flask/app.py", line 1477, in full_dispatch_request
    rv = self.handle_user_exception(e)
  File "/home/tfb/FrameworkBenchmarks/installs/pypy/site-packages/Flask-0.10.1-py2.7.egg/flask/app.py", line 1381, in handle_user_exception
    reraise(exc_type, exc_value, tb)
  File "/home/tfb/FrameworkBenchmarks/installs/pypy/site-packages/Flask-0.10.1-py2.7.egg/flask/app.py", line 1475, in full_dispatch_request
    rv = self.dispatch_request()
  File "/home/tfb/FrameworkBenchmarks/installs/pypy/site-packages/Flask-0.10.1-py2.7.egg/flask/app.py", line 1461, in dispatch_request
    return self.view_functions[rule.endpoint](**req.view_args)
  File "/home/tfb/FrameworkBenchmarks/flask/app.py", line 152, in raw_updates
    (randomNumber, world['id']))
  File "/home/tfb/FrameworkBenchmarks/installs/pypy/site-packages/SQLAlchemy-0.8.3-py2.7.egg/sqlalchemy/engine/base.py", line 1613, in execute
    connection = self.contextual_connect(close_with_result=True)
  File "/home/tfb/FrameworkBenchmarks/installs/pypy/site-packages/SQLAlchemy-0.8.3-py2.7.egg/sqlalchemy/engine/base.py", line 1661, in contextual_connect
    self.pool.connect(),
  File "/home/tfb/FrameworkBenchmarks/installs/pypy/site-packages/SQLAlchemy-0.8.3-py2.7.egg/sqlalchemy/pool.py", line 272, in connect
    return _ConnectionFairy(self).checkout()
  File "/home/tfb/FrameworkBenchmarks/installs/pypy/site-packages/SQLAlchemy-0.8.3-py2.7.egg/sqlalchemy/pool.py", line 431, in __init__
    rec = self._connection_record = pool._do_get()
  File "/home/tfb/FrameworkBenchmarks/installs/pypy/site-packages/SQLAlchemy-0.8.3-py2.7.egg/sqlalchemy/pool.py", line 780, in _do_get
    (self.size(), self.overflow(), self._timeout))
TimeoutError: QueuePool limit of size 5 overflow 10 reached, connection timed out, timeout 30
ERROR:app:Exception on /raw-updates [GET]
Traceback (most recent call last):
  File "/home/tfb/FrameworkBenchmarks/installs/pypy/site-packages/Flask-0.10.1-py2.7.egg/flask/app.py", line 1817, in wsgi_app
    response = self.full_dispatch_request()
  File "/home/tfb/FrameworkBenchmarks/installs/pypy/site-packages/Flask-0.10.1-py2.7.egg/flask/app.py", line 1477, in full_dispatch_request
    rv = self.handle_user_exception(e)
  File "/home/tfb/FrameworkBenchmarks/installs/pypy/site-packages/Flask-0.10.1-py2.7.egg/flask/app.py", line 1381, in handle_user_exception
    reraise(exc_type, exc_value, tb)
  File "/home/tfb/FrameworkBenchmarks/installs/pypy/site-packages/Flask-0.10.1-py2.7.egg/flask/app.py", line 1475, in full_dispatch_request
    rv = self.dispatch_request()
  File "/home/tfb/FrameworkBenchmarks/installs/pypy/site-packages/Flask-0.10.1-py2.7.egg/flask/app.py", line 1461, in dispatch_request
    return self.view_functions[rule.endpoint](**req.view_args)
  File "/home/tfb/FrameworkBenchmarks/flask/app.py", line 152, in raw_updates
    (randomNumber, world['id']))
  File "/home/tfb/FrameworkBenchmarks/installs/pypy/site-packages/SQLAlchemy-0.8.3-py2.7.egg/sqlalchemy/engine/base.py", line 1613, in execute
    connection = self.contextual_connect(close_with_result=True)
  File "/home/tfb/FrameworkBenchmarks/installs/pypy/site-packages/SQLAlchemy-0.8.3-py2.7.egg/sqlalchemy/engine/base.py", line 1661, in contextual_connect
    self.pool.connect(),
  File "/home/tfb/FrameworkBenchmarks/installs/pypy/site-packages/SQLAlchemy-0.8.3-py2.7.egg/sqlalchemy/pool.py", line 272, in connect
    return _ConnectionFairy(self).checkout()
  File "/home/tfb/FrameworkBenchmarks/installs/pypy/site-packages/SQLAlchemy-0.8.3-py2.7.egg/sqlalchemy/pool.py", line 431, in __init__
    rec = self._connection_record = pool._do_get()
  File "/home/tfb/FrameworkBenchmarks/installs/pypy/site-packages/SQLAlchemy-0.8.3-py2.7.egg/sqlalchemy/pool.py", line 780, in _do_get
    (self.size(), self.overflow(), self._timeout))
TimeoutError: QueuePool limit of size 5 overflow 10 reached, connection timed out, timeout 30
ERROR:tornado.access:500 GET /raw-updates?queries=2 (172.16.98.98) 30037.80ms
ERROR:tornado.access:500 GET /raw-updates?queries=2 (172.16.98.98) 30031.30ms
ERROR:tornado.access:500 GET /raw-updates?queries=2 (172.16.98.98) 30045.84ms
2013-12-06 15:08:48 [3521] [CRITICAL] WORKER TIMEOUT (pid:3538)
2013-12-06 15:08:48 [3521] [CRITICAL] WORKER TIMEOUT (pid:3540)
2013-12-06 15:08:48 [3521] [CRITICAL] WORKER TIMEOUT (pid:3541)
2013-12-06 15:08:48 [3521] [CRITICAL] WORKER TIMEOUT (pid:3542)
2013-12-06 15:08:48 [3521] [CRITICAL] WORKER TIMEOUT (pid:3543)
2013-12-06 15:08:48 [3521] [CRITICAL] WORKER TIMEOUT (pid:3544)
2013-12-06 15:08:48 [3521] [CRITICAL] WORKER TIMEOUT (pid:3538)
2013-12-06 15:08:48 [3521] [CRITICAL] WORKER TIMEOUT (pid:3540)
2013-12-06 15:08:48 [3521] [CRITICAL] WORKER TIMEOUT (pid:3541)
2013-12-06 15:08:48 [3521] [CRITICAL] WORKER TIMEOUT (pid:3542)
2013-12-06 15:08:48 [3521] [CRITICAL] WORKER TIMEOUT (pid:3543)
2013-12-06 15:08:48 [3521] [CRITICAL] WORKER TIMEOUT (pid:3544)
2013-12-06 15:08:48 [3521] [CRITICAL] WORKER TIMEOUT (pid:3541)
2013-12-06 15:08:48 [3521] [CRITICAL] WORKER TIMEOUT (pid:3544)
2013-12-06 15:08:48 [3521] [CRITICAL] WORKER TIMEOUT (pid:3545)
2013-12-06 15:08:48 [3521] [CRITICAL] WORKER TIMEOUT (pid:3546)
2013-12-06 15:08:48 [3521] [CRITICAL] WORKER TIMEOUT (pid:3552)
ERROR:app:Exception on /raw-updates [GET]
Traceback (most recent call last):
  File "/home/tfb/FrameworkBenchmarks/installs/pypy/site-packages/Flask-0.10.1-py2.7.egg/flask/app.py", line 1817, in wsgi_app
    response = self.full_dispatch_request()
  File "/home/tfb/FrameworkBenchmarks/installs/pypy/site-packages/Flask-0.10.1-py2.7.egg/flask/app.py", line 1477, in full_dispatch_request
    rv = self.handle_user_exception(e)
  File "/home/tfb/FrameworkBenchmarks/installs/pypy/site-packages/Flask-0.10.1-py2.7.egg/flask/app.py", line 1381, in handle_user_exception
    reraise(exc_type, exc_value, tb)
  File "/home/tfb/FrameworkBenchmarks/installs/pypy/site-packages/Flask-0.10.1-py2.7.egg/flask/app.py", line 1475, in full_dispatch_request
    rv = self.dispatch_request()
  File "/home/tfb/FrameworkBenchmarks/installs/pypy/site-packages/Flask-0.10.1-py2.7.egg/flask/app.py", line 1461, in dispatch_request
    return self.view_functions[rule.endpoint](**req.view_args)
  File "/home/tfb/FrameworkBenchmarks/flask/app.py", line 152, in raw_updates
    (randomNumber, world['id']))
  File "/home/tfb/FrameworkBenchmarks/installs/pypy/site-packages/SQLAlchemy-0.8.3-py2.7.egg/sqlalchemy/engine/base.py", line 1613, in execute
    connection = self.contextual_connect(close_with_result=True)
  File "/home/tfb/FrameworkBenchmarks/installs/pypy/site-packages/SQLAlchemy-0.8.3-py2.7.egg/sqlalchemy/engine/base.py", line 1661, in contextual_connect
    self.pool.connect(),
  File "/home/tfb/FrameworkBenchmarks/installs/pypy/site-packages/SQLAlchemy-0.8.3-py2.7.egg/sqlalchemy/pool.py", line 272, in connect
    return _ConnectionFairy(self).checkout()
  File "/home/tfb/FrameworkBenchmarks/installs/pypy/site-packages/SQLAlchemy-0.8.3-py2.7.egg/sqlalchemy/pool.py", line 431, in __init__
    rec = self._connection_record = pool._do_get()
  File "/home/tfb/FrameworkBenchmarks/installs/pypy/site-packages/SQLAlchemy-0.8.3-py2.7.egg/sqlalchemy/pool.py", line 780, in _do_get
    (self.size(), self.overflow(), self._timeout))
TimeoutError: QueuePool limit of size 5 overflow 10 reached, connection timed out, timeout 30
ERROR:app:Exception on /raw-updates [GET]
Traceback (most recent call last):
  File "/home/tfb/FrameworkBenchmarks/installs/pypy/site-packages/Flask-0.10.1-py2.7.egg/flask/app.py", line 1817, in wsgi_app
    response = self.full_dispatch_request()
  File "/home/tfb/FrameworkBenchmarks/installs/pypy/site-packages/Flask-0.10.1-py2.7.egg/flask/app.py", line 1477, in full_dispatch_request
    rv = self.handle_user_exception(e)
  File "/home/tfb/FrameworkBenchmarks/installs/pypy/site-packages/Flask-0.10.1-py2.7.egg/flask/app.py", line 1381, in handle_user_exception
    reraise(exc_type, exc_value, tb)
  File "/home/tfb/FrameworkBenchmarks/installs/pypy/site-packages/Flask-0.10.1-py2.7.egg/flask/app.py", line 1475, in full_dispatch_request
    rv = self.dispatch_request()
  File "/home/tfb/FrameworkBenchmarks/installs/pypy/site-packages/Flask-0.10.1-py2.7.egg/flask/app.py", line 1461, in dispatch_request
    return self.view_functions[rule.endpoint](**req.view_args)
  File "/home/tfb/FrameworkBenchmarks/flask/app.py", line 152, in raw_updates
    (randomNumber, world['id']))
  File "/home/tfb/FrameworkBenchmarks/installs/pypy/site-packages/SQLAlchemy-0.8.3-py2.7.egg/sqlalchemy/engine/base.py", line 1613, in execute
    connection = self.contextual_connect(close_with_result=True)
  File "/home/tfb/FrameworkBenchmarks/installs/pypy/site-packages/SQLAlchemy-0.8.3-py2.7.egg/sqlalchemy/engine/base.py", line 1661, in contextual_connect
    self.pool.connect(),
  File "/home/tfb/FrameworkBenchmarks/installs/pypy/site-packages/SQLAlchemy-0.8.3-py2.7.egg/sqlalchemy/pool.py", line 272, in connect
    return _ConnectionFairy(self).checkout()
  File "/home/tfb/FrameworkBenchmarks/installs/pypy/site-packages/SQLAlchemy-0.8.3-py2.7.egg/sqlalchemy/pool.py", line 431, in __init__
    rec = self._connection_record = pool._do_get()
  File "/home/tfb/FrameworkBenchmarks/installs/pypy/site-packages/SQLAlchemy-0.8.3-py2.7.egg/sqlalchemy/pool.py", line 780, in _do_get
    (self.size(), self.overflow(), self._timeout))
TimeoutError: QueuePool limit of size 5 overflow 10 reached, connection timed out, timeout 30
ERROR:app:Exception on /raw-updates [GET]
Traceback (most recent call last):
  File "/home/tfb/FrameworkBenchmarks/installs/pypy/site-packages/Flask-0.10.1-py2.7.egg/flask/app.py", line 1817, in wsgi_app
    response = self.full_dispatch_request()
  File "/home/tfb/FrameworkBenchmarks/installs/pypy/site-packages/Flask-0.10.1-py2.7.egg/flask/app.py", line 1477, in full_dispatch_request
    rv = self.handle_user_exception(e)
  File "/home/tfb/FrameworkBenchmarks/installs/pypy/site-packages/Flask-0.10.1-py2.7.egg/flask/app.py", line 1381, in handle_user_exception
    reraise(exc_type, exc_value, tb)
  File "/home/tfb/FrameworkBenchmarks/installs/pypy/site-packages/Flask-0.10.1-py2.7.egg/flask/app.py", line 1475, in full_dispatch_request
    rv = self.dispatch_request()
  File "/home/tfb/FrameworkBenchmarks/installs/pypy/site-packages/Flask-0.10.1-py2.7.egg/flask/app.py", line 1461, in dispatch_request
    return self.view_functions[rule.endpoint](**req.view_args)
  File "/home/tfb/FrameworkBenchmarks/flask/app.py", line 152, in raw_updates
    (randomNumber, world['id']))
  File "/home/tfb/FrameworkBenchmarks/installs/pypy/site-packages/SQLAlchemy-0.8.3-py2.7.egg/sqlalchemy/engine/base.py", line 1613, in execute
    connection = self.contextual_connect(close_with_result=True)
  File "/home/tfb/FrameworkBenchmarks/installs/pypy/site-packages/SQLAlchemy-0.8.3-py2.7.egg/sqlalchemy/engine/base.py", line 1661, in contextual_connect
    self.pool.connect(),
  File "/home/tfb/FrameworkBenchmarks/installs/pypy/site-packages/SQLAlchemy-0.8.3-py2.7.egg/sqlalchemy/pool.py", line 272, in connect
    return _ConnectionFairy(self).checkout()
  File "/home/tfb/FrameworkBenchmarks/installs/pypy/site-packages/SQLAlchemy-0.8.3-py2.7.egg/sqlalchemy/pool.py", line 431, in __init__
    rec = self._connection_record = pool._do_get()
  File "/home/tfb/FrameworkBenchmarks/installs/pypy/site-packages/SQLAlchemy-0.8.3-py2.7.egg/sqlalchemy/pool.py", line 780, in _do_get
    (self.size(), self.overflow(), self._timeout))
TimeoutError: QueuePool limit of size 5 overflow 10 reached, connection timed out, timeout 30
ERROR:app:Exception on /raw-updates [GET]
Traceback (most recent call last):
  File "/home/tfb/FrameworkBenchmarks/installs/pypy/site-packages/Flask-0.10.1-py2.7.egg/flask/app.py", line 1817, in wsgi_app
    response = self.full_dispatch_request()
  File "/home/tfb/FrameworkBenchmarks/installs/pypy/site-packages/Flask-0.10.1-py2.7.egg/flask/app.py", line 1477, in full_dispatch_request
    rv = self.handle_user_exception(e)
  File "/home/tfb/FrameworkBenchmarks/installs/pypy/site-packages/Flask-0.10.1-py2.7.egg/flask/app.py", line 1381, in handle_user_exception
    reraise(exc_type, exc_value, tb)
  File "/home/tfb/FrameworkBenchmarks/installs/pypy/site-packages/Flask-0.10.1-py2.7.egg/flask/app.py", line 1475, in full_dispatch_request
    rv = self.dispatch_request()
  File "/home/tfb/FrameworkBenchmarks/installs/pypy/site-packages/Flask-0.10.1-py2.7.egg/flask/app.py", line 1461, in dispatch_request
    return self.view_functions[rule.endpoint](**req.view_args)
  File "/home/tfb/FrameworkBenchmarks/flask/app.py", line 152, in raw_updates
    (randomNumber, world['id']))
  File "/home/tfb/FrameworkBenchmarks/installs/pypy/site-packages/SQLAlchemy-0.8.3-py2.7.egg/sqlalchemy/engine/base.py", line 1613, in execute
    connection = self.contextual_connect(close_with_result=True)
  File "/home/tfb/FrameworkBenchmarks/installs/pypy/site-packages/SQLAlchemy-0.8.3-py2.7.egg/sqlalchemy/engine/base.py", line 1661, in contextual_connect
    self.pool.connect(),
  File "/home/tfb/FrameworkBenchmarks/installs/pypy/site-packages/SQLAlchemy-0.8.3-py2.7.egg/sqlalchemy/pool.py", line 272, in connect
    return _ConnectionFairy(self).checkout()
  File "/home/tfb/FrameworkBenchmarks/installs/pypy/site-packages/SQLAlchemy-0.8.3-py2.7.egg/sqlalchemy/pool.py", line 431, in __init__
    rec = self._connection_record = pool._do_get()
  File "/home/tfb/FrameworkBenchmarks/installs/pypy/site-packages/SQLAlchemy-0.8.3-py2.7.egg/sqlalchemy/pool.py", line 780, in _do_get
    (self.size(), self.overflow(), self._timeout))
TimeoutError: QueuePool limit of size 5 overflow 10 reached, connection timed out, timeout 30
ERROR:tornado.access:500 GET /raw-updates?queries=2 (172.16.98.98) 30017.47ms
ERROR:app:Exception on /raw-updates [GET]
Traceback (most recent call last):
  File "/home/tfb/FrameworkBenchmarks/installs/pypy/site-packages/Flask-0.10.1-py2.7.egg/flask/app.py", line 1817, in wsgi_app
    response = self.full_dispatch_request()
  File "/home/tfb/FrameworkBenchmarks/installs/pypy/site-packages/Flask-0.10.1-py2.7.egg/flask/app.py", line 1477, in full_dispatch_request
    rv = self.handle_user_exception(e)
  File "/home/tfb/FrameworkBenchmarks/installs/pypy/site-packages/Flask-0.10.1-py2.7.egg/flask/app.py", line 1381, in handle_user_exception
    reraise(exc_type, exc_value, tb)
  File "/home/tfb/FrameworkBenchmarks/installs/pypy/site-packages/Flask-0.10.1-py2.7.egg/flask/app.py", line 1475, in full_dispatch_request
    rv = self.dispatch_request()
  File "/home/tfb/FrameworkBenchmarks/installs/pypy/site-packages/Flask-0.10.1-py2.7.egg/flask/app.py", line 1461, in dispatch_request
    return self.view_functions[rule.endpoint](**req.view_args)
  File "/home/tfb/FrameworkBenchmarks/flask/app.py", line 152, in raw_updates
    (randomNumber, world['id']))
  File "/home/tfb/FrameworkBenchmarks/installs/pypy/site-packages/SQLAlchemy-0.8.3-py2.7.egg/sqlalchemy/engine/base.py", line 1613, in execute
    connection = self.contextual_connect(close_with_result=True)
  File "/home/tfb/FrameworkBenchmarks/installs/pypy/site-packages/SQLAlchemy-0.8.3-py2.7.egg/sqlalchemy/engine/base.py", line 1661, in contextual_connect
    self.pool.connect(),
  File "/home/tfb/FrameworkBenchmarks/installs/pypy/site-packages/SQLAlchemy-0.8.3-py2.7.egg/sqlalchemy/pool.py", line 272, in connect
    return _ConnectionFairy(self).checkout()
  File "/home/tfb/FrameworkBenchmarks/installs/pypy/site-packages/SQLAlchemy-0.8.3-py2.7.egg/sqlalchemy/pool.py", line 431, in __init__
    rec = self._connection_record = pool._do_get()
  File "/home/tfb/FrameworkBenchmarks/installs/pypy/site-packages/SQLAlchemy-0.8.3-py2.7.egg/sqlalchemy/pool.py", line 780, in _do_get
    (self.size(), self.overflow(), self._timeout))
TimeoutError: QueuePool limit of size 5 overflow 10 reached, connection timed out, timeout 30
ERROR:app:Exception on /raw-updates [GET]
Traceback (most recent call last):
  File "/home/tfb/FrameworkBenchmarks/installs/pypy/site-packages/Flask-0.10.1-py2.7.egg/flask/app.py", line 1817, in wsgi_app
    response = self.full_dispatch_request()
  File "/home/tfb/FrameworkBenchmarks/installs/pypy/site-packages/Flask-0.10.1-py2.7.egg/flask/app.py", line 1477, in full_dispatch_request
    rv = self.handle_user_exception(e)
  File "/home/tfb/FrameworkBenchmarks/installs/pypy/site-packages/Flask-0.10.1-py2.7.egg/flask/app.py", line 1381, in handle_user_exception
    reraise(exc_type, exc_value, tb)
  File "/home/tfb/FrameworkBenchmarks/installs/pypy/site-packages/Flask-0.10.1-py2.7.egg/flask/app.py", line 1475, in full_dispatch_request
    rv = self.dispatch_request()
  File "/home/tfb/FrameworkBenchmarks/installs/pypy/site-packages/Flask-0.10.1-py2.7.egg/flask/app.py", line 1461, in dispatch_request
    return self.view_functions[rule.endpoint](**req.view_args)
  File "/home/tfb/FrameworkBenchmarks/flask/app.py", line 152, in raw_updates
    (randomNumber, world['id']))
  File "/home/tfb/FrameworkBenchmarks/installs/pypy/site-packages/SQLAlchemy-0.8.3-py2.7.egg/sqlalchemy/engine/base.py", line 1613, in execute
    connection = self.contextual_connect(close_with_result=True)
  File "/home/tfb/FrameworkBenchmarks/installs/pypy/site-packages/SQLAlchemy-0.8.3-py2.7.egg/sqlalchemy/engine/base.py", line 1661, in contextual_connect
    self.pool.connect(),
  File "/home/tfb/FrameworkBenchmarks/installs/pypy/site-packages/SQLAlchemy-0.8.3-py2.7.egg/sqlalchemy/pool.py", line 272, in connect
    return _ConnectionFairy(self).checkout()
  File "/home/tfb/FrameworkBenchmarks/installs/pypy/site-packages/SQLAlchemy-0.8.3-py2.7.egg/sqlalchemy/pool.py", line 431, in __init__
    rec = self._connection_record = pool._do_get()
  File "/home/tfb/FrameworkBenchmarks/installs/pypy/site-packages/SQLAlchemy-0.8.3-py2.7.egg/sqlalchemy/pool.py", line 780, in _do_get
    (self.size(), self.overflow(), self._timeout))
TimeoutError: QueuePool limit of size 5 overflow 10 reached, connection timed out, timeout 30
ERROR:app:Exception on /raw-updates [GET]
Traceback (most recent call last):
  File "/home/tfb/FrameworkBenchmarks/installs/pypy/site-packages/Flask-0.10.1-py2.7.egg/flask/app.py", line 1817, in wsgi_app
    response = self.full_dispatch_request()
  File "/home/tfb/FrameworkBenchmarks/installs/pypy/site-packages/Flask-0.10.1-py2.7.egg/flask/app.py", line 1477, in full_dispatch_request
    rv = self.handle_user_exception(e)
  File "/home/tfb/FrameworkBenchmarks/installs/pypy/site-packages/Flask-0.10.1-py2.7.egg/flask/app.py", line 1381, in handle_user_exception
    reraise(exc_type, exc_value, tb)
  File "/home/tfb/FrameworkBenchmarks/installs/pypy/site-packages/Flask-0.10.1-py2.7.egg/flask/app.py", line 1475, in full_dispatch_request
    rv = self.dispatch_request()
  File "/home/tfb/FrameworkBenchmarks/installs/pypy/site-packages/Flask-0.10.1-py2.7.egg/flask/app.py", line 1461, in dispatch_request
    return self.view_functions[rule.endpoint](**req.view_args)
  File "/home/tfb/FrameworkBenchmarks/flask/app.py", line 152, in raw_updates
    (randomNumber, world['id']))
  File "/home/tfb/FrameworkBenchmarks/installs/pypy/site-packages/SQLAlchemy-0.8.3-py2.7.egg/sqlalchemy/engine/base.py", line 1613, in execute
    connection = self.contextual_connect(close_with_result=True)
  File "/home/tfb/FrameworkBenchmarks/installs/pypy/site-packages/SQLAlchemy-0.8.3-py2.7.egg/sqlalchemy/engine/base.py", line 1661, in contextual_connect
    self.pool.connect(),
  File "/home/tfb/FrameworkBenchmarks/installs/pypy/site-packages/SQLAlchemy-0.8.3-py2.7.egg/sqlalchemy/pool.py", line 272, in connect
    return _ConnectionFairy(self).checkout()
  File "/home/tfb/FrameworkBenchmarks/installs/pypy/site-packages/SQLAlchemy-0.8.3-py2.7.egg/sqlalchemy/pool.py", line 431, in __init__
    rec = self._connection_record = pool._do_get()
  File "/home/tfb/FrameworkBenchmarks/installs/pypy/site-packages/SQLAlchemy-0.8.3-py2.7.egg/sqlalchemy/pool.py", line 780, in _do_get
    (self.size(), self.overflow(), self._timeout))
TimeoutError: QueuePool limit of size 5 overflow 10 reached, connection timed out, timeout 30
ERROR:tornado.access:500 GET /raw-updates?queries=2 (172.16.98.98) 30018.97ms
ERROR:tornado.access:500 GET /raw-updates?queries=2 (172.16.98.98) 30022.98ms
ERROR:tornado.access:500 GET /raw-updates?queries=2 (172.16.98.98) 30022.46ms
ERROR:tornado.access:500 GET /raw-updates?queries=2 (172.16.98.98) 30033.16ms
ERROR:app:Exception on /raw-updates [GET]
Traceback (most recent call last):
  File "/home/tfb/FrameworkBenchmarks/installs/pypy/site-packages/Flask-0.10.1-py2.7.egg/flask/app.py", line 1817, in wsgi_app
    response = self.full_dispatch_request()
  File "/home/tfb/FrameworkBenchmarks/installs/pypy/site-packages/Flask-0.10.1-py2.7.egg/flask/app.py", line 1477, in full_dispatch_request
    rv = self.handle_user_exception(e)
  File "/home/tfb/FrameworkBenchmarks/installs/pypy/site-packages/Flask-0.10.1-py2.7.egg/flask/app.py", line 1381, in handle_user_exception
    reraise(exc_type, exc_value, tb)
  File "/home/tfb/FrameworkBenchmarks/installs/pypy/site-packages/Flask-0.10.1-py2.7.egg/flask/app.py", line 1475, in full_dispatch_request
    rv = self.dispatch_request()
  File "/home/tfb/FrameworkBenchmarks/installs/pypy/site-packages/Flask-0.10.1-py2.7.egg/flask/app.py", line 1461, in dispatch_request
    return self.view_functions[rule.endpoint](**req.view_args)
  File "/home/tfb/FrameworkBenchmarks/flask/app.py", line 152, in raw_updates
    (randomNumber, world['id']))
  File "/home/tfb/FrameworkBenchmarks/installs/pypy/site-packages/SQLAlchemy-0.8.3-py2.7.egg/sqlalchemy/engine/base.py", line 1613, in execute
    connection = self.contextual_connect(close_with_result=True)
  File "/home/tfb/FrameworkBenchmarks/installs/pypy/site-packages/SQLAlchemy-0.8.3-py2.7.egg/sqlalchemy/engine/base.py", line 1661, in contextual_connect
    self.pool.connect(),
  File "/home/tfb/FrameworkBenchmarks/installs/pypy/site-packages/SQLAlchemy-0.8.3-py2.7.egg/sqlalchemy/pool.py", line 272, in connect
    return _ConnectionFairy(self).checkout()
  File "/home/tfb/FrameworkBenchmarks/installs/pypy/site-packages/SQLAlchemy-0.8.3-py2.7.egg/sqlalchemy/pool.py", line 431, in __init__
    rec = self._connection_record = pool._do_get()
  File "/home/tfb/FrameworkBenchmarks/installs/pypy/site-packages/SQLAlchemy-0.8.3-py2.7.egg/sqlalchemy/pool.py", line 780, in _do_get
    (self.size(), self.overflow(), self._timeout))
TimeoutError: QueuePool limit of size 5 overflow 10 reached, connection timed out, timeout 30
ERROR:tornado.access:500 GET /raw-updates?queries=2 (172.16.98.98) 30030.83ms
ERROR:tornado.access:500 GET /raw-updates?queries=2 (172.16.98.98) 30028.46ms
ERROR:tornado.access:500 GET /raw-updates?queries=2 (172.16.98.98) 30019.06ms
2013-12-06 15:08:49 [3521] [CRITICAL] WORKER TIMEOUT (pid:3533)
2013-12-06 15:08:49 [3521] [CRITICAL] WORKER TIMEOUT (pid:3534)
2013-12-06 15:08:49 [3521] [CRITICAL] WORKER TIMEOUT (pid:3536)
2013-12-06 15:08:49 [3521] [CRITICAL] WORKER TIMEOUT (pid:3537)
2013-12-06 15:08:49 [3521] [CRITICAL] WORKER TIMEOUT (pid:3533)
2013-12-06 15:08:49 [3521] [CRITICAL] WORKER TIMEOUT (pid:3534)
2013-12-06 15:08:49 [3521] [CRITICAL] WORKER TIMEOUT (pid:3536)
2013-12-06 15:08:49 [3521] [CRITICAL] WORKER TIMEOUT (pid:3537)
ERROR:app:Exception on /raw-updates [GET]
Traceback (most recent call last):
  File "/home/tfb/FrameworkBenchmarks/installs/pypy/site-packages/Flask-0.10.1-py2.7.egg/flask/app.py", line 1817, in wsgi_app
    response = self.full_dispatch_request()
  File "/home/tfb/FrameworkBenchmarks/installs/pypy/site-packages/Flask-0.10.1-py2.7.egg/flask/app.py", line 1477, in full_dispatch_request
    rv = self.handle_user_exception(e)
  File "/home/tfb/FrameworkBenchmarks/installs/pypy/site-packages/Flask-0.10.1-py2.7.egg/flask/app.py", line 1381, in handle_user_exception
    reraise(exc_type, exc_value, tb)
  File "/home/tfb/FrameworkBenchmarks/installs/pypy/site-packages/Flask-0.10.1-py2.7.egg/flask/app.py", line 1475, in full_dispatch_request
    rv = self.dispatch_request()
  File "/home/tfb/FrameworkBenchmarks/installs/pypy/site-packages/Flask-0.10.1-py2.7.egg/flask/app.py", line 1461, in dispatch_request
    return self.view_functions[rule.endpoint](**req.view_args)
  File "/home/tfb/FrameworkBenchmarks/flask/app.py", line 148, in raw_updates
    world = dbraw_engine.execute("SELECT * FROM World WHERE id=%s", (rp(),)).fetchone()
  File "/home/tfb/FrameworkBenchmarks/installs/pypy/site-packages/SQLAlchemy-0.8.3-py2.7.egg/sqlalchemy/engine/base.py", line 1613, in execute
    connection = self.contextual_connect(close_with_result=True)
  File "/home/tfb/FrameworkBenchmarks/installs/pypy/site-packages/SQLAlchemy-0.8.3-py2.7.egg/sqlalchemy/engine/base.py", line 1661, in contextual_connect
    self.pool.connect(),
  File "/home/tfb/FrameworkBenchmarks/installs/pypy/site-packages/SQLAlchemy-0.8.3-py2.7.egg/sqlalchemy/pool.py", line 272, in connect
    return _ConnectionFairy(self).checkout()
  File "/home/tfb/FrameworkBenchmarks/installs/pypy/site-packages/SQLAlchemy-0.8.3-py2.7.egg/sqlalchemy/pool.py", line 431, in __init__
    rec = self._connection_record = pool._do_get()
  File "/home/tfb/FrameworkBenchmarks/installs/pypy/site-packages/SQLAlchemy-0.8.3-py2.7.egg/sqlalchemy/pool.py", line 780, in _do_get
    (self.size(), self.overflow(), self._timeout))
TimeoutError: QueuePool limit of size 5 overflow 10 reached, connection timed out, timeout 30
ERROR:app:Exception on /raw-updates [GET]
Traceback (most recent call last):
  File "/home/tfb/FrameworkBenchmarks/installs/pypy/site-packages/Flask-0.10.1-py2.7.egg/flask/app.py", line 1817, in wsgi_app
    response = self.full_dispatch_request()
  File "/home/tfb/FrameworkBenchmarks/installs/pypy/site-packages/Flask-0.10.1-py2.7.egg/flask/app.py", line 1477, in full_dispatch_request
    rv = self.handle_user_exception(e)
  File "/home/tfb/FrameworkBenchmarks/installs/pypy/site-packages/Flask-0.10.1-py2.7.egg/flask/app.py", line 1381, in handle_user_exception
    reraise(exc_type, exc_value, tb)
  File "/home/tfb/FrameworkBenchmarks/installs/pypy/site-packages/Flask-0.10.1-py2.7.egg/flask/app.py", line 1475, in full_dispatch_request
    rv = self.dispatch_request()
  File "/home/tfb/FrameworkBenchmarks/installs/pypy/site-packages/Flask-0.10.1-py2.7.egg/flask/app.py", line 1461, in dispatch_request
    return self.view_functions[rule.endpoint](**req.view_args)
  File "/home/tfb/FrameworkBenchmarks/flask/app.py", line 148, in raw_updates
    world = dbraw_engine.execute("SELECT * FROM World WHERE id=%s", (rp(),)).fetchone()
  File "/home/tfb/FrameworkBenchmarks/installs/pypy/site-packages/SQLAlchemy-0.8.3-py2.7.egg/sqlalchemy/engine/base.py", line 1613, in execute
    connection = self.contextual_connect(close_with_result=True)
  File "/home/tfb/FrameworkBenchmarks/installs/pypy/site-packages/SQLAlchemy-0.8.3-py2.7.egg/sqlalchemy/engine/base.py", line 1661, in contextual_connect
    self.pool.connect(),
  File "/home/tfb/FrameworkBenchmarks/installs/pypy/site-packages/SQLAlchemy-0.8.3-py2.7.egg/sqlalchemy/pool.py", line 272, in connect
    return _ConnectionFairy(self).checkout()
  File "/home/tfb/FrameworkBenchmarks/installs/pypy/site-packages/SQLAlchemy-0.8.3-py2.7.egg/sqlalchemy/pool.py", line 431, in __init__
    rec = self._connection_record = pool._do_get()
  File "/home/tfb/FrameworkBenchmarks/installs/pypy/site-packages/SQLAlchemy-0.8.3-py2.7.egg/sqlalchemy/pool.py", line 780, in _do_get
    (self.size(), self.overflow(), self._timeout))
TimeoutError: QueuePool limit of size 5 overflow 10 reached, connection timed out, timeout 30
ERROR:app:Exception on /raw-updates [GET]
Traceback (most recent call last):
  File "/home/tfb/FrameworkBenchmarks/installs/pypy/site-packages/Flask-0.10.1-py2.7.egg/flask/app.py", line 1817, in wsgi_app
    response = self.full_dispatch_request()
  File "/home/tfb/FrameworkBenchmarks/installs/pypy/site-packages/Flask-0.10.1-py2.7.egg/flask/app.py", line 1477, in full_dispatch_request
    rv = self.handle_user_exception(e)
  File "/home/tfb/FrameworkBenchmarks/installs/pypy/site-packages/Flask-0.10.1-py2.7.egg/flask/app.py", line 1381, in handle_user_exception
    reraise(exc_type, exc_value, tb)
  File "/home/tfb/FrameworkBenchmarks/installs/pypy/site-packages/Flask-0.10.1-py2.7.egg/flask/app.py", line 1475, in full_dispatch_request
    rv = self.dispatch_request()
  File "/home/tfb/FrameworkBenchmarks/installs/pypy/site-packages/Flask-0.10.1-py2.7.egg/flask/app.py", line 1461, in dispatch_request
    return self.view_functions[rule.endpoint](**req.view_args)
  File "/home/tfb/FrameworkBenchmarks/flask/app.py", line 148, in raw_updates
    world = dbraw_engine.execute("SELECT * FROM World WHERE id=%s", (rp(),)).fetchone()
  File "/home/tfb/FrameworkBenchmarks/installs/pypy/site-packages/SQLAlchemy-0.8.3-py2.7.egg/sqlalchemy/engine/base.py", line 1613, in execute
    connection = self.contextual_connect(close_with_result=True)
  File "/home/tfb/FrameworkBenchmarks/installs/pypy/site-packages/SQLAlchemy-0.8.3-py2.7.egg/sqlalchemy/engine/base.py", line 1661, in contextual_connect
    self.pool.connect(),
  File "/home/tfb/FrameworkBenchmarks/installs/pypy/site-packages/SQLAlchemy-0.8.3-py2.7.egg/sqlalchemy/pool.py", line 272, in connect
    return _ConnectionFairy(self).checkout()
  File "/home/tfb/FrameworkBenchmarks/installs/pypy/site-packages/SQLAlchemy-0.8.3-py2.7.egg/sqlalchemy/pool.py", line 431, in __init__
    rec = self._connection_record = pool._do_get()
  File "/home/tfb/FrameworkBenchmarks/installs/pypy/site-packages/SQLAlchemy-0.8.3-py2.7.egg/sqlalchemy/pool.py", line 780, in _do_get
    (self.size(), self.overflow(), self._timeout))
TimeoutError: QueuePool limit of size 5 overflow 10 reached, connection timed out, timeout 30
ERROR:app:Exception on /raw-updates [GET]
Traceback (most recent call last):
  File "/home/tfb/FrameworkBenchmarks/installs/pypy/site-packages/Flask-0.10.1-py2.7.egg/flask/app.py", line 1817, in wsgi_app
    response = self.full_dispatch_request()
  File "/home/tfb/FrameworkBenchmarks/installs/pypy/site-packages/Flask-0.10.1-py2.7.egg/flask/app.py", line 1477, in full_dispatch_request
    rv = self.handle_user_exception(e)
  File "/home/tfb/FrameworkBenchmarks/installs/pypy/site-packages/Flask-0.10.1-py2.7.egg/flask/app.py", line 1381, in handle_user_exception
    reraise(exc_type, exc_value, tb)
  File "/home/tfb/FrameworkBenchmarks/installs/pypy/site-packages/Flask-0.10.1-py2.7.egg/flask/app.py", line 1475, in full_dispatch_request
    rv = self.dispatch_request()
  File "/home/tfb/FrameworkBenchmarks/installs/pypy/site-packages/Flask-0.10.1-py2.7.egg/flask/app.py", line 1461, in dispatch_request
    return self.view_functions[rule.endpoint](**req.view_args)
  File "/home/tfb/FrameworkBenchmarks/flask/app.py", line 148, in raw_updates
    world = dbraw_engine.execute("SELECT * FROM World WHERE id=%s", (rp(),)).fetchone()
  File "/home/tfb/FrameworkBenchmarks/installs/pypy/site-packages/SQLAlchemy-0.8.3-py2.7.egg/sqlalchemy/engine/base.py", line 1613, in execute
    connection = self.contextual_connect(close_with_result=True)
  File "/home/tfb/FrameworkBenchmarks/installs/pypy/site-packages/SQLAlchemy-0.8.3-py2.7.egg/sqlalchemy/engine/base.py", line 1661, in contextual_connect
    self.pool.connect(),
  File "/home/tfb/FrameworkBenchmarks/installs/pypy/site-packages/SQLAlchemy-0.8.3-py2.7.egg/sqlalchemy/pool.py", line 272, in connect
    return _ConnectionFairy(self).checkout()
  File "/home/tfb/FrameworkBenchmarks/installs/pypy/site-packages/SQLAlchemy-0.8.3-py2.7.egg/sqlalchemy/pool.py", line 431, in __init__
    rec = self._connection_record = pool._do_get()
  File "/home/tfb/FrameworkBenchmarks/installs/pypy/site-packages/SQLAlchemy-0.8.3-py2.7.egg/sqlalchemy/pool.py", line 780, in _do_get
    (self.size(), self.overflow(), self._timeout))
TimeoutError: QueuePool limit of size 5 overflow 10 reached, connection timed out, timeout 30
ERROR:tornado.access:500 GET /raw-updates?queries=2 (172.16.98.98) 30001.98ms
ERROR:tornado.access:500 GET /raw-updates?queries=2 (172.16.98.98) 30001.84ms
ERROR:tornado.access:500 GET /raw-updates?queries=2 (172.16.98.98) 30002.51ms
ERROR:tornado.access:500 GET /raw-updates?queries=2 (172.16.98.98) 30002.50ms
ERROR:app:Exception on /raw-updates [GET]
Traceback (most recent call last):
  File "/home/tfb/FrameworkBenchmarks/installs/pypy/site-packages/Flask-0.10.1-py2.7.egg/flask/app.py", line 1817, in wsgi_app
    response = self.full_dispatch_request()
  File "/home/tfb/FrameworkBenchmarks/installs/pypy/site-packages/Flask-0.10.1-py2.7.egg/flask/app.py", line 1477, in full_dispatch_request
    rv = self.handle_user_exception(e)
  File "/home/tfb/FrameworkBenchmarks/installs/pypy/site-packages/Flask-0.10.1-py2.7.egg/flask/app.py", line 1381, in handle_user_exception
    reraise(exc_type, exc_value, tb)
  File "/home/tfb/FrameworkBenchmarks/installs/pypy/site-packages/Flask-0.10.1-py2.7.egg/flask/app.py", line 1475, in full_dispatch_request
    rv = self.dispatch_request()
  File "/home/tfb/FrameworkBenchmarks/installs/pypy/site-packages/Flask-0.10.1-py2.7.egg/flask/app.py", line 1461, in dispatch_request
    return self.view_functions[rule.endpoint](**req.view_args)
  File "/home/tfb/FrameworkBenchmarks/flask/app.py", line 148, in raw_updates
    world = dbraw_engine.execute("SELECT * FROM World WHERE id=%s", (rp(),)).fetchone()
  File "/home/tfb/FrameworkBenchmarks/installs/pypy/site-packages/SQLAlchemy-0.8.3-py2.7.egg/sqlalchemy/engine/base.py", line 1613, in execute
    connection = self.contextual_connect(close_with_result=True)
  File "/home/tfb/FrameworkBenchmarks/installs/pypy/site-packages/SQLAlchemy-0.8.3-py2.7.egg/sqlalchemy/engine/base.py", line 1661, in contextual_connect
    self.pool.connect(),
  File "/home/tfb/FrameworkBenchmarks/installs/pypy/site-packages/SQLAlchemy-0.8.3-py2.7.egg/sqlalchemy/pool.py", line 272, in connect
    return _ConnectionFairy(self).checkout()
  File "/home/tfb/FrameworkBenchmarks/installs/pypy/site-packages/SQLAlchemy-0.8.3-py2.7.egg/sqlalchemy/pool.py", line 431, in __init__
    rec = self._connection_record = pool._do_get()
  File "/home/tfb/FrameworkBenchmarks/installs/pypy/site-packages/SQLAlchemy-0.8.3-py2.7.egg/sqlalchemy/pool.py", line 780, in _do_get
    (self.size(), self.overflow(), self._timeout))
TimeoutError: QueuePool limit of size 5 overflow 10 reached, connection timed out, timeout 30
ERROR:tornado.access:500 GET /raw-updates?queries=2 (172.16.98.98) 30003.54ms
2013-12-06 15:09:08 [3521] [CRITICAL] WORKER TIMEOUT (pid:3535)
2013-12-06 15:09:08 [3521] [CRITICAL] WORKER TIMEOUT (pid:3539)
2013-12-06 15:09:08 [3521] [CRITICAL] WORKER TIMEOUT (pid:3547)
2013-12-06 15:09:08 [3521] [CRITICAL] WORKER TIMEOUT (pid:3548)
2013-12-06 15:09:08 [3521] [CRITICAL] WORKER TIMEOUT (pid:3549)
2013-12-06 15:09:08 [3521] [CRITICAL] WORKER TIMEOUT (pid:3551)
2013-12-06 15:09:08 [3521] [CRITICAL] WORKER TIMEOUT (pid:3535)
2013-12-06 15:09:08 [3521] [CRITICAL] WORKER TIMEOUT (pid:3539)
2013-12-06 15:09:08 [3521] [CRITICAL] WORKER TIMEOUT (pid:3547)
2013-12-06 15:09:08 [3521] [CRITICAL] WORKER TIMEOUT (pid:3548)
2013-12-06 15:09:08 [3521] [CRITICAL] WORKER TIMEOUT (pid:3549)
2013-12-06 15:09:08 [3521] [CRITICAL] WORKER TIMEOUT (pid:3551)
2013-12-06 15:09:08 [3521] [CRITICAL] WORKER TIMEOUT (pid:3535)
2013-12-06 15:09:08 [3521] [CRITICAL] WORKER TIMEOUT (pid:3539)
2013-12-06 15:09:08 [3521] [CRITICAL] WORKER TIMEOUT (pid:3547)
2013-12-06 15:09:08 [3521] [CRITICAL] WORKER TIMEOUT (pid:3549)
2013-12-06 15:09:08 [3521] [CRITICAL] WORKER TIMEOUT (pid:3551)
ERROR:app:Exception on /raw-updates [GET]
Traceback (most recent call last):
  File "/home/tfb/FrameworkBenchmarks/installs/pypy/site-packages/Flask-0.10.1-py2.7.egg/flask/app.py", line 1817, in wsgi_app
    response = self.full_dispatch_request()
  File "/home/tfb/FrameworkBenchmarks/installs/pypy/site-packages/Flask-0.10.1-py2.7.egg/flask/app.py", line 1477, in full_dispatch_request
    rv = self.handle_user_exception(e)
  File "/home/tfb/FrameworkBenchmarks/installs/pypy/site-packages/Flask-0.10.1-py2.7.egg/flask/app.py", line 1381, in handle_user_exception
    reraise(exc_type, exc_value, tb)
  File "/home/tfb/FrameworkBenchmarks/installs/pypy/site-packages/Flask-0.10.1-py2.7.egg/flask/app.py", line 1475, in full_dispatch_request
    rv = self.dispatch_request()
  File "/home/tfb/FrameworkBenchmarks/installs/pypy/site-packages/Flask-0.10.1-py2.7.egg/flask/app.py", line 1461, in dispatch_request
    return self.view_functions[rule.endpoint](**req.view_args)
  File "/home/tfb/FrameworkBenchmarks/flask/app.py", line 148, in raw_updates
    world = dbraw_engine.execute("SELECT * FROM World WHERE id=%s", (rp(),)).fetchone()
  File "/home/tfb/FrameworkBenchmarks/installs/pypy/site-packages/SQLAlchemy-0.8.3-py2.7.egg/sqlalchemy/engine/base.py", line 1613, in execute
    connection = self.contextual_connect(close_with_result=True)
  File "/home/tfb/FrameworkBenchmarks/installs/pypy/site-packages/SQLAlchemy-0.8.3-py2.7.egg/sqlalchemy/engine/base.py", line 1661, in contextual_connect
    self.pool.connect(),
  File "/home/tfb/FrameworkBenchmarks/installs/pypy/site-packages/SQLAlchemy-0.8.3-py2.7.egg/sqlalchemy/pool.py", line 272, in connect
    return _ConnectionFairy(self).checkout()
  File "/home/tfb/FrameworkBenchmarks/installs/pypy/site-packages/SQLAlchemy-0.8.3-py2.7.egg/sqlalchemy/pool.py", line 431, in __init__
    rec = self._connection_record = pool._do_get()
  File "/home/tfb/FrameworkBenchmarks/installs/pypy/site-packages/SQLAlchemy-0.8.3-py2.7.egg/sqlalchemy/pool.py", line 780, in _do_get
    (self.size(), self.overflow(), self._timeout))
TimeoutError: QueuePool limit of size 5 overflow 10 reached, connection timed out, timeout 30
ERROR:tornado.access:500 GET /raw-updates?queries=1 (172.16.98.98) 30001.72ms
2013-12-06 15:09:10 [3521] [CRITICAL] WORKER TIMEOUT (pid:3550)
2013-12-06 15:09:10 [3521] [CRITICAL] WORKER TIMEOUT (pid:3550)
2013-12-06 15:09:18 [3521] [CRITICAL] WORKER TIMEOUT (pid:3592)
2013-12-06 15:09:18 [3521] [CRITICAL] WORKER TIMEOUT (pid:3592)
ERROR:app:Exception on /raw-updates [GET]
Traceback (most recent call last):
  File "/home/tfb/FrameworkBenchmarks/installs/pypy/site-packages/Flask-0.10.1-py2.7.egg/flask/app.py", line 1817, in wsgi_app
    response = self.full_dispatch_request()
  File "/home/tfb/FrameworkBenchmarks/installs/pypy/site-packages/Flask-0.10.1-py2.7.egg/flask/app.py", line 1477, in full_dispatch_request
    rv = self.handle_user_exception(e)
  File "/home/tfb/FrameworkBenchmarks/installs/pypy/site-packages/Flask-0.10.1-py2.7.egg/flask/app.py", line 1381, in handle_user_exception
    reraise(exc_type, exc_value, tb)
  File "/home/tfb/FrameworkBenchmarks/installs/pypy/site-packages/Flask-0.10.1-py2.7.egg/flask/app.py", line 1475, in full_dispatch_request
    rv = self.dispatch_request()
  File "/home/tfb/FrameworkBenchmarks/installs/pypy/site-packages/Flask-0.10.1-py2.7.egg/flask/app.py", line 1461, in dispatch_request
    return self.view_functions[rule.endpoint](**req.view_args)
  File "/home/tfb/FrameworkBenchmarks/flask/app.py", line 148, in raw_updates
    world = dbraw_engine.execute("SELECT * FROM World WHERE id=%s", (rp(),)).fetchone()
  File "/home/tfb/FrameworkBenchmarks/installs/pypy/site-packages/SQLAlchemy-0.8.3-py2.7.egg/sqlalchemy/engine/base.py", line 1613, in execute
    connection = self.contextual_connect(close_with_result=True)
  File "/home/tfb/FrameworkBenchmarks/installs/pypy/site-packages/SQLAlchemy-0.8.3-py2.7.egg/sqlalchemy/engine/base.py", line 1661, in contextual_connect
    self.pool.connect(),
  File "/home/tfb/FrameworkBenchmarks/installs/pypy/site-packages/SQLAlchemy-0.8.3-py2.7.egg/sqlalchemy/pool.py", line 272, in connect
    return _ConnectionFairy(self).checkout()
  File "/home/tfb/FrameworkBenchmarks/installs/pypy/site-packages/SQLAlchemy-0.8.3-py2.7.egg/sqlalchemy/pool.py", line 431, in __init__
    rec = self._connection_record = pool._do_get()
  File "/home/tfb/FrameworkBenchmarks/installs/pypy/site-packages/SQLAlchemy-0.8.3-py2.7.egg/sqlalchemy/pool.py", line 780, in _do_get
    (self.size(), self.overflow(), self._timeout))
TimeoutError: QueuePool limit of size 5 overflow 10 reached, connection timed out, timeout 30
ERROR:tornado.access:500 GET /raw-updates?queries=2 (172.16.98.98) 30001.72ms
2013-12-06 15:09:19 [3521] [CRITICAL] WORKER TIMEOUT (pid:3553)
2013-12-06 15:09:19 [3521] [CRITICAL] WORKER TIMEOUT (pid:3553)
2013-12-06 15:09:27 [3521] [CRITICAL] WORKER TIMEOUT (pid:3599)
2013-12-06 15:09:27 [3521] [CRITICAL] WORKER TIMEOUT (pid:3600)
2013-12-06 15:09:27 [3521] [CRITICAL] WORKER TIMEOUT (pid:3601)
2013-12-06 15:09:27 [3521] [CRITICAL] WORKER TIMEOUT (pid:3603)
2013-12-06 15:09:27 [3521] [CRITICAL] WORKER TIMEOUT (pid:3604)
2013-12-06 15:09:27 [3521] [CRITICAL] WORKER TIMEOUT (pid:3605)
2013-12-06 15:09:27 [3521] [CRITICAL] WORKER TIMEOUT (pid:3599)
2013-12-06 15:09:27 [3521] [CRITICAL] WORKER TIMEOUT (pid:3600)
2013-12-06 15:09:27 [3521] [CRITICAL] WORKER TIMEOUT (pid:3601)
2013-12-06 15:09:27 [3521] [CRITICAL] WORKER TIMEOUT (pid:3603)
2013-12-06 15:09:27 [3521] [CRITICAL] WORKER TIMEOUT (pid:3604)
2013-12-06 15:09:27 [3521] [CRITICAL] WORKER TIMEOUT (pid:3605)
ERROR:app:Exception on /raw-updates [GET]
Traceback (most recent call last):
  File "/home/tfb/FrameworkBenchmarks/installs/pypy/site-packages/Flask-0.10.1-py2.7.egg/flask/app.py", line 1817, in wsgi_app
    response = self.full_dispatch_request()
  File "/home/tfb/FrameworkBenchmarks/installs/pypy/site-packages/Flask-0.10.1-py2.7.egg/flask/app.py", line 1477, in full_dispatch_request
    rv = self.handle_user_exception(e)
  File "/home/tfb/FrameworkBenchmarks/installs/pypy/site-packages/Flask-0.10.1-py2.7.egg/flask/app.py", line 1381, in handle_user_exception
    reraise(exc_type, exc_value, tb)
  File "/home/tfb/FrameworkBenchmarks/installs/pypy/site-packages/Flask-0.10.1-py2.7.egg/flask/app.py", line 1475, in full_dispatch_request
    rv = self.dispatch_request()
  File "/home/tfb/FrameworkBenchmarks/installs/pypy/site-packages/Flask-0.10.1-py2.7.egg/flask/app.py", line 1461, in dispatch_request
    return self.view_functions[rule.endpoint](**req.view_args)
  File "/home/tfb/FrameworkBenchmarks/flask/app.py", line 148, in raw_updates
    world = dbraw_engine.execute("SELECT * FROM World WHERE id=%s", (rp(),)).fetchone()
  File "/home/tfb/FrameworkBenchmarks/installs/pypy/site-packages/SQLAlchemy-0.8.3-py2.7.egg/sqlalchemy/engine/base.py", line 1613, in execute
    connection = self.contextual_connect(close_with_result=True)
  File "/home/tfb/FrameworkBenchmarks/installs/pypy/site-packages/SQLAlchemy-0.8.3-py2.7.egg/sqlalchemy/engine/base.py", line 1661, in contextual_connect
    self.pool.connect(),
  File "/home/tfb/FrameworkBenchmarks/installs/pypy/site-packages/SQLAlchemy-0.8.3-py2.7.egg/sqlalchemy/pool.py", line 272, in connect
    return _ConnectionFairy(self).checkout()
  File "/home/tfb/FrameworkBenchmarks/installs/pypy/site-packages/SQLAlchemy-0.8.3-py2.7.egg/sqlalchemy/pool.py", line 431, in __init__
    rec = self._connection_record = pool._do_get()
  File "/home/tfb/FrameworkBenchmarks/installs/pypy/site-packages/SQLAlchemy-0.8.3-py2.7.egg/sqlalchemy/pool.py", line 780, in _do_get
    (self.size(), self.overflow(), self._timeout))
TimeoutError: QueuePool limit of size 5 overflow 10 reached, connection timed out, timeout 30
ERROR:app:Exception on /raw-updates [GET]
Traceback (most recent call last):
  File "/home/tfb/FrameworkBenchmarks/installs/pypy/site-packages/Flask-0.10.1-py2.7.egg/flask/app.py", line 1817, in wsgi_app
    response = self.full_dispatch_request()
  File "/home/tfb/FrameworkBenchmarks/installs/pypy/site-packages/Flask-0.10.1-py2.7.egg/flask/app.py", line 1477, in full_dispatch_request
    rv = self.handle_user_exception(e)
  File "/home/tfb/FrameworkBenchmarks/installs/pypy/site-packages/Flask-0.10.1-py2.7.egg/flask/app.py", line 1381, in handle_user_exception
    reraise(exc_type, exc_value, tb)
  File "/home/tfb/FrameworkBenchmarks/installs/pypy/site-packages/Flask-0.10.1-py2.7.egg/flask/app.py", line 1475, in full_dispatch_request
    rv = self.dispatch_request()
  File "/home/tfb/FrameworkBenchmarks/installs/pypy/site-packages/Flask-0.10.1-py2.7.egg/flask/app.py", line 1461, in dispatch_request
    return self.view_functions[rule.endpoint](**req.view_args)
  File "/home/tfb/FrameworkBenchmarks/flask/app.py", line 148, in raw_updates
    world = dbraw_engine.execute("SELECT * FROM World WHERE id=%s", (rp(),)).fetchone()
  File "/home/tfb/FrameworkBenchmarks/installs/pypy/site-packages/SQLAlchemy-0.8.3-py2.7.egg/sqlalchemy/engine/base.py", line 1613, in execute
    connection = self.contextual_connect(close_with_result=True)
  File "/home/tfb/FrameworkBenchmarks/installs/pypy/site-packages/SQLAlchemy-0.8.3-py2.7.egg/sqlalchemy/engine/base.py", line 1661, in contextual_connect
    self.pool.connect(),
  File "/home/tfb/FrameworkBenchmarks/installs/pypy/site-packages/SQLAlchemy-0.8.3-py2.7.egg/sqlalchemy/pool.py", line 272, in connect
    return _ConnectionFairy(self).checkout()
  File "/home/tfb/FrameworkBenchmarks/installs/pypy/site-packages/SQLAlchemy-0.8.3-py2.7.egg/sqlalchemy/pool.py", line 431, in __init__
    rec = self._connection_record = pool._do_get()
  File "/home/tfb/FrameworkBenchmarks/installs/pypy/site-packages/SQLAlchemy-0.8.3-py2.7.egg/sqlalchemy/pool.py", line 780, in _do_get
    (self.size(), self.overflow(), self._timeout))
TimeoutError: QueuePool limit of size 5 overflow 10 reached, connection timed out, timeout 30
ERROR:tornado.access:500 GET /raw-updates?queries=5 (172.16.98.98) 30002.50ms
ERROR:tornado.access:500 GET /raw-updates?queries=5 (172.16.98.98) 30002.62ms
ERROR:app:Exception on /raw-updates [GET]
Traceback (most recent call last):
  File "/home/tfb/FrameworkBenchmarks/installs/pypy/site-packages/Flask-0.10.1-py2.7.egg/flask/app.py", line 1817, in wsgi_app
    response = self.full_dispatch_request()
  File "/home/tfb/FrameworkBenchmarks/installs/pypy/site-packages/Flask-0.10.1-py2.7.egg/flask/app.py", line 1477, in full_dispatch_request
    rv = self.handle_user_exception(e)
  File "/home/tfb/FrameworkBenchmarks/installs/pypy/site-packages/Flask-0.10.1-py2.7.egg/flask/app.py", line 1381, in handle_user_exception
    reraise(exc_type, exc_value, tb)
  File "/home/tfb/FrameworkBenchmarks/installs/pypy/site-packages/Flask-0.10.1-py2.7.egg/flask/app.py", line 1475, in full_dispatch_request
    rv = self.dispatch_request()
  File "/home/tfb/FrameworkBenchmarks/installs/pypy/site-packages/Flask-0.10.1-py2.7.egg/flask/app.py", line 1461, in dispatch_request
    return self.view_functions[rule.endpoint](**req.view_args)
  File "/home/tfb/FrameworkBenchmarks/flask/app.py", line 148, in raw_updates
    world = dbraw_engine.execute("SELECT * FROM World WHERE id=%s", (rp(),)).fetchone()
  File "/home/tfb/FrameworkBenchmarks/installs/pypy/site-packages/SQLAlchemy-0.8.3-py2.7.egg/sqlalchemy/engine/base.py", line 1613, in execute
    connection = self.contextual_connect(close_with_result=True)
  File "/home/tfb/FrameworkBenchmarks/installs/pypy/site-packages/SQLAlchemy-0.8.3-py2.7.egg/sqlalchemy/engine/base.py", line 1661, in contextual_connect
    self.pool.connect(),
  File "/home/tfb/FrameworkBenchmarks/installs/pypy/site-packages/SQLAlchemy-0.8.3-py2.7.egg/sqlalchemy/pool.py", line 272, in connect
    return _ConnectionFairy(self).checkout()
  File "/home/tfb/FrameworkBenchmarks/installs/pypy/site-packages/SQLAlchemy-0.8.3-py2.7.egg/sqlalchemy/pool.py", line 431, in __init__
    rec = self._connection_record = pool._do_get()
  File "/home/tfb/FrameworkBenchmarks/installs/pypy/site-packages/SQLAlchemy-0.8.3-py2.7.egg/sqlalchemy/pool.py", line 780, in _do_get
    (self.size(), self.overflow(), self._timeout))
TimeoutError: QueuePool limit of size 5 overflow 10 reached, connection timed out, timeout 30
ERROR:tornado.access:500 GET /raw-updates?queries=5 (172.16.98.98) 30003.39ms
ERROR:app:Exception on /raw-updates [GET]
Traceback (most recent call last):
  File "/home/tfb/FrameworkBenchmarks/installs/pypy/site-packages/Flask-0.10.1-py2.7.egg/flask/app.py", line 1817, in wsgi_app
    response = self.full_dispatch_request()
  File "/home/tfb/FrameworkBenchmarks/installs/pypy/site-packages/Flask-0.10.1-py2.7.egg/flask/app.py", line 1477, in full_dispatch_request
    rv = self.handle_user_exception(e)
  File "/home/tfb/FrameworkBenchmarks/installs/pypy/site-packages/Flask-0.10.1-py2.7.egg/flask/app.py", line 1381, in handle_user_exception
    reraise(exc_type, exc_value, tb)
  File "/home/tfb/FrameworkBenchmarks/installs/pypy/site-packages/Flask-0.10.1-py2.7.egg/flask/app.py", line 1475, in full_dispatch_request
    rv = self.dispatch_request()
  File "/home/tfb/FrameworkBenchmarks/installs/pypy/site-packages/Flask-0.10.1-py2.7.egg/flask/app.py", line 1461, in dispatch_request
    return self.view_functions[rule.endpoint](**req.view_args)
  File "/home/tfb/FrameworkBenchmarks/flask/app.py", line 152, in raw_updates
    (randomNumber, world['id']))
  File "/home/tfb/FrameworkBenchmarks/installs/pypy/site-packages/SQLAlchemy-0.8.3-py2.7.egg/sqlalchemy/engine/base.py", line 1613, in execute
    connection = self.contextual_connect(close_with_result=True)
  File "/home/tfb/FrameworkBenchmarks/installs/pypy/site-packages/SQLAlchemy-0.8.3-py2.7.egg/sqlalchemy/engine/base.py", line 1661, in contextual_connect
    self.pool.connect(),
  File "/home/tfb/FrameworkBenchmarks/installs/pypy/site-packages/SQLAlchemy-0.8.3-py2.7.egg/sqlalchemy/pool.py", line 272, in connect
    return _ConnectionFairy(self).checkout()
  File "/home/tfb/FrameworkBenchmarks/installs/pypy/site-packages/SQLAlchemy-0.8.3-py2.7.egg/sqlalchemy/pool.py", line 431, in __init__
    rec = self._connection_record = pool._do_get()
  File "/home/tfb/FrameworkBenchmarks/installs/pypy/site-packages/SQLAlchemy-0.8.3-py2.7.egg/sqlalchemy/pool.py", line 780, in _do_get
    (self.size(), self.overflow(), self._timeout))
TimeoutError: QueuePool limit of size 5 overflow 10 reached, connection timed out, timeout 30
ERROR:app:Exception on /raw-updates [GET]
Traceback (most recent call last):
  File "/home/tfb/FrameworkBenchmarks/installs/pypy/site-packages/Flask-0.10.1-py2.7.egg/flask/app.py", line 1817, in wsgi_app
    response = self.full_dispatch_request()
  File "/home/tfb/FrameworkBenchmarks/installs/pypy/site-packages/Flask-0.10.1-py2.7.egg/flask/app.py", line 1477, in full_dispatch_request
    rv = self.handle_user_exception(e)
  File "/home/tfb/FrameworkBenchmarks/installs/pypy/site-packages/Flask-0.10.1-py2.7.egg/flask/app.py", line 1381, in handle_user_exception
    reraise(exc_type, exc_value, tb)
  File "/home/tfb/FrameworkBenchmarks/installs/pypy/site-packages/Flask-0.10.1-py2.7.egg/flask/app.py", line 1475, in full_dispatch_request
    rv = self.dispatch_request()
  File "/home/tfb/FrameworkBenchmarks/installs/pypy/site-packages/Flask-0.10.1-py2.7.egg/flask/app.py", line 1461, in dispatch_request
    return self.view_functions[rule.endpoint](**req.view_args)
  File "/home/tfb/FrameworkBenchmarks/flask/app.py", line 152, in raw_updates
    (randomNumber, world['id']))
  File "/home/tfb/FrameworkBenchmarks/installs/pypy/site-packages/SQLAlchemy-0.8.3-py2.7.egg/sqlalchemy/engine/base.py", line 1613, in execute
    connection = self.contextual_connect(close_with_result=True)
  File "/home/tfb/FrameworkBenchmarks/installs/pypy/site-packages/SQLAlchemy-0.8.3-py2.7.egg/sqlalchemy/engine/base.py", line 1661, in contextual_connect
    self.pool.connect(),
  File "/home/tfb/FrameworkBenchmarks/installs/pypy/site-packages/SQLAlchemy-0.8.3-py2.7.egg/sqlalchemy/pool.py", line 272, in connect
    return _ConnectionFairy(self).checkout()
  File "/home/tfb/FrameworkBenchmarks/installs/pypy/site-packages/SQLAlchemy-0.8.3-py2.7.egg/sqlalchemy/pool.py", line 431, in __init__
    rec = self._connection_record = pool._do_get()
  File "/home/tfb/FrameworkBenchmarks/installs/pypy/site-packages/SQLAlchemy-0.8.3-py2.7.egg/sqlalchemy/pool.py", line 780, in _do_get
    (self.size(), self.overflow(), self._timeout))
TimeoutError: QueuePool limit of size 5 overflow 10 reached, connection timed out, timeout 30
ERROR:app:Exception on /raw-updates [GET]
Traceback (most recent call last):
  File "/home/tfb/FrameworkBenchmarks/installs/pypy/site-packages/Flask-0.10.1-py2.7.egg/flask/app.py", line 1817, in wsgi_app
    response = self.full_dispatch_request()
  File "/home/tfb/FrameworkBenchmarks/installs/pypy/site-packages/Flask-0.10.1-py2.7.egg/flask/app.py", line 1477, in full_dispatch_request
    rv = self.handle_user_exception(e)
  File "/home/tfb/FrameworkBenchmarks/installs/pypy/site-packages/Flask-0.10.1-py2.7.egg/flask/app.py", line 1381, in handle_user_exception
    reraise(exc_type, exc_value, tb)
  File "/home/tfb/FrameworkBenchmarks/installs/pypy/site-packages/Flask-0.10.1-py2.7.egg/flask/app.py", line 1475, in full_dispatch_request
    rv = self.dispatch_request()
  File "/home/tfb/FrameworkBenchmarks/installs/pypy/site-packages/Flask-0.10.1-py2.7.egg/flask/app.py", line 1461, in dispatch_request
    return self.view_functions[rule.endpoint](**req.view_args)
  File "/home/tfb/FrameworkBenchmarks/flask/app.py", line 152, in raw_updates
    (randomNumber, world['id']))
  File "/home/tfb/FrameworkBenchmarks/installs/pypy/site-packages/SQLAlchemy-0.8.3-py2.7.egg/sqlalchemy/engine/base.py", line 1613, in execute
    connection = self.contextual_connect(close_with_result=True)
  File "/home/tfb/FrameworkBenchmarks/installs/pypy/site-packages/SQLAlchemy-0.8.3-py2.7.egg/sqlalchemy/engine/base.py", line 1661, in contextual_connect
    self.pool.connect(),
  File "/home/tfb/FrameworkBenchmarks/installs/pypy/site-packages/SQLAlchemy-0.8.3-py2.7.egg/sqlalchemy/pool.py", line 272, in connect
    return _ConnectionFairy(self).checkout()
  File "/home/tfb/FrameworkBenchmarks/installs/pypy/site-packages/SQLAlchemy-0.8.3-py2.7.egg/sqlalchemy/pool.py", line 431, in __init__
    rec = self._connection_record = pool._do_get()
  File "/home/tfb/FrameworkBenchmarks/installs/pypy/site-packages/SQLAlchemy-0.8.3-py2.7.egg/sqlalchemy/pool.py", line 780, in _do_get
    (self.size(), self.overflow(), self._timeout))
TimeoutError: QueuePool limit of size 5 overflow 10 reached, connection timed out, timeout 30
ERROR:app:Exception on /raw-updates [GET]
Traceback (most recent call last):
  File "/home/tfb/FrameworkBenchmarks/installs/pypy/site-packages/Flask-0.10.1-py2.7.egg/flask/app.py", line 1817, in wsgi_app
    response = self.full_dispatch_request()
  File "/home/tfb/FrameworkBenchmarks/installs/pypy/site-packages/Flask-0.10.1-py2.7.egg/flask/app.py", line 1477, in full_dispatch_request
    rv = self.handle_user_exception(e)
  File "/home/tfb/FrameworkBenchmarks/installs/pypy/site-packages/Flask-0.10.1-py2.7.egg/flask/app.py", line 1381, in handle_user_exception
    reraise(exc_type, exc_value, tb)
  File "/home/tfb/FrameworkBenchmarks/installs/pypy/site-packages/Flask-0.10.1-py2.7.egg/flask/app.py", line 1475, in full_dispatch_request
    rv = self.dispatch_request()
  File "/home/tfb/FrameworkBenchmarks/installs/pypy/site-packages/Flask-0.10.1-py2.7.egg/flask/app.py", line 1461, in dispatch_request
    return self.view_functions[rule.endpoint](**req.view_args)
  File "/home/tfb/FrameworkBenchmarks/flask/app.py", line 152, in raw_updates
    (randomNumber, world['id']))
  File "/home/tfb/FrameworkBenchmarks/installs/pypy/site-packages/SQLAlchemy-0.8.3-py2.7.egg/sqlalchemy/engine/base.py", line 1613, in execute
    connection = self.contextual_connect(close_with_result=True)
  File "/home/tfb/FrameworkBenchmarks/installs/pypy/site-packages/SQLAlchemy-0.8.3-py2.7.egg/sqlalchemy/engine/base.py", line 1661, in contextual_connect
    self.pool.connect(),
  File "/home/tfb/FrameworkBenchmarks/installs/pypy/site-packages/SQLAlchemy-0.8.3-py2.7.egg/sqlalchemy/pool.py", line 272, in connect
    return _ConnectionFairy(self).checkout()
  File "/home/tfb/FrameworkBenchmarks/installs/pypy/site-packages/SQLAlchemy-0.8.3-py2.7.egg/sqlalchemy/pool.py", line 431, in __init__
    rec = self._connection_record = pool._do_get()
  File "/home/tfb/FrameworkBenchmarks/installs/pypy/site-packages/SQLAlchemy-0.8.3-py2.7.egg/sqlalchemy/pool.py", line 780, in _do_get
    (self.size(), self.overflow(), self._timeout))
TimeoutError: QueuePool limit of size 5 overflow 10 reached, connection timed out, timeout 30
ERROR:app:Exception on /raw-updates [GET]
Traceback (most recent call last):
  File "/home/tfb/FrameworkBenchmarks/installs/pypy/site-packages/Flask-0.10.1-py2.7.egg/flask/app.py", line 1817, in wsgi_app
    response = self.full_dispatch_request()
  File "/home/tfb/FrameworkBenchmarks/installs/pypy/site-packages/Flask-0.10.1-py2.7.egg/flask/app.py", line 1477, in full_dispatch_request
    rv = self.handle_user_exception(e)
  File "/home/tfb/FrameworkBenchmarks/installs/pypy/site-packages/Flask-0.10.1-py2.7.egg/flask/app.py", line 1381, in handle_user_exception
    reraise(exc_type, exc_value, tb)
  File "/home/tfb/FrameworkBenchmarks/installs/pypy/site-packages/Flask-0.10.1-py2.7.egg/flask/app.py", line 1475, in full_dispatch_request
    rv = self.dispatch_request()
  File "/home/tfb/FrameworkBenchmarks/installs/pypy/site-packages/Flask-0.10.1-py2.7.egg/flask/app.py", line 1461, in dispatch_request
    return self.view_functions[rule.endpoint](**req.view_args)
  File "/home/tfb/FrameworkBenchmarks/flask/app.py", line 152, in raw_updates
    (randomNumber, world['id']))
  File "/home/tfb/FrameworkBenchmarks/installs/pypy/site-packages/SQLAlchemy-0.8.3-py2.7.egg/sqlalchemy/engine/base.py", line 1613, in execute
    connection = self.contextual_connect(close_with_result=True)
  File "/home/tfb/FrameworkBenchmarks/installs/pypy/site-packages/SQLAlchemy-0.8.3-py2.7.egg/sqlalchemy/engine/base.py", line 1661, in contextual_connect
    self.pool.connect(),
  File "/home/tfb/FrameworkBenchmarks/installs/pypy/site-packages/SQLAlchemy-0.8.3-py2.7.egg/sqlalchemy/pool.py", line 272, in connect
    return _ConnectionFairy(self).checkout()
  File "/home/tfb/FrameworkBenchmarks/installs/pypy/site-packages/SQLAlchemy-0.8.3-py2.7.egg/sqlalchemy/pool.py", line 431, in __init__
    rec = self._connection_record = pool._do_get()
  File "/home/tfb/FrameworkBenchmarks/installs/pypy/site-packages/SQLAlchemy-0.8.3-py2.7.egg/sqlalchemy/pool.py", line 780, in _do_get
    (self.size(), self.overflow(), self._timeout))
TimeoutError: QueuePool limit of size 5 overflow 10 reached, connection timed out, timeout 30
ERROR:app:Exception on /raw-updates [GET]
Traceback (most recent call last):
  File "/home/tfb/FrameworkBenchmarks/installs/pypy/site-packages/Flask-0.10.1-py2.7.egg/flask/app.py", line 1817, in wsgi_app
    response = self.full_dispatch_request()
  File "/home/tfb/FrameworkBenchmarks/installs/pypy/site-packages/Flask-0.10.1-py2.7.egg/flask/app.py", line 1477, in full_dispatch_request
    rv = self.handle_user_exception(e)
  File "/home/tfb/FrameworkBenchmarks/installs/pypy/site-packages/Flask-0.10.1-py2.7.egg/flask/app.py", line 1381, in handle_user_exception
    reraise(exc_type, exc_value, tb)
  File "/home/tfb/FrameworkBenchmarks/installs/pypy/site-packages/Flask-0.10.1-py2.7.egg/flask/app.py", line 1475, in full_dispatch_request
    rv = self.dispatch_request()
  File "/home/tfb/FrameworkBenchmarks/installs/pypy/site-packages/Flask-0.10.1-py2.7.egg/flask/app.py", line 1461, in dispatch_request
    return self.view_functions[rule.endpoint](**req.view_args)
  File "/home/tfb/FrameworkBenchmarks/flask/app.py", line 152, in raw_updates
    (randomNumber, world['id']))
  File "/home/tfb/FrameworkBenchmarks/installs/pypy/site-packages/SQLAlchemy-0.8.3-py2.7.egg/sqlalchemy/engine/base.py", line 1613, in execute
    connection = self.contextual_connect(close_with_result=True)
  File "/home/tfb/FrameworkBenchmarks/installs/pypy/site-packages/SQLAlchemy-0.8.3-py2.7.egg/sqlalchemy/engine/base.py", line 1661, in contextual_connect
    self.pool.connect(),
  File "/home/tfb/FrameworkBenchmarks/installs/pypy/site-packages/SQLAlchemy-0.8.3-py2.7.egg/sqlalchemy/pool.py", line 272, in connect
    return _ConnectionFairy(self).checkout()
  File "/home/tfb/FrameworkBenchmarks/installs/pypy/site-packages/SQLAlchemy-0.8.3-py2.7.egg/sqlalchemy/pool.py", line 431, in __init__
    rec = self._connection_record = pool._do_get()
  File "/home/tfb/FrameworkBenchmarks/installs/pypy/site-packages/SQLAlchemy-0.8.3-py2.7.egg/sqlalchemy/pool.py", line 780, in _do_get
    (self.size(), self.overflow(), self._timeout))
TimeoutError: QueuePool limit of size 5 overflow 10 reached, connection timed out, timeout 30
ERROR:tornado.access:500 GET /raw-updates?queries=5 (172.16.98.98) 30064.28ms
ERROR:tornado.access:500 GET /raw-updates?queries=5 (172.16.98.98) 30065.08ms
ERROR:tornado.access:500 GET /raw-updates?queries=5 (172.16.98.98) 30064.66ms
ERROR:tornado.access:500 GET /raw-updates?queries=5 (172.16.98.98) 30066.49ms
ERROR:tornado.access:500 GET /raw-updates?queries=5 (172.16.98.98) 30064.75ms
2013-12-06 15:09:29 [3521] [CRITICAL] WORKER TIMEOUT (pid:3593)
2013-12-06 15:09:29 [3521] [CRITICAL] WORKER TIMEOUT (pid:3594)
2013-12-06 15:09:29 [3521] [CRITICAL] WORKER TIMEOUT (pid:3596)
2013-12-06 15:09:29 [3521] [CRITICAL] WORKER TIMEOUT (pid:3597)
2013-12-06 15:09:29 [3521] [CRITICAL] WORKER TIMEOUT (pid:3598)
2013-12-06 15:09:29 [3521] [CRITICAL] WORKER TIMEOUT (pid:3554)
2013-12-06 15:09:29 [3521] [CRITICAL] WORKER TIMEOUT (pid:3555)
2013-12-06 15:09:29 [3521] [CRITICAL] WORKER TIMEOUT (pid:3593)
2013-12-06 15:09:29 [3521] [CRITICAL] WORKER TIMEOUT (pid:3594)
2013-12-06 15:09:29 [3521] [CRITICAL] WORKER TIMEOUT (pid:3596)
2013-12-06 15:09:29 [3521] [CRITICAL] WORKER TIMEOUT (pid:3597)
2013-12-06 15:09:29 [3521] [CRITICAL] WORKER TIMEOUT (pid:3598)
2013-12-06 15:09:29 [3521] [CRITICAL] WORKER TIMEOUT (pid:3554)
2013-12-06 15:09:29 [3521] [CRITICAL] WORKER TIMEOUT (pid:3555)
2013-12-06 15:09:29 [3521] [CRITICAL] WORKER TIMEOUT (pid:3554)
2013-12-06 15:09:29 [3521] [CRITICAL] WORKER TIMEOUT (pid:3555)
ERROR:app:Exception on /raw-updates [GET]
Traceback (most recent call last):
  File "/home/tfb/FrameworkBenchmarks/installs/pypy/site-packages/Flask-0.10.1-py2.7.egg/flask/app.py", line 1817, in wsgi_app
    response = self.full_dispatch_request()
  File "/home/tfb/FrameworkBenchmarks/installs/pypy/site-packages/Flask-0.10.1-py2.7.egg/flask/app.py", line 1477, in full_dispatch_request
    rv = self.handle_user_exception(e)
  File "/home/tfb/FrameworkBenchmarks/installs/pypy/site-packages/Flask-0.10.1-py2.7.egg/flask/app.py", line 1381, in handle_user_exception
    reraise(exc_type, exc_value, tb)
  File "/home/tfb/FrameworkBenchmarks/installs/pypy/site-packages/Flask-0.10.1-py2.7.egg/flask/app.py", line 1475, in full_dispatch_request
    rv = self.dispatch_request()
  File "/home/tfb/FrameworkBenchmarks/installs/pypy/site-packages/Flask-0.10.1-py2.7.egg/flask/app.py", line 1461, in dispatch_request
    return self.view_functions[rule.endpoint](**req.view_args)
  File "/home/tfb/FrameworkBenchmarks/flask/app.py", line 152, in raw_updates
    (randomNumber, world['id']))
  File "/home/tfb/FrameworkBenchmarks/installs/pypy/site-packages/SQLAlchemy-0.8.3-py2.7.egg/sqlalchemy/engine/base.py", line 1613, in execute
    connection = self.contextual_connect(close_with_result=True)
  File "/home/tfb/FrameworkBenchmarks/installs/pypy/site-packages/SQLAlchemy-0.8.3-py2.7.egg/sqlalchemy/engine/base.py", line 1661, in contextual_connect
    self.pool.connect(),
  File "/home/tfb/FrameworkBenchmarks/installs/pypy/site-packages/SQLAlchemy-0.8.3-py2.7.egg/sqlalchemy/pool.py", line 272, in connect
    return _ConnectionFairy(self).checkout()
  File "/home/tfb/FrameworkBenchmarks/installs/pypy/site-packages/SQLAlchemy-0.8.3-py2.7.egg/sqlalchemy/pool.py", line 431, in __init__
    rec = self._connection_record = pool._do_get()
  File "/home/tfb/FrameworkBenchmarks/installs/pypy/site-packages/SQLAlchemy-0.8.3-py2.7.egg/sqlalchemy/pool.py", line 780, in _do_get
    (self.size(), self.overflow(), self._timeout))
TimeoutError: QueuePool limit of size 5 overflow 10 reached, connection timed out, timeout 30
ERROR:tornado.access:500 GET /raw-updates?queries=5 (172.16.98.98) 30037.01ms
2013-12-06 15:09:39 [3521] [CRITICAL] WORKER TIMEOUT (pid:3618)
2013-12-06 15:09:39 [3521] [CRITICAL] WORKER TIMEOUT (pid:3618)
2013-12-06 15:09:45 [3521] [CRITICAL] WORKER TIMEOUT (pid:3619)
2013-12-06 15:09:45 [3521] [CRITICAL] WORKER TIMEOUT (pid:3620)
2013-12-06 15:09:45 [3521] [CRITICAL] WORKER TIMEOUT (pid:3619)
2013-12-06 15:09:45 [3521] [CRITICAL] WORKER TIMEOUT (pid:3620)
ERROR:app:Exception on /raw-updates [GET]
Traceback (most recent call last):
  File "/home/tfb/FrameworkBenchmarks/installs/pypy/site-packages/Flask-0.10.1-py2.7.egg/flask/app.py", line 1817, in wsgi_app
    response = self.full_dispatch_request()
  File "/home/tfb/FrameworkBenchmarks/installs/pypy/site-packages/Flask-0.10.1-py2.7.egg/flask/app.py", line 1477, in full_dispatch_request
    rv = self.handle_user_exception(e)
  File "/home/tfb/FrameworkBenchmarks/installs/pypy/site-packages/Flask-0.10.1-py2.7.egg/flask/app.py", line 1381, in handle_user_exception
    reraise(exc_type, exc_value, tb)
  File "/home/tfb/FrameworkBenchmarks/installs/pypy/site-packages/Flask-0.10.1-py2.7.egg/flask/app.py", line 1475, in full_dispatch_request
    rv = self.dispatch_request()
  File "/home/tfb/FrameworkBenchmarks/installs/pypy/site-packages/Flask-0.10.1-py2.7.egg/flask/app.py", line 1461, in dispatch_request
    return self.view_functions[rule.endpoint](**req.view_args)
  File "/home/tfb/FrameworkBenchmarks/flask/app.py", line 152, in raw_updates
    (randomNumber, world['id']))
  File "/home/tfb/FrameworkBenchmarks/installs/pypy/site-packages/SQLAlchemy-0.8.3-py2.7.egg/sqlalchemy/engine/base.py", line 1613, in execute
    connection = self.contextual_connect(close_with_result=True)
  File "/home/tfb/FrameworkBenchmarks/installs/pypy/site-packages/SQLAlchemy-0.8.3-py2.7.egg/sqlalchemy/engine/base.py", line 1661, in contextual_connect
    self.pool.connect(),
  File "/home/tfb/FrameworkBenchmarks/installs/pypy/site-packages/SQLAlchemy-0.8.3-py2.7.egg/sqlalchemy/pool.py", line 272, in connect
    return _ConnectionFairy(self).checkout()
  File "/home/tfb/FrameworkBenchmarks/installs/pypy/site-packages/SQLAlchemy-0.8.3-py2.7.egg/sqlalchemy/pool.py", line 431, in __init__
    rec = self._connection_record = pool._do_get()
  File "/home/tfb/FrameworkBenchmarks/installs/pypy/site-packages/SQLAlchemy-0.8.3-py2.7.egg/sqlalchemy/pool.py", line 780, in _do_get
    (self.size(), self.overflow(), self._timeout))
TimeoutError: QueuePool limit of size 5 overflow 10 reached, connection timed out, timeout 30
ERROR:app:Exception on /raw-updates [GET]
Traceback (most recent call last):
  File "/home/tfb/FrameworkBenchmarks/installs/pypy/site-packages/Flask-0.10.1-py2.7.egg/flask/app.py", line 1817, in wsgi_app
    response = self.full_dispatch_request()
  File "/home/tfb/FrameworkBenchmarks/installs/pypy/site-packages/Flask-0.10.1-py2.7.egg/flask/app.py", line 1477, in full_dispatch_request
    rv = self.handle_user_exception(e)
  File "/home/tfb/FrameworkBenchmarks/installs/pypy/site-packages/Flask-0.10.1-py2.7.egg/flask/app.py", line 1381, in handle_user_exception
    reraise(exc_type, exc_value, tb)
  File "/home/tfb/FrameworkBenchmarks/installs/pypy/site-packages/Flask-0.10.1-py2.7.egg/flask/app.py", line 1475, in full_dispatch_request
    rv = self.dispatch_request()
  File "/home/tfb/FrameworkBenchmarks/installs/pypy/site-packages/Flask-0.10.1-py2.7.egg/flask/app.py", line 1461, in dispatch_request
    return self.view_functions[rule.endpoint](**req.view_args)
  File "/home/tfb/FrameworkBenchmarks/flask/app.py", line 152, in raw_updates
    (randomNumber, world['id']))
  File "/home/tfb/FrameworkBenchmarks/installs/pypy/site-packages/SQLAlchemy-0.8.3-py2.7.egg/sqlalchemy/engine/base.py", line 1613, in execute
    connection = self.contextual_connect(close_with_result=True)
  File "/home/tfb/FrameworkBenchmarks/installs/pypy/site-packages/SQLAlchemy-0.8.3-py2.7.egg/sqlalchemy/engine/base.py", line 1661, in contextual_connect
    self.pool.connect(),
  File "/home/tfb/FrameworkBenchmarks/installs/pypy/site-packages/SQLAlchemy-0.8.3-py2.7.egg/sqlalchemy/pool.py", line 272, in connect
    return _ConnectionFairy(self).checkout()
  File "/home/tfb/FrameworkBenchmarks/installs/pypy/site-packages/SQLAlchemy-0.8.3-py2.7.egg/sqlalchemy/pool.py", line 431, in __init__
    rec = self._connection_record = pool._do_get()
  File "/home/tfb/FrameworkBenchmarks/installs/pypy/site-packages/SQLAlchemy-0.8.3-py2.7.egg/sqlalchemy/pool.py", line 780, in _do_get
    (self.size(), self.overflow(), self._timeout))
TimeoutError: QueuePool limit of size 5 overflow 10 reached, connection timed out, timeout 30
ERROR:app:Exception on /raw-updates [GET]
Traceback (most recent call last):
  File "/home/tfb/FrameworkBenchmarks/installs/pypy/site-packages/Flask-0.10.1-py2.7.egg/flask/app.py", line 1817, in wsgi_app
    response = self.full_dispatch_request()
  File "/home/tfb/FrameworkBenchmarks/installs/pypy/site-packages/Flask-0.10.1-py2.7.egg/flask/app.py", line 1477, in full_dispatch_request
    rv = self.handle_user_exception(e)
  File "/home/tfb/FrameworkBenchmarks/installs/pypy/site-packages/Flask-0.10.1-py2.7.egg/flask/app.py", line 1381, in handle_user_exception
    reraise(exc_type, exc_value, tb)
  File "/home/tfb/FrameworkBenchmarks/installs/pypy/site-packages/Flask-0.10.1-py2.7.egg/flask/app.py", line 1475, in full_dispatch_request
    rv = self.dispatch_request()
  File "/home/tfb/FrameworkBenchmarks/installs/pypy/site-packages/Flask-0.10.1-py2.7.egg/flask/app.py", line 1461, in dispatch_request
    return self.view_functions[rule.endpoint](**req.view_args)
  File "/home/tfb/FrameworkBenchmarks/flask/app.py", line 152, in raw_updates
    (randomNumber, world['id']))
  File "/home/tfb/FrameworkBenchmarks/installs/pypy/site-packages/SQLAlchemy-0.8.3-py2.7.egg/sqlalchemy/engine/base.py", line 1613, in execute
    connection = self.contextual_connect(close_with_result=True)
  File "/home/tfb/FrameworkBenchmarks/installs/pypy/site-packages/SQLAlchemy-0.8.3-py2.7.egg/sqlalchemy/engine/base.py", line 1661, in contextual_connect
    self.pool.connect(),
  File "/home/tfb/FrameworkBenchmarks/installs/pypy/site-packages/SQLAlchemy-0.8.3-py2.7.egg/sqlalchemy/pool.py", line 272, in connect
    return _ConnectionFairy(self).checkout()
  File "/home/tfb/FrameworkBenchmarks/installs/pypy/site-packages/SQLAlchemy-0.8.3-py2.7.egg/sqlalchemy/pool.py", line 431, in __init__
    rec = self._connection_record = pool._do_get()
  File "/home/tfb/FrameworkBenchmarks/installs/pypy/site-packages/SQLAlchemy-0.8.3-py2.7.egg/sqlalchemy/pool.py", line 780, in _do_get
    (self.size(), self.overflow(), self._timeout))
TimeoutError: QueuePool limit of size 5 overflow 10 reached, connection timed out, timeout 30
ERROR:tornado.access:500 GET /raw-updates?queries=10 (172.16.98.98) 30040.63ms
ERROR:tornado.access:500 GET /raw-updates?queries=10 (172.16.98.98) 30042.21ms
ERROR:tornado.access:500 GET /raw-updates?queries=10 (172.16.98.98) 30040.11ms
2013-12-06 15:09:46 [3521] [CRITICAL] WORKER TIMEOUT (pid:3622)
2013-12-06 15:09:46 [3521] [CRITICAL] WORKER TIMEOUT (pid:3623)
2013-12-06 15:09:46 [3521] [CRITICAL] WORKER TIMEOUT (pid:3624)
2013-12-06 15:09:46 [3521] [CRITICAL] WORKER TIMEOUT (pid:3625)
2013-12-06 15:09:46 [3521] [CRITICAL] WORKER TIMEOUT (pid:3622)
2013-12-06 15:09:46 [3521] [CRITICAL] WORKER TIMEOUT (pid:3623)
2013-12-06 15:09:46 [3521] [CRITICAL] WORKER TIMEOUT (pid:3624)
2013-12-06 15:09:46 [3521] [CRITICAL] WORKER TIMEOUT (pid:3625)
ERROR:app:Exception on /raw-updates [GET]
Traceback (most recent call last):
  File "/home/tfb/FrameworkBenchmarks/installs/pypy/site-packages/Flask-0.10.1-py2.7.egg/flask/app.py", line 1817, in wsgi_app
    response = self.full_dispatch_request()
  File "/home/tfb/FrameworkBenchmarks/installs/pypy/site-packages/Flask-0.10.1-py2.7.egg/flask/app.py", line 1477, in full_dispatch_request
    rv = self.handle_user_exception(e)
  File "/home/tfb/FrameworkBenchmarks/installs/pypy/site-packages/Flask-0.10.1-py2.7.egg/flask/app.py", line 1381, in handle_user_exception
    reraise(exc_type, exc_value, tb)
  File "/home/tfb/FrameworkBenchmarks/installs/pypy/site-packages/Flask-0.10.1-py2.7.egg/flask/app.py", line 1475, in full_dispatch_request
    rv = self.dispatch_request()
  File "/home/tfb/FrameworkBenchmarks/installs/pypy/site-packages/Flask-0.10.1-py2.7.egg/flask/app.py", line 1461, in dispatch_request
    return self.view_functions[rule.endpoint](**req.view_args)
  File "/home/tfb/FrameworkBenchmarks/flask/app.py", line 152, in raw_updates
    (randomNumber, world['id']))
  File "/home/tfb/FrameworkBenchmarks/installs/pypy/site-packages/SQLAlchemy-0.8.3-py2.7.egg/sqlalchemy/engine/base.py", line 1613, in execute
    connection = self.contextual_connect(close_with_result=True)
  File "/home/tfb/FrameworkBenchmarks/installs/pypy/site-packages/SQLAlchemy-0.8.3-py2.7.egg/sqlalchemy/engine/base.py", line 1661, in contextual_connect
    self.pool.connect(),
  File "/home/tfb/FrameworkBenchmarks/installs/pypy/site-packages/SQLAlchemy-0.8.3-py2.7.egg/sqlalchemy/pool.py", line 272, in connect
    return _ConnectionFairy(self).checkout()
  File "/home/tfb/FrameworkBenchmarks/installs/pypy/site-packages/SQLAlchemy-0.8.3-py2.7.egg/sqlalchemy/pool.py", line 431, in __init__
    rec = self._connection_record = pool._do_get()
  File "/home/tfb/FrameworkBenchmarks/installs/pypy/site-packages/SQLAlchemy-0.8.3-py2.7.egg/sqlalchemy/pool.py", line 780, in _do_get
    (self.size(), self.overflow(), self._timeout))
TimeoutError: QueuePool limit of size 5 overflow 10 reached, connection timed out, timeout 30
ERROR:tornado.access:500 GET /raw-updates?queries=10 (172.16.98.98) 30035.81ms
2013-12-06 15:09:48 [3521] [CRITICAL] WORKER TIMEOUT (pid:3632)
2013-12-06 15:09:48 [3521] [CRITICAL] WORKER TIMEOUT (pid:3632)
ERROR:app:Exception on /raw-updates [GET]
Traceback (most recent call last):
  File "/home/tfb/FrameworkBenchmarks/installs/pypy/site-packages/Flask-0.10.1-py2.7.egg/flask/app.py", line 1817, in wsgi_app
    response = self.full_dispatch_request()
  File "/home/tfb/FrameworkBenchmarks/installs/pypy/site-packages/Flask-0.10.1-py2.7.egg/flask/app.py", line 1477, in full_dispatch_request
    rv = self.handle_user_exception(e)
  File "/home/tfb/FrameworkBenchmarks/installs/pypy/site-packages/Flask-0.10.1-py2.7.egg/flask/app.py", line 1381, in handle_user_exception
    reraise(exc_type, exc_value, tb)
  File "/home/tfb/FrameworkBenchmarks/installs/pypy/site-packages/Flask-0.10.1-py2.7.egg/flask/app.py", line 1475, in full_dispatch_request
    rv = self.dispatch_request()
  File "/home/tfb/FrameworkBenchmarks/installs/pypy/site-packages/Flask-0.10.1-py2.7.egg/flask/app.py", line 1461, in dispatch_request
    return self.view_functions[rule.endpoint](**req.view_args)
  File "/home/tfb/FrameworkBenchmarks/flask/app.py", line 148, in raw_updates
    world = dbraw_engine.execute("SELECT * FROM World WHERE id=%s", (rp(),)).fetchone()
  File "/home/tfb/FrameworkBenchmarks/installs/pypy/site-packages/SQLAlchemy-0.8.3-py2.7.egg/sqlalchemy/engine/base.py", line 1613, in execute
    connection = self.contextual_connect(close_with_result=True)
  File "/home/tfb/FrameworkBenchmarks/installs/pypy/site-packages/SQLAlchemy-0.8.3-py2.7.egg/sqlalchemy/engine/base.py", line 1661, in contextual_connect
    self.pool.connect(),
  File "/home/tfb/FrameworkBenchmarks/installs/pypy/site-packages/SQLAlchemy-0.8.3-py2.7.egg/sqlalchemy/pool.py", line 272, in connect
    return _ConnectionFairy(self).checkout()
  File "/home/tfb/FrameworkBenchmarks/installs/pypy/site-packages/SQLAlchemy-0.8.3-py2.7.egg/sqlalchemy/pool.py", line 431, in __init__
    rec = self._connection_record = pool._do_get()
  File "/home/tfb/FrameworkBenchmarks/installs/pypy/site-packages/SQLAlchemy-0.8.3-py2.7.egg/sqlalchemy/pool.py", line 780, in _do_get
    (self.size(), self.overflow(), self._timeout))
TimeoutError: QueuePool limit of size 5 overflow 10 reached, connection timed out, timeout 30
ERROR:tornado.access:500 GET /raw-updates?queries=5 (172.16.98.98) 30001.82ms
2013-12-06 15:10:03 [3521] [CRITICAL] WORKER TIMEOUT (pid:3602)
2013-12-06 15:10:03 [3521] [CRITICAL] WORKER TIMEOUT (pid:3634)
2013-12-06 15:10:03 [3521] [CRITICAL] WORKER TIMEOUT (pid:3635)
2013-12-06 15:10:03 [3521] [CRITICAL] WORKER TIMEOUT (pid:3637)
2013-12-06 15:10:03 [3521] [CRITICAL] WORKER TIMEOUT (pid:3638)
2013-12-06 15:10:03 [3521] [CRITICAL] WORKER TIMEOUT (pid:3639)
2013-12-06 15:10:03 [3521] [CRITICAL] WORKER TIMEOUT (pid:3640)
2013-12-06 15:10:03 [3521] [CRITICAL] WORKER TIMEOUT (pid:3641)
2013-12-06 15:10:03 [3521] [CRITICAL] WORKER TIMEOUT (pid:3642)
2013-12-06 15:10:03 [3521] [CRITICAL] WORKER TIMEOUT (pid:3643)
2013-12-06 15:10:03 [3521] [CRITICAL] WORKER TIMEOUT (pid:3644)
2013-12-06 15:10:03 [3521] [CRITICAL] WORKER TIMEOUT (pid:3645)
2013-12-06 15:10:03 [3521] [CRITICAL] WORKER TIMEOUT (pid:3646)
2013-12-06 15:10:03 [3521] [CRITICAL] WORKER TIMEOUT (pid:3647)
2013-12-06 15:10:03 [3521] [CRITICAL] WORKER TIMEOUT (pid:3602)
2013-12-06 15:10:03 [3521] [CRITICAL] WORKER TIMEOUT (pid:3634)
2013-12-06 15:10:03 [3521] [CRITICAL] WORKER TIMEOUT (pid:3635)
2013-12-06 15:10:03 [3521] [CRITICAL] WORKER TIMEOUT (pid:3637)
2013-12-06 15:10:03 [3521] [CRITICAL] WORKER TIMEOUT (pid:3638)
2013-12-06 15:10:03 [3521] [CRITICAL] WORKER TIMEOUT (pid:3639)
2013-12-06 15:10:03 [3521] [CRITICAL] WORKER TIMEOUT (pid:3640)
2013-12-06 15:10:03 [3521] [CRITICAL] WORKER TIMEOUT (pid:3641)
2013-12-06 15:10:03 [3521] [CRITICAL] WORKER TIMEOUT (pid:3642)
2013-12-06 15:10:03 [3521] [CRITICAL] WORKER TIMEOUT (pid:3643)
2013-12-06 15:10:03 [3521] [CRITICAL] WORKER TIMEOUT (pid:3644)
2013-12-06 15:10:03 [3521] [CRITICAL] WORKER TIMEOUT (pid:3645)
2013-12-06 15:10:03 [3521] [CRITICAL] WORKER TIMEOUT (pid:3646)
2013-12-06 15:10:03 [3521] [CRITICAL] WORKER TIMEOUT (pid:3647)
2013-12-06 15:10:03 [3521] [CRITICAL] WORKER TIMEOUT (pid:3637)
2013-12-06 15:10:03 [3521] [CRITICAL] WORKER TIMEOUT (pid:3641)
2013-12-06 15:10:03 [3521] [CRITICAL] WORKER TIMEOUT (pid:3642)
2013-12-06 15:10:03 [3521] [CRITICAL] WORKER TIMEOUT (pid:3643)
2013-12-06 15:10:03 [3521] [CRITICAL] WORKER TIMEOUT (pid:3645)
2013-12-06 15:10:03 [3521] [CRITICAL] WORKER TIMEOUT (pid:3646)
ERROR:app:Exception on /raw-updates [GET]
Traceback (most recent call last):
  File "/home/tfb/FrameworkBenchmarks/installs/pypy/site-packages/Flask-0.10.1-py2.7.egg/flask/app.py", line 1817, in wsgi_app
    response = self.full_dispatch_request()
  File "/home/tfb/FrameworkBenchmarks/installs/pypy/site-packages/Flask-0.10.1-py2.7.egg/flask/app.py", line 1477, in full_dispatch_request
    rv = self.handle_user_exception(e)
  File "/home/tfb/FrameworkBenchmarks/installs/pypy/site-packages/Flask-0.10.1-py2.7.egg/flask/app.py", line 1381, in handle_user_exception
    reraise(exc_type, exc_value, tb)
  File "/home/tfb/FrameworkBenchmarks/installs/pypy/site-packages/Flask-0.10.1-py2.7.egg/flask/app.py", line 1475, in full_dispatch_request
    rv = self.dispatch_request()
  File "/home/tfb/FrameworkBenchmarks/installs/pypy/site-packages/Flask-0.10.1-py2.7.egg/flask/app.py", line 1461, in dispatch_request
    return self.view_functions[rule.endpoint](**req.view_args)
  File "/home/tfb/FrameworkBenchmarks/flask/app.py", line 152, in raw_updates
    (randomNumber, world['id']))
  File "/home/tfb/FrameworkBenchmarks/installs/pypy/site-packages/SQLAlchemy-0.8.3-py2.7.egg/sqlalchemy/engine/base.py", line 1613, in execute
    connection = self.contextual_connect(close_with_result=True)
  File "/home/tfb/FrameworkBenchmarks/installs/pypy/site-packages/SQLAlchemy-0.8.3-py2.7.egg/sqlalchemy/engine/base.py", line 1661, in contextual_connect
    self.pool.connect(),
  File "/home/tfb/FrameworkBenchmarks/installs/pypy/site-packages/SQLAlchemy-0.8.3-py2.7.egg/sqlalchemy/pool.py", line 272, in connect
    return _ConnectionFairy(self).checkout()
  File "/home/tfb/FrameworkBenchmarks/installs/pypy/site-packages/SQLAlchemy-0.8.3-py2.7.egg/sqlalchemy/pool.py", line 431, in __init__
    rec = self._connection_record = pool._do_get()
  File "/home/tfb/FrameworkBenchmarks/installs/pypy/site-packages/SQLAlchemy-0.8.3-py2.7.egg/sqlalchemy/pool.py", line 780, in _do_get
    (self.size(), self.overflow(), self._timeout))
TimeoutError: QueuePool limit of size 5 overflow 10 reached, connection timed out, timeout 30
ERROR:tornado.access:500 GET /raw-updates?queries=15 (172.16.98.98) 30114.22ms
2013-12-06 15:10:04 [3521] [CRITICAL] WORKER TIMEOUT (pid:3636)
ERROR:app:Exception on /raw-updates [GET]
Traceback (most recent call last):
  File "/home/tfb/FrameworkBenchmarks/installs/pypy/site-packages/Flask-0.10.1-py2.7.egg/flask/app.py", line 1817, in wsgi_app
    response = self.full_dispatch_request()
  File "/home/tfb/FrameworkBenchmarks/installs/pypy/site-packages/Flask-0.10.1-py2.7.egg/flask/app.py", line 1477, in full_dispatch_request
    rv = self.handle_user_exception(e)
  File "/home/tfb/FrameworkBenchmarks/installs/pypy/site-packages/Flask-0.10.1-py2.7.egg/flask/app.py", line 1381, in handle_user_exception
    reraise(exc_type, exc_value, tb)
  File "/home/tfb/FrameworkBenchmarks/installs/pypy/site-packages/Flask-0.10.1-py2.7.egg/flask/app.py", line 1475, in full_dispatch_request
    rv = self.dispatch_request()
  File "/home/tfb/FrameworkBenchmarks/installs/pypy/site-packages/Flask-0.10.1-py2.7.egg/flask/app.py", line 1461, in dispatch_request
    return self.view_functions[rule.endpoint](**req.view_args)
  File "/home/tfb/FrameworkBenchmarks/flask/app.py", line 152, in raw_updates
    (randomNumber, world['id']))
  File "/home/tfb/FrameworkBenchmarks/installs/pypy/site-packages/SQLAlchemy-0.8.3-py2.7.egg/sqlalchemy/engine/base.py", line 1613, in execute
    connection = self.contextual_connect(close_with_result=True)
  File "/home/tfb/FrameworkBenchmarks/installs/pypy/site-packages/SQLAlchemy-0.8.3-py2.7.egg/sqlalchemy/engine/base.py", line 1661, in contextual_connect
    self.pool.connect(),
  File "/home/tfb/FrameworkBenchmarks/installs/pypy/site-packages/SQLAlchemy-0.8.3-py2.7.egg/sqlalchemy/pool.py", line 272, in connect
    return _ConnectionFairy(self).checkout()
  File "/home/tfb/FrameworkBenchmarks/installs/pypy/site-packages/SQLAlchemy-0.8.3-py2.7.egg/sqlalchemy/pool.py", line 431, in __init__
    rec = self._connection_record = pool._do_get()
  File "/home/tfb/FrameworkBenchmarks/installs/pypy/site-packages/SQLAlchemy-0.8.3-py2.7.egg/sqlalchemy/pool.py", line 780, in _do_get
    (self.size(), self.overflow(), self._timeout))
TimeoutError: QueuePool limit of size 5 overflow 10 reached, connection timed out, timeout 30
2013-12-06 15:10:09 [3521] [CRITICAL] WORKER TIMEOUT (pid:3662)
2013-12-06 15:10:09 [3521] [CRITICAL] WORKER TIMEOUT (pid:3662)
ERROR:tornado.application:Uncaught exception, closing connection.
Traceback (most recent call last):
  File "/home/tfb/FrameworkBenchmarks/installs/pypy/site-packages/tornado-3.1-py2.7.egg/tornado/iostream.py", line 341, in wrapper
    callback(*args)
  File "/home/tfb/FrameworkBenchmarks/installs/pypy/site-packages/tornado-3.1-py2.7.egg/tornado/stack_context.py", line 331, in wrapped
    raise_exc_info(exc)
  File "/home/tfb/FrameworkBenchmarks/installs/pypy/site-packages/tornado-3.1-py2.7.egg/tornado/stack_context.py", line 302, in wrapped
    ret = fn(*args, **kwargs)
TypeError: exceptions must be old-style classes or derived from BaseException, not NoneType
ERROR:tornado.application:Uncaught exception, closing connection.
Traceback (most recent call last):
  File "/home/tfb/FrameworkBenchmarks/installs/pypy/site-packages/tornado-3.1-py2.7.egg/tornado/iostream.py", line 341, in wrapper
    callback(*args)
  File "/home/tfb/FrameworkBenchmarks/installs/pypy/site-packages/tornado-3.1-py2.7.egg/tornado/stack_context.py", line 331, in wrapped
    raise_exc_info(exc)
  File "/home/tfb/FrameworkBenchmarks/installs/pypy/site-packages/tornado-3.1-py2.7.egg/tornado/stack_context.py", line 302, in wrapped
    ret = fn(*args, **kwargs)
TypeError: exceptions must be old-style classes or derived from BaseException, not NoneType
ERROR:tornado.application:Uncaught exception, closing connection.
Traceback (most recent call last):
  File "/home/tfb/FrameworkBenchmarks/installs/pypy/site-packages/tornado-3.1-py2.7.egg/tornado/iostream.py", line 341, in wrapper
    callback(*args)
  File "/home/tfb/FrameworkBenchmarks/installs/pypy/site-packages/tornado-3.1-py2.7.egg/tornado/stack_context.py", line 331, in wrapped
    raise_exc_info(exc)
  File "/home/tfb/FrameworkBenchmarks/installs/pypy/site-packages/tornado-3.1-py2.7.egg/tornado/stack_context.py", line 302, in wrapped
    ret = fn(*args, **kwargs)
TypeError: exceptions must be old-style classes or derived from BaseException, not NoneType
ERROR:tornado.application:Exception in callback <_functools.partial object at 0x0000000009749ec0>
Traceback (most recent call last):
  File "/home/tfb/FrameworkBenchmarks/installs/pypy/site-packages/tornado-3.1-py2.7.egg/tornado/ioloop.py", line 458, in _run_callback
    callback()
  File "/home/tfb/FrameworkBenchmarks/installs/pypy/lib_pypy/_functools.py", line 22, in __call__
    return self.func(*(self.args + fargs), **fkeywords)
  File "/home/tfb/FrameworkBenchmarks/installs/pypy/site-packages/tornado-3.1-py2.7.egg/tornado/stack_context.py", line 331, in wrapped
    raise_exc_info(exc)
  File "/home/tfb/FrameworkBenchmarks/installs/pypy/site-packages/tornado-3.1-py2.7.egg/tornado/stack_context.py", line 302, in wrapped
    ret = fn(*args, **kwargs)
  File "/home/tfb/FrameworkBenchmarks/installs/pypy/site-packages/tornado-3.1-py2.7.egg/tornado/iostream.py", line 341, in wrapper
    callback(*args)
  File "/home/tfb/FrameworkBenchmarks/installs/pypy/site-packages/tornado-3.1-py2.7.egg/tornado/stack_context.py", line 331, in wrapped
    raise_exc_info(exc)
  File "/home/tfb/FrameworkBenchmarks/installs/pypy/site-packages/tornado-3.1-py2.7.egg/tornado/stack_context.py", line 302, in wrapped
    ret = fn(*args, **kwargs)
TypeError: exceptions must be old-style classes or derived from BaseException, not NoneType
ERROR:tornado.application:Exception in callback <_functools.partial object at 0x00007fce37a36640>
Traceback (most recent call last):
  File "/home/tfb/FrameworkBenchmarks/installs/pypy/site-packages/tornado-3.1-py2.7.egg/tornado/ioloop.py", line 458, in _run_callback
    callback()
  File "/home/tfb/FrameworkBenchmarks/installs/pypy/lib_pypy/_functools.py", line 22, in __call__
    return self.func(*(self.args + fargs), **fkeywords)
  File "/home/tfb/FrameworkBenchmarks/installs/pypy/site-packages/tornado-3.1-py2.7.egg/tornado/stack_context.py", line 331, in wrapped
    raise_exc_info(exc)
  File "/home/tfb/FrameworkBenchmarks/installs/pypy/site-packages/tornado-3.1-py2.7.egg/tornado/stack_context.py", line 302, in wrapped
    ret = fn(*args, **kwargs)
  File "/home/tfb/FrameworkBenchmarks/installs/pypy/site-packages/tornado-3.1-py2.7.egg/tornado/iostream.py", line 341, in wrapper
    callback(*args)
  File "/home/tfb/FrameworkBenchmarks/installs/pypy/site-packages/tornado-3.1-py2.7.egg/tornado/stack_context.py", line 331, in wrapped
    raise_exc_info(exc)
  File "/home/tfb/FrameworkBenchmarks/installs/pypy/site-packages/tornado-3.1-py2.7.egg/tornado/stack_context.py", line 302, in wrapped
    ret = fn(*args, **kwargs)
TypeError: exceptions must be old-style classes or derived from BaseException, not NoneType
ERROR:tornado.application:Exception in callback <_functools.partial object at 0x00007fce37a36598>
Traceback (most recent call last):
  File "/home/tfb/FrameworkBenchmarks/installs/pypy/site-packages/tornado-3.1-py2.7.egg/tornado/ioloop.py", line 458, in _run_callback
    callback()
  File "/home/tfb/FrameworkBenchmarks/installs/pypy/lib_pypy/_functools.py", line 22, in __call__
    return self.func(*(self.args + fargs), **fkeywords)
  File "/home/tfb/FrameworkBenchmarks/installs/pypy/site-packages/tornado-3.1-py2.7.egg/tornado/stack_context.py", line 331, in wrapped
    raise_exc_info(exc)
  File "/home/tfb/FrameworkBenchmarks/installs/pypy/site-packages/tornado-3.1-py2.7.egg/tornado/stack_context.py", line 302, in wrapped
    ret = fn(*args, **kwargs)
  File "/home/tfb/FrameworkBenchmarks/installs/pypy/site-packages/tornado-3.1-py2.7.egg/tornado/iostream.py", line 341, in wrapper
    callback(*args)
  File "/home/tfb/FrameworkBenchmarks/installs/pypy/site-packages/tornado-3.1-py2.7.egg/tornado/stack_context.py", line 331, in wrapped
    raise_exc_info(exc)
  File "/home/tfb/FrameworkBenchmarks/installs/pypy/site-packages/tornado-3.1-py2.7.egg/tornado/stack_context.py", line 302, in wrapped
    ret = fn(*args, **kwargs)
TypeError: exceptions must be old-style classes or derived from BaseException, not NoneType
ERROR:tornado.application:Exception in callback <_functools.partial object at 0x00007fce37a36838>
Traceback (most recent call last):
  File "/home/tfb/FrameworkBenchmarks/installs/pypy/site-packages/tornado-3.1-py2.7.egg/tornado/ioloop.py", line 458, in _run_callback
    callback()
  File "/home/tfb/FrameworkBenchmarks/installs/pypy/lib_pypy/_functools.py", line 22, in __call__
    return self.func(*(self.args + fargs), **fkeywords)
  File "/home/tfb/FrameworkBenchmarks/installs/pypy/site-packages/tornado-3.1-py2.7.egg/tornado/stack_context.py", line 331, in wrapped
    raise_exc_info(exc)
  File "/home/tfb/FrameworkBenchmarks/installs/pypy/site-packages/tornado-3.1-py2.7.egg/tornado/stack_context.py", line 302, in wrapped
    ret = fn(*args, **kwargs)
  File "/home/tfb/FrameworkBenchmarks/installs/pypy/site-packages/tornado-3.1-py2.7.egg/tornado/iostream.py", line 341, in wrapper
    callback(*args)
  File "/home/tfb/FrameworkBenchmarks/installs/pypy/site-packages/tornado-3.1-py2.7.egg/tornado/stack_context.py", line 331, in wrapped
    raise_exc_info(exc)
  File "/home/tfb/FrameworkBenchmarks/installs/pypy/site-packages/tornado-3.1-py2.7.egg/tornado/stack_context.py", line 302, in wrapped
    ret = fn(*args, **kwargs)
TypeError: exceptions must be old-style classes or derived from BaseException, not NoneType
debug: OperationError:
debug:  operror-type: SystemExit
debug:  operror-value: 0
ERROR:tornado.application:Uncaught exception, closing connection.
Traceback (most recent call last):
  File "/home/tfb/FrameworkBenchmarks/installs/pypy/site-packages/tornado-3.1-py2.7.egg/tornado/iostream.py", line 341, in wrapper
    callback(*args)
  File "/home/tfb/FrameworkBenchmarks/installs/pypy/site-packages/tornado-3.1-py2.7.egg/tornado/stack_context.py", line 331, in wrapped
    raise_exc_info(exc)
  File "/home/tfb/FrameworkBenchmarks/installs/pypy/site-packages/tornado-3.1-py2.7.egg/tornado/stack_context.py", line 302, in wrapped
    ret = fn(*args, **kwargs)
TypeError: exceptions must be old-style classes or derived from BaseException, not NoneType
ERROR:tornado.application:Uncaught exception, closing connection.
Traceback (most recent call last):
  File "/home/tfb/FrameworkBenchmarks/installs/pypy/site-packages/tornado-3.1-py2.7.egg/tornado/iostream.py", line 341, in wrapper
    callback(*args)
  File "/home/tfb/FrameworkBenchmarks/installs/pypy/site-packages/tornado-3.1-py2.7.egg/tornado/stack_context.py", line 331, in wrapped
    raise_exc_info(exc)
  File "/home/tfb/FrameworkBenchmarks/installs/pypy/site-packages/tornado-3.1-py2.7.egg/tornado/stack_context.py", line 302, in wrapped
    ret = fn(*args, **kwargs)
TypeError: exceptions must be old-style classes or derived from BaseException, not NoneType
ERROR:tornado.application:Uncaught exception, closing connection.
Traceback (most recent call last):
  File "/home/tfb/FrameworkBenchmarks/installs/pypy/site-packages/tornado-3.1-py2.7.egg/tornado/iostream.py", line 341, in wrapper
    callback(*args)
  File "/home/tfb/FrameworkBenchmarks/installs/pypy/site-packages/tornado-3.1-py2.7.egg/tornado/stack_context.py", line 331, in wrapped
    raise_exc_info(exc)
  File "/home/tfb/FrameworkBenchmarks/installs/pypy/site-packages/tornado-3.1-py2.7.egg/tornado/stack_context.py", line 302, in wrapped
    ret = fn(*args, **kwargs)
TypeError: exceptions must be old-style classes or derived from BaseException, not NoneType
ERROR:tornado.application:Exception in callback <_functools.partial object at 0x00007fce37a36d40>
Traceback (most recent call last):
  File "/home/tfb/FrameworkBenchmarks/installs/pypy/site-packages/tornado-3.1-py2.7.egg/tornado/ioloop.py", line 458, in _run_callback
    callback()
  File "/home/tfb/FrameworkBenchmarks/installs/pypy/lib_pypy/_functools.py", line 22, in __call__
    return self.func(*(self.args + fargs), **fkeywords)
  File "/home/tfb/FrameworkBenchmarks/installs/pypy/site-packages/tornado-3.1-py2.7.egg/tornado/stack_context.py", line 331, in wrapped
    raise_exc_info(exc)
  File "/home/tfb/FrameworkBenchmarks/installs/pypy/site-packages/tornado-3.1-py2.7.egg/tornado/stack_context.py", line 302, in wrapped
    ret = fn(*args, **kwargs)
  File "/home/tfb/FrameworkBenchmarks/installs/pypy/site-packages/tornado-3.1-py2.7.egg/tornado/iostream.py", line 341, in wrapper
    callback(*args)
  File "/home/tfb/FrameworkBenchmarks/installs/pypy/site-packages/tornado-3.1-py2.7.egg/tornado/stack_context.py", line 331, in wrapped
    raise_exc_info(exc)
  File "/home/tfb/FrameworkBenchmarks/installs/pypy/site-packages/tornado-3.1-py2.7.egg/tornado/stack_context.py", line 302, in wrapped
    ret = fn(*args, **kwargs)
TypeError: exceptions must be old-style classes or derived from BaseException, not NoneType
ERROR:tornado.application:Exception in callback <_functools.partial object at 0x00007fce37a36b48>
Traceback (most recent call last):
  File "/home/tfb/FrameworkBenchmarks/installs/pypy/site-packages/tornado-3.1-py2.7.egg/tornado/ioloop.py", line 458, in _run_callback
    callback()
  File "/home/tfb/FrameworkBenchmarks/installs/pypy/lib_pypy/_functools.py", line 22, in __call__
    return self.func(*(self.args + fargs), **fkeywords)
  File "/home/tfb/FrameworkBenchmarks/installs/pypy/site-packages/tornado-3.1-py2.7.egg/tornado/stack_context.py", line 331, in wrapped
    raise_exc_info(exc)
  File "/home/tfb/FrameworkBenchmarks/installs/pypy/site-packages/tornado-3.1-py2.7.egg/tornado/stack_context.py", line 302, in wrapped
    ret = fn(*args, **kwargs)
  File "/home/tfb/FrameworkBenchmarks/installs/pypy/site-packages/tornado-3.1-py2.7.egg/tornado/iostream.py", line 341, in wrapper
    callback(*args)
  File "/home/tfb/FrameworkBenchmarks/installs/pypy/site-packages/tornado-3.1-py2.7.egg/tornado/stack_context.py", line 331, in wrapped
    raise_exc_info(exc)
  File "/home/tfb/FrameworkBenchmarks/installs/pypy/site-packages/tornado-3.1-py2.7.egg/tornado/stack_context.py", line 302, in wrapped
    ret = fn(*args, **kwargs)
TypeError: exceptions must be old-style classes or derived from BaseException, not NoneType
ERROR:tornado.application:Exception in callback <_functools.partial object at 0x0000000009749ef8>
Traceback (most recent call last):
  File "/home/tfb/FrameworkBenchmarks/installs/pypy/site-packages/tornado-3.1-py2.7.egg/tornado/ioloop.py", line 458, in _run_callback
    callback()
  File "/home/tfb/FrameworkBenchmarks/installs/pypy/lib_pypy/_functools.py", line 22, in __call__
    return self.func(*(self.args + fargs), **fkeywords)
  File "/home/tfb/FrameworkBenchmarks/installs/pypy/site-packages/tornado-3.1-py2.7.egg/tornado/stack_context.py", line 331, in wrapped
    raise_exc_info(exc)
  File "/home/tfb/FrameworkBenchmarks/installs/pypy/site-packages/tornado-3.1-py2.7.egg/tornado/stack_context.py", line 302, in wrapped
    ret = fn(*args, **kwargs)
  File "/home/tfb/FrameworkBenchmarks/installs/pypy/site-packages/tornado-3.1-py2.7.egg/tornado/iostream.py", line 341, in wrapper
    callback(*args)
  File "/home/tfb/FrameworkBenchmarks/installs/pypy/site-packages/tornado-3.1-py2.7.egg/tornado/stack_context.py", line 331, in wrapped
    raise_exc_info(exc)
  File "/home/tfb/FrameworkBenchmarks/installs/pypy/site-packages/tornado-3.1-py2.7.egg/tornado/stack_context.py", line 302, in wrapped
    ret = fn(*args, **kwargs)
TypeError: exceptions must be old-style classes or derived from BaseException, not NoneType
ERROR:tornado.application:Uncaught exception, closing connection.
Traceback (most recent call last):
  File "/home/tfb/FrameworkBenchmarks/installs/pypy/site-packages/tornado-3.1-py2.7.egg/tornado/iostream.py", line 341, in wrapper
    callback(*args)
  File "/home/tfb/FrameworkBenchmarks/installs/pypy/site-packages/tornado-3.1-py2.7.egg/tornado/stack_context.py", line 331, in wrapped
    raise_exc_info(exc)
  File "/home/tfb/FrameworkBenchmarks/installs/pypy/site-packages/tornado-3.1-py2.7.egg/tornado/stack_context.py", line 302, in wrapped
    ret = fn(*args, **kwargs)
TypeError: exceptions must be old-style classes or derived from BaseException, not NoneType
ERROR:tornado.application:Exception in callback <_functools.partial object at 0x0000000006acbcc8>
Traceback (most recent call last):
  File "/home/tfb/FrameworkBenchmarks/installs/pypy/site-packages/tornado-3.1-py2.7.egg/tornado/ioloop.py", line 458, in _run_callback
    callback()
  File "/home/tfb/FrameworkBenchmarks/installs/pypy/lib_pypy/_functools.py", line 22, in __call__
    return self.func(*(self.args + fargs), **fkeywords)
  File "/home/tfb/FrameworkBenchmarks/installs/pypy/site-packages/tornado-3.1-py2.7.egg/tornado/stack_context.py", line 331, in wrapped
    raise_exc_info(exc)
  File "/home/tfb/FrameworkBenchmarks/installs/pypy/site-packages/tornado-3.1-py2.7.egg/tornado/stack_context.py", line 302, in wrapped
    ret = fn(*args, **kwargs)
  File "/home/tfb/FrameworkBenchmarks/installs/pypy/site-packages/tornado-3.1-py2.7.egg/tornado/iostream.py", line 341, in wrapper
    callback(*args)
  File "/home/tfb/FrameworkBenchmarks/installs/pypy/site-packages/tornado-3.1-py2.7.egg/tornado/stack_context.py", line 331, in wrapped
    raise_exc_info(exc)
  File "/home/tfb/FrameworkBenchmarks/installs/pypy/site-packages/tornado-3.1-py2.7.egg/tornado/stack_context.py", line 302, in wrapped
    ret = fn(*args, **kwargs)
TypeError: exceptions must be old-style classes or derived from BaseException, not NoneType
debug: OperationError:
debug:  operror-type: SystemExit
debug:  operror-value: 0
ERROR:tornado.application:Uncaught exception, closing connection.
Traceback (most recent call last):
  File "/home/tfb/FrameworkBenchmarks/installs/pypy/site-packages/tornado-3.1-py2.7.egg/tornado/iostream.py", line 341, in wrapper
    callback(*args)
  File "/home/tfb/FrameworkBenchmarks/installs/pypy/site-packages/tornado-3.1-py2.7.egg/tornado/stack_context.py", line 331, in wrapped
    raise_exc_info(exc)
  File "/home/tfb/FrameworkBenchmarks/installs/pypy/site-packages/tornado-3.1-py2.7.egg/tornado/stack_context.py", line 302, in wrapped
    ret = fn(*args, **kwargs)
TypeError: exceptions must be old-style classes or derived from BaseException, not NoneType
ERROR:tornado.application:Exception in callback <_functools.partial object at 0x00007fce37a36d78>
Traceback (most recent call last):
  File "/home/tfb/FrameworkBenchmarks/installs/pypy/site-packages/tornado-3.1-py2.7.egg/tornado/ioloop.py", line 458, in _run_callback
    callback()
  File "/home/tfb/FrameworkBenchmarks/installs/pypy/lib_pypy/_functools.py", line 22, in __call__
    return self.func(*(self.args + fargs), **fkeywords)
  File "/home/tfb/FrameworkBenchmarks/installs/pypy/site-packages/tornado-3.1-py2.7.egg/tornado/stack_context.py", line 331, in wrapped
    raise_exc_info(exc)
  File "/home/tfb/FrameworkBenchmarks/installs/pypy/site-packages/tornado-3.1-py2.7.egg/tornado/stack_context.py", line 302, in wrapped
    ret = fn(*args, **kwargs)
  File "/home/tfb/FrameworkBenchmarks/installs/pypy/site-packages/tornado-3.1-py2.7.egg/tornado/iostream.py", line 341, in wrapper
    callback(*args)
  File "/home/tfb/FrameworkBenchmarks/installs/pypy/site-packages/tornado-3.1-py2.7.egg/tornado/stack_context.py", line 331, in wrapped
    raise_exc_info(exc)
  File "/home/tfb/FrameworkBenchmarks/installs/pypy/site-packages/tornado-3.1-py2.7.egg/tornado/stack_context.py", line 302, in wrapped
    ret = fn(*args, **kwargs)
TypeError: exceptions must be old-style classes or derived from BaseException, not NoneType
ERROR:tornado.application:Uncaught exception, closing connection.
Traceback (most recent call last):
  File "/home/tfb/FrameworkBenchmarks/installs/pypy/site-packages/tornado-3.1-py2.7.egg/tornado/iostream.py", line 341, in wrapper
    callback(*args)
  File "/home/tfb/FrameworkBenchmarks/installs/pypy/site-packages/tornado-3.1-py2.7.egg/tornado/stack_context.py", line 331, in wrapped
    raise_exc_info(exc)
  File "/home/tfb/FrameworkBenchmarks/installs/pypy/site-packages/tornado-3.1-py2.7.egg/tornado/stack_context.py", line 302, in wrapped
    ret = fn(*args, **kwargs)
TypeError: exceptions must be old-style classes or derived from BaseException, not NoneType
ERROR:tornado.application:Uncaught exception, closing connection.
Traceback (most recent call last):
  File "/home/tfb/FrameworkBenchmarks/installs/pypy/site-packages/tornado-3.1-py2.7.egg/tornado/iostream.py", line 341, in wrapper
    callback(*args)
  File "/home/tfb/FrameworkBenchmarks/installs/pypy/site-packages/tornado-3.1-py2.7.egg/tornado/stack_context.py", line 331, in wrapped
    raise_exc_info(exc)
  File "/home/tfb/FrameworkBenchmarks/installs/pypy/site-packages/tornado-3.1-py2.7.egg/tornado/stack_context.py", line 302, in wrapped
    ret = fn(*args, **kwargs)
TypeError: exceptions must be old-style classes or derived from BaseException, not NoneType
ERROR:tornado.application:Exception in callback <_functools.partial object at 0x0000000009749f30>
Traceback (most recent call last):
  File "/home/tfb/FrameworkBenchmarks/installs/pypy/site-packages/tornado-3.1-py2.7.egg/tornado/ioloop.py", line 458, in _run_callback
    callback()
  File "/home/tfb/FrameworkBenchmarks/installs/pypy/lib_pypy/_functools.py", line 22, in __call__
    return self.func(*(self.args + fargs), **fkeywords)
  File "/home/tfb/FrameworkBenchmarks/installs/pypy/site-packages/tornado-3.1-py2.7.egg/tornado/stack_context.py", line 331, in wrapped
    raise_exc_info(exc)
  File "/home/tfb/FrameworkBenchmarks/installs/pypy/site-packages/tornado-3.1-py2.7.egg/tornado/stack_context.py", line 302, in wrapped
    ret = fn(*args, **kwargs)
  File "/home/tfb/FrameworkBenchmarks/installs/pypy/site-packages/tornado-3.1-py2.7.egg/tornado/iostream.py", line 341, in wrapper
    callback(*args)
  File "/home/tfb/FrameworkBenchmarks/installs/pypy/site-packages/tornado-3.1-py2.7.egg/tornado/stack_context.py", line 331, in wrapped
    raise_exc_info(exc)
  File "/home/tfb/FrameworkBenchmarks/installs/pypy/site-packages/tornado-3.1-py2.7.egg/tornado/stack_context.py", line 302, in wrapped
    ret = fn(*args, **kwargs)
TypeError: exceptions must be old-style classes or derived from BaseException, not NoneType
ERROR:tornado.application:Exception in callback <_functools.partial object at 0x00007fce37a36b80>
Traceback (most recent call last):
  File "/home/tfb/FrameworkBenchmarks/installs/pypy/site-packages/tornado-3.1-py2.7.egg/tornado/ioloop.py", line 458, in _run_callback
    callback()
  File "/home/tfb/FrameworkBenchmarks/installs/pypy/lib_pypy/_functools.py", line 22, in __call__
    return self.func(*(self.args + fargs), **fkeywords)
  File "/home/tfb/FrameworkBenchmarks/installs/pypy/site-packages/tornado-3.1-py2.7.egg/tornado/stack_context.py", line 331, in wrapped
    raise_exc_info(exc)
  File "/home/tfb/FrameworkBenchmarks/installs/pypy/site-packages/tornado-3.1-py2.7.egg/tornado/stack_context.py", line 302, in wrapped
    ret = fn(*args, **kwargs)
  File "/home/tfb/FrameworkBenchmarks/installs/pypy/site-packages/tornado-3.1-py2.7.egg/tornado/iostream.py", line 341, in wrapper
    callback(*args)
  File "/home/tfb/FrameworkBenchmarks/installs/pypy/site-packages/tornado-3.1-py2.7.egg/tornado/stack_context.py", line 331, in wrapped
    raise_exc_info(exc)
  File "/home/tfb/FrameworkBenchmarks/installs/pypy/site-packages/tornado-3.1-py2.7.egg/tornado/stack_context.py", line 302, in wrapped
    ret = fn(*args, **kwargs)
TypeError: exceptions must be old-style classes or derived from BaseException, not NoneType
ERROR:tornado.application:Uncaught exception, closing connection.
Traceback (most recent call last):
  File "/home/tfb/FrameworkBenchmarks/installs/pypy/site-packages/tornado-3.1-py2.7.egg/tornado/iostream.py", line 341, in wrapper
    callback(*args)
  File "/home/tfb/FrameworkBenchmarks/installs/pypy/site-packages/tornado-3.1-py2.7.egg/tornado/stack_context.py", line 331, in wrapped
    raise_exc_info(exc)
  File "/home/tfb/FrameworkBenchmarks/installs/pypy/site-packages/tornado-3.1-py2.7.egg/tornado/stack_context.py", line 302, in wrapped
    ret = fn(*args, **kwargs)
TypeError: exceptions must be old-style classes or derived from BaseException, not NoneType
ERROR:tornado.application:Exception in callback <_functools.partial object at 0x00007fce37a37de0>
Traceback (most recent call last):
  File "/home/tfb/FrameworkBenchmarks/installs/pypy/site-packages/tornado-3.1-py2.7.egg/tornado/ioloop.py", line 458, in _run_callback
    callback()
  File "/home/tfb/FrameworkBenchmarks/installs/pypy/lib_pypy/_functools.py", line 22, in __call__
    return self.func(*(self.args + fargs), **fkeywords)
  File "/home/tfb/FrameworkBenchmarks/installs/pypy/site-packages/tornado-3.1-py2.7.egg/tornado/stack_context.py", line 331, in wrapped
    raise_exc_info(exc)
  File "/home/tfb/FrameworkBenchmarks/installs/pypy/site-packages/tornado-3.1-py2.7.egg/tornado/stack_context.py", line 302, in wrapped
    ret = fn(*args, **kwargs)
  File "/home/tfb/FrameworkBenchmarks/installs/pypy/site-packages/tornado-3.1-py2.7.egg/tornado/iostream.py", line 341, in wrapper
    callback(*args)
  File "/home/tfb/FrameworkBenchmarks/installs/pypy/site-packages/tornado-3.1-py2.7.egg/tornado/stack_context.py", line 331, in wrapped
    raise_exc_info(exc)
  File "/home/tfb/FrameworkBenchmarks/installs/pypy/site-packages/tornado-3.1-py2.7.egg/tornado/stack_context.py", line 302, in wrapped
    ret = fn(*args, **kwargs)
TypeError: exceptions must be old-style classes or derived from BaseException, not NoneType
ERROR:tornado.application:Uncaught exception, closing connection.
Traceback (most recent call last):
  File "/home/tfb/FrameworkBenchmarks/installs/pypy/site-packages/tornado-3.1-py2.7.egg/tornado/iostream.py", line 341, in wrapper
    callback(*args)
  File "/home/tfb/FrameworkBenchmarks/installs/pypy/site-packages/tornado-3.1-py2.7.egg/tornado/stack_context.py", line 331, in wrapped
    raise_exc_info(exc)
  File "/home/tfb/FrameworkBenchmarks/installs/pypy/site-packages/tornado-3.1-py2.7.egg/tornado/stack_context.py", line 302, in wrapped
    ret = fn(*args, **kwargs)
TypeError: exceptions must be old-style classes or derived from BaseException, not NoneType
ERROR:tornado.application:Uncaught exception, closing connection.
Traceback (most recent call last):
  File "/home/tfb/FrameworkBenchmarks/installs/pypy/site-packages/tornado-3.1-py2.7.egg/tornado/iostream.py", line 341, in wrapper
    callback(*args)
  File "/home/tfb/FrameworkBenchmarks/installs/pypy/site-packages/tornado-3.1-py2.7.egg/tornado/stack_context.py", line 331, in wrapped
    raise_exc_info(exc)
  File "/home/tfb/FrameworkBenchmarks/installs/pypy/site-packages/tornado-3.1-py2.7.egg/tornado/stack_context.py", line 302, in wrapped
    ret = fn(*args, **kwargs)
TypeError: exceptions must be old-style classes or derived from BaseException, not NoneType
ERROR:tornado.application:Exception in callback <_functools.partial object at 0x00007fce37a36db0>
Traceback (most recent call last):
  File "/home/tfb/FrameworkBenchmarks/installs/pypy/site-packages/tornado-3.1-py2.7.egg/tornado/ioloop.py", line 458, in _run_callback
    callback()
  File "/home/tfb/FrameworkBenchmarks/installs/pypy/lib_pypy/_functools.py", line 22, in __call__
    return self.func(*(self.args + fargs), **fkeywords)
  File "/home/tfb/FrameworkBenchmarks/installs/pypy/site-packages/tornado-3.1-py2.7.egg/tornado/stack_context.py", line 331, in wrapped
    raise_exc_info(exc)
  File "/home/tfb/FrameworkBenchmarks/installs/pypy/site-packages/tornado-3.1-py2.7.egg/tornado/stack_context.py", line 302, in wrapped
    ret = fn(*args, **kwargs)
  File "/home/tfb/FrameworkBenchmarks/installs/pypy/site-packages/tornado-3.1-py2.7.egg/tornado/iostream.py", line 341, in wrapper
    callback(*args)
  File "/home/tfb/FrameworkBenchmarks/installs/pypy/site-packages/tornado-3.1-py2.7.egg/tornado/stack_context.py", line 331, in wrapped
    raise_exc_info(exc)
  File "/home/tfb/FrameworkBenchmarks/installs/pypy/site-packages/tornado-3.1-py2.7.egg/tornado/stack_context.py", line 302, in wrapped
    ret = fn(*args, **kwargs)
TypeError: exceptions must be old-style classes or derived from BaseException, not NoneType
ERROR:tornado.application:Exception in callback <_functools.partial object at 0x00007fce37a36bb8>
Traceback (most recent call last):
  File "/home/tfb/FrameworkBenchmarks/installs/pypy/site-packages/tornado-3.1-py2.7.egg/tornado/ioloop.py", line 458, in _run_callback
    callback()
  File "/home/tfb/FrameworkBenchmarks/installs/pypy/lib_pypy/_functools.py", line 22, in __call__
    return self.func(*(self.args + fargs), **fkeywords)
  File "/home/tfb/FrameworkBenchmarks/installs/pypy/site-packages/tornado-3.1-py2.7.egg/tornado/stack_context.py", line 331, in wrapped
    raise_exc_info(exc)
  File "/home/tfb/FrameworkBenchmarks/installs/pypy/site-packages/tornado-3.1-py2.7.egg/tornado/stack_context.py", line 302, in wrapped
    ret = fn(*args, **kwargs)
  File "/home/tfb/FrameworkBenchmarks/installs/pypy/site-packages/tornado-3.1-py2.7.egg/tornado/iostream.py", line 341, in wrapper
    callback(*args)
  File "/home/tfb/FrameworkBenchmarks/installs/pypy/site-packages/tornado-3.1-py2.7.egg/tornado/stack_context.py", line 331, in wrapped
    raise_exc_info(exc)
  File "/home/tfb/FrameworkBenchmarks/installs/pypy/site-packages/tornado-3.1-py2.7.egg/tornado/stack_context.py", line 302, in wrapped
    ret = fn(*args, **kwargs)
TypeError: exceptions must be old-style classes or derived from BaseException, not NoneType
ERROR:tornado.application:Uncaught exception, closing connection.
Traceback (most recent call last):
  File "/home/tfb/FrameworkBenchmarks/installs/pypy/site-packages/tornado-3.1-py2.7.egg/tornado/iostream.py", line 341, in wrapper
    callback(*args)
  File "/home/tfb/FrameworkBenchmarks/installs/pypy/site-packages/tornado-3.1-py2.7.egg/tornado/stack_context.py", line 331, in wrapped
    raise_exc_info(exc)
  File "/home/tfb/FrameworkBenchmarks/installs/pypy/site-packages/tornado-3.1-py2.7.egg/tornado/stack_context.py", line 302, in wrapped
    ret = fn(*args, **kwargs)
TypeError: exceptions must be old-style classes or derived from BaseException, not NoneType
ERROR:tornado.application:Exception in callback <_functools.partial object at 0x00007fce37a36de8>
Traceback (most recent call last):
  File "/home/tfb/FrameworkBenchmarks/installs/pypy/site-packages/tornado-3.1-py2.7.egg/tornado/ioloop.py", line 458, in _run_callback
    callback()
  File "/home/tfb/FrameworkBenchmarks/installs/pypy/lib_pypy/_functools.py", line 22, in __call__
    return self.func(*(self.args + fargs), **fkeywords)
  File "/home/tfb/FrameworkBenchmarks/installs/pypy/site-packages/tornado-3.1-py2.7.egg/tornado/stack_context.py", line 331, in wrapped
    raise_exc_info(exc)
  File "/home/tfb/FrameworkBenchmarks/installs/pypy/site-packages/tornado-3.1-py2.7.egg/tornado/stack_context.py", line 302, in wrapped
    ret = fn(*args, **kwargs)
  File "/home/tfb/FrameworkBenchmarks/installs/pypy/site-packages/tornado-3.1-py2.7.egg/tornado/iostream.py", line 341, in wrapper
    callback(*args)
  File "/home/tfb/FrameworkBenchmarks/installs/pypy/site-packages/tornado-3.1-py2.7.egg/tornado/stack_context.py", line 331, in wrapped
    raise_exc_info(exc)
  File "/home/tfb/FrameworkBenchmarks/installs/pypy/site-packages/tornado-3.1-py2.7.egg/tornado/stack_context.py", line 302, in wrapped
    ret = fn(*args, **kwargs)
TypeError: exceptions must be old-style classes or derived from BaseException, not NoneType
ERROR:tornado.application:Exception in callback <_functools.partial object at 0x0000000009749fa0>
Traceback (most recent call last):
  File "/home/tfb/FrameworkBenchmarks/installs/pypy/site-packages/tornado-3.1-py2.7.egg/tornado/ioloop.py", line 458, in _run_callback
    callback()
  File "/home/tfb/FrameworkBenchmarks/installs/pypy/lib_pypy/_functools.py", line 22, in __call__
    return self.func(*(self.args + fargs), **fkeywords)
  File "/home/tfb/FrameworkBenchmarks/installs/pypy/site-packages/tornado-3.1-py2.7.egg/tornado/stack_context.py", line 331, in wrapped
    raise_exc_info(exc)
  File "/home/tfb/FrameworkBenchmarks/installs/pypy/site-packages/tornado-3.1-py2.7.egg/tornado/stack_context.py", line 302, in wrapped
    ret = fn(*args, **kwargs)
  File "/home/tfb/FrameworkBenchmarks/installs/pypy/site-packages/tornado-3.1-py2.7.egg/tornado/iostream.py", line 341, in wrapper
    callback(*args)
  File "/home/tfb/FrameworkBenchmarks/installs/pypy/site-packages/tornado-3.1-py2.7.egg/tornado/stack_context.py", line 331, in wrapped
    raise_exc_info(exc)
  File "/home/tfb/FrameworkBenchmarks/installs/pypy/site-packages/tornado-3.1-py2.7.egg/tornado/stack_context.py", line 302, in wrapped
    ret = fn(*args, **kwargs)
TypeError: exceptions must be old-style classes or derived from BaseException, not NoneType
ERROR:tornado.application:Uncaught exception, closing connection.
Traceback (most recent call last):
  File "/home/tfb/FrameworkBenchmarks/installs/pypy/site-packages/tornado-3.1-py2.7.egg/tornado/iostream.py", line 341, in wrapper
    callback(*args)
  File "/home/tfb/FrameworkBenchmarks/installs/pypy/site-packages/tornado-3.1-py2.7.egg/tornado/stack_context.py", line 331, in wrapped
    raise_exc_info(exc)
  File "/home/tfb/FrameworkBenchmarks/installs/pypy/site-packages/tornado-3.1-py2.7.egg/tornado/stack_context.py", line 302, in wrapped
    ret = fn(*args, **kwargs)
TypeError: exceptions must be old-style classes or derived from BaseException, not NoneType
ERROR:tornado.application:Exception in callback <_functools.partial object at 0x00007fce37a36bf0>
Traceback (most recent call last):
  File "/home/tfb/FrameworkBenchmarks/installs/pypy/site-packages/tornado-3.1-py2.7.egg/tornado/ioloop.py", line 458, in _run_callback
    callback()
  File "/home/tfb/FrameworkBenchmarks/installs/pypy/lib_pypy/_functools.py", line 22, in __call__
    return self.func(*(self.args + fargs), **fkeywords)
  File "/home/tfb/FrameworkBenchmarks/installs/pypy/site-packages/tornado-3.1-py2.7.egg/tornado/stack_context.py", line 331, in wrapped
    raise_exc_info(exc)
  File "/home/tfb/FrameworkBenchmarks/installs/pypy/site-packages/tornado-3.1-py2.7.egg/tornado/stack_context.py", line 302, in wrapped
    ret = fn(*args, **kwargs)
  File "/home/tfb/FrameworkBenchmarks/installs/pypy/site-packages/tornado-3.1-py2.7.egg/tornado/iostream.py", line 341, in wrapper
    callback(*args)
  File "/home/tfb/FrameworkBenchmarks/installs/pypy/site-packages/tornado-3.1-py2.7.egg/tornado/stack_context.py", line 331, in wrapped
    raise_exc_info(exc)
  File "/home/tfb/FrameworkBenchmarks/installs/pypy/site-packages/tornado-3.1-py2.7.egg/tornado/stack_context.py", line 302, in wrapped
    ret = fn(*args, **kwargs)
TypeError: exceptions must be old-style classes or derived from BaseException, not NoneType
debug: OperationError:
debug:  operror-type: SystemExit
debug:  operror-value: 0
debug: OperationError:
debug:  operror-type: SystemExit
debug:  operror-value: 0
