2013-11-20 20:01:26 [11689] [CRITICAL] WORKER TIMEOUT (pid:11706)
2013-11-20 20:01:26 [11689] [CRITICAL] WORKER TIMEOUT (pid:11715)
2013-11-20 20:01:26 [11689] [CRITICAL] WORKER TIMEOUT (pid:11716)
2013-11-20 20:01:26 [11689] [CRITICAL] WORKER TIMEOUT (pid:11719)
2013-11-20 20:01:26 [11689] [CRITICAL] WORKER TIMEOUT (pid:11720)
2013-11-20 20:01:26 [11689] [CRITICAL] WORKER TIMEOUT (pid:11721)
2013-11-20 20:01:26 [11689] [CRITICAL] WORKER TIMEOUT (pid:11722)
2013-11-20 20:01:26 [11689] [CRITICAL] WORKER TIMEOUT (pid:11706)
2013-11-20 20:01:26 [11689] [CRITICAL] WORKER TIMEOUT (pid:11715)
2013-11-20 20:01:26 [11689] [CRITICAL] WORKER TIMEOUT (pid:11716)
2013-11-20 20:01:26 [11689] [CRITICAL] WORKER TIMEOUT (pid:11719)
2013-11-20 20:01:26 [11689] [CRITICAL] WORKER TIMEOUT (pid:11720)
2013-11-20 20:01:26 [11689] [CRITICAL] WORKER TIMEOUT (pid:11721)
2013-11-20 20:01:26 [11689] [CRITICAL] WORKER TIMEOUT (pid:11722)
2013-11-20 20:01:26 [11689] [CRITICAL] WORKER TIMEOUT (pid:11706)
2013-11-20 20:01:26 [11689] [CRITICAL] WORKER TIMEOUT (pid:11715)
2013-11-20 20:01:26 [11689] [CRITICAL] WORKER TIMEOUT (pid:11716)
2013-11-20 20:01:26 [11689] [CRITICAL] WORKER TIMEOUT (pid:11719)
2013-11-20 20:01:26 [11689] [CRITICAL] WORKER TIMEOUT (pid:11720)
2013-11-20 20:01:26 [11689] [CRITICAL] WORKER TIMEOUT (pid:11721)
2013-11-20 20:01:36 [11689] [CRITICAL] WORKER TIMEOUT (pid:11700)
2013-11-20 20:01:36 [11689] [CRITICAL] WORKER TIMEOUT (pid:11701)
2013-11-20 20:01:37 [11689] [CRITICAL] WORKER TIMEOUT (pid:11700)
2013-11-20 20:01:37 [11689] [CRITICAL] WORKER TIMEOUT (pid:11701)
2013-11-20 20:01:37 [11689] [CRITICAL] WORKER TIMEOUT (pid:11717)
2013-11-20 20:01:37 [11689] [CRITICAL] WORKER TIMEOUT (pid:11717)
2013-11-20 20:01:37 [11689] [CRITICAL] WORKER TIMEOUT (pid:11702)
2013-11-20 20:01:37 [11689] [CRITICAL] WORKER TIMEOUT (pid:11703)
2013-11-20 20:01:37 [11689] [CRITICAL] WORKER TIMEOUT (pid:11718)
2013-11-20 20:01:37 [11689] [CRITICAL] WORKER TIMEOUT (pid:11702)
2013-11-20 20:01:37 [11689] [CRITICAL] WORKER TIMEOUT (pid:11703)
2013-11-20 20:01:37 [11689] [CRITICAL] WORKER TIMEOUT (pid:11704)
2013-11-20 20:01:37 [11689] [CRITICAL] WORKER TIMEOUT (pid:11704)
2013-11-20 20:01:37 [11689] [CRITICAL] WORKER TIMEOUT (pid:11705)
2013-11-20 20:01:37 [11689] [CRITICAL] WORKER TIMEOUT (pid:11723)
2013-11-20 20:01:37 [11689] [CRITICAL] WORKER TIMEOUT (pid:11705)
2013-11-20 20:01:37 [11689] [CRITICAL] WORKER TIMEOUT (pid:11723)
2013-11-20 20:01:37 [11689] [CRITICAL] WORKER TIMEOUT (pid:11705)
ERROR:app:Exception on /raw-updates [GET]
Traceback (most recent call last):
  File "/home/tfb/FrameworkBenchmarks/installs/pypy/site-packages/Flask-0.10.1-py2.7.egg/flask/app.py", line 1817, in wsgi_app
    response = self.full_dispatch_request()
  File "/home/tfb/FrameworkBenchmarks/installs/pypy/site-packages/Flask-0.10.1-py2.7.egg/flask/app.py", line 1477, in full_dispatch_request
    rv = self.handle_user_exception(e)
  File "/home/tfb/FrameworkBenchmarks/installs/pypy/site-packages/Flask-0.10.1-py2.7.egg/flask/app.py", line 1381, in handle_user_exception
    reraise(exc_type, exc_value, tb)
  File "/home/tfb/FrameworkBenchmarks/installs/pypy/site-packages/Flask-0.10.1-py2.7.egg/flask/app.py", line 1475, in full_dispatch_request
    rv = self.dispatch_request()
  File "/home/tfb/FrameworkBenchmarks/installs/pypy/site-packages/Flask-0.10.1-py2.7.egg/flask/app.py", line 1461, in dispatch_request
    return self.view_functions[rule.endpoint](**req.view_args)
  File "/home/tfb/FrameworkBenchmarks/flask/app.py", line 143, in raw_updates
    (randomNumber, world['id']))
  File "/home/tfb/FrameworkBenchmarks/installs/pypy/site-packages/SQLAlchemy-0.8.2-py2.7.egg/sqlalchemy/engine/base.py", line 1613, in execute
    connection = self.contextual_connect(close_with_result=True)
  File "/home/tfb/FrameworkBenchmarks/installs/pypy/site-packages/SQLAlchemy-0.8.2-py2.7.egg/sqlalchemy/engine/base.py", line 1661, in contextual_connect
    self.pool.connect(),
  File "/home/tfb/FrameworkBenchmarks/installs/pypy/site-packages/SQLAlchemy-0.8.2-py2.7.egg/sqlalchemy/pool.py", line 272, in connect
    return _ConnectionFairy(self).checkout()
  File "/home/tfb/FrameworkBenchmarks/installs/pypy/site-packages/SQLAlchemy-0.8.2-py2.7.egg/sqlalchemy/pool.py", line 425, in __init__
    rec = self._connection_record = pool._do_get()
  File "/home/tfb/FrameworkBenchmarks/installs/pypy/site-packages/SQLAlchemy-0.8.2-py2.7.egg/sqlalchemy/pool.py", line 770, in _do_get
    (self.size(), self.overflow(), self._timeout))
TimeoutError: QueuePool limit of size 5 overflow 10 reached, connection timed out, timeout 30
ERROR:app:Exception on /raw-updates [GET]
Traceback (most recent call last):
  File "/home/tfb/FrameworkBenchmarks/installs/pypy/site-packages/Flask-0.10.1-py2.7.egg/flask/app.py", line 1817, in wsgi_app
    response = self.full_dispatch_request()
  File "/home/tfb/FrameworkBenchmarks/installs/pypy/site-packages/Flask-0.10.1-py2.7.egg/flask/app.py", line 1477, in full_dispatch_request
    rv = self.handle_user_exception(e)
  File "/home/tfb/FrameworkBenchmarks/installs/pypy/site-packages/Flask-0.10.1-py2.7.egg/flask/app.py", line 1381, in handle_user_exception
    reraise(exc_type, exc_value, tb)
  File "/home/tfb/FrameworkBenchmarks/installs/pypy/site-packages/Flask-0.10.1-py2.7.egg/flask/app.py", line 1475, in full_dispatch_request
    rv = self.dispatch_request()
  File "/home/tfb/FrameworkBenchmarks/installs/pypy/site-packages/Flask-0.10.1-py2.7.egg/flask/app.py", line 1461, in dispatch_request
    return self.view_functions[rule.endpoint](**req.view_args)
  File "/home/tfb/FrameworkBenchmarks/flask/app.py", line 143, in raw_updates
    (randomNumber, world['id']))
  File "/home/tfb/FrameworkBenchmarks/installs/pypy/site-packages/SQLAlchemy-0.8.2-py2.7.egg/sqlalchemy/engine/base.py", line 1613, in execute
    connection = self.contextual_connect(close_with_result=True)
  File "/home/tfb/FrameworkBenchmarks/installs/pypy/site-packages/SQLAlchemy-0.8.2-py2.7.egg/sqlalchemy/engine/base.py", line 1661, in contextual_connect
    self.pool.connect(),
  File "/home/tfb/FrameworkBenchmarks/installs/pypy/site-packages/SQLAlchemy-0.8.2-py2.7.egg/sqlalchemy/pool.py", line 272, in connect
    return _ConnectionFairy(self).checkout()
  File "/home/tfb/FrameworkBenchmarks/installs/pypy/site-packages/SQLAlchemy-0.8.2-py2.7.egg/sqlalchemy/pool.py", line 425, in __init__
    rec = self._connection_record = pool._do_get()
  File "/home/tfb/FrameworkBenchmarks/installs/pypy/site-packages/SQLAlchemy-0.8.2-py2.7.egg/sqlalchemy/pool.py", line 770, in _do_get
    (self.size(), self.overflow(), self._timeout))
TimeoutError: QueuePool limit of size 5 overflow 10 reached, connection timed out, timeout 30
ERROR:app:Exception on /raw-updates [GET]
Traceback (most recent call last):
  File "/home/tfb/FrameworkBenchmarks/installs/pypy/site-packages/Flask-0.10.1-py2.7.egg/flask/app.py", line 1817, in wsgi_app
    response = self.full_dispatch_request()
  File "/home/tfb/FrameworkBenchmarks/installs/pypy/site-packages/Flask-0.10.1-py2.7.egg/flask/app.py", line 1477, in full_dispatch_request
    rv = self.handle_user_exception(e)
  File "/home/tfb/FrameworkBenchmarks/installs/pypy/site-packages/Flask-0.10.1-py2.7.egg/flask/app.py", line 1381, in handle_user_exception
    reraise(exc_type, exc_value, tb)
  File "/home/tfb/FrameworkBenchmarks/installs/pypy/site-packages/Flask-0.10.1-py2.7.egg/flask/app.py", line 1475, in full_dispatch_request
    rv = self.dispatch_request()
  File "/home/tfb/FrameworkBenchmarks/installs/pypy/site-packages/Flask-0.10.1-py2.7.egg/flask/app.py", line 1461, in dispatch_request
    return self.view_functions[rule.endpoint](**req.view_args)
  File "/home/tfb/FrameworkBenchmarks/flask/app.py", line 143, in raw_updates
    (randomNumber, world['id']))
  File "/home/tfb/FrameworkBenchmarks/installs/pypy/site-packages/SQLAlchemy-0.8.2-py2.7.egg/sqlalchemy/engine/base.py", line 1613, in execute
    connection = self.contextual_connect(close_with_result=True)
  File "/home/tfb/FrameworkBenchmarks/installs/pypy/site-packages/SQLAlchemy-0.8.2-py2.7.egg/sqlalchemy/engine/base.py", line 1661, in contextual_connect
    self.pool.connect(),
  File "/home/tfb/FrameworkBenchmarks/installs/pypy/site-packages/SQLAlchemy-0.8.2-py2.7.egg/sqlalchemy/pool.py", line 272, in connect
    return _ConnectionFairy(self).checkout()
  File "/home/tfb/FrameworkBenchmarks/installs/pypy/site-packages/SQLAlchemy-0.8.2-py2.7.egg/sqlalchemy/pool.py", line 425, in __init__
    rec = self._connection_record = pool._do_get()
  File "/home/tfb/FrameworkBenchmarks/installs/pypy/site-packages/SQLAlchemy-0.8.2-py2.7.egg/sqlalchemy/pool.py", line 770, in _do_get
    (self.size(), self.overflow(), self._timeout))
TimeoutError: QueuePool limit of size 5 overflow 10 reached, connection timed out, timeout 30
ERROR:app:Exception on /raw-updates [GET]
Traceback (most recent call last):
  File "/home/tfb/FrameworkBenchmarks/installs/pypy/site-packages/Flask-0.10.1-py2.7.egg/flask/app.py", line 1817, in wsgi_app
    response = self.full_dispatch_request()
  File "/home/tfb/FrameworkBenchmarks/installs/pypy/site-packages/Flask-0.10.1-py2.7.egg/flask/app.py", line 1477, in full_dispatch_request
    rv = self.handle_user_exception(e)
  File "/home/tfb/FrameworkBenchmarks/installs/pypy/site-packages/Flask-0.10.1-py2.7.egg/flask/app.py", line 1381, in handle_user_exception
    reraise(exc_type, exc_value, tb)
  File "/home/tfb/FrameworkBenchmarks/installs/pypy/site-packages/Flask-0.10.1-py2.7.egg/flask/app.py", line 1475, in full_dispatch_request
    rv = self.dispatch_request()
  File "/home/tfb/FrameworkBenchmarks/installs/pypy/site-packages/Flask-0.10.1-py2.7.egg/flask/app.py", line 1461, in dispatch_request
    return self.view_functions[rule.endpoint](**req.view_args)
  File "/home/tfb/FrameworkBenchmarks/flask/app.py", line 143, in raw_updates
    (randomNumber, world['id']))
  File "/home/tfb/FrameworkBenchmarks/installs/pypy/site-packages/SQLAlchemy-0.8.2-py2.7.egg/sqlalchemy/engine/base.py", line 1613, in execute
    connection = self.contextual_connect(close_with_result=True)
  File "/home/tfb/FrameworkBenchmarks/installs/pypy/site-packages/SQLAlchemy-0.8.2-py2.7.egg/sqlalchemy/engine/base.py", line 1661, in contextual_connect
    self.pool.connect(),
  File "/home/tfb/FrameworkBenchmarks/installs/pypy/site-packages/SQLAlchemy-0.8.2-py2.7.egg/sqlalchemy/pool.py", line 272, in connect
    return _ConnectionFairy(self).checkout()
  File "/home/tfb/FrameworkBenchmarks/installs/pypy/site-packages/SQLAlchemy-0.8.2-py2.7.egg/sqlalchemy/pool.py", line 425, in __init__
    rec = self._connection_record = pool._do_get()
  File "/home/tfb/FrameworkBenchmarks/installs/pypy/site-packages/SQLAlchemy-0.8.2-py2.7.egg/sqlalchemy/pool.py", line 770, in _do_get
    (self.size(), self.overflow(), self._timeout))
TimeoutError: QueuePool limit of size 5 overflow 10 reached, connection timed out, timeout 30
ERROR:app:Exception on /raw-updates [GET]
Traceback (most recent call last):
  File "/home/tfb/FrameworkBenchmarks/installs/pypy/site-packages/Flask-0.10.1-py2.7.egg/flask/app.py", line 1817, in wsgi_app
    response = self.full_dispatch_request()
  File "/home/tfb/FrameworkBenchmarks/installs/pypy/site-packages/Flask-0.10.1-py2.7.egg/flask/app.py", line 1477, in full_dispatch_request
    rv = self.handle_user_exception(e)
  File "/home/tfb/FrameworkBenchmarks/installs/pypy/site-packages/Flask-0.10.1-py2.7.egg/flask/app.py", line 1381, in handle_user_exception
    reraise(exc_type, exc_value, tb)
  File "/home/tfb/FrameworkBenchmarks/installs/pypy/site-packages/Flask-0.10.1-py2.7.egg/flask/app.py", line 1475, in full_dispatch_request
    rv = self.dispatch_request()
  File "/home/tfb/FrameworkBenchmarks/installs/pypy/site-packages/Flask-0.10.1-py2.7.egg/flask/app.py", line 1461, in dispatch_request
    return self.view_functions[rule.endpoint](**req.view_args)
  File "/home/tfb/FrameworkBenchmarks/flask/app.py", line 143, in raw_updates
    (randomNumber, world['id']))
  File "/home/tfb/FrameworkBenchmarks/installs/pypy/site-packages/SQLAlchemy-0.8.2-py2.7.egg/sqlalchemy/engine/base.py", line 1613, in execute
    connection = self.contextual_connect(close_with_result=True)
  File "/home/tfb/FrameworkBenchmarks/installs/pypy/site-packages/SQLAlchemy-0.8.2-py2.7.egg/sqlalchemy/engine/base.py", line 1661, in contextual_connect
    self.pool.connect(),
  File "/home/tfb/FrameworkBenchmarks/installs/pypy/site-packages/SQLAlchemy-0.8.2-py2.7.egg/sqlalchemy/pool.py", line 272, in connect
    return _ConnectionFairy(self).checkout()
  File "/home/tfb/FrameworkBenchmarks/installs/pypy/site-packages/SQLAlchemy-0.8.2-py2.7.egg/sqlalchemy/pool.py", line 425, in __init__
    rec = self._connection_record = pool._do_get()
  File "/home/tfb/FrameworkBenchmarks/installs/pypy/site-packages/SQLAlchemy-0.8.2-py2.7.egg/sqlalchemy/pool.py", line 770, in _do_get
    (self.size(), self.overflow(), self._timeout))
TimeoutError: QueuePool limit of size 5 overflow 10 reached, connection timed out, timeout 30
ERROR:tornado.access:500 GET /raw-updates?queries=2 (172.16.98.98) 30107.50ms
ERROR:tornado.access:500 GET /raw-updates?queries=2 (172.16.98.98) 30121.30ms
ERROR:tornado.access:500 GET /raw-updates?queries=2 (172.16.98.98) 30127.49ms
ERROR:tornado.access:500 GET /raw-updates?queries=2 (172.16.98.98) 30119.60ms
ERROR:tornado.access:500 GET /raw-updates?queries=2 (172.16.98.98) 30151.09ms
ERROR:tornado.access:500 GET /raw-updates?queries=2 (172.16.98.98) 30130.11ms
ERROR:tornado.access:500 GET /raw-updates?queries=2 (172.16.98.98) 30135.63ms
2013-11-20 20:01:38 [11689] [CRITICAL] WORKER TIMEOUT (pid:11707)
2013-11-20 20:01:38 [11689] [CRITICAL] WORKER TIMEOUT (pid:11708)
2013-11-20 20:01:38 [11689] [CRITICAL] WORKER TIMEOUT (pid:11709)
2013-11-20 20:01:38 [11689] [CRITICAL] WORKER TIMEOUT (pid:11711)
2013-11-20 20:01:38 [11689] [CRITICAL] WORKER TIMEOUT (pid:11712)
2013-11-20 20:01:38 [11689] [CRITICAL] WORKER TIMEOUT (pid:11713)
2013-11-20 20:01:38 [11689] [CRITICAL] WORKER TIMEOUT (pid:11714)
2013-11-20 20:01:38 [11689] [CRITICAL] WORKER TIMEOUT (pid:11707)
2013-11-20 20:01:38 [11689] [CRITICAL] WORKER TIMEOUT (pid:11708)
2013-11-20 20:01:38 [11689] [CRITICAL] WORKER TIMEOUT (pid:11709)
2013-11-20 20:01:38 [11689] [CRITICAL] WORKER TIMEOUT (pid:11711)
2013-11-20 20:01:38 [11689] [CRITICAL] WORKER TIMEOUT (pid:11712)
2013-11-20 20:01:38 [11689] [CRITICAL] WORKER TIMEOUT (pid:11713)
2013-11-20 20:01:38 [11689] [CRITICAL] WORKER TIMEOUT (pid:11714)
2013-11-20 20:01:38 [11689] [CRITICAL] WORKER TIMEOUT (pid:11709)
2013-11-20 20:01:38 [11689] [CRITICAL] WORKER TIMEOUT (pid:11711)
2013-11-20 20:01:38 [11689] [CRITICAL] WORKER TIMEOUT (pid:11712)
2013-11-20 20:01:38 [11689] [CRITICAL] WORKER TIMEOUT (pid:11713)
2013-11-20 20:01:38 [11689] [CRITICAL] WORKER TIMEOUT (pid:11714)
2013-11-20 20:01:56 [11689] [CRITICAL] WORKER TIMEOUT (pid:11760)
2013-11-20 20:01:56 [11689] [CRITICAL] WORKER TIMEOUT (pid:11760)
ERROR:app:Exception on /raw-updates [GET]
Traceback (most recent call last):
  File "/home/tfb/FrameworkBenchmarks/installs/pypy/site-packages/Flask-0.10.1-py2.7.egg/flask/app.py", line 1817, in wsgi_app
    response = self.full_dispatch_request()
  File "/home/tfb/FrameworkBenchmarks/installs/pypy/site-packages/Flask-0.10.1-py2.7.egg/flask/app.py", line 1477, in full_dispatch_request
    rv = self.handle_user_exception(e)
  File "/home/tfb/FrameworkBenchmarks/installs/pypy/site-packages/Flask-0.10.1-py2.7.egg/flask/app.py", line 1381, in handle_user_exception
    reraise(exc_type, exc_value, tb)
  File "/home/tfb/FrameworkBenchmarks/installs/pypy/site-packages/Flask-0.10.1-py2.7.egg/flask/app.py", line 1475, in full_dispatch_request
    rv = self.dispatch_request()
  File "/home/tfb/FrameworkBenchmarks/installs/pypy/site-packages/Flask-0.10.1-py2.7.egg/flask/app.py", line 1461, in dispatch_request
    return self.view_functions[rule.endpoint](**req.view_args)
  File "/home/tfb/FrameworkBenchmarks/flask/app.py", line 143, in raw_updates
    (randomNumber, world['id']))
  File "/home/tfb/FrameworkBenchmarks/installs/pypy/site-packages/SQLAlchemy-0.8.2-py2.7.egg/sqlalchemy/engine/base.py", line 1613, in execute
    connection = self.contextual_connect(close_with_result=True)
  File "/home/tfb/FrameworkBenchmarks/installs/pypy/site-packages/SQLAlchemy-0.8.2-py2.7.egg/sqlalchemy/engine/base.py", line 1661, in contextual_connect
    self.pool.connect(),
  File "/home/tfb/FrameworkBenchmarks/installs/pypy/site-packages/SQLAlchemy-0.8.2-py2.7.egg/sqlalchemy/pool.py", line 272, in connect
    return _ConnectionFairy(self).checkout()
  File "/home/tfb/FrameworkBenchmarks/installs/pypy/site-packages/SQLAlchemy-0.8.2-py2.7.egg/sqlalchemy/pool.py", line 425, in __init__
    rec = self._connection_record = pool._do_get()
  File "/home/tfb/FrameworkBenchmarks/installs/pypy/site-packages/SQLAlchemy-0.8.2-py2.7.egg/sqlalchemy/pool.py", line 770, in _do_get
    (self.size(), self.overflow(), self._timeout))
TimeoutError: QueuePool limit of size 5 overflow 10 reached, connection timed out, timeout 30
ERROR:app:Exception on /raw-updates [GET]
Traceback (most recent call last):
  File "/home/tfb/FrameworkBenchmarks/installs/pypy/site-packages/Flask-0.10.1-py2.7.egg/flask/app.py", line 1817, in wsgi_app
    response = self.full_dispatch_request()
  File "/home/tfb/FrameworkBenchmarks/installs/pypy/site-packages/Flask-0.10.1-py2.7.egg/flask/app.py", line 1477, in full_dispatch_request
    rv = self.handle_user_exception(e)
  File "/home/tfb/FrameworkBenchmarks/installs/pypy/site-packages/Flask-0.10.1-py2.7.egg/flask/app.py", line 1381, in handle_user_exception
    reraise(exc_type, exc_value, tb)
  File "/home/tfb/FrameworkBenchmarks/installs/pypy/site-packages/Flask-0.10.1-py2.7.egg/flask/app.py", line 1475, in full_dispatch_request
    rv = self.dispatch_request()
  File "/home/tfb/FrameworkBenchmarks/installs/pypy/site-packages/Flask-0.10.1-py2.7.egg/flask/app.py", line 1461, in dispatch_request
    return self.view_functions[rule.endpoint](**req.view_args)
  File "/home/tfb/FrameworkBenchmarks/flask/app.py", line 143, in raw_updates
    (randomNumber, world['id']))
  File "/home/tfb/FrameworkBenchmarks/installs/pypy/site-packages/SQLAlchemy-0.8.2-py2.7.egg/sqlalchemy/engine/base.py", line 1613, in execute
    connection = self.contextual_connect(close_with_result=True)
  File "/home/tfb/FrameworkBenchmarks/installs/pypy/site-packages/SQLAlchemy-0.8.2-py2.7.egg/sqlalchemy/engine/base.py", line 1661, in contextual_connect
    self.pool.connect(),
  File "/home/tfb/FrameworkBenchmarks/installs/pypy/site-packages/SQLAlchemy-0.8.2-py2.7.egg/sqlalchemy/pool.py", line 272, in connect
    return _ConnectionFairy(self).checkout()
  File "/home/tfb/FrameworkBenchmarks/installs/pypy/site-packages/SQLAlchemy-0.8.2-py2.7.egg/sqlalchemy/pool.py", line 425, in __init__
    rec = self._connection_record = pool._do_get()
  File "/home/tfb/FrameworkBenchmarks/installs/pypy/site-packages/SQLAlchemy-0.8.2-py2.7.egg/sqlalchemy/pool.py", line 770, in _do_get
    (self.size(), self.overflow(), self._timeout))
TimeoutError: QueuePool limit of size 5 overflow 10 reached, connection timed out, timeout 30
ERROR:app:Exception on /raw-updates [GET]
Traceback (most recent call last):
  File "/home/tfb/FrameworkBenchmarks/installs/pypy/site-packages/Flask-0.10.1-py2.7.egg/flask/app.py", line 1817, in wsgi_app
    response = self.full_dispatch_request()
  File "/home/tfb/FrameworkBenchmarks/installs/pypy/site-packages/Flask-0.10.1-py2.7.egg/flask/app.py", line 1477, in full_dispatch_request
    rv = self.handle_user_exception(e)
  File "/home/tfb/FrameworkBenchmarks/installs/pypy/site-packages/Flask-0.10.1-py2.7.egg/flask/app.py", line 1381, in handle_user_exception
    reraise(exc_type, exc_value, tb)
  File "/home/tfb/FrameworkBenchmarks/installs/pypy/site-packages/Flask-0.10.1-py2.7.egg/flask/app.py", line 1475, in full_dispatch_request
    rv = self.dispatch_request()
  File "/home/tfb/FrameworkBenchmarks/installs/pypy/site-packages/Flask-0.10.1-py2.7.egg/flask/app.py", line 1461, in dispatch_request
    return self.view_functions[rule.endpoint](**req.view_args)
  File "/home/tfb/FrameworkBenchmarks/flask/app.py", line 143, in raw_updates
    (randomNumber, world['id']))
  File "/home/tfb/FrameworkBenchmarks/installs/pypy/site-packages/SQLAlchemy-0.8.2-py2.7.egg/sqlalchemy/engine/base.py", line 1613, in execute
    connection = self.contextual_connect(close_with_result=True)
  File "/home/tfb/FrameworkBenchmarks/installs/pypy/site-packages/SQLAlchemy-0.8.2-py2.7.egg/sqlalchemy/engine/base.py", line 1661, in contextual_connect
    self.pool.connect(),
  File "/home/tfb/FrameworkBenchmarks/installs/pypy/site-packages/SQLAlchemy-0.8.2-py2.7.egg/sqlalchemy/pool.py", line 272, in connect
    return _ConnectionFairy(self).checkout()
  File "/home/tfb/FrameworkBenchmarks/installs/pypy/site-packages/SQLAlchemy-0.8.2-py2.7.egg/sqlalchemy/pool.py", line 425, in __init__
    rec = self._connection_record = pool._do_get()
  File "/home/tfb/FrameworkBenchmarks/installs/pypy/site-packages/SQLAlchemy-0.8.2-py2.7.egg/sqlalchemy/pool.py", line 770, in _do_get
    (self.size(), self.overflow(), self._timeout))
TimeoutError: QueuePool limit of size 5 overflow 10 reached, connection timed out, timeout 30
ERROR:app:Exception on /raw-updates [GET]
Traceback (most recent call last):
  File "/home/tfb/FrameworkBenchmarks/installs/pypy/site-packages/Flask-0.10.1-py2.7.egg/flask/app.py", line 1817, in wsgi_app
    response = self.full_dispatch_request()
  File "/home/tfb/FrameworkBenchmarks/installs/pypy/site-packages/Flask-0.10.1-py2.7.egg/flask/app.py", line 1477, in full_dispatch_request
    rv = self.handle_user_exception(e)
  File "/home/tfb/FrameworkBenchmarks/installs/pypy/site-packages/Flask-0.10.1-py2.7.egg/flask/app.py", line 1381, in handle_user_exception
    reraise(exc_type, exc_value, tb)
  File "/home/tfb/FrameworkBenchmarks/installs/pypy/site-packages/Flask-0.10.1-py2.7.egg/flask/app.py", line 1475, in full_dispatch_request
    rv = self.dispatch_request()
  File "/home/tfb/FrameworkBenchmarks/installs/pypy/site-packages/Flask-0.10.1-py2.7.egg/flask/app.py", line 1461, in dispatch_request
    return self.view_functions[rule.endpoint](**req.view_args)
  File "/home/tfb/FrameworkBenchmarks/flask/app.py", line 143, in raw_updates
    (randomNumber, world['id']))
  File "/home/tfb/FrameworkBenchmarks/installs/pypy/site-packages/SQLAlchemy-0.8.2-py2.7.egg/sqlalchemy/engine/base.py", line 1613, in execute
    connection = self.contextual_connect(close_with_result=True)
  File "/home/tfb/FrameworkBenchmarks/installs/pypy/site-packages/SQLAlchemy-0.8.2-py2.7.egg/sqlalchemy/engine/base.py", line 1661, in contextual_connect
    self.pool.connect(),
  File "/home/tfb/FrameworkBenchmarks/installs/pypy/site-packages/SQLAlchemy-0.8.2-py2.7.egg/sqlalchemy/pool.py", line 272, in connect
    return _ConnectionFairy(self).checkout()
  File "/home/tfb/FrameworkBenchmarks/installs/pypy/site-packages/SQLAlchemy-0.8.2-py2.7.egg/sqlalchemy/pool.py", line 425, in __init__
    rec = self._connection_record = pool._do_get()
  File "/home/tfb/FrameworkBenchmarks/installs/pypy/site-packages/SQLAlchemy-0.8.2-py2.7.egg/sqlalchemy/pool.py", line 770, in _do_get
    (self.size(), self.overflow(), self._timeout))
TimeoutError: QueuePool limit of size 5 overflow 10 reached, connection timed out, timeout 30
ERROR:app:Exception on /raw-updates [GET]
Traceback (most recent call last):
  File "/home/tfb/FrameworkBenchmarks/installs/pypy/site-packages/Flask-0.10.1-py2.7.egg/flask/app.py", line 1817, in wsgi_app
    response = self.full_dispatch_request()
  File "/home/tfb/FrameworkBenchmarks/installs/pypy/site-packages/Flask-0.10.1-py2.7.egg/flask/app.py", line 1477, in full_dispatch_request
    rv = self.handle_user_exception(e)
  File "/home/tfb/FrameworkBenchmarks/installs/pypy/site-packages/Flask-0.10.1-py2.7.egg/flask/app.py", line 1381, in handle_user_exception
    reraise(exc_type, exc_value, tb)
  File "/home/tfb/FrameworkBenchmarks/installs/pypy/site-packages/Flask-0.10.1-py2.7.egg/flask/app.py", line 1475, in full_dispatch_request
    rv = self.dispatch_request()
  File "/home/tfb/FrameworkBenchmarks/installs/pypy/site-packages/Flask-0.10.1-py2.7.egg/flask/app.py", line 1461, in dispatch_request
    return self.view_functions[rule.endpoint](**req.view_args)
  File "/home/tfb/FrameworkBenchmarks/flask/app.py", line 143, in raw_updates
    (randomNumber, world['id']))
  File "/home/tfb/FrameworkBenchmarks/installs/pypy/site-packages/SQLAlchemy-0.8.2-py2.7.egg/sqlalchemy/engine/base.py", line 1613, in execute
    connection = self.contextual_connect(close_with_result=True)
  File "/home/tfb/FrameworkBenchmarks/installs/pypy/site-packages/SQLAlchemy-0.8.2-py2.7.egg/sqlalchemy/engine/base.py", line 1661, in contextual_connect
    self.pool.connect(),
  File "/home/tfb/FrameworkBenchmarks/installs/pypy/site-packages/SQLAlchemy-0.8.2-py2.7.egg/sqlalchemy/pool.py", line 272, in connect
    return _ConnectionFairy(self).checkout()
  File "/home/tfb/FrameworkBenchmarks/installs/pypy/site-packages/SQLAlchemy-0.8.2-py2.7.egg/sqlalchemy/pool.py", line 425, in __init__
    rec = self._connection_record = pool._do_get()
  File "/home/tfb/FrameworkBenchmarks/installs/pypy/site-packages/SQLAlchemy-0.8.2-py2.7.egg/sqlalchemy/pool.py", line 770, in _do_get
    (self.size(), self.overflow(), self._timeout))
TimeoutError: QueuePool limit of size 5 overflow 10 reached, connection timed out, timeout 30
ERROR:app:Exception on /raw-updates [GET]
Traceback (most recent call last):
  File "/home/tfb/FrameworkBenchmarks/installs/pypy/site-packages/Flask-0.10.1-py2.7.egg/flask/app.py", line 1817, in wsgi_app
    response = self.full_dispatch_request()
  File "/home/tfb/FrameworkBenchmarks/installs/pypy/site-packages/Flask-0.10.1-py2.7.egg/flask/app.py", line 1477, in full_dispatch_request
    rv = self.handle_user_exception(e)
  File "/home/tfb/FrameworkBenchmarks/installs/pypy/site-packages/Flask-0.10.1-py2.7.egg/flask/app.py", line 1381, in handle_user_exception
    reraise(exc_type, exc_value, tb)
  File "/home/tfb/FrameworkBenchmarks/installs/pypy/site-packages/Flask-0.10.1-py2.7.egg/flask/app.py", line 1475, in full_dispatch_request
    rv = self.dispatch_request()
  File "/home/tfb/FrameworkBenchmarks/installs/pypy/site-packages/Flask-0.10.1-py2.7.egg/flask/app.py", line 1461, in dispatch_request
    return self.view_functions[rule.endpoint](**req.view_args)
  File "/home/tfb/FrameworkBenchmarks/flask/app.py", line 143, in raw_updates
    (randomNumber, world['id']))
  File "/home/tfb/FrameworkBenchmarks/installs/pypy/site-packages/SQLAlchemy-0.8.2-py2.7.egg/sqlalchemy/engine/base.py", line 1613, in execute
    connection = self.contextual_connect(close_with_result=True)
  File "/home/tfb/FrameworkBenchmarks/installs/pypy/site-packages/SQLAlchemy-0.8.2-py2.7.egg/sqlalchemy/engine/base.py", line 1661, in contextual_connect
    self.pool.connect(),
  File "/home/tfb/FrameworkBenchmarks/installs/pypy/site-packages/SQLAlchemy-0.8.2-py2.7.egg/sqlalchemy/pool.py", line 272, in connect
    return _ConnectionFairy(self).checkout()
  File "/home/tfb/FrameworkBenchmarks/installs/pypy/site-packages/SQLAlchemy-0.8.2-py2.7.egg/sqlalchemy/pool.py", line 425, in __init__
    rec = self._connection_record = pool._do_get()
  File "/home/tfb/FrameworkBenchmarks/installs/pypy/site-packages/SQLAlchemy-0.8.2-py2.7.egg/sqlalchemy/pool.py", line 770, in _do_get
    (self.size(), self.overflow(), self._timeout))
TimeoutError: QueuePool limit of size 5 overflow 10 reached, connection timed out, timeout 30
ERROR:tornado.access:500 GET /raw-updates?queries=1 (172.16.98.98) 30032.10ms
ERROR:tornado.access:500 GET /raw-updates?queries=1 (172.16.98.98) 30032.12ms
ERROR:tornado.access:500 GET /raw-updates?queries=1 (172.16.98.98) 30043.62ms
ERROR:tornado.access:500 GET /raw-updates?queries=1 (172.16.98.98) 30047.09ms
ERROR:tornado.access:500 GET /raw-updates?queries=1 (172.16.98.98) 30046.43ms
ERROR:tornado.access:500 GET /raw-updates?queries=1 (172.16.98.98) 30047.07ms
2013-11-20 20:01:58 [11689] [CRITICAL] WORKER TIMEOUT (pid:11761)
2013-11-20 20:01:58 [11689] [CRITICAL] WORKER TIMEOUT (pid:11762)
2013-11-20 20:01:58 [11689] [CRITICAL] WORKER TIMEOUT (pid:11763)
2013-11-20 20:01:58 [11689] [CRITICAL] WORKER TIMEOUT (pid:11764)
2013-11-20 20:01:58 [11689] [CRITICAL] WORKER TIMEOUT (pid:11766)
2013-11-20 20:01:58 [11689] [CRITICAL] WORKER TIMEOUT (pid:11767)
2013-11-20 20:01:58 [11689] [CRITICAL] WORKER TIMEOUT (pid:11761)
2013-11-20 20:01:58 [11689] [CRITICAL] WORKER TIMEOUT (pid:11762)
2013-11-20 20:01:58 [11689] [CRITICAL] WORKER TIMEOUT (pid:11763)
2013-11-20 20:01:58 [11689] [CRITICAL] WORKER TIMEOUT (pid:11764)
2013-11-20 20:01:58 [11689] [CRITICAL] WORKER TIMEOUT (pid:11766)
2013-11-20 20:01:58 [11689] [CRITICAL] WORKER TIMEOUT (pid:11767)
2013-11-20 20:01:58 [11689] [CRITICAL] WORKER TIMEOUT (pid:11761)
2013-11-20 20:01:58 [11689] [CRITICAL] WORKER TIMEOUT (pid:11763)
2013-11-20 20:01:58 [11689] [CRITICAL] WORKER TIMEOUT (pid:11766)
2013-11-20 20:01:58 [11689] [CRITICAL] WORKER TIMEOUT (pid:11767)
2013-11-20 20:02:07 [11689] [CRITICAL] WORKER TIMEOUT (pid:11775)
2013-11-20 20:02:07 [11689] [CRITICAL] WORKER TIMEOUT (pid:11775)
ERROR:app:Exception on /raw-updates [GET]
Traceback (most recent call last):
  File "/home/tfb/FrameworkBenchmarks/installs/pypy/site-packages/Flask-0.10.1-py2.7.egg/flask/app.py", line 1817, in wsgi_app
    response = self.full_dispatch_request()
  File "/home/tfb/FrameworkBenchmarks/installs/pypy/site-packages/Flask-0.10.1-py2.7.egg/flask/app.py", line 1477, in full_dispatch_request
    rv = self.handle_user_exception(e)
  File "/home/tfb/FrameworkBenchmarks/installs/pypy/site-packages/Flask-0.10.1-py2.7.egg/flask/app.py", line 1381, in handle_user_exception
    reraise(exc_type, exc_value, tb)
  File "/home/tfb/FrameworkBenchmarks/installs/pypy/site-packages/Flask-0.10.1-py2.7.egg/flask/app.py", line 1475, in full_dispatch_request
    rv = self.dispatch_request()
  File "/home/tfb/FrameworkBenchmarks/installs/pypy/site-packages/Flask-0.10.1-py2.7.egg/flask/app.py", line 1461, in dispatch_request
    return self.view_functions[rule.endpoint](**req.view_args)
  File "/home/tfb/FrameworkBenchmarks/flask/app.py", line 139, in raw_updates
    world = dbraw_engine.execute("SELECT * FROM World WHERE id=%s", (rp(),)).fetchone()
  File "/home/tfb/FrameworkBenchmarks/installs/pypy/site-packages/SQLAlchemy-0.8.2-py2.7.egg/sqlalchemy/engine/base.py", line 1613, in execute
    connection = self.contextual_connect(close_with_result=True)
  File "/home/tfb/FrameworkBenchmarks/installs/pypy/site-packages/SQLAlchemy-0.8.2-py2.7.egg/sqlalchemy/engine/base.py", line 1661, in contextual_connect
    self.pool.connect(),
  File "/home/tfb/FrameworkBenchmarks/installs/pypy/site-packages/SQLAlchemy-0.8.2-py2.7.egg/sqlalchemy/pool.py", line 272, in connect
    return _ConnectionFairy(self).checkout()
  File "/home/tfb/FrameworkBenchmarks/installs/pypy/site-packages/SQLAlchemy-0.8.2-py2.7.egg/sqlalchemy/pool.py", line 425, in __init__
    rec = self._connection_record = pool._do_get()
  File "/home/tfb/FrameworkBenchmarks/installs/pypy/site-packages/SQLAlchemy-0.8.2-py2.7.egg/sqlalchemy/pool.py", line 770, in _do_get
    (self.size(), self.overflow(), self._timeout))
TimeoutError: QueuePool limit of size 5 overflow 10 reached, connection timed out, timeout 30
ERROR:tornado.access:500 GET /raw-updates?queries=2 (172.16.98.98) 30001.73ms
2013-11-20 20:02:08 [11689] [CRITICAL] WORKER TIMEOUT (pid:11710)
2013-11-20 20:02:08 [11689] [CRITICAL] WORKER TIMEOUT (pid:11710)
2013-11-20 20:02:16 [11689] [CRITICAL] WORKER TIMEOUT (pid:11776)
2013-11-20 20:02:16 [11689] [CRITICAL] WORKER TIMEOUT (pid:11777)
2013-11-20 20:02:16 [11689] [CRITICAL] WORKER TIMEOUT (pid:11789)
2013-11-20 20:02:16 [11689] [CRITICAL] WORKER TIMEOUT (pid:11790)
2013-11-20 20:02:16 [11689] [CRITICAL] WORKER TIMEOUT (pid:11774)
2013-11-20 20:02:16 [11689] [CRITICAL] WORKER TIMEOUT (pid:11776)
2013-11-20 20:02:16 [11689] [CRITICAL] WORKER TIMEOUT (pid:11777)
2013-11-20 20:02:16 [11689] [CRITICAL] WORKER TIMEOUT (pid:11789)
2013-11-20 20:02:16 [11689] [CRITICAL] WORKER TIMEOUT (pid:11790)
2013-11-20 20:02:16 [11689] [CRITICAL] WORKER TIMEOUT (pid:11774)
ERROR:app:Exception on /raw-updates [GET]
Traceback (most recent call last):
  File "/home/tfb/FrameworkBenchmarks/installs/pypy/site-packages/Flask-0.10.1-py2.7.egg/flask/app.py", line 1817, in wsgi_app
    response = self.full_dispatch_request()
  File "/home/tfb/FrameworkBenchmarks/installs/pypy/site-packages/Flask-0.10.1-py2.7.egg/flask/app.py", line 1477, in full_dispatch_request
    rv = self.handle_user_exception(e)
  File "/home/tfb/FrameworkBenchmarks/installs/pypy/site-packages/Flask-0.10.1-py2.7.egg/flask/app.py", line 1381, in handle_user_exception
    reraise(exc_type, exc_value, tb)
  File "/home/tfb/FrameworkBenchmarks/installs/pypy/site-packages/Flask-0.10.1-py2.7.egg/flask/app.py", line 1475, in full_dispatch_request
    rv = self.dispatch_request()
  File "/home/tfb/FrameworkBenchmarks/installs/pypy/site-packages/Flask-0.10.1-py2.7.egg/flask/app.py", line 1461, in dispatch_request
    return self.view_functions[rule.endpoint](**req.view_args)
  File "/home/tfb/FrameworkBenchmarks/flask/app.py", line 143, in raw_updates
    (randomNumber, world['id']))
  File "/home/tfb/FrameworkBenchmarks/installs/pypy/site-packages/SQLAlchemy-0.8.2-py2.7.egg/sqlalchemy/engine/base.py", line 1613, in execute
    connection = self.contextual_connect(close_with_result=True)
  File "/home/tfb/FrameworkBenchmarks/installs/pypy/site-packages/SQLAlchemy-0.8.2-py2.7.egg/sqlalchemy/engine/base.py", line 1661, in contextual_connect
    self.pool.connect(),
  File "/home/tfb/FrameworkBenchmarks/installs/pypy/site-packages/SQLAlchemy-0.8.2-py2.7.egg/sqlalchemy/pool.py", line 272, in connect
    return _ConnectionFairy(self).checkout()
  File "/home/tfb/FrameworkBenchmarks/installs/pypy/site-packages/SQLAlchemy-0.8.2-py2.7.egg/sqlalchemy/pool.py", line 425, in __init__
    rec = self._connection_record = pool._do_get()
  File "/home/tfb/FrameworkBenchmarks/installs/pypy/site-packages/SQLAlchemy-0.8.2-py2.7.egg/sqlalchemy/pool.py", line 770, in _do_get
    (self.size(), self.overflow(), self._timeout))
TimeoutError: QueuePool limit of size 5 overflow 10 reached, connection timed out, timeout 30
ERROR:app:Exception on /raw-updates [GET]
Traceback (most recent call last):
  File "/home/tfb/FrameworkBenchmarks/installs/pypy/site-packages/Flask-0.10.1-py2.7.egg/flask/app.py", line 1817, in wsgi_app
    response = self.full_dispatch_request()
  File "/home/tfb/FrameworkBenchmarks/installs/pypy/site-packages/Flask-0.10.1-py2.7.egg/flask/app.py", line 1477, in full_dispatch_request
    rv = self.handle_user_exception(e)
  File "/home/tfb/FrameworkBenchmarks/installs/pypy/site-packages/Flask-0.10.1-py2.7.egg/flask/app.py", line 1381, in handle_user_exception
    reraise(exc_type, exc_value, tb)
  File "/home/tfb/FrameworkBenchmarks/installs/pypy/site-packages/Flask-0.10.1-py2.7.egg/flask/app.py", line 1475, in full_dispatch_request
    rv = self.dispatch_request()
  File "/home/tfb/FrameworkBenchmarks/installs/pypy/site-packages/Flask-0.10.1-py2.7.egg/flask/app.py", line 1461, in dispatch_request
    return self.view_functions[rule.endpoint](**req.view_args)
  File "/home/tfb/FrameworkBenchmarks/flask/app.py", line 143, in raw_updates
    (randomNumber, world['id']))
  File "/home/tfb/FrameworkBenchmarks/installs/pypy/site-packages/SQLAlchemy-0.8.2-py2.7.egg/sqlalchemy/engine/base.py", line 1613, in execute
    connection = self.contextual_connect(close_with_result=True)
  File "/home/tfb/FrameworkBenchmarks/installs/pypy/site-packages/SQLAlchemy-0.8.2-py2.7.egg/sqlalchemy/engine/base.py", line 1661, in contextual_connect
    self.pool.connect(),
  File "/home/tfb/FrameworkBenchmarks/installs/pypy/site-packages/SQLAlchemy-0.8.2-py2.7.egg/sqlalchemy/pool.py", line 272, in connect
    return _ConnectionFairy(self).checkout()
  File "/home/tfb/FrameworkBenchmarks/installs/pypy/site-packages/SQLAlchemy-0.8.2-py2.7.egg/sqlalchemy/pool.py", line 425, in __init__
    rec = self._connection_record = pool._do_get()
  File "/home/tfb/FrameworkBenchmarks/installs/pypy/site-packages/SQLAlchemy-0.8.2-py2.7.egg/sqlalchemy/pool.py", line 770, in _do_get
    (self.size(), self.overflow(), self._timeout))
TimeoutError: QueuePool limit of size 5 overflow 10 reached, connection timed out, timeout 30
ERROR:app:Exception on /raw-updates [GET]
Traceback (most recent call last):
  File "/home/tfb/FrameworkBenchmarks/installs/pypy/site-packages/Flask-0.10.1-py2.7.egg/flask/app.py", line 1817, in wsgi_app
    response = self.full_dispatch_request()
  File "/home/tfb/FrameworkBenchmarks/installs/pypy/site-packages/Flask-0.10.1-py2.7.egg/flask/app.py", line 1477, in full_dispatch_request
    rv = self.handle_user_exception(e)
  File "/home/tfb/FrameworkBenchmarks/installs/pypy/site-packages/Flask-0.10.1-py2.7.egg/flask/app.py", line 1381, in handle_user_exception
    reraise(exc_type, exc_value, tb)
  File "/home/tfb/FrameworkBenchmarks/installs/pypy/site-packages/Flask-0.10.1-py2.7.egg/flask/app.py", line 1475, in full_dispatch_request
    rv = self.dispatch_request()
  File "/home/tfb/FrameworkBenchmarks/installs/pypy/site-packages/Flask-0.10.1-py2.7.egg/flask/app.py", line 1461, in dispatch_request
    return self.view_functions[rule.endpoint](**req.view_args)
  File "/home/tfb/FrameworkBenchmarks/flask/app.py", line 143, in raw_updates
    (randomNumber, world['id']))
  File "/home/tfb/FrameworkBenchmarks/installs/pypy/site-packages/SQLAlchemy-0.8.2-py2.7.egg/sqlalchemy/engine/base.py", line 1613, in execute
    connection = self.contextual_connect(close_with_result=True)
  File "/home/tfb/FrameworkBenchmarks/installs/pypy/site-packages/SQLAlchemy-0.8.2-py2.7.egg/sqlalchemy/engine/base.py", line 1661, in contextual_connect
    self.pool.connect(),
  File "/home/tfb/FrameworkBenchmarks/installs/pypy/site-packages/SQLAlchemy-0.8.2-py2.7.egg/sqlalchemy/pool.py", line 272, in connect
    return _ConnectionFairy(self).checkout()
  File "/home/tfb/FrameworkBenchmarks/installs/pypy/site-packages/SQLAlchemy-0.8.2-py2.7.egg/sqlalchemy/pool.py", line 425, in __init__
    rec = self._connection_record = pool._do_get()
  File "/home/tfb/FrameworkBenchmarks/installs/pypy/site-packages/SQLAlchemy-0.8.2-py2.7.egg/sqlalchemy/pool.py", line 770, in _do_get
    (self.size(), self.overflow(), self._timeout))
TimeoutError: QueuePool limit of size 5 overflow 10 reached, connection timed out, timeout 30
ERROR:app:Exception on /raw-updates [GET]
Traceback (most recent call last):
  File "/home/tfb/FrameworkBenchmarks/installs/pypy/site-packages/Flask-0.10.1-py2.7.egg/flask/app.py", line 1817, in wsgi_app
    response = self.full_dispatch_request()
  File "/home/tfb/FrameworkBenchmarks/installs/pypy/site-packages/Flask-0.10.1-py2.7.egg/flask/app.py", line 1477, in full_dispatch_request
    rv = self.handle_user_exception(e)
  File "/home/tfb/FrameworkBenchmarks/installs/pypy/site-packages/Flask-0.10.1-py2.7.egg/flask/app.py", line 1381, in handle_user_exception
    reraise(exc_type, exc_value, tb)
  File "/home/tfb/FrameworkBenchmarks/installs/pypy/site-packages/Flask-0.10.1-py2.7.egg/flask/app.py", line 1475, in full_dispatch_request
    rv = self.dispatch_request()
  File "/home/tfb/FrameworkBenchmarks/installs/pypy/site-packages/Flask-0.10.1-py2.7.egg/flask/app.py", line 1461, in dispatch_request
    return self.view_functions[rule.endpoint](**req.view_args)
  File "/home/tfb/FrameworkBenchmarks/flask/app.py", line 143, in raw_updates
    (randomNumber, world['id']))
  File "/home/tfb/FrameworkBenchmarks/installs/pypy/site-packages/SQLAlchemy-0.8.2-py2.7.egg/sqlalchemy/engine/base.py", line 1613, in execute
    connection = self.contextual_connect(close_with_result=True)
  File "/home/tfb/FrameworkBenchmarks/installs/pypy/site-packages/SQLAlchemy-0.8.2-py2.7.egg/sqlalchemy/engine/base.py", line 1661, in contextual_connect
    self.pool.connect(),
  File "/home/tfb/FrameworkBenchmarks/installs/pypy/site-packages/SQLAlchemy-0.8.2-py2.7.egg/sqlalchemy/pool.py", line 272, in connect
    return _ConnectionFairy(self).checkout()
  File "/home/tfb/FrameworkBenchmarks/installs/pypy/site-packages/SQLAlchemy-0.8.2-py2.7.egg/sqlalchemy/pool.py", line 425, in __init__
    rec = self._connection_record = pool._do_get()
  File "/home/tfb/FrameworkBenchmarks/installs/pypy/site-packages/SQLAlchemy-0.8.2-py2.7.egg/sqlalchemy/pool.py", line 770, in _do_get
    (self.size(), self.overflow(), self._timeout))
TimeoutError: QueuePool limit of size 5 overflow 10 reached, connection timed out, timeout 30
ERROR:app:Exception on /raw-updates [GET]
Traceback (most recent call last):
  File "/home/tfb/FrameworkBenchmarks/installs/pypy/site-packages/Flask-0.10.1-py2.7.egg/flask/app.py", line 1817, in wsgi_app
    response = self.full_dispatch_request()
  File "/home/tfb/FrameworkBenchmarks/installs/pypy/site-packages/Flask-0.10.1-py2.7.egg/flask/app.py", line 1477, in full_dispatch_request
    rv = self.handle_user_exception(e)
  File "/home/tfb/FrameworkBenchmarks/installs/pypy/site-packages/Flask-0.10.1-py2.7.egg/flask/app.py", line 1381, in handle_user_exception
    reraise(exc_type, exc_value, tb)
  File "/home/tfb/FrameworkBenchmarks/installs/pypy/site-packages/Flask-0.10.1-py2.7.egg/flask/app.py", line 1475, in full_dispatch_request
    rv = self.dispatch_request()
  File "/home/tfb/FrameworkBenchmarks/installs/pypy/site-packages/Flask-0.10.1-py2.7.egg/flask/app.py", line 1461, in dispatch_request
    return self.view_functions[rule.endpoint](**req.view_args)
  File "/home/tfb/FrameworkBenchmarks/flask/app.py", line 143, in raw_updates
    (randomNumber, world['id']))
  File "/home/tfb/FrameworkBenchmarks/installs/pypy/site-packages/SQLAlchemy-0.8.2-py2.7.egg/sqlalchemy/engine/base.py", line 1613, in execute
    connection = self.contextual_connect(close_with_result=True)
  File "/home/tfb/FrameworkBenchmarks/installs/pypy/site-packages/SQLAlchemy-0.8.2-py2.7.egg/sqlalchemy/engine/base.py", line 1661, in contextual_connect
    self.pool.connect(),
  File "/home/tfb/FrameworkBenchmarks/installs/pypy/site-packages/SQLAlchemy-0.8.2-py2.7.egg/sqlalchemy/pool.py", line 272, in connect
    return _ConnectionFairy(self).checkout()
  File "/home/tfb/FrameworkBenchmarks/installs/pypy/site-packages/SQLAlchemy-0.8.2-py2.7.egg/sqlalchemy/pool.py", line 425, in __init__
    rec = self._connection_record = pool._do_get()
  File "/home/tfb/FrameworkBenchmarks/installs/pypy/site-packages/SQLAlchemy-0.8.2-py2.7.egg/sqlalchemy/pool.py", line 770, in _do_get
    (self.size(), self.overflow(), self._timeout))
TimeoutError: QueuePool limit of size 5 overflow 10 reached, connection timed out, timeout 30
ERROR:app:Exception on /raw-updates [GET]
Traceback (most recent call last):
  File "/home/tfb/FrameworkBenchmarks/installs/pypy/site-packages/Flask-0.10.1-py2.7.egg/flask/app.py", line 1817, in wsgi_app
    response = self.full_dispatch_request()
  File "/home/tfb/FrameworkBenchmarks/installs/pypy/site-packages/Flask-0.10.1-py2.7.egg/flask/app.py", line 1477, in full_dispatch_request
    rv = self.handle_user_exception(e)
  File "/home/tfb/FrameworkBenchmarks/installs/pypy/site-packages/Flask-0.10.1-py2.7.egg/flask/app.py", line 1381, in handle_user_exception
    reraise(exc_type, exc_value, tb)
  File "/home/tfb/FrameworkBenchmarks/installs/pypy/site-packages/Flask-0.10.1-py2.7.egg/flask/app.py", line 1475, in full_dispatch_request
    rv = self.dispatch_request()
  File "/home/tfb/FrameworkBenchmarks/installs/pypy/site-packages/Flask-0.10.1-py2.7.egg/flask/app.py", line 1461, in dispatch_request
    return self.view_functions[rule.endpoint](**req.view_args)
  File "/home/tfb/FrameworkBenchmarks/flask/app.py", line 143, in raw_updates
    (randomNumber, world['id']))
  File "/home/tfb/FrameworkBenchmarks/installs/pypy/site-packages/SQLAlchemy-0.8.2-py2.7.egg/sqlalchemy/engine/base.py", line 1613, in execute
    connection = self.contextual_connect(close_with_result=True)
  File "/home/tfb/FrameworkBenchmarks/installs/pypy/site-packages/SQLAlchemy-0.8.2-py2.7.egg/sqlalchemy/engine/base.py", line 1661, in contextual_connect
    self.pool.connect(),
  File "/home/tfb/FrameworkBenchmarks/installs/pypy/site-packages/SQLAlchemy-0.8.2-py2.7.egg/sqlalchemy/pool.py", line 272, in connect
    return _ConnectionFairy(self).checkout()
  File "/home/tfb/FrameworkBenchmarks/installs/pypy/site-packages/SQLAlchemy-0.8.2-py2.7.egg/sqlalchemy/pool.py", line 425, in __init__
    rec = self._connection_record = pool._do_get()
  File "/home/tfb/FrameworkBenchmarks/installs/pypy/site-packages/SQLAlchemy-0.8.2-py2.7.egg/sqlalchemy/pool.py", line 770, in _do_get
    (self.size(), self.overflow(), self._timeout))
TimeoutError: QueuePool limit of size 5 overflow 10 reached, connection timed out, timeout 30
ERROR:app:Exception on /raw-updates [GET]
Traceback (most recent call last):
  File "/home/tfb/FrameworkBenchmarks/installs/pypy/site-packages/Flask-0.10.1-py2.7.egg/flask/app.py", line 1817, in wsgi_app
    response = self.full_dispatch_request()
  File "/home/tfb/FrameworkBenchmarks/installs/pypy/site-packages/Flask-0.10.1-py2.7.egg/flask/app.py", line 1477, in full_dispatch_request
    rv = self.handle_user_exception(e)
  File "/home/tfb/FrameworkBenchmarks/installs/pypy/site-packages/Flask-0.10.1-py2.7.egg/flask/app.py", line 1381, in handle_user_exception
    reraise(exc_type, exc_value, tb)
  File "/home/tfb/FrameworkBenchmarks/installs/pypy/site-packages/Flask-0.10.1-py2.7.egg/flask/app.py", line 1475, in full_dispatch_request
    rv = self.dispatch_request()
  File "/home/tfb/FrameworkBenchmarks/installs/pypy/site-packages/Flask-0.10.1-py2.7.egg/flask/app.py", line 1461, in dispatch_request
    return self.view_functions[rule.endpoint](**req.view_args)
  File "/home/tfb/FrameworkBenchmarks/flask/app.py", line 143, in raw_updates
    (randomNumber, world['id']))
  File "/home/tfb/FrameworkBenchmarks/installs/pypy/site-packages/SQLAlchemy-0.8.2-py2.7.egg/sqlalchemy/engine/base.py", line 1613, in execute
    connection = self.contextual_connect(close_with_result=True)
  File "/home/tfb/FrameworkBenchmarks/installs/pypy/site-packages/SQLAlchemy-0.8.2-py2.7.egg/sqlalchemy/engine/base.py", line 1661, in contextual_connect
    self.pool.connect(),
  File "/home/tfb/FrameworkBenchmarks/installs/pypy/site-packages/SQLAlchemy-0.8.2-py2.7.egg/sqlalchemy/pool.py", line 272, in connect
    return _ConnectionFairy(self).checkout()
  File "/home/tfb/FrameworkBenchmarks/installs/pypy/site-packages/SQLAlchemy-0.8.2-py2.7.egg/sqlalchemy/pool.py", line 425, in __init__
    rec = self._connection_record = pool._do_get()
  File "/home/tfb/FrameworkBenchmarks/installs/pypy/site-packages/SQLAlchemy-0.8.2-py2.7.egg/sqlalchemy/pool.py", line 770, in _do_get
    (self.size(), self.overflow(), self._timeout))
TimeoutError: QueuePool limit of size 5 overflow 10 reached, connection timed out, timeout 30
ERROR:app:Exception on /raw-updates [GET]
Traceback (most recent call last):
  File "/home/tfb/FrameworkBenchmarks/installs/pypy/site-packages/Flask-0.10.1-py2.7.egg/flask/app.py", line 1817, in wsgi_app
    response = self.full_dispatch_request()
  File "/home/tfb/FrameworkBenchmarks/installs/pypy/site-packages/Flask-0.10.1-py2.7.egg/flask/app.py", line 1477, in full_dispatch_request
    rv = self.handle_user_exception(e)
  File "/home/tfb/FrameworkBenchmarks/installs/pypy/site-packages/Flask-0.10.1-py2.7.egg/flask/app.py", line 1381, in handle_user_exception
    reraise(exc_type, exc_value, tb)
  File "/home/tfb/FrameworkBenchmarks/installs/pypy/site-packages/Flask-0.10.1-py2.7.egg/flask/app.py", line 1475, in full_dispatch_request
    rv = self.dispatch_request()
  File "/home/tfb/FrameworkBenchmarks/installs/pypy/site-packages/Flask-0.10.1-py2.7.egg/flask/app.py", line 1461, in dispatch_request
    return self.view_functions[rule.endpoint](**req.view_args)
  File "/home/tfb/FrameworkBenchmarks/flask/app.py", line 143, in raw_updates
    (randomNumber, world['id']))
  File "/home/tfb/FrameworkBenchmarks/installs/pypy/site-packages/SQLAlchemy-0.8.2-py2.7.egg/sqlalchemy/engine/base.py", line 1613, in execute
    connection = self.contextual_connect(close_with_result=True)
  File "/home/tfb/FrameworkBenchmarks/installs/pypy/site-packages/SQLAlchemy-0.8.2-py2.7.egg/sqlalchemy/engine/base.py", line 1661, in contextual_connect
    self.pool.connect(),
  File "/home/tfb/FrameworkBenchmarks/installs/pypy/site-packages/SQLAlchemy-0.8.2-py2.7.egg/sqlalchemy/pool.py", line 272, in connect
    return _ConnectionFairy(self).checkout()
  File "/home/tfb/FrameworkBenchmarks/installs/pypy/site-packages/SQLAlchemy-0.8.2-py2.7.egg/sqlalchemy/pool.py", line 425, in __init__
    rec = self._connection_record = pool._do_get()
  File "/home/tfb/FrameworkBenchmarks/installs/pypy/site-packages/SQLAlchemy-0.8.2-py2.7.egg/sqlalchemy/pool.py", line 770, in _do_get
    (self.size(), self.overflow(), self._timeout))
TimeoutError: QueuePool limit of size 5 overflow 10 reached, connection timed out, timeout 30
ERROR:app:Exception on /raw-updates [GET]
Traceback (most recent call last):
  File "/home/tfb/FrameworkBenchmarks/installs/pypy/site-packages/Flask-0.10.1-py2.7.egg/flask/app.py", line 1817, in wsgi_app
    response = self.full_dispatch_request()
  File "/home/tfb/FrameworkBenchmarks/installs/pypy/site-packages/Flask-0.10.1-py2.7.egg/flask/app.py", line 1477, in full_dispatch_request
    rv = self.handle_user_exception(e)
  File "/home/tfb/FrameworkBenchmarks/installs/pypy/site-packages/Flask-0.10.1-py2.7.egg/flask/app.py", line 1381, in handle_user_exception
    reraise(exc_type, exc_value, tb)
  File "/home/tfb/FrameworkBenchmarks/installs/pypy/site-packages/Flask-0.10.1-py2.7.egg/flask/app.py", line 1475, in full_dispatch_request
    rv = self.dispatch_request()
  File "/home/tfb/FrameworkBenchmarks/installs/pypy/site-packages/Flask-0.10.1-py2.7.egg/flask/app.py", line 1461, in dispatch_request
    return self.view_functions[rule.endpoint](**req.view_args)
  File "/home/tfb/FrameworkBenchmarks/flask/app.py", line 143, in raw_updates
    (randomNumber, world['id']))
  File "/home/tfb/FrameworkBenchmarks/installs/pypy/site-packages/SQLAlchemy-0.8.2-py2.7.egg/sqlalchemy/engine/base.py", line 1613, in execute
    connection = self.contextual_connect(close_with_result=True)
  File "/home/tfb/FrameworkBenchmarks/installs/pypy/site-packages/SQLAlchemy-0.8.2-py2.7.egg/sqlalchemy/engine/base.py", line 1661, in contextual_connect
    self.pool.connect(),
  File "/home/tfb/FrameworkBenchmarks/installs/pypy/site-packages/SQLAlchemy-0.8.2-py2.7.egg/sqlalchemy/pool.py", line 272, in connect
    return _ConnectionFairy(self).checkout()
  File "/home/tfb/FrameworkBenchmarks/installs/pypy/site-packages/SQLAlchemy-0.8.2-py2.7.egg/sqlalchemy/pool.py", line 425, in __init__
    rec = self._connection_record = pool._do_get()
  File "/home/tfb/FrameworkBenchmarks/installs/pypy/site-packages/SQLAlchemy-0.8.2-py2.7.egg/sqlalchemy/pool.py", line 770, in _do_get
    (self.size(), self.overflow(), self._timeout))
TimeoutError: QueuePool limit of size 5 overflow 10 reached, connection timed out, timeout 30
ERROR:tornado.access:500 GET /raw-updates?queries=5 (172.16.98.98) 30074.81ms
ERROR:tornado.access:500 GET /raw-updates?queries=5 (172.16.98.98) 30081.54ms
ERROR:tornado.access:500 GET /raw-updates?queries=5 (172.16.98.98) 30091.61ms
ERROR:tornado.access:500 GET /raw-updates?queries=5 (172.16.98.98) 30095.06ms
ERROR:tornado.access:500 GET /raw-updates?queries=5 (172.16.98.98) 30115.43ms
ERROR:tornado.access:500 GET /raw-updates?queries=5 (172.16.98.98) 30097.27ms
ERROR:tornado.access:500 GET /raw-updates?queries=5 (172.16.98.98) 30113.99ms
ERROR:tornado.access:500 GET /raw-updates?queries=5 (172.16.98.98) 30101.44ms
ERROR:tornado.access:500 GET /raw-updates?queries=5 (172.16.98.98) 30105.87ms
ERROR:tornado.access:500 GET /raw-updates?queries=5 (172.16.98.98) 30107.77ms
2013-11-20 20:02:17 [11689] [CRITICAL] WORKER TIMEOUT (pid:11778)
2013-11-20 20:02:17 [11689] [CRITICAL] WORKER TIMEOUT (pid:11779)
2013-11-20 20:02:17 [11689] [CRITICAL] WORKER TIMEOUT (pid:11781)
2013-11-20 20:02:17 [11689] [CRITICAL] WORKER TIMEOUT (pid:11782)
2013-11-20 20:02:17 [11689] [CRITICAL] WORKER TIMEOUT (pid:11783)
2013-11-20 20:02:17 [11689] [CRITICAL] WORKER TIMEOUT (pid:11785)
2013-11-20 20:02:17 [11689] [CRITICAL] WORKER TIMEOUT (pid:11786)
2013-11-20 20:02:17 [11689] [CRITICAL] WORKER TIMEOUT (pid:11778)
2013-11-20 20:02:17 [11689] [CRITICAL] WORKER TIMEOUT (pid:11779)
2013-11-20 20:02:17 [11689] [CRITICAL] WORKER TIMEOUT (pid:11781)
2013-11-20 20:02:17 [11689] [CRITICAL] WORKER TIMEOUT (pid:11782)
2013-11-20 20:02:17 [11689] [CRITICAL] WORKER TIMEOUT (pid:11783)
2013-11-20 20:02:17 [11689] [CRITICAL] WORKER TIMEOUT (pid:11785)
2013-11-20 20:02:17 [11689] [CRITICAL] WORKER TIMEOUT (pid:11786)
2013-11-20 20:02:17 [11689] [CRITICAL] WORKER TIMEOUT (pid:11783)
ERROR:app:Exception on /raw-updates [GET]
Traceback (most recent call last):
  File "/home/tfb/FrameworkBenchmarks/installs/pypy/site-packages/Flask-0.10.1-py2.7.egg/flask/app.py", line 1817, in wsgi_app
    response = self.full_dispatch_request()
  File "/home/tfb/FrameworkBenchmarks/installs/pypy/site-packages/Flask-0.10.1-py2.7.egg/flask/app.py", line 1477, in full_dispatch_request
    rv = self.handle_user_exception(e)
  File "/home/tfb/FrameworkBenchmarks/installs/pypy/site-packages/Flask-0.10.1-py2.7.egg/flask/app.py", line 1381, in handle_user_exception
    reraise(exc_type, exc_value, tb)
  File "/home/tfb/FrameworkBenchmarks/installs/pypy/site-packages/Flask-0.10.1-py2.7.egg/flask/app.py", line 1475, in full_dispatch_request
    rv = self.dispatch_request()
  File "/home/tfb/FrameworkBenchmarks/installs/pypy/site-packages/Flask-0.10.1-py2.7.egg/flask/app.py", line 1461, in dispatch_request
    return self.view_functions[rule.endpoint](**req.view_args)
  File "/home/tfb/FrameworkBenchmarks/flask/app.py", line 143, in raw_updates
    (randomNumber, world['id']))
  File "/home/tfb/FrameworkBenchmarks/installs/pypy/site-packages/SQLAlchemy-0.8.2-py2.7.egg/sqlalchemy/engine/base.py", line 1613, in execute
    connection = self.contextual_connect(close_with_result=True)
  File "/home/tfb/FrameworkBenchmarks/installs/pypy/site-packages/SQLAlchemy-0.8.2-py2.7.egg/sqlalchemy/engine/base.py", line 1661, in contextual_connect
    self.pool.connect(),
  File "/home/tfb/FrameworkBenchmarks/installs/pypy/site-packages/SQLAlchemy-0.8.2-py2.7.egg/sqlalchemy/pool.py", line 272, in connect
    return _ConnectionFairy(self).checkout()
  File "/home/tfb/FrameworkBenchmarks/installs/pypy/site-packages/SQLAlchemy-0.8.2-py2.7.egg/sqlalchemy/pool.py", line 425, in __init__
    rec = self._connection_record = pool._do_get()
  File "/home/tfb/FrameworkBenchmarks/installs/pypy/site-packages/SQLAlchemy-0.8.2-py2.7.egg/sqlalchemy/pool.py", line 770, in _do_get
    (self.size(), self.overflow(), self._timeout))
TimeoutError: QueuePool limit of size 5 overflow 10 reached, connection timed out, timeout 30
ERROR:tornado.access:500 GET /raw-updates?queries=5 (172.16.98.98) 30034.69ms
2013-11-20 20:02:27 [11689] [CRITICAL] WORKER TIMEOUT (pid:11806)
2013-11-20 20:02:27 [11689] [CRITICAL] WORKER TIMEOUT (pid:11806)
2013-11-20 20:02:34 [11689] [CRITICAL] WORKER TIMEOUT (pid:11808)
2013-11-20 20:02:34 [11689] [CRITICAL] WORKER TIMEOUT (pid:11809)
2013-11-20 20:02:34 [11689] [CRITICAL] WORKER TIMEOUT (pid:11808)
2013-11-20 20:02:34 [11689] [CRITICAL] WORKER TIMEOUT (pid:11809)
ERROR:app:Exception on /raw-updates [GET]
Traceback (most recent call last):
  File "/home/tfb/FrameworkBenchmarks/installs/pypy/site-packages/Flask-0.10.1-py2.7.egg/flask/app.py", line 1817, in wsgi_app
    response = self.full_dispatch_request()
  File "/home/tfb/FrameworkBenchmarks/installs/pypy/site-packages/Flask-0.10.1-py2.7.egg/flask/app.py", line 1477, in full_dispatch_request
    rv = self.handle_user_exception(e)
  File "/home/tfb/FrameworkBenchmarks/installs/pypy/site-packages/Flask-0.10.1-py2.7.egg/flask/app.py", line 1381, in handle_user_exception
    reraise(exc_type, exc_value, tb)
  File "/home/tfb/FrameworkBenchmarks/installs/pypy/site-packages/Flask-0.10.1-py2.7.egg/flask/app.py", line 1475, in full_dispatch_request
    rv = self.dispatch_request()
  File "/home/tfb/FrameworkBenchmarks/installs/pypy/site-packages/Flask-0.10.1-py2.7.egg/flask/app.py", line 1461, in dispatch_request
    return self.view_functions[rule.endpoint](**req.view_args)
  File "/home/tfb/FrameworkBenchmarks/flask/app.py", line 143, in raw_updates
    (randomNumber, world['id']))
  File "/home/tfb/FrameworkBenchmarks/installs/pypy/site-packages/SQLAlchemy-0.8.2-py2.7.egg/sqlalchemy/engine/base.py", line 1613, in execute
    connection = self.contextual_connect(close_with_result=True)
  File "/home/tfb/FrameworkBenchmarks/installs/pypy/site-packages/SQLAlchemy-0.8.2-py2.7.egg/sqlalchemy/engine/base.py", line 1661, in contextual_connect
    self.pool.connect(),
  File "/home/tfb/FrameworkBenchmarks/installs/pypy/site-packages/SQLAlchemy-0.8.2-py2.7.egg/sqlalchemy/pool.py", line 272, in connect
    return _ConnectionFairy(self).checkout()
  File "/home/tfb/FrameworkBenchmarks/installs/pypy/site-packages/SQLAlchemy-0.8.2-py2.7.egg/sqlalchemy/pool.py", line 425, in __init__
    rec = self._connection_record = pool._do_get()
  File "/home/tfb/FrameworkBenchmarks/installs/pypy/site-packages/SQLAlchemy-0.8.2-py2.7.egg/sqlalchemy/pool.py", line 770, in _do_get
    (self.size(), self.overflow(), self._timeout))
TimeoutError: QueuePool limit of size 5 overflow 10 reached, connection timed out, timeout 30
ERROR:app:Exception on /raw-updates [GET]
Traceback (most recent call last):
  File "/home/tfb/FrameworkBenchmarks/installs/pypy/site-packages/Flask-0.10.1-py2.7.egg/flask/app.py", line 1817, in wsgi_app
    response = self.full_dispatch_request()
  File "/home/tfb/FrameworkBenchmarks/installs/pypy/site-packages/Flask-0.10.1-py2.7.egg/flask/app.py", line 1477, in full_dispatch_request
    rv = self.handle_user_exception(e)
  File "/home/tfb/FrameworkBenchmarks/installs/pypy/site-packages/Flask-0.10.1-py2.7.egg/flask/app.py", line 1381, in handle_user_exception
    reraise(exc_type, exc_value, tb)
  File "/home/tfb/FrameworkBenchmarks/installs/pypy/site-packages/Flask-0.10.1-py2.7.egg/flask/app.py", line 1475, in full_dispatch_request
    rv = self.dispatch_request()
  File "/home/tfb/FrameworkBenchmarks/installs/pypy/site-packages/Flask-0.10.1-py2.7.egg/flask/app.py", line 1461, in dispatch_request
    return self.view_functions[rule.endpoint](**req.view_args)
  File "/home/tfb/FrameworkBenchmarks/flask/app.py", line 143, in raw_updates
    (randomNumber, world['id']))
  File "/home/tfb/FrameworkBenchmarks/installs/pypy/site-packages/SQLAlchemy-0.8.2-py2.7.egg/sqlalchemy/engine/base.py", line 1613, in execute
    connection = self.contextual_connect(close_with_result=True)
  File "/home/tfb/FrameworkBenchmarks/installs/pypy/site-packages/SQLAlchemy-0.8.2-py2.7.egg/sqlalchemy/engine/base.py", line 1661, in contextual_connect
    self.pool.connect(),
  File "/home/tfb/FrameworkBenchmarks/installs/pypy/site-packages/SQLAlchemy-0.8.2-py2.7.egg/sqlalchemy/pool.py", line 272, in connect
    return _ConnectionFairy(self).checkout()
  File "/home/tfb/FrameworkBenchmarks/installs/pypy/site-packages/SQLAlchemy-0.8.2-py2.7.egg/sqlalchemy/pool.py", line 425, in __init__
    rec = self._connection_record = pool._do_get()
  File "/home/tfb/FrameworkBenchmarks/installs/pypy/site-packages/SQLAlchemy-0.8.2-py2.7.egg/sqlalchemy/pool.py", line 770, in _do_get
    (self.size(), self.overflow(), self._timeout))
TimeoutError: QueuePool limit of size 5 overflow 10 reached, connection timed out, timeout 30
ERROR:app:Exception on /raw-updates [GET]
Traceback (most recent call last):
  File "/home/tfb/FrameworkBenchmarks/installs/pypy/site-packages/Flask-0.10.1-py2.7.egg/flask/app.py", line 1817, in wsgi_app
    response = self.full_dispatch_request()
  File "/home/tfb/FrameworkBenchmarks/installs/pypy/site-packages/Flask-0.10.1-py2.7.egg/flask/app.py", line 1477, in full_dispatch_request
    rv = self.handle_user_exception(e)
  File "/home/tfb/FrameworkBenchmarks/installs/pypy/site-packages/Flask-0.10.1-py2.7.egg/flask/app.py", line 1381, in handle_user_exception
    reraise(exc_type, exc_value, tb)
  File "/home/tfb/FrameworkBenchmarks/installs/pypy/site-packages/Flask-0.10.1-py2.7.egg/flask/app.py", line 1475, in full_dispatch_request
    rv = self.dispatch_request()
  File "/home/tfb/FrameworkBenchmarks/installs/pypy/site-packages/Flask-0.10.1-py2.7.egg/flask/app.py", line 1461, in dispatch_request
    return self.view_functions[rule.endpoint](**req.view_args)
  File "/home/tfb/FrameworkBenchmarks/flask/app.py", line 143, in raw_updates
    (randomNumber, world['id']))
  File "/home/tfb/FrameworkBenchmarks/installs/pypy/site-packages/SQLAlchemy-0.8.2-py2.7.egg/sqlalchemy/engine/base.py", line 1613, in execute
    connection = self.contextual_connect(close_with_result=True)
  File "/home/tfb/FrameworkBenchmarks/installs/pypy/site-packages/SQLAlchemy-0.8.2-py2.7.egg/sqlalchemy/engine/base.py", line 1661, in contextual_connect
    self.pool.connect(),
  File "/home/tfb/FrameworkBenchmarks/installs/pypy/site-packages/SQLAlchemy-0.8.2-py2.7.egg/sqlalchemy/pool.py", line 272, in connect
    return _ConnectionFairy(self).checkout()
  File "/home/tfb/FrameworkBenchmarks/installs/pypy/site-packages/SQLAlchemy-0.8.2-py2.7.egg/sqlalchemy/pool.py", line 425, in __init__
    rec = self._connection_record = pool._do_get()
  File "/home/tfb/FrameworkBenchmarks/installs/pypy/site-packages/SQLAlchemy-0.8.2-py2.7.egg/sqlalchemy/pool.py", line 770, in _do_get
    (self.size(), self.overflow(), self._timeout))
TimeoutError: QueuePool limit of size 5 overflow 10 reached, connection timed out, timeout 30
ERROR:app:Exception on /raw-updates [GET]
Traceback (most recent call last):
  File "/home/tfb/FrameworkBenchmarks/installs/pypy/site-packages/Flask-0.10.1-py2.7.egg/flask/app.py", line 1817, in wsgi_app
    response = self.full_dispatch_request()
  File "/home/tfb/FrameworkBenchmarks/installs/pypy/site-packages/Flask-0.10.1-py2.7.egg/flask/app.py", line 1477, in full_dispatch_request
    rv = self.handle_user_exception(e)
  File "/home/tfb/FrameworkBenchmarks/installs/pypy/site-packages/Flask-0.10.1-py2.7.egg/flask/app.py", line 1381, in handle_user_exception
    reraise(exc_type, exc_value, tb)
  File "/home/tfb/FrameworkBenchmarks/installs/pypy/site-packages/Flask-0.10.1-py2.7.egg/flask/app.py", line 1475, in full_dispatch_request
    rv = self.dispatch_request()
  File "/home/tfb/FrameworkBenchmarks/installs/pypy/site-packages/Flask-0.10.1-py2.7.egg/flask/app.py", line 1461, in dispatch_request
    return self.view_functions[rule.endpoint](**req.view_args)
  File "/home/tfb/FrameworkBenchmarks/flask/app.py", line 143, in raw_updates
    (randomNumber, world['id']))
  File "/home/tfb/FrameworkBenchmarks/installs/pypy/site-packages/SQLAlchemy-0.8.2-py2.7.egg/sqlalchemy/engine/base.py", line 1613, in execute
    connection = self.contextual_connect(close_with_result=True)
  File "/home/tfb/FrameworkBenchmarks/installs/pypy/site-packages/SQLAlchemy-0.8.2-py2.7.egg/sqlalchemy/engine/base.py", line 1661, in contextual_connect
    self.pool.connect(),
  File "/home/tfb/FrameworkBenchmarks/installs/pypy/site-packages/SQLAlchemy-0.8.2-py2.7.egg/sqlalchemy/pool.py", line 272, in connect
    return _ConnectionFairy(self).checkout()
  File "/home/tfb/FrameworkBenchmarks/installs/pypy/site-packages/SQLAlchemy-0.8.2-py2.7.egg/sqlalchemy/pool.py", line 425, in __init__
    rec = self._connection_record = pool._do_get()
  File "/home/tfb/FrameworkBenchmarks/installs/pypy/site-packages/SQLAlchemy-0.8.2-py2.7.egg/sqlalchemy/pool.py", line 770, in _do_get
    (self.size(), self.overflow(), self._timeout))
TimeoutError: QueuePool limit of size 5 overflow 10 reached, connection timed out, timeout 30
ERROR:tornado.access:500 GET /raw-updates?queries=10 (172.16.98.98) 30040.54ms
ERROR:tornado.access:500 GET /raw-updates?queries=10 (172.16.98.98) 30040.23ms
ERROR:tornado.access:500 GET /raw-updates?queries=10 (172.16.98.98) 30046.23ms
2013-11-20 20:02:35 [11689] [CRITICAL] WORKER TIMEOUT (pid:11810)
2013-11-20 20:02:35 [11689] [CRITICAL] WORKER TIMEOUT (pid:11811)
2013-11-20 20:02:35 [11689] [CRITICAL] WORKER TIMEOUT (pid:11812)
2013-11-20 20:02:35 [11689] [CRITICAL] WORKER TIMEOUT (pid:11813)
2013-11-20 20:02:35 [11689] [CRITICAL] WORKER TIMEOUT (pid:11810)
2013-11-20 20:02:35 [11689] [CRITICAL] WORKER TIMEOUT (pid:11811)
2013-11-20 20:02:35 [11689] [CRITICAL] WORKER TIMEOUT (pid:11812)
2013-11-20 20:02:35 [11689] [CRITICAL] WORKER TIMEOUT (pid:11813)
ERROR:app:Exception on /raw-updates [GET]
Traceback (most recent call last):
  File "/home/tfb/FrameworkBenchmarks/installs/pypy/site-packages/Flask-0.10.1-py2.7.egg/flask/app.py", line 1817, in wsgi_app
    response = self.full_dispatch_request()
  File "/home/tfb/FrameworkBenchmarks/installs/pypy/site-packages/Flask-0.10.1-py2.7.egg/flask/app.py", line 1477, in full_dispatch_request
    rv = self.handle_user_exception(e)
  File "/home/tfb/FrameworkBenchmarks/installs/pypy/site-packages/Flask-0.10.1-py2.7.egg/flask/app.py", line 1381, in handle_user_exception
    reraise(exc_type, exc_value, tb)
  File "/home/tfb/FrameworkBenchmarks/installs/pypy/site-packages/Flask-0.10.1-py2.7.egg/flask/app.py", line 1475, in full_dispatch_request
    rv = self.dispatch_request()
  File "/home/tfb/FrameworkBenchmarks/installs/pypy/site-packages/Flask-0.10.1-py2.7.egg/flask/app.py", line 1461, in dispatch_request
    return self.view_functions[rule.endpoint](**req.view_args)
  File "/home/tfb/FrameworkBenchmarks/flask/app.py", line 139, in raw_updates
    world = dbraw_engine.execute("SELECT * FROM World WHERE id=%s", (rp(),)).fetchone()
  File "/home/tfb/FrameworkBenchmarks/installs/pypy/site-packages/SQLAlchemy-0.8.2-py2.7.egg/sqlalchemy/engine/base.py", line 1613, in execute
    connection = self.contextual_connect(close_with_result=True)
  File "/home/tfb/FrameworkBenchmarks/installs/pypy/site-packages/SQLAlchemy-0.8.2-py2.7.egg/sqlalchemy/engine/base.py", line 1661, in contextual_connect
    self.pool.connect(),
  File "/home/tfb/FrameworkBenchmarks/installs/pypy/site-packages/SQLAlchemy-0.8.2-py2.7.egg/sqlalchemy/pool.py", line 272, in connect
    return _ConnectionFairy(self).checkout()
  File "/home/tfb/FrameworkBenchmarks/installs/pypy/site-packages/SQLAlchemy-0.8.2-py2.7.egg/sqlalchemy/pool.py", line 425, in __init__
    rec = self._connection_record = pool._do_get()
  File "/home/tfb/FrameworkBenchmarks/installs/pypy/site-packages/SQLAlchemy-0.8.2-py2.7.egg/sqlalchemy/pool.py", line 770, in _do_get
    (self.size(), self.overflow(), self._timeout))
TimeoutError: QueuePool limit of size 5 overflow 10 reached, connection timed out, timeout 30
ERROR:tornado.access:500 GET /raw-updates?queries=5 (172.16.98.98) 30002.03ms
2013-11-20 20:02:47 [11689] [CRITICAL] WORKER TIMEOUT (pid:11784)
2013-11-20 20:02:47 [11689] [CRITICAL] WORKER TIMEOUT (pid:11784)
2013-11-20 20:02:52 [11689] [CRITICAL] WORKER TIMEOUT (pid:11788)
2013-11-20 20:02:52 [11689] [CRITICAL] WORKER TIMEOUT (pid:11820)
2013-11-20 20:02:52 [11689] [CRITICAL] WORKER TIMEOUT (pid:11821)
2013-11-20 20:02:52 [11689] [CRITICAL] WORKER TIMEOUT (pid:11823)
2013-11-20 20:02:52 [11689] [CRITICAL] WORKER TIMEOUT (pid:11824)
2013-11-20 20:02:52 [11689] [CRITICAL] WORKER TIMEOUT (pid:11825)
2013-11-20 20:02:52 [11689] [CRITICAL] WORKER TIMEOUT (pid:11826)
2013-11-20 20:02:52 [11689] [CRITICAL] WORKER TIMEOUT (pid:11827)
2013-11-20 20:02:52 [11689] [CRITICAL] WORKER TIMEOUT (pid:11828)
2013-11-20 20:02:52 [11689] [CRITICAL] WORKER TIMEOUT (pid:11829)
2013-11-20 20:02:52 [11689] [CRITICAL] WORKER TIMEOUT (pid:11831)
2013-11-20 20:02:52 [11689] [CRITICAL] WORKER TIMEOUT (pid:11832)
2013-11-20 20:02:52 [11689] [CRITICAL] WORKER TIMEOUT (pid:11833)
2013-11-20 20:02:52 [11689] [CRITICAL] WORKER TIMEOUT (pid:11788)
2013-11-20 20:02:52 [11689] [CRITICAL] WORKER TIMEOUT (pid:11820)
2013-11-20 20:02:52 [11689] [CRITICAL] WORKER TIMEOUT (pid:11821)
2013-11-20 20:02:52 [11689] [CRITICAL] WORKER TIMEOUT (pid:11822)
2013-11-20 20:02:52 [11689] [CRITICAL] WORKER TIMEOUT (pid:11823)
2013-11-20 20:02:52 [11689] [CRITICAL] WORKER TIMEOUT (pid:11824)
2013-11-20 20:02:52 [11689] [CRITICAL] WORKER TIMEOUT (pid:11825)
2013-11-20 20:02:52 [11689] [CRITICAL] WORKER TIMEOUT (pid:11826)
2013-11-20 20:02:52 [11689] [CRITICAL] WORKER TIMEOUT (pid:11827)
2013-11-20 20:02:52 [11689] [CRITICAL] WORKER TIMEOUT (pid:11828)
2013-11-20 20:02:52 [11689] [CRITICAL] WORKER TIMEOUT (pid:11829)
2013-11-20 20:02:52 [11689] [CRITICAL] WORKER TIMEOUT (pid:11831)
2013-11-20 20:02:52 [11689] [CRITICAL] WORKER TIMEOUT (pid:11832)
2013-11-20 20:02:52 [11689] [CRITICAL] WORKER TIMEOUT (pid:11833)
2013-11-20 20:02:52 [11689] [CRITICAL] WORKER TIMEOUT (pid:11820)
2013-11-20 20:02:52 [11689] [CRITICAL] WORKER TIMEOUT (pid:11822)
2013-11-20 20:02:52 [11689] [CRITICAL] WORKER TIMEOUT (pid:11825)
2013-11-20 20:02:52 [11689] [CRITICAL] WORKER TIMEOUT (pid:11827)
2013-11-20 20:02:52 [11689] [CRITICAL] WORKER TIMEOUT (pid:11828)
2013-11-20 20:02:52 [11689] [CRITICAL] WORKER TIMEOUT (pid:11831)
2013-11-20 20:02:52 [11689] [CRITICAL] WORKER TIMEOUT (pid:11833)
ERROR:app:Exception on /raw-updates [GET]
Traceback (most recent call last):
  File "/home/tfb/FrameworkBenchmarks/installs/pypy/site-packages/Flask-0.10.1-py2.7.egg/flask/app.py", line 1817, in wsgi_app
    response = self.full_dispatch_request()
  File "/home/tfb/FrameworkBenchmarks/installs/pypy/site-packages/Flask-0.10.1-py2.7.egg/flask/app.py", line 1477, in full_dispatch_request
    rv = self.handle_user_exception(e)
  File "/home/tfb/FrameworkBenchmarks/installs/pypy/site-packages/Flask-0.10.1-py2.7.egg/flask/app.py", line 1381, in handle_user_exception
    reraise(exc_type, exc_value, tb)
  File "/home/tfb/FrameworkBenchmarks/installs/pypy/site-packages/Flask-0.10.1-py2.7.egg/flask/app.py", line 1475, in full_dispatch_request
    rv = self.dispatch_request()
  File "/home/tfb/FrameworkBenchmarks/installs/pypy/site-packages/Flask-0.10.1-py2.7.egg/flask/app.py", line 1461, in dispatch_request
    return self.view_functions[rule.endpoint](**req.view_args)
  File "/home/tfb/FrameworkBenchmarks/flask/app.py", line 139, in raw_updates
    world = dbraw_engine.execute("SELECT * FROM World WHERE id=%s", (rp(),)).fetchone()
  File "/home/tfb/FrameworkBenchmarks/installs/pypy/site-packages/SQLAlchemy-0.8.2-py2.7.egg/sqlalchemy/engine/base.py", line 1613, in execute
    connection = self.contextual_connect(close_with_result=True)
  File "/home/tfb/FrameworkBenchmarks/installs/pypy/site-packages/SQLAlchemy-0.8.2-py2.7.egg/sqlalchemy/engine/base.py", line 1661, in contextual_connect
    self.pool.connect(),
  File "/home/tfb/FrameworkBenchmarks/installs/pypy/site-packages/SQLAlchemy-0.8.2-py2.7.egg/sqlalchemy/pool.py", line 272, in connect
    return _ConnectionFairy(self).checkout()
  File "/home/tfb/FrameworkBenchmarks/installs/pypy/site-packages/SQLAlchemy-0.8.2-py2.7.egg/sqlalchemy/pool.py", line 425, in __init__
    rec = self._connection_record = pool._do_get()
  File "/home/tfb/FrameworkBenchmarks/installs/pypy/site-packages/SQLAlchemy-0.8.2-py2.7.egg/sqlalchemy/pool.py", line 770, in _do_get
    (self.size(), self.overflow(), self._timeout))
TimeoutError: QueuePool limit of size 5 overflow 10 reached, connection timed out, timeout 30
ERROR:tornado.access:500 GET /raw-updates?queries=15 (172.16.98.98) 30002.13ms
2013-11-20 20:02:53 [11689] [CRITICAL] WORKER TIMEOUT (pid:11787)
2013-11-20 20:02:53 [11689] [CRITICAL] WORKER TIMEOUT (pid:11830)
ERROR:tornado.application:Uncaught exception, closing connection.
Traceback (most recent call last):
  File "/home/tfb/FrameworkBenchmarks/installs/pypy/site-packages/tornado-3.1-py2.7.egg/tornado/iostream.py", line 341, in wrapper
    callback(*args)
  File "/home/tfb/FrameworkBenchmarks/installs/pypy/site-packages/tornado-3.1-py2.7.egg/tornado/stack_context.py", line 331, in wrapped
    raise_exc_info(exc)
  File "/home/tfb/FrameworkBenchmarks/installs/pypy/site-packages/tornado-3.1-py2.7.egg/tornado/stack_context.py", line 302, in wrapped
    ret = fn(*args, **kwargs)
TypeError: exceptions must be old-style classes or derived from BaseException, not NoneType
ERROR:tornado.application:Uncaught exception, closing connection.
Traceback (most recent call last):
  File "/home/tfb/FrameworkBenchmarks/installs/pypy/site-packages/tornado-3.1-py2.7.egg/tornado/iostream.py", line 341, in wrapper
    callback(*args)
  File "/home/tfb/FrameworkBenchmarks/installs/pypy/site-packages/tornado-3.1-py2.7.egg/tornado/stack_context.py", line 331, in wrapped
    raise_exc_info(exc)
  File "/home/tfb/FrameworkBenchmarks/installs/pypy/site-packages/tornado-3.1-py2.7.egg/tornado/stack_context.py", line 302, in wrapped
    ret = fn(*args, **kwargs)
TypeError: exceptions must be old-style classes or derived from BaseException, not NoneType
ERROR:tornado.application:Uncaught exception, closing connection.
Traceback (most recent call last):
  File "/home/tfb/FrameworkBenchmarks/installs/pypy/site-packages/tornado-3.1-py2.7.egg/tornado/iostream.py", line 341, in wrapper
    callback(*args)
  File "/home/tfb/FrameworkBenchmarks/installs/pypy/site-packages/tornado-3.1-py2.7.egg/tornado/stack_context.py", line 331, in wrapped
    raise_exc_info(exc)
  File "/home/tfb/FrameworkBenchmarks/installs/pypy/site-packages/tornado-3.1-py2.7.egg/tornado/stack_context.py", line 302, in wrapped
    ret = fn(*args, **kwargs)
TypeError: exceptions must be old-style classes or derived from BaseException, not NoneType
ERROR:tornado.application:Uncaught exception, closing connection.
Traceback (most recent call last):
  File "/home/tfb/FrameworkBenchmarks/installs/pypy/site-packages/tornado-3.1-py2.7.egg/tornado/iostream.py", line 341, in wrapper
    callback(*args)
  File "/home/tfb/FrameworkBenchmarks/installs/pypy/site-packages/tornado-3.1-py2.7.egg/tornado/stack_context.py", line 331, in wrapped
    raise_exc_info(exc)
  File "/home/tfb/FrameworkBenchmarks/installs/pypy/site-packages/tornado-3.1-py2.7.egg/tornado/stack_context.py", line 302, in wrapped
    ret = fn(*args, **kwargs)
TypeError: exceptions must be old-style classes or derived from BaseException, not NoneType
ERROR:tornado.application:Uncaught exception, closing connection.
Traceback (most recent call last):
  File "/home/tfb/FrameworkBenchmarks/installs/pypy/site-packages/tornado-3.1-py2.7.egg/tornado/iostream.py", line 341, in wrapper
    callback(*args)
  File "/home/tfb/FrameworkBenchmarks/installs/pypy/site-packages/tornado-3.1-py2.7.egg/tornado/stack_context.py", line 331, in wrapped
    raise_exc_info(exc)
  File "/home/tfb/FrameworkBenchmarks/installs/pypy/site-packages/tornado-3.1-py2.7.egg/tornado/stack_context.py", line 302, in wrapped
    ret = fn(*args, **kwargs)
TypeError: exceptions must be old-style classes or derived from BaseException, not NoneType
ERROR:tornado.application:Exception in callback <_functools.partial object at 0x00007f34117b8f00>
Traceback (most recent call last):
  File "/home/tfb/FrameworkBenchmarks/installs/pypy/site-packages/tornado-3.1-py2.7.egg/tornado/ioloop.py", line 458, in _run_callback
    callback()
  File "/home/tfb/FrameworkBenchmarks/installs/pypy/lib_pypy/_functools.py", line 22, in __call__
    return self.func(*(self.args + fargs), **fkeywords)
  File "/home/tfb/FrameworkBenchmarks/installs/pypy/site-packages/tornado-3.1-py2.7.egg/tornado/stack_context.py", line 331, in wrapped
    raise_exc_info(exc)
  File "/home/tfb/FrameworkBenchmarks/installs/pypy/site-packages/tornado-3.1-py2.7.egg/tornado/stack_context.py", line 302, in wrapped
    ret = fn(*args, **kwargs)
  File "/home/tfb/FrameworkBenchmarks/installs/pypy/site-packages/tornado-3.1-py2.7.egg/tornado/iostream.py", line 341, in wrapper
    callback(*args)
  File "/home/tfb/FrameworkBenchmarks/installs/pypy/site-packages/tornado-3.1-py2.7.egg/tornado/stack_context.py", line 331, in wrapped
    raise_exc_info(exc)
  File "/home/tfb/FrameworkBenchmarks/installs/pypy/site-packages/tornado-3.1-py2.7.egg/tornado/stack_context.py", line 302, in wrapped
    ret = fn(*args, **kwargs)
TypeError: exceptions must be old-style classes or derived from BaseException, not NoneType
ERROR:tornado.application:Exception in callback <_functools.partial object at 0x00007f34117b90f8>
Traceback (most recent call last):
  File "/home/tfb/FrameworkBenchmarks/installs/pypy/site-packages/tornado-3.1-py2.7.egg/tornado/ioloop.py", line 458, in _run_callback
    callback()
  File "/home/tfb/FrameworkBenchmarks/installs/pypy/lib_pypy/_functools.py", line 22, in __call__
    return self.func(*(self.args + fargs), **fkeywords)
  File "/home/tfb/FrameworkBenchmarks/installs/pypy/site-packages/tornado-3.1-py2.7.egg/tornado/stack_context.py", line 331, in wrapped
    raise_exc_info(exc)
  File "/home/tfb/FrameworkBenchmarks/installs/pypy/site-packages/tornado-3.1-py2.7.egg/tornado/stack_context.py", line 302, in wrapped
    ret = fn(*args, **kwargs)
  File "/home/tfb/FrameworkBenchmarks/installs/pypy/site-packages/tornado-3.1-py2.7.egg/tornado/iostream.py", line 341, in wrapper
    callback(*args)
  File "/home/tfb/FrameworkBenchmarks/installs/pypy/site-packages/tornado-3.1-py2.7.egg/tornado/stack_context.py", line 331, in wrapped
    raise_exc_info(exc)
  File "/home/tfb/FrameworkBenchmarks/installs/pypy/site-packages/tornado-3.1-py2.7.egg/tornado/stack_context.py", line 302, in wrapped
    ret = fn(*args, **kwargs)
TypeError: exceptions must be old-style classes or derived from BaseException, not NoneType
ERROR:tornado.application:Exception in callback <_functools.partial object at 0x00007f34117b90f8>
Traceback (most recent call last):
  File "/home/tfb/FrameworkBenchmarks/installs/pypy/site-packages/tornado-3.1-py2.7.egg/tornado/ioloop.py", line 458, in _run_callback
    callback()
  File "/home/tfb/FrameworkBenchmarks/installs/pypy/lib_pypy/_functools.py", line 22, in __call__
    return self.func(*(self.args + fargs), **fkeywords)
  File "/home/tfb/FrameworkBenchmarks/installs/pypy/site-packages/tornado-3.1-py2.7.egg/tornado/stack_context.py", line 331, in wrapped
    raise_exc_info(exc)
  File "/home/tfb/FrameworkBenchmarks/installs/pypy/site-packages/tornado-3.1-py2.7.egg/tornado/stack_context.py", line 302, in wrapped
    ret = fn(*args, **kwargs)
  File "/home/tfb/FrameworkBenchmarks/installs/pypy/site-packages/tornado-3.1-py2.7.egg/tornado/iostream.py", line 341, in wrapper
    callback(*args)
  File "/home/tfb/FrameworkBenchmarks/installs/pypy/site-packages/tornado-3.1-py2.7.egg/tornado/stack_context.py", line 331, in wrapped
    raise_exc_info(exc)
  File "/home/tfb/FrameworkBenchmarks/installs/pypy/site-packages/tornado-3.1-py2.7.egg/tornado/stack_context.py", line 302, in wrapped
    ret = fn(*args, **kwargs)
TypeError: exceptions must be old-style classes or derived from BaseException, not NoneType
ERROR:tornado.application:Exception in callback <_functools.partial object at 0x00007f34117b8f70>
Traceback (most recent call last):
  File "/home/tfb/FrameworkBenchmarks/installs/pypy/site-packages/tornado-3.1-py2.7.egg/tornado/ioloop.py", line 458, in _run_callback
    callback()
  File "/home/tfb/FrameworkBenchmarks/installs/pypy/lib_pypy/_functools.py", line 22, in __call__
    return self.func(*(self.args + fargs), **fkeywords)
  File "/home/tfb/FrameworkBenchmarks/installs/pypy/site-packages/tornado-3.1-py2.7.egg/tornado/stack_context.py", line 331, in wrapped
    raise_exc_info(exc)
  File "/home/tfb/FrameworkBenchmarks/installs/pypy/site-packages/tornado-3.1-py2.7.egg/tornado/stack_context.py", line 302, in wrapped
    ret = fn(*args, **kwargs)
  File "/home/tfb/FrameworkBenchmarks/installs/pypy/site-packages/tornado-3.1-py2.7.egg/tornado/iostream.py", line 341, in wrapper
    callback(*args)
  File "/home/tfb/FrameworkBenchmarks/installs/pypy/site-packages/tornado-3.1-py2.7.egg/tornado/stack_context.py", line 331, in wrapped
    raise_exc_info(exc)
  File "/home/tfb/FrameworkBenchmarks/installs/pypy/site-packages/tornado-3.1-py2.7.egg/tornado/stack_context.py", line 302, in wrapped
    ret = fn(*args, **kwargs)
TypeError: exceptions must be old-style classes or derived from BaseException, not NoneType
ERROR:tornado.application:Exception in callback <_functools.partial object at 0x00007f34117b8cd0>
Traceback (most recent call last):
  File "/home/tfb/FrameworkBenchmarks/installs/pypy/site-packages/tornado-3.1-py2.7.egg/tornado/ioloop.py", line 458, in _run_callback
    callback()
  File "/home/tfb/FrameworkBenchmarks/installs/pypy/lib_pypy/_functools.py", line 22, in __call__
    return self.func(*(self.args + fargs), **fkeywords)
  File "/home/tfb/FrameworkBenchmarks/installs/pypy/site-packages/tornado-3.1-py2.7.egg/tornado/stack_context.py", line 331, in wrapped
    raise_exc_info(exc)
  File "/home/tfb/FrameworkBenchmarks/installs/pypy/site-packages/tornado-3.1-py2.7.egg/tornado/stack_context.py", line 302, in wrapped
    ret = fn(*args, **kwargs)
  File "/home/tfb/FrameworkBenchmarks/installs/pypy/site-packages/tornado-3.1-py2.7.egg/tornado/iostream.py", line 341, in wrapper
    callback(*args)
  File "/home/tfb/FrameworkBenchmarks/installs/pypy/site-packages/tornado-3.1-py2.7.egg/tornado/stack_context.py", line 331, in wrapped
    raise_exc_info(exc)
  File "/home/tfb/FrameworkBenchmarks/installs/pypy/site-packages/tornado-3.1-py2.7.egg/tornado/stack_context.py", line 302, in wrapped
    ret = fn(*args, **kwargs)
TypeError: exceptions must be old-style classes or derived from BaseException, not NoneType
ERROR:tornado.application:Uncaught exception, closing connection.
Traceback (most recent call last):
  File "/home/tfb/FrameworkBenchmarks/installs/pypy/site-packages/tornado-3.1-py2.7.egg/tornado/iostream.py", line 341, in wrapper
    callback(*args)
  File "/home/tfb/FrameworkBenchmarks/installs/pypy/site-packages/tornado-3.1-py2.7.egg/tornado/stack_context.py", line 331, in wrapped
    raise_exc_info(exc)
  File "/home/tfb/FrameworkBenchmarks/installs/pypy/site-packages/tornado-3.1-py2.7.egg/tornado/stack_context.py", line 302, in wrapped
    ret = fn(*args, **kwargs)
TypeError: exceptions must be old-style classes or derived from BaseException, not NoneType
ERROR:tornado.application:Exception in callback <_functools.partial object at 0x00007f34117b88a8>
Traceback (most recent call last):
  File "/home/tfb/FrameworkBenchmarks/installs/pypy/site-packages/tornado-3.1-py2.7.egg/tornado/ioloop.py", line 458, in _run_callback
    callback()
  File "/home/tfb/FrameworkBenchmarks/installs/pypy/lib_pypy/_functools.py", line 22, in __call__
    return self.func(*(self.args + fargs), **fkeywords)
  File "/home/tfb/FrameworkBenchmarks/installs/pypy/site-packages/tornado-3.1-py2.7.egg/tornado/stack_context.py", line 331, in wrapped
    raise_exc_info(exc)
  File "/home/tfb/FrameworkBenchmarks/installs/pypy/site-packages/tornado-3.1-py2.7.egg/tornado/stack_context.py", line 302, in wrapped
    ret = fn(*args, **kwargs)
  File "/home/tfb/FrameworkBenchmarks/installs/pypy/site-packages/tornado-3.1-py2.7.egg/tornado/iostream.py", line 341, in wrapper
    callback(*args)
  File "/home/tfb/FrameworkBenchmarks/installs/pypy/site-packages/tornado-3.1-py2.7.egg/tornado/stack_context.py", line 331, in wrapped
    raise_exc_info(exc)
  File "/home/tfb/FrameworkBenchmarks/installs/pypy/site-packages/tornado-3.1-py2.7.egg/tornado/stack_context.py", line 302, in wrapped
    ret = fn(*args, **kwargs)
TypeError: exceptions must be old-style classes or derived from BaseException, not NoneType
ERROR:tornado.application:Uncaught exception, closing connection.
Traceback (most recent call last):
  File "/home/tfb/FrameworkBenchmarks/installs/pypy/site-packages/tornado-3.1-py2.7.egg/tornado/iostream.py", line 341, in wrapper
    callback(*args)
  File "/home/tfb/FrameworkBenchmarks/installs/pypy/site-packages/tornado-3.1-py2.7.egg/tornado/stack_context.py", line 331, in wrapped
    raise_exc_info(exc)
  File "/home/tfb/FrameworkBenchmarks/installs/pypy/site-packages/tornado-3.1-py2.7.egg/tornado/stack_context.py", line 302, in wrapped
    ret = fn(*args, **kwargs)
TypeError: exceptions must be old-style classes or derived from BaseException, not NoneType
ERROR:tornado.application:Exception in callback <_functools.partial object at 0x00007f34117b9478>
Traceback (most recent call last):
  File "/home/tfb/FrameworkBenchmarks/installs/pypy/site-packages/tornado-3.1-py2.7.egg/tornado/ioloop.py", line 458, in _run_callback
    callback()
  File "/home/tfb/FrameworkBenchmarks/installs/pypy/lib_pypy/_functools.py", line 22, in __call__
    return self.func(*(self.args + fargs), **fkeywords)
  File "/home/tfb/FrameworkBenchmarks/installs/pypy/site-packages/tornado-3.1-py2.7.egg/tornado/stack_context.py", line 331, in wrapped
    raise_exc_info(exc)
  File "/home/tfb/FrameworkBenchmarks/installs/pypy/site-packages/tornado-3.1-py2.7.egg/tornado/stack_context.py", line 302, in wrapped
    ret = fn(*args, **kwargs)
  File "/home/tfb/FrameworkBenchmarks/installs/pypy/site-packages/tornado-3.1-py2.7.egg/tornado/iostream.py", line 341, in wrapper
    callback(*args)
  File "/home/tfb/FrameworkBenchmarks/installs/pypy/site-packages/tornado-3.1-py2.7.egg/tornado/stack_context.py", line 331, in wrapped
    raise_exc_info(exc)
  File "/home/tfb/FrameworkBenchmarks/installs/pypy/site-packages/tornado-3.1-py2.7.egg/tornado/stack_context.py", line 302, in wrapped
    ret = fn(*args, **kwargs)
TypeError: exceptions must be old-style classes or derived from BaseException, not NoneType
ERROR:tornado.application:Exception in callback <_functools.partial object at 0x00007f34117b91d8>
Traceback (most recent call last):
  File "/home/tfb/FrameworkBenchmarks/installs/pypy/site-packages/tornado-3.1-py2.7.egg/tornado/ioloop.py", line 458, in _run_callback
    callback()
  File "/home/tfb/FrameworkBenchmarks/installs/pypy/lib_pypy/_functools.py", line 22, in __call__
    return self.func(*(self.args + fargs), **fkeywords)
  File "/home/tfb/FrameworkBenchmarks/installs/pypy/site-packages/tornado-3.1-py2.7.egg/tornado/stack_context.py", line 331, in wrapped
    raise_exc_info(exc)
  File "/home/tfb/FrameworkBenchmarks/installs/pypy/site-packages/tornado-3.1-py2.7.egg/tornado/stack_context.py", line 302, in wrapped
    ret = fn(*args, **kwargs)
  File "/home/tfb/FrameworkBenchmarks/installs/pypy/site-packages/tornado-3.1-py2.7.egg/tornado/iostream.py", line 341, in wrapper
    callback(*args)
  File "/home/tfb/FrameworkBenchmarks/installs/pypy/site-packages/tornado-3.1-py2.7.egg/tornado/stack_context.py", line 331, in wrapped
    raise_exc_info(exc)
  File "/home/tfb/FrameworkBenchmarks/installs/pypy/site-packages/tornado-3.1-py2.7.egg/tornado/stack_context.py", line 302, in wrapped
    ret = fn(*args, **kwargs)
TypeError: exceptions must be old-style classes or derived from BaseException, not NoneType
ERROR:tornado.application:Uncaught exception, closing connection.
Traceback (most recent call last):
  File "/home/tfb/FrameworkBenchmarks/installs/pypy/site-packages/tornado-3.1-py2.7.egg/tornado/iostream.py", line 341, in wrapper
    callback(*args)
  File "/home/tfb/FrameworkBenchmarks/installs/pypy/site-packages/tornado-3.1-py2.7.egg/tornado/stack_context.py", line 331, in wrapped
    raise_exc_info(exc)
  File "/home/tfb/FrameworkBenchmarks/installs/pypy/site-packages/tornado-3.1-py2.7.egg/tornado/stack_context.py", line 302, in wrapped
    ret = fn(*args, **kwargs)
TypeError: exceptions must be old-style classes or derived from BaseException, not NoneType
ERROR:tornado.application:Exception in callback <_functools.partial object at 0x00007f34117b94b0>
Traceback (most recent call last):
  File "/home/tfb/FrameworkBenchmarks/installs/pypy/site-packages/tornado-3.1-py2.7.egg/tornado/ioloop.py", line 458, in _run_callback
    callback()
  File "/home/tfb/FrameworkBenchmarks/installs/pypy/lib_pypy/_functools.py", line 22, in __call__
    return self.func(*(self.args + fargs), **fkeywords)
  File "/home/tfb/FrameworkBenchmarks/installs/pypy/site-packages/tornado-3.1-py2.7.egg/tornado/stack_context.py", line 331, in wrapped
    raise_exc_info(exc)
  File "/home/tfb/FrameworkBenchmarks/installs/pypy/site-packages/tornado-3.1-py2.7.egg/tornado/stack_context.py", line 302, in wrapped
    ret = fn(*args, **kwargs)
  File "/home/tfb/FrameworkBenchmarks/installs/pypy/site-packages/tornado-3.1-py2.7.egg/tornado/iostream.py", line 341, in wrapper
    callback(*args)
  File "/home/tfb/FrameworkBenchmarks/installs/pypy/site-packages/tornado-3.1-py2.7.egg/tornado/stack_context.py", line 331, in wrapped
    raise_exc_info(exc)
  File "/home/tfb/FrameworkBenchmarks/installs/pypy/site-packages/tornado-3.1-py2.7.egg/tornado/stack_context.py", line 302, in wrapped
    ret = fn(*args, **kwargs)
TypeError: exceptions must be old-style classes or derived from BaseException, not NoneType
ERROR:tornado.application:Uncaught exception, closing connection.
Traceback (most recent call last):
  File "/home/tfb/FrameworkBenchmarks/installs/pypy/site-packages/tornado-3.1-py2.7.egg/tornado/iostream.py", line 341, in wrapper
    callback(*args)
  File "/home/tfb/FrameworkBenchmarks/installs/pypy/site-packages/tornado-3.1-py2.7.egg/tornado/stack_context.py", line 331, in wrapped
    raise_exc_info(exc)
  File "/home/tfb/FrameworkBenchmarks/installs/pypy/site-packages/tornado-3.1-py2.7.egg/tornado/stack_context.py", line 302, in wrapped
    ret = fn(*args, **kwargs)
TypeError: exceptions must be old-style classes or derived from BaseException, not NoneType
ERROR:tornado.application:Exception in callback <_functools.partial object at 0x00007f34117b9248>
Traceback (most recent call last):
  File "/home/tfb/FrameworkBenchmarks/installs/pypy/site-packages/tornado-3.1-py2.7.egg/tornado/ioloop.py", line 458, in _run_callback
    callback()
  File "/home/tfb/FrameworkBenchmarks/installs/pypy/lib_pypy/_functools.py", line 22, in __call__
    return self.func(*(self.args + fargs), **fkeywords)
  File "/home/tfb/FrameworkBenchmarks/installs/pypy/site-packages/tornado-3.1-py2.7.egg/tornado/stack_context.py", line 331, in wrapped
    raise_exc_info(exc)
  File "/home/tfb/FrameworkBenchmarks/installs/pypy/site-packages/tornado-3.1-py2.7.egg/tornado/stack_context.py", line 302, in wrapped
    ret = fn(*args, **kwargs)
  File "/home/tfb/FrameworkBenchmarks/installs/pypy/site-packages/tornado-3.1-py2.7.egg/tornado/iostream.py", line 341, in wrapper
    callback(*args)
  File "/home/tfb/FrameworkBenchmarks/installs/pypy/site-packages/tornado-3.1-py2.7.egg/tornado/stack_context.py", line 331, in wrapped
    raise_exc_info(exc)
  File "/home/tfb/FrameworkBenchmarks/installs/pypy/site-packages/tornado-3.1-py2.7.egg/tornado/stack_context.py", line 302, in wrapped
    ret = fn(*args, **kwargs)
TypeError: exceptions must be old-style classes or derived from BaseException, not NoneType
ERROR:tornado.application:Uncaught exception, closing connection.
Traceback (most recent call last):
  File "/home/tfb/FrameworkBenchmarks/installs/pypy/site-packages/tornado-3.1-py2.7.egg/tornado/iostream.py", line 341, in wrapper
    callback(*args)
  File "/home/tfb/FrameworkBenchmarks/installs/pypy/site-packages/tornado-3.1-py2.7.egg/tornado/stack_context.py", line 331, in wrapped
    raise_exc_info(exc)
  File "/home/tfb/FrameworkBenchmarks/installs/pypy/site-packages/tornado-3.1-py2.7.egg/tornado/stack_context.py", line 302, in wrapped
    ret = fn(*args, **kwargs)
TypeError: exceptions must be old-style classes or derived from BaseException, not NoneType
ERROR:tornado.application:Uncaught exception, closing connection.
Traceback (most recent call last):
  File "/home/tfb/FrameworkBenchmarks/installs/pypy/site-packages/tornado-3.1-py2.7.egg/tornado/iostream.py", line 341, in wrapper
    callback(*args)
  File "/home/tfb/FrameworkBenchmarks/installs/pypy/site-packages/tornado-3.1-py2.7.egg/tornado/stack_context.py", line 331, in wrapped
    raise_exc_info(exc)
  File "/home/tfb/FrameworkBenchmarks/installs/pypy/site-packages/tornado-3.1-py2.7.egg/tornado/stack_context.py", line 302, in wrapped
    ret = fn(*args, **kwargs)
TypeError: exceptions must be old-style classes or derived from BaseException, not NoneType
ERROR:tornado.application:Uncaught exception, closing connection.
Traceback (most recent call last):
  File "/home/tfb/FrameworkBenchmarks/installs/pypy/site-packages/tornado-3.1-py2.7.egg/tornado/iostream.py", line 341, in wrapper
    callback(*args)
  File "/home/tfb/FrameworkBenchmarks/installs/pypy/site-packages/tornado-3.1-py2.7.egg/tornado/stack_context.py", line 331, in wrapped
    raise_exc_info(exc)
  File "/home/tfb/FrameworkBenchmarks/installs/pypy/site-packages/tornado-3.1-py2.7.egg/tornado/stack_context.py", line 302, in wrapped
    ret = fn(*args, **kwargs)
TypeError: exceptions must be old-style classes or derived from BaseException, not NoneType
ERROR:tornado.application:Exception in callback <_functools.partial object at 0x00007f34117b9280>
Traceback (most recent call last):
  File "/home/tfb/FrameworkBenchmarks/installs/pypy/site-packages/tornado-3.1-py2.7.egg/tornado/ioloop.py", line 458, in _run_callback
    callback()
  File "/home/tfb/FrameworkBenchmarks/installs/pypy/lib_pypy/_functools.py", line 22, in __call__
    return self.func(*(self.args + fargs), **fkeywords)
  File "/home/tfb/FrameworkBenchmarks/installs/pypy/site-packages/tornado-3.1-py2.7.egg/tornado/stack_context.py", line 331, in wrapped
    raise_exc_info(exc)
  File "/home/tfb/FrameworkBenchmarks/installs/pypy/site-packages/tornado-3.1-py2.7.egg/tornado/stack_context.py", line 302, in wrapped
    ret = fn(*args, **kwargs)
  File "/home/tfb/FrameworkBenchmarks/installs/pypy/site-packages/tornado-3.1-py2.7.egg/tornado/iostream.py", line 341, in wrapper
    callback(*args)
  File "/home/tfb/FrameworkBenchmarks/installs/pypy/site-packages/tornado-3.1-py2.7.egg/tornado/stack_context.py", line 331, in wrapped
    raise_exc_info(exc)
  File "/home/tfb/FrameworkBenchmarks/installs/pypy/site-packages/tornado-3.1-py2.7.egg/tornado/stack_context.py", line 302, in wrapped
    ret = fn(*args, **kwargs)
TypeError: exceptions must be old-style classes or derived from BaseException, not NoneType
ERROR:tornado.application:Exception in callback <_functools.partial object at 0x00007f34117b9788>
Traceback (most recent call last):
  File "/home/tfb/FrameworkBenchmarks/installs/pypy/site-packages/tornado-3.1-py2.7.egg/tornado/ioloop.py", line 458, in _run_callback
    callback()
  File "/home/tfb/FrameworkBenchmarks/installs/pypy/lib_pypy/_functools.py", line 22, in __call__
    return self.func(*(self.args + fargs), **fkeywords)
  File "/home/tfb/FrameworkBenchmarks/installs/pypy/site-packages/tornado-3.1-py2.7.egg/tornado/stack_context.py", line 331, in wrapped
    raise_exc_info(exc)
  File "/home/tfb/FrameworkBenchmarks/installs/pypy/site-packages/tornado-3.1-py2.7.egg/tornado/stack_context.py", line 302, in wrapped
    ret = fn(*args, **kwargs)
  File "/home/tfb/FrameworkBenchmarks/installs/pypy/site-packages/tornado-3.1-py2.7.egg/tornado/iostream.py", line 341, in wrapper
    callback(*args)
  File "/home/tfb/FrameworkBenchmarks/installs/pypy/site-packages/tornado-3.1-py2.7.egg/tornado/stack_context.py", line 331, in wrapped
    raise_exc_info(exc)
  File "/home/tfb/FrameworkBenchmarks/installs/pypy/site-packages/tornado-3.1-py2.7.egg/tornado/stack_context.py", line 302, in wrapped
    ret = fn(*args, **kwargs)
TypeError: exceptions must be old-style classes or derived from BaseException, not NoneType
ERROR:tornado.application:Exception in callback <_functools.partial object at 0x00007f34117b9440>
Traceback (most recent call last):
  File "/home/tfb/FrameworkBenchmarks/installs/pypy/site-packages/tornado-3.1-py2.7.egg/tornado/ioloop.py", line 458, in _run_callback
    callback()
  File "/home/tfb/FrameworkBenchmarks/installs/pypy/lib_pypy/_functools.py", line 22, in __call__
    return self.func(*(self.args + fargs), **fkeywords)
  File "/home/tfb/FrameworkBenchmarks/installs/pypy/site-packages/tornado-3.1-py2.7.egg/tornado/stack_context.py", line 331, in wrapped
    raise_exc_info(exc)
  File "/home/tfb/FrameworkBenchmarks/installs/pypy/site-packages/tornado-3.1-py2.7.egg/tornado/stack_context.py", line 302, in wrapped
    ret = fn(*args, **kwargs)
  File "/home/tfb/FrameworkBenchmarks/installs/pypy/site-packages/tornado-3.1-py2.7.egg/tornado/iostream.py", line 341, in wrapper
    callback(*args)
  File "/home/tfb/FrameworkBenchmarks/installs/pypy/site-packages/tornado-3.1-py2.7.egg/tornado/stack_context.py", line 331, in wrapped
    raise_exc_info(exc)
  File "/home/tfb/FrameworkBenchmarks/installs/pypy/site-packages/tornado-3.1-py2.7.egg/tornado/stack_context.py", line 302, in wrapped
    ret = fn(*args, **kwargs)
TypeError: exceptions must be old-style classes or derived from BaseException, not NoneType
ERROR:tornado.application:Uncaught exception, closing connection.
Traceback (most recent call last):
  File "/home/tfb/FrameworkBenchmarks/installs/pypy/site-packages/tornado-3.1-py2.7.egg/tornado/iostream.py", line 341, in wrapper
    callback(*args)
  File "/home/tfb/FrameworkBenchmarks/installs/pypy/site-packages/tornado-3.1-py2.7.egg/tornado/stack_context.py", line 331, in wrapped
    raise_exc_info(exc)
  File "/home/tfb/FrameworkBenchmarks/installs/pypy/site-packages/tornado-3.1-py2.7.egg/tornado/stack_context.py", line 302, in wrapped
    ret = fn(*args, **kwargs)
TypeError: exceptions must be old-style classes or derived from BaseException, not NoneType
ERROR:tornado.application:Uncaught exception, closing connection.
Traceback (most recent call last):
  File "/home/tfb/FrameworkBenchmarks/installs/pypy/site-packages/tornado-3.1-py2.7.egg/tornado/iostream.py", line 341, in wrapper
    callback(*args)
  File "/home/tfb/FrameworkBenchmarks/installs/pypy/site-packages/tornado-3.1-py2.7.egg/tornado/stack_context.py", line 331, in wrapped
    raise_exc_info(exc)
  File "/home/tfb/FrameworkBenchmarks/installs/pypy/site-packages/tornado-3.1-py2.7.egg/tornado/stack_context.py", line 302, in wrapped
    ret = fn(*args, **kwargs)
TypeError: exceptions must be old-style classes or derived from BaseException, not NoneType
ERROR:tornado.application:Exception in callback <_functools.partial object at 0x00007f34117b92b8>
Traceback (most recent call last):
  File "/home/tfb/FrameworkBenchmarks/installs/pypy/site-packages/tornado-3.1-py2.7.egg/tornado/ioloop.py", line 458, in _run_callback
    callback()
  File "/home/tfb/FrameworkBenchmarks/installs/pypy/lib_pypy/_functools.py", line 22, in __call__
    return self.func(*(self.args + fargs), **fkeywords)
  File "/home/tfb/FrameworkBenchmarks/installs/pypy/site-packages/tornado-3.1-py2.7.egg/tornado/stack_context.py", line 331, in wrapped
    raise_exc_info(exc)
  File "/home/tfb/FrameworkBenchmarks/installs/pypy/site-packages/tornado-3.1-py2.7.egg/tornado/stack_context.py", line 302, in wrapped
    ret = fn(*args, **kwargs)
  File "/home/tfb/FrameworkBenchmarks/installs/pypy/site-packages/tornado-3.1-py2.7.egg/tornado/iostream.py", line 341, in wrapper
    callback(*args)
  File "/home/tfb/FrameworkBenchmarks/installs/pypy/site-packages/tornado-3.1-py2.7.egg/tornado/stack_context.py", line 331, in wrapped
    raise_exc_info(exc)
  File "/home/tfb/FrameworkBenchmarks/installs/pypy/site-packages/tornado-3.1-py2.7.egg/tornado/stack_context.py", line 302, in wrapped
    ret = fn(*args, **kwargs)
TypeError: exceptions must be old-style classes or derived from BaseException, not NoneType
ERROR:tornado.application:Exception in callback <_functools.partial object at 0x00007f34117b9478>
Traceback (most recent call last):
  File "/home/tfb/FrameworkBenchmarks/installs/pypy/site-packages/tornado-3.1-py2.7.egg/tornado/ioloop.py", line 458, in _run_callback
    callback()
  File "/home/tfb/FrameworkBenchmarks/installs/pypy/lib_pypy/_functools.py", line 22, in __call__
    return self.func(*(self.args + fargs), **fkeywords)
  File "/home/tfb/FrameworkBenchmarks/installs/pypy/site-packages/tornado-3.1-py2.7.egg/tornado/stack_context.py", line 331, in wrapped
    raise_exc_info(exc)
  File "/home/tfb/FrameworkBenchmarks/installs/pypy/site-packages/tornado-3.1-py2.7.egg/tornado/stack_context.py", line 302, in wrapped
    ret = fn(*args, **kwargs)
  File "/home/tfb/FrameworkBenchmarks/installs/pypy/site-packages/tornado-3.1-py2.7.egg/tornado/iostream.py", line 341, in wrapper
    callback(*args)
  File "/home/tfb/FrameworkBenchmarks/installs/pypy/site-packages/tornado-3.1-py2.7.egg/tornado/stack_context.py", line 331, in wrapped
    raise_exc_info(exc)
  File "/home/tfb/FrameworkBenchmarks/installs/pypy/site-packages/tornado-3.1-py2.7.egg/tornado/stack_context.py", line 302, in wrapped
    ret = fn(*args, **kwargs)
TypeError: exceptions must be old-style classes or derived from BaseException, not NoneType
ERROR:tornado.application:Uncaught exception, closing connection.
Traceback (most recent call last):
  File "/home/tfb/FrameworkBenchmarks/installs/pypy/site-packages/tornado-3.1-py2.7.egg/tornado/iostream.py", line 341, in wrapper
    callback(*args)
  File "/home/tfb/FrameworkBenchmarks/installs/pypy/site-packages/tornado-3.1-py2.7.egg/tornado/stack_context.py", line 331, in wrapped
    raise_exc_info(exc)
  File "/home/tfb/FrameworkBenchmarks/installs/pypy/site-packages/tornado-3.1-py2.7.egg/tornado/stack_context.py", line 302, in wrapped
    ret = fn(*args, **kwargs)
TypeError: exceptions must be old-style classes or derived from BaseException, not NoneType
ERROR:tornado.application:Exception in callback <_functools.partial object at 0x00007f34117b9670>
Traceback (most recent call last):
  File "/home/tfb/FrameworkBenchmarks/installs/pypy/site-packages/tornado-3.1-py2.7.egg/tornado/ioloop.py", line 458, in _run_callback
    callback()
  File "/home/tfb/FrameworkBenchmarks/installs/pypy/lib_pypy/_functools.py", line 22, in __call__
    return self.func(*(self.args + fargs), **fkeywords)
  File "/home/tfb/FrameworkBenchmarks/installs/pypy/site-packages/tornado-3.1-py2.7.egg/tornado/stack_context.py", line 331, in wrapped
    raise_exc_info(exc)
  File "/home/tfb/FrameworkBenchmarks/installs/pypy/site-packages/tornado-3.1-py2.7.egg/tornado/stack_context.py", line 302, in wrapped
    ret = fn(*args, **kwargs)
  File "/home/tfb/FrameworkBenchmarks/installs/pypy/site-packages/tornado-3.1-py2.7.egg/tornado/iostream.py", line 341, in wrapper
    callback(*args)
  File "/home/tfb/FrameworkBenchmarks/installs/pypy/site-packages/tornado-3.1-py2.7.egg/tornado/stack_context.py", line 331, in wrapped
    raise_exc_info(exc)
  File "/home/tfb/FrameworkBenchmarks/installs/pypy/site-packages/tornado-3.1-py2.7.egg/tornado/stack_context.py", line 302, in wrapped
    ret = fn(*args, **kwargs)
TypeError: exceptions must be old-style classes or derived from BaseException, not NoneType
debug: OperationError:
debug:  operror-type: SystemExit
debug:  operror-value: 0
ERROR:tornado.application:Uncaught exception, closing connection.
Traceback (most recent call last):
  File "/home/tfb/FrameworkBenchmarks/installs/pypy/site-packages/tornado-3.1-py2.7.egg/tornado/iostream.py", line 341, in wrapper
    callback(*args)
  File "/home/tfb/FrameworkBenchmarks/installs/pypy/site-packages/tornado-3.1-py2.7.egg/tornado/stack_context.py", line 331, in wrapped
    raise_exc_info(exc)
  File "/home/tfb/FrameworkBenchmarks/installs/pypy/site-packages/tornado-3.1-py2.7.egg/tornado/stack_context.py", line 302, in wrapped
    ret = fn(*args, **kwargs)
TypeError: exceptions must be old-style classes or derived from BaseException, not NoneType
ERROR:tornado.application:Exception in callback <_functools.partial object at 0x00007f34117b97c0>
Traceback (most recent call last):
  File "/home/tfb/FrameworkBenchmarks/installs/pypy/site-packages/tornado-3.1-py2.7.egg/tornado/ioloop.py", line 458, in _run_callback
    callback()
  File "/home/tfb/FrameworkBenchmarks/installs/pypy/lib_pypy/_functools.py", line 22, in __call__
    return self.func(*(self.args + fargs), **fkeywords)
  File "/home/tfb/FrameworkBenchmarks/installs/pypy/site-packages/tornado-3.1-py2.7.egg/tornado/stack_context.py", line 331, in wrapped
    raise_exc_info(exc)
  File "/home/tfb/FrameworkBenchmarks/installs/pypy/site-packages/tornado-3.1-py2.7.egg/tornado/stack_context.py", line 302, in wrapped
    ret = fn(*args, **kwargs)
  File "/home/tfb/FrameworkBenchmarks/installs/pypy/site-packages/tornado-3.1-py2.7.egg/tornado/iostream.py", line 341, in wrapper
    callback(*args)
  File "/home/tfb/FrameworkBenchmarks/installs/pypy/site-packages/tornado-3.1-py2.7.egg/tornado/stack_context.py", line 331, in wrapped
    raise_exc_info(exc)
  File "/home/tfb/FrameworkBenchmarks/installs/pypy/site-packages/tornado-3.1-py2.7.egg/tornado/stack_context.py", line 302, in wrapped
    ret = fn(*args, **kwargs)
TypeError: exceptions must be old-style classes or derived from BaseException, not NoneType
ERROR:tornado.application:Uncaught exception, closing connection.
Traceback (most recent call last):
  File "/home/tfb/FrameworkBenchmarks/installs/pypy/site-packages/tornado-3.1-py2.7.egg/tornado/iostream.py", line 341, in wrapper
    callback(*args)
  File "/home/tfb/FrameworkBenchmarks/installs/pypy/site-packages/tornado-3.1-py2.7.egg/tornado/stack_context.py", line 331, in wrapped
    raise_exc_info(exc)
  File "/home/tfb/FrameworkBenchmarks/installs/pypy/site-packages/tornado-3.1-py2.7.egg/tornado/stack_context.py", line 302, in wrapped
    ret = fn(*args, **kwargs)
TypeError: exceptions must be old-style classes or derived from BaseException, not NoneType
debug: OperationError:
debug:  operror-type: SystemExit
debug:  operror-value: 0
debug: OperationError:
debug:  operror-type: SystemExit
debug:  operror-value: 0
