2013-12-14 09:23:42 [1529] [INFO] Starting gunicorn 18.0
2013-12-14 09:23:42 [1529] [INFO] Listening at: http://0.0.0.0:6543 (1529)
2013-12-14 09:23:42 [1529] [INFO] Using worker: sync
2013-12-14 09:23:42 [1532] [INFO] Booting worker with pid: 1532
2013-12-14 09:23:42 [1533] [INFO] Booting worker with pid: 1533
2013-12-14 09:23:42 [1534] [INFO] Booting worker with pid: 1534
2013-12-14 09:23:42 [1535] [INFO] Booting worker with pid: 1535
2013-12-14 09:23:42 [1536] [INFO] Booting worker with pid: 1536
2013-12-14 09:23:43 [1537] [INFO] Booting worker with pid: 1537
2013-12-14 09:24:42 [1532] [ERROR] Error handling request
Traceback (most recent call last):
  File "/home/ubuntu/FrameworkBenchmarks/installs/py3/lib/python3.3/site-packages/SQLAlchemy-0.9.0b1-py3.3-linux-x86_64.egg/sqlalchemy/engine/base.py", line 867, in _execute_context
    context)
  File "/home/ubuntu/FrameworkBenchmarks/installs/py3/lib/python3.3/site-packages/SQLAlchemy-0.9.0b1-py3.3-linux-x86_64.egg/sqlalchemy/engine/default.py", line 376, in do_execute
    cursor.execute(statement, parameters)
psycopg2.ProgrammingError: relation "World" does not exist
LINE 2: FROM "World" 
             ^


The above exception was the direct cause of the following exception:

Traceback (most recent call last):
  File "/home/ubuntu/FrameworkBenchmarks/installs/py3/lib/python3.3/site-packages/gunicorn-18.0-py3.3.egg/gunicorn/workers/sync.py", line 131, in handle_request
    respiter = self.wsgi(environ, resp.start_response)
  File "/home/ubuntu/FrameworkBenchmarks/installs/py3/lib/python3.3/site-packages/pyramid/router.py", line 251, in __call__
    response = self.invoke_subrequest(request, use_tweens=True)
  File "/home/ubuntu/FrameworkBenchmarks/installs/py3/lib/python3.3/site-packages/pyramid/router.py", line 227, in invoke_subrequest
    response = handle_request(request)
  File "/home/ubuntu/FrameworkBenchmarks/installs/py3/lib/python3.3/site-packages/pyramid/tweens.py", line 21, in excview_tween
    response = handler(request)
  File "/home/ubuntu/FrameworkBenchmarks/installs/py3/lib/python3.3/site-packages/pyramid/router.py", line 161, in handle_request
    response = view_callable(context, request)
  File "/home/ubuntu/FrameworkBenchmarks/installs/py3/lib/python3.3/site-packages/pyramid/config/views.py", line 347, in rendered_view
    result = view(context, request)
  File "/home/ubuntu/FrameworkBenchmarks/installs/py3/lib/python3.3/site-packages/pyramid/config/views.py", line 493, in _requestonly_view
    response = view(request)
  File "/home/ubuntu/FrameworkBenchmarks/pyramid/frameworkbenchmarks/views.py", line 25, in test_2
    result = DBSession.query(World).filter(World.id == num).one()
  File "/home/ubuntu/FrameworkBenchmarks/installs/py3/lib/python3.3/site-packages/SQLAlchemy-0.9.0b1-py3.3-linux-x86_64.egg/sqlalchemy/orm/query.py", line 2303, in one
    ret = list(self)
  File "/home/ubuntu/FrameworkBenchmarks/installs/py3/lib/python3.3/site-packages/SQLAlchemy-0.9.0b1-py3.3-linux-x86_64.egg/sqlalchemy/orm/query.py", line 2346, in __iter__
    return self._execute_and_instances(context)
  File "/home/ubuntu/FrameworkBenchmarks/installs/py3/lib/python3.3/site-packages/SQLAlchemy-0.9.0b1-py3.3-linux-x86_64.egg/sqlalchemy/orm/query.py", line 2361, in _execute_and_instances
    result = conn.execute(querycontext.statement, self._params)
  File "/home/ubuntu/FrameworkBenchmarks/installs/py3/lib/python3.3/site-packages/SQLAlchemy-0.9.0b1-py3.3-linux-x86_64.egg/sqlalchemy/engine/base.py", line 664, in execute
    return meth(self, multiparams, params)
  File "/home/ubuntu/FrameworkBenchmarks/installs/py3/lib/python3.3/site-packages/SQLAlchemy-0.9.0b1-py3.3-linux-x86_64.egg/sqlalchemy/sql/elements.py", line 272, in _execute_on_connection
    return connection._execute_clauseelement(self, multiparams, params)
  File "/home/ubuntu/FrameworkBenchmarks/installs/py3/lib/python3.3/site-packages/SQLAlchemy-0.9.0b1-py3.3-linux-x86_64.egg/sqlalchemy/engine/base.py", line 761, in _execute_clauseelement
    compiled_sql, distilled_params
  File "/home/ubuntu/FrameworkBenchmarks/installs/py3/lib/python3.3/site-packages/SQLAlchemy-0.9.0b1-py3.3-linux-x86_64.egg/sqlalchemy/engine/base.py", line 874, in _execute_context
    context)
  File "/home/ubuntu/FrameworkBenchmarks/installs/py3/lib/python3.3/site-packages/SQLAlchemy-0.9.0b1-py3.3-linux-x86_64.egg/sqlalchemy/engine/base.py", line 1023, in _handle_dbapi_exception
    exc_info
  File "/home/ubuntu/FrameworkBenchmarks/installs/py3/lib/python3.3/site-packages/SQLAlchemy-0.9.0b1-py3.3-linux-x86_64.egg/sqlalchemy/util/compat.py", line 174, in raise_from_cause
    reraise(type(exception), exception, tb=exc_tb, cause=exc_value)
  File "/home/ubuntu/FrameworkBenchmarks/installs/py3/lib/python3.3/site-packages/SQLAlchemy-0.9.0b1-py3.3-linux-x86_64.egg/sqlalchemy/util/compat.py", line 167, in reraise
    raise value.with_traceback(tb)
  File "/home/ubuntu/FrameworkBenchmarks/installs/py3/lib/python3.3/site-packages/SQLAlchemy-0.9.0b1-py3.3-linux-x86_64.egg/sqlalchemy/engine/base.py", line 867, in _execute_context
    context)
  File "/home/ubuntu/FrameworkBenchmarks/installs/py3/lib/python3.3/site-packages/SQLAlchemy-0.9.0b1-py3.3-linux-x86_64.egg/sqlalchemy/engine/default.py", line 376, in do_execute
    cursor.execute(statement, parameters)
sqlalchemy.exc.ProgrammingError: (ProgrammingError) relation "World" does not exist
LINE 2: FROM "World" 
             ^
 'SELECT "World".randomnumber AS "World_randomnumber", "World".id AS "World_id" \nFROM "World" \nWHERE "World".id = %(id_1)s' {'id_1': 4597}
2013-12-14 09:24:42 [1532] [ERROR] Error handling request
Traceback (most recent call last):
  File "/home/ubuntu/FrameworkBenchmarks/installs/py3/lib/python3.3/site-packages/SQLAlchemy-0.9.0b1-py3.3-linux-x86_64.egg/sqlalchemy/engine/base.py", line 867, in _execute_context
    context)
  File "/home/ubuntu/FrameworkBenchmarks/installs/py3/lib/python3.3/site-packages/SQLAlchemy-0.9.0b1-py3.3-linux-x86_64.egg/sqlalchemy/engine/default.py", line 376, in do_execute
    cursor.execute(statement, parameters)
psycopg2.InternalError: current transaction is aborted, commands ignored until end of transaction block


The above exception was the direct cause of the following exception:

Traceback (most recent call last):
  File "/home/ubuntu/FrameworkBenchmarks/installs/py3/lib/python3.3/site-packages/gunicorn-18.0-py3.3.egg/gunicorn/workers/sync.py", line 131, in handle_request
    respiter = self.wsgi(environ, resp.start_response)
  File "/home/ubuntu/FrameworkBenchmarks/installs/py3/lib/python3.3/site-packages/pyramid/router.py", line 251, in __call__
    response = self.invoke_subrequest(request, use_tweens=True)
  File "/home/ubuntu/FrameworkBenchmarks/installs/py3/lib/python3.3/site-packages/pyramid/router.py", line 227, in invoke_subrequest
    response = handle_request(request)
  File "/home/ubuntu/FrameworkBenchmarks/installs/py3/lib/python3.3/site-packages/pyramid/tweens.py", line 21, in excview_tween
    response = handler(request)
  File "/home/ubuntu/FrameworkBenchmarks/installs/py3/lib/python3.3/site-packages/pyramid/router.py", line 161, in handle_request
    response = view_callable(context, request)
  File "/home/ubuntu/FrameworkBenchmarks/installs/py3/lib/python3.3/site-packages/pyramid/config/views.py", line 347, in rendered_view
    result = view(context, request)
  File "/home/ubuntu/FrameworkBenchmarks/installs/py3/lib/python3.3/site-packages/pyramid/config/views.py", line 493, in _requestonly_view
    response = view(request)
  File "/home/ubuntu/FrameworkBenchmarks/pyramid/frameworkbenchmarks/views.py", line 25, in test_2
    result = DBSession.query(World).filter(World.id == num).one()
  File "/home/ubuntu/FrameworkBenchmarks/installs/py3/lib/python3.3/site-packages/SQLAlchemy-0.9.0b1-py3.3-linux-x86_64.egg/sqlalchemy/orm/query.py", line 2303, in one
    ret = list(self)
  File "/home/ubuntu/FrameworkBenchmarks/installs/py3/lib/python3.3/site-packages/SQLAlchemy-0.9.0b1-py3.3-linux-x86_64.egg/sqlalchemy/orm/query.py", line 2346, in __iter__
    return self._execute_and_instances(context)
  File "/home/ubuntu/FrameworkBenchmarks/installs/py3/lib/python3.3/site-packages/SQLAlchemy-0.9.0b1-py3.3-linux-x86_64.egg/sqlalchemy/orm/query.py", line 2361, in _execute_and_instances
    result = conn.execute(querycontext.statement, self._params)
  File "/home/ubuntu/FrameworkBenchmarks/installs/py3/lib/python3.3/site-packages/SQLAlchemy-0.9.0b1-py3.3-linux-x86_64.egg/sqlalchemy/engine/base.py", line 664, in execute
    return meth(self, multiparams, params)
  File "/home/ubuntu/FrameworkBenchmarks/installs/py3/lib/python3.3/site-packages/SQLAlchemy-0.9.0b1-py3.3-linux-x86_64.egg/sqlalchemy/sql/elements.py", line 272, in _execute_on_connection
    return connection._execute_clauseelement(self, multiparams, params)
  File "/home/ubuntu/FrameworkBenchmarks/installs/py3/lib/python3.3/site-packages/SQLAlchemy-0.9.0b1-py3.3-linux-x86_64.egg/sqlalchemy/engine/base.py", line 761, in _execute_clauseelement
    compiled_sql, distilled_params
  File "/home/ubuntu/FrameworkBenchmarks/installs/py3/lib/python3.3/site-packages/SQLAlchemy-0.9.0b1-py3.3-linux-x86_64.egg/sqlalchemy/engine/base.py", line 874, in _execute_context
    context)
  File "/home/ubuntu/FrameworkBenchmarks/installs/py3/lib/python3.3/site-packages/SQLAlchemy-0.9.0b1-py3.3-linux-x86_64.egg/sqlalchemy/engine/base.py", line 1023, in _handle_dbapi_exception
    exc_info
  File "/home/ubuntu/FrameworkBenchmarks/installs/py3/lib/python3.3/site-packages/SQLAlchemy-0.9.0b1-py3.3-linux-x86_64.egg/sqlalchemy/util/compat.py", line 174, in raise_from_cause
    reraise(type(exception), exception, tb=exc_tb, cause=exc_value)
  File "/home/ubuntu/FrameworkBenchmarks/installs/py3/lib/python3.3/site-packages/SQLAlchemy-0.9.0b1-py3.3-linux-x86_64.egg/sqlalchemy/util/compat.py", line 167, in reraise
    raise value.with_traceback(tb)
  File "/home/ubuntu/FrameworkBenchmarks/installs/py3/lib/python3.3/site-packages/SQLAlchemy-0.9.0b1-py3.3-linux-x86_64.egg/sqlalchemy/engine/base.py", line 867, in _execute_context
    context)
  File "/home/ubuntu/FrameworkBenchmarks/installs/py3/lib/python3.3/site-packages/SQLAlchemy-0.9.0b1-py3.3-linux-x86_64.egg/sqlalchemy/engine/default.py", line 376, in do_execute
    cursor.execute(statement, parameters)
sqlalchemy.exc.InternalError: (InternalError) current transaction is aborted, commands ignored until end of transaction block
 'SELECT "World".randomnumber AS "World_randomnumber", "World".id AS "World_id" \nFROM "World" \nWHERE "World".id = %(id_1)s' {'id_1': 3123}
curl: (22) The requested URL returned error: 500
2013-12-14 09:24:42 [1532] [ERROR] Error handling request
Traceback (most recent call last):
  File "/home/ubuntu/FrameworkBenchmarks/installs/py3/lib/python3.3/site-packages/SQLAlchemy-0.9.0b1-py3.3-linux-x86_64.egg/sqlalchemy/engine/base.py", line 867, in _execute_context
    context)
  File "/home/ubuntu/FrameworkBenchmarks/installs/py3/lib/python3.3/site-packages/SQLAlchemy-0.9.0b1-py3.3-linux-x86_64.egg/sqlalchemy/engine/default.py", line 376, in do_execute
    cursor.execute(statement, parameters)
psycopg2.InternalError: current transaction is aborted, commands ignored until end of transaction block


The above exception was the direct cause of the following exception:

Traceback (most recent call last):
  File "/home/ubuntu/FrameworkBenchmarks/installs/py3/lib/python3.3/site-packages/gunicorn-18.0-py3.3.egg/gunicorn/workers/sync.py", line 131, in handle_request
    respiter = self.wsgi(environ, resp.start_response)
  File "/home/ubuntu/FrameworkBenchmarks/installs/py3/lib/python3.3/site-packages/pyramid/router.py", line 251, in __call__
    response = self.invoke_subrequest(request, use_tweens=True)
  File "/home/ubuntu/FrameworkBenchmarks/installs/py3/lib/python3.3/site-packages/pyramid/router.py", line 227, in invoke_subrequest
    response = handle_request(request)
  File "/home/ubuntu/FrameworkBenchmarks/installs/py3/lib/python3.3/site-packages/pyramid/tweens.py", line 21, in excview_tween
    response = handler(request)
  File "/home/ubuntu/FrameworkBenchmarks/installs/py3/lib/python3.3/site-packages/pyramid/router.py", line 161, in handle_request
    response = view_callable(context, request)
  File "/home/ubuntu/FrameworkBenchmarks/installs/py3/lib/python3.3/site-packages/pyramid/config/views.py", line 347, in rendered_view
    result = view(context, request)
  File "/home/ubuntu/FrameworkBenchmarks/installs/py3/lib/python3.3/site-packages/pyramid/config/views.py", line 493, in _requestonly_view
    response = view(request)
  File "/home/ubuntu/FrameworkBenchmarks/pyramid/frameworkbenchmarks/views.py", line 46, in test_3
    for num in [randint(1, 10001) for _ in range(1, queries + 1)]
  File "/home/ubuntu/FrameworkBenchmarks/pyramid/frameworkbenchmarks/views.py", line 46, in <listcomp>
    for num in [randint(1, 10001) for _ in range(1, queries + 1)]
  File "/home/ubuntu/FrameworkBenchmarks/installs/py3/lib/python3.3/site-packages/SQLAlchemy-0.9.0b1-py3.3-linux-x86_64.egg/sqlalchemy/orm/query.py", line 2303, in one
    ret = list(self)
  File "/home/ubuntu/FrameworkBenchmarks/installs/py3/lib/python3.3/site-packages/SQLAlchemy-0.9.0b1-py3.3-linux-x86_64.egg/sqlalchemy/orm/query.py", line 2346, in __iter__
    return self._execute_and_instances(context)
  File "/home/ubuntu/FrameworkBenchmarks/installs/py3/lib/python3.3/site-packages/SQLAlchemy-0.9.0b1-py3.3-linux-x86_64.egg/sqlalchemy/orm/query.py", line 2361, in _execute_and_instances
    result = conn.execute(querycontext.statement, self._params)
  File "/home/ubuntu/FrameworkBenchmarks/installs/py3/lib/python3.3/site-packages/SQLAlchemy-0.9.0b1-py3.3-linux-x86_64.egg/sqlalchemy/engine/base.py", line 664, in execute
    return meth(self, multiparams, params)
  File "/home/ubuntu/FrameworkBenchmarks/installs/py3/lib/python3.3/site-packages/SQLAlchemy-0.9.0b1-py3.3-linux-x86_64.egg/sqlalchemy/sql/elements.py", line 272, in _execute_on_connection
    return connection._execute_clauseelement(self, multiparams, params)
  File "/home/ubuntu/FrameworkBenchmarks/installs/py3/lib/python3.3/site-packages/SQLAlchemy-0.9.0b1-py3.3-linux-x86_64.egg/sqlalchemy/engine/base.py", line 761, in _execute_clauseelement
    compiled_sql, distilled_params
  File "/home/ubuntu/FrameworkBenchmarks/installs/py3/lib/python3.3/site-packages/SQLAlchemy-0.9.0b1-py3.3-linux-x86_64.egg/sqlalchemy/engine/base.py", line 874, in _execute_context
    context)
  File "/home/ubuntu/FrameworkBenchmarks/installs/py3/lib/python3.3/site-packages/SQLAlchemy-0.9.0b1-py3.3-linux-x86_64.egg/sqlalchemy/engine/base.py", line 1023, in _handle_dbapi_exception
    exc_info
  File "/home/ubuntu/FrameworkBenchmarks/installs/py3/lib/python3.3/site-packages/SQLAlchemy-0.9.0b1-py3.3-linux-x86_64.egg/sqlalchemy/util/compat.py", line 174, in raise_from_cause
    reraise(type(exception), exception, tb=exc_tb, cause=exc_value)
  File "/home/ubuntu/FrameworkBenchmarks/installs/py3/lib/python3.3/site-packages/SQLAlchemy-0.9.0b1-py3.3-linux-x86_64.egg/sqlalchemy/util/compat.py", line 167, in reraise
    raise value.with_traceback(tb)
  File "/home/ubuntu/FrameworkBenchmarks/installs/py3/lib/python3.3/site-packages/SQLAlchemy-0.9.0b1-py3.3-linux-x86_64.egg/sqlalchemy/engine/base.py", line 867, in _execute_context
    context)
  File "/home/ubuntu/FrameworkBenchmarks/installs/py3/lib/python3.3/site-packages/SQLAlchemy-0.9.0b1-py3.3-linux-x86_64.egg/sqlalchemy/engine/default.py", line 376, in do_execute
    cursor.execute(statement, parameters)
sqlalchemy.exc.InternalError: (InternalError) current transaction is aborted, commands ignored until end of transaction block
 'SELECT "World".randomnumber AS "World_randomnumber", "World".id AS "World_id" \nFROM "World" \nWHERE "World".id = %(id_1)s' {'id_1': 2126}
2013-12-14 09:24:42 [1532] [ERROR] Error handling request
Traceback (most recent call last):
  File "/home/ubuntu/FrameworkBenchmarks/installs/py3/lib/python3.3/site-packages/SQLAlchemy-0.9.0b1-py3.3-linux-x86_64.egg/sqlalchemy/engine/base.py", line 867, in _execute_context
    context)
  File "/home/ubuntu/FrameworkBenchmarks/installs/py3/lib/python3.3/site-packages/SQLAlchemy-0.9.0b1-py3.3-linux-x86_64.egg/sqlalchemy/engine/default.py", line 376, in do_execute
    cursor.execute(statement, parameters)
psycopg2.InternalError: current transaction is aborted, commands ignored until end of transaction block


The above exception was the direct cause of the following exception:

Traceback (most recent call last):
  File "/home/ubuntu/FrameworkBenchmarks/installs/py3/lib/python3.3/site-packages/gunicorn-18.0-py3.3.egg/gunicorn/workers/sync.py", line 131, in handle_request
    respiter = self.wsgi(environ, resp.start_response)
  File "/home/ubuntu/FrameworkBenchmarks/installs/py3/lib/python3.3/site-packages/pyramid/router.py", line 251, in __call__
    response = self.invoke_subrequest(request, use_tweens=True)
  File "/home/ubuntu/FrameworkBenchmarks/installs/py3/lib/python3.3/site-packages/pyramid/router.py", line 227, in invoke_subrequest
    response = handle_request(request)
  File "/home/ubuntu/FrameworkBenchmarks/installs/py3/lib/python3.3/site-packages/pyramid/tweens.py", line 21, in excview_tween
    response = handler(request)
  File "/home/ubuntu/FrameworkBenchmarks/installs/py3/lib/python3.3/site-packages/pyramid/router.py", line 161, in handle_request
    response = view_callable(context, request)
  File "/home/ubuntu/FrameworkBenchmarks/installs/py3/lib/python3.3/site-packages/pyramid/config/views.py", line 347, in rendered_view
    result = view(context, request)
  File "/home/ubuntu/FrameworkBenchmarks/installs/py3/lib/python3.3/site-packages/pyramid/config/views.py", line 493, in _requestonly_view
    response = view(request)
  File "/home/ubuntu/FrameworkBenchmarks/pyramid/frameworkbenchmarks/views.py", line 46, in test_3
    for num in [randint(1, 10001) for _ in range(1, queries + 1)]
  File "/home/ubuntu/FrameworkBenchmarks/pyramid/frameworkbenchmarks/views.py", line 46, in <listcomp>
    for num in [randint(1, 10001) for _ in range(1, queries + 1)]
  File "/home/ubuntu/FrameworkBenchmarks/installs/py3/lib/python3.3/site-packages/SQLAlchemy-0.9.0b1-py3.3-linux-x86_64.egg/sqlalchemy/orm/query.py", line 2303, in one
    ret = list(self)
  File "/home/ubuntu/FrameworkBenchmarks/installs/py3/lib/python3.3/site-packages/SQLAlchemy-0.9.0b1-py3.3-linux-x86_64.egg/sqlalchemy/orm/query.py", line 2346, in __iter__
    return self._execute_and_instances(context)
  File "/home/ubuntu/FrameworkBenchmarks/installs/py3/lib/python3.3/site-packages/SQLAlchemy-0.9.0b1-py3.3-linux-x86_64.egg/sqlalchemy/orm/query.py", line 2361, in _execute_and_instances
    result = conn.execute(querycontext.statement, self._params)
  File "/home/ubuntu/FrameworkBenchmarks/installs/py3/lib/python3.3/site-packages/SQLAlchemy-0.9.0b1-py3.3-linux-x86_64.egg/sqlalchemy/engine/base.py", line 664, in execute
    return meth(self, multiparams, params)
  File "/home/ubuntu/FrameworkBenchmarks/installs/py3/lib/python3.3/site-packages/SQLAlchemy-0.9.0b1-py3.3-linux-x86_64.egg/sqlalchemy/sql/elements.py", line 272, in _execute_on_connection
    return connection._execute_clauseelement(self, multiparams, params)
  File "/home/ubuntu/FrameworkBenchmarks/installs/py3/lib/python3.3/site-packages/SQLAlchemy-0.9.0b1-py3.3-linux-x86_64.egg/sqlalchemy/engine/base.py", line 761, in _execute_clauseelement
    compiled_sql, distilled_params
  File "/home/ubuntu/FrameworkBenchmarks/installs/py3/lib/python3.3/site-packages/SQLAlchemy-0.9.0b1-py3.3-linux-x86_64.egg/sqlalchemy/engine/base.py", line 874, in _execute_context
    context)
  File "/home/ubuntu/FrameworkBenchmarks/installs/py3/lib/python3.3/site-packages/SQLAlchemy-0.9.0b1-py3.3-linux-x86_64.egg/sqlalchemy/engine/base.py", line 1023, in _handle_dbapi_exception
    exc_info
  File "/home/ubuntu/FrameworkBenchmarks/installs/py3/lib/python3.3/site-packages/SQLAlchemy-0.9.0b1-py3.3-linux-x86_64.egg/sqlalchemy/util/compat.py", line 174, in raise_from_cause
    reraise(type(exception), exception, tb=exc_tb, cause=exc_value)
  File "/home/ubuntu/FrameworkBenchmarks/installs/py3/lib/python3.3/site-packages/SQLAlchemy-0.9.0b1-py3.3-linux-x86_64.egg/sqlalchemy/util/compat.py", line 167, in reraise
    raise value.with_traceback(tb)
  File "/home/ubuntu/FrameworkBenchmarks/installs/py3/lib/python3.3/site-packages/SQLAlchemy-0.9.0b1-py3.3-linux-x86_64.egg/sqlalchemy/engine/base.py", line 867, in _execute_context
    context)
  File "/home/ubuntu/FrameworkBenchmarks/installs/py3/lib/python3.3/site-packages/SQLAlchemy-0.9.0b1-py3.3-linux-x86_64.egg/sqlalchemy/engine/default.py", line 376, in do_execute
    cursor.execute(statement, parameters)
sqlalchemy.exc.InternalError: (InternalError) current transaction is aborted, commands ignored until end of transaction block
 'SELECT "World".randomnumber AS "World_randomnumber", "World".id AS "World_id" \nFROM "World" \nWHERE "World".id = %(id_1)s' {'id_1': 7360}
curl: (22) The requested URL returned error: 500
2013-12-14 09:24:42 [1532] [ERROR] Error handling request
Traceback (most recent call last):
  File "/home/ubuntu/FrameworkBenchmarks/installs/py3/lib/python3.3/site-packages/SQLAlchemy-0.9.0b1-py3.3-linux-x86_64.egg/sqlalchemy/engine/base.py", line 867, in _execute_context
    context)
  File "/home/ubuntu/FrameworkBenchmarks/installs/py3/lib/python3.3/site-packages/SQLAlchemy-0.9.0b1-py3.3-linux-x86_64.egg/sqlalchemy/engine/default.py", line 376, in do_execute
    cursor.execute(statement, parameters)
psycopg2.InternalError: current transaction is aborted, commands ignored until end of transaction block


The above exception was the direct cause of the following exception:

Traceback (most recent call last):
  File "/home/ubuntu/FrameworkBenchmarks/installs/py3/lib/python3.3/site-packages/gunicorn-18.0-py3.3.egg/gunicorn/workers/sync.py", line 131, in handle_request
    respiter = self.wsgi(environ, resp.start_response)
  File "/home/ubuntu/FrameworkBenchmarks/installs/py3/lib/python3.3/site-packages/pyramid/router.py", line 251, in __call__
    response = self.invoke_subrequest(request, use_tweens=True)
  File "/home/ubuntu/FrameworkBenchmarks/installs/py3/lib/python3.3/site-packages/pyramid/router.py", line 227, in invoke_subrequest
    response = handle_request(request)
  File "/home/ubuntu/FrameworkBenchmarks/installs/py3/lib/python3.3/site-packages/pyramid/tweens.py", line 21, in excview_tween
    response = handler(request)
  File "/home/ubuntu/FrameworkBenchmarks/installs/py3/lib/python3.3/site-packages/pyramid/router.py", line 161, in handle_request
    response = view_callable(context, request)
  File "/home/ubuntu/FrameworkBenchmarks/installs/py3/lib/python3.3/site-packages/pyramid/config/views.py", line 347, in rendered_view
    result = view(context, request)
  File "/home/ubuntu/FrameworkBenchmarks/installs/py3/lib/python3.3/site-packages/pyramid/config/views.py", line 493, in _requestonly_view
    response = view(request)
  File "/home/ubuntu/FrameworkBenchmarks/pyramid/frameworkbenchmarks/views.py", line 56, in test_4
    fortunes = [obj.__json__() for obj in DBSession.query(Fortune).all()]
  File "/home/ubuntu/FrameworkBenchmarks/installs/py3/lib/python3.3/site-packages/SQLAlchemy-0.9.0b1-py3.3-linux-x86_64.egg/sqlalchemy/orm/query.py", line 2234, in all
    return list(self)
  File "/home/ubuntu/FrameworkBenchmarks/installs/py3/lib/python3.3/site-packages/SQLAlchemy-0.9.0b1-py3.3-linux-x86_64.egg/sqlalchemy/orm/query.py", line 2346, in __iter__
    return self._execute_and_instances(context)
  File "/home/ubuntu/FrameworkBenchmarks/installs/py3/lib/python3.3/site-packages/SQLAlchemy-0.9.0b1-py3.3-linux-x86_64.egg/sqlalchemy/orm/query.py", line 2361, in _execute_and_instances
    result = conn.execute(querycontext.statement, self._params)
  File "/home/ubuntu/FrameworkBenchmarks/installs/py3/lib/python3.3/site-packages/SQLAlchemy-0.9.0b1-py3.3-linux-x86_64.egg/sqlalchemy/engine/base.py", line 664, in execute
    return meth(self, multiparams, params)
  File "/home/ubuntu/FrameworkBenchmarks/installs/py3/lib/python3.3/site-packages/SQLAlchemy-0.9.0b1-py3.3-linux-x86_64.egg/sqlalchemy/sql/elements.py", line 272, in _execute_on_connection
    return connection._execute_clauseelement(self, multiparams, params)
  File "/home/ubuntu/FrameworkBenchmarks/installs/py3/lib/python3.3/site-packages/SQLAlchemy-0.9.0b1-py3.3-linux-x86_64.egg/sqlalchemy/engine/base.py", line 761, in _execute_clauseelement
    compiled_sql, distilled_params
  File "/home/ubuntu/FrameworkBenchmarks/installs/py3/lib/python3.3/site-packages/SQLAlchemy-0.9.0b1-py3.3-linux-x86_64.egg/sqlalchemy/engine/base.py", line 874, in _execute_context
    context)
  File "/home/ubuntu/FrameworkBenchmarks/installs/py3/lib/python3.3/site-packages/SQLAlchemy-0.9.0b1-py3.3-linux-x86_64.egg/sqlalchemy/engine/base.py", line 1023, in _handle_dbapi_exception
    exc_info
  File "/home/ubuntu/FrameworkBenchmarks/installs/py3/lib/python3.3/site-packages/SQLAlchemy-0.9.0b1-py3.3-linux-x86_64.egg/sqlalchemy/util/compat.py", line 174, in raise_from_cause
    reraise(type(exception), exception, tb=exc_tb, cause=exc_value)
  File "/home/ubuntu/FrameworkBenchmarks/installs/py3/lib/python3.3/site-packages/SQLAlchemy-0.9.0b1-py3.3-linux-x86_64.egg/sqlalchemy/util/compat.py", line 167, in reraise
    raise value.with_traceback(tb)
  File "/home/ubuntu/FrameworkBenchmarks/installs/py3/lib/python3.3/site-packages/SQLAlchemy-0.9.0b1-py3.3-linux-x86_64.egg/sqlalchemy/engine/base.py", line 867, in _execute_context
    context)
  File "/home/ubuntu/FrameworkBenchmarks/installs/py3/lib/python3.3/site-packages/SQLAlchemy-0.9.0b1-py3.3-linux-x86_64.egg/sqlalchemy/engine/default.py", line 376, in do_execute
    cursor.execute(statement, parameters)
sqlalchemy.exc.InternalError: (InternalError) current transaction is aborted, commands ignored until end of transaction block
 'SELECT "Fortune".id AS "Fortune_id", "Fortune".message AS "Fortune_message" \nFROM "Fortune"' {}
2013-12-14 09:24:42 [1532] [ERROR] Error handling request
Traceback (most recent call last):
  File "/home/ubuntu/FrameworkBenchmarks/installs/py3/lib/python3.3/site-packages/SQLAlchemy-0.9.0b1-py3.3-linux-x86_64.egg/sqlalchemy/engine/base.py", line 867, in _execute_context
    context)
  File "/home/ubuntu/FrameworkBenchmarks/installs/py3/lib/python3.3/site-packages/SQLAlchemy-0.9.0b1-py3.3-linux-x86_64.egg/sqlalchemy/engine/default.py", line 376, in do_execute
    cursor.execute(statement, parameters)
psycopg2.InternalError: current transaction is aborted, commands ignored until end of transaction block


The above exception was the direct cause of the following exception:

Traceback (most recent call last):
  File "/home/ubuntu/FrameworkBenchmarks/installs/py3/lib/python3.3/site-packages/gunicorn-18.0-py3.3.egg/gunicorn/workers/sync.py", line 131, in handle_request
    respiter = self.wsgi(environ, resp.start_response)
  File "/home/ubuntu/FrameworkBenchmarks/installs/py3/lib/python3.3/site-packages/pyramid/router.py", line 251, in __call__
    response = self.invoke_subrequest(request, use_tweens=True)
  File "/home/ubuntu/FrameworkBenchmarks/installs/py3/lib/python3.3/site-packages/pyramid/router.py", line 227, in invoke_subrequest
    response = handle_request(request)
  File "/home/ubuntu/FrameworkBenchmarks/installs/py3/lib/python3.3/site-packages/pyramid/tweens.py", line 21, in excview_tween
    response = handler(request)
  File "/home/ubuntu/FrameworkBenchmarks/installs/py3/lib/python3.3/site-packages/pyramid/router.py", line 161, in handle_request
    response = view_callable(context, request)
  File "/home/ubuntu/FrameworkBenchmarks/installs/py3/lib/python3.3/site-packages/pyramid/config/views.py", line 347, in rendered_view
    result = view(context, request)
  File "/home/ubuntu/FrameworkBenchmarks/installs/py3/lib/python3.3/site-packages/pyramid/config/views.py", line 493, in _requestonly_view
    response = view(request)
  File "/home/ubuntu/FrameworkBenchmarks/pyramid/frameworkbenchmarks/views.py", line 56, in test_4
    fortunes = [obj.__json__() for obj in DBSession.query(Fortune).all()]
  File "/home/ubuntu/FrameworkBenchmarks/installs/py3/lib/python3.3/site-packages/SQLAlchemy-0.9.0b1-py3.3-linux-x86_64.egg/sqlalchemy/orm/query.py", line 2234, in all
    return list(self)
  File "/home/ubuntu/FrameworkBenchmarks/installs/py3/lib/python3.3/site-packages/SQLAlchemy-0.9.0b1-py3.3-linux-x86_64.egg/sqlalchemy/orm/query.py", line 2346, in __iter__
    return self._execute_and_instances(context)
  File "/home/ubuntu/FrameworkBenchmarks/installs/py3/lib/python3.3/site-packages/SQLAlchemy-0.9.0b1-py3.3-linux-x86_64.egg/sqlalchemy/orm/query.py", line 2361, in _execute_and_instances
    result = conn.execute(querycontext.statement, self._params)
  File "/home/ubuntu/FrameworkBenchmarks/installs/py3/lib/python3.3/site-packages/SQLAlchemy-0.9.0b1-py3.3-linux-x86_64.egg/sqlalchemy/engine/base.py", line 664, in execute
    return meth(self, multiparams, params)
  File "/home/ubuntu/FrameworkBenchmarks/installs/py3/lib/python3.3/site-packages/SQLAlchemy-0.9.0b1-py3.3-linux-x86_64.egg/sqlalchemy/sql/elements.py", line 272, in _execute_on_connection
    return connection._execute_clauseelement(self, multiparams, params)
  File "/home/ubuntu/FrameworkBenchmarks/installs/py3/lib/python3.3/site-packages/SQLAlchemy-0.9.0b1-py3.3-linux-x86_64.egg/sqlalchemy/engine/base.py", line 761, in _execute_clauseelement
    compiled_sql, distilled_params
  File "/home/ubuntu/FrameworkBenchmarks/installs/py3/lib/python3.3/site-packages/SQLAlchemy-0.9.0b1-py3.3-linux-x86_64.egg/sqlalchemy/engine/base.py", line 874, in _execute_context
    context)
  File "/home/ubuntu/FrameworkBenchmarks/installs/py3/lib/python3.3/site-packages/SQLAlchemy-0.9.0b1-py3.3-linux-x86_64.egg/sqlalchemy/engine/base.py", line 1023, in _handle_dbapi_exception
    exc_info
  File "/home/ubuntu/FrameworkBenchmarks/installs/py3/lib/python3.3/site-packages/SQLAlchemy-0.9.0b1-py3.3-linux-x86_64.egg/sqlalchemy/util/compat.py", line 174, in raise_from_cause
    reraise(type(exception), exception, tb=exc_tb, cause=exc_value)
  File "/home/ubuntu/FrameworkBenchmarks/installs/py3/lib/python3.3/site-packages/SQLAlchemy-0.9.0b1-py3.3-linux-x86_64.egg/sqlalchemy/util/compat.py", line 167, in reraise
    raise value.with_traceback(tb)
  File "/home/ubuntu/FrameworkBenchmarks/installs/py3/lib/python3.3/site-packages/SQLAlchemy-0.9.0b1-py3.3-linux-x86_64.egg/sqlalchemy/engine/base.py", line 867, in _execute_context
    context)
  File "/home/ubuntu/FrameworkBenchmarks/installs/py3/lib/python3.3/site-packages/SQLAlchemy-0.9.0b1-py3.3-linux-x86_64.egg/sqlalchemy/engine/default.py", line 376, in do_execute
    cursor.execute(statement, parameters)
sqlalchemy.exc.InternalError: (InternalError) current transaction is aborted, commands ignored until end of transaction block
 'SELECT "Fortune".id AS "Fortune_id", "Fortune".message AS "Fortune_message" \nFROM "Fortune"' {}
curl: (22) The requested URL returned error: 500
2013-12-14 09:24:42 [1533] [ERROR] Error handling request
Traceback (most recent call last):
  File "/home/ubuntu/FrameworkBenchmarks/installs/py3/lib/python3.3/site-packages/SQLAlchemy-0.9.0b1-py3.3-linux-x86_64.egg/sqlalchemy/engine/base.py", line 867, in _execute_context
    context)
  File "/home/ubuntu/FrameworkBenchmarks/installs/py3/lib/python3.3/site-packages/SQLAlchemy-0.9.0b1-py3.3-linux-x86_64.egg/sqlalchemy/engine/default.py", line 376, in do_execute
    cursor.execute(statement, parameters)
psycopg2.ProgrammingError: relation "World" does not exist
LINE 2: FROM "World" 
             ^


The above exception was the direct cause of the following exception:

Traceback (most recent call last):
  File "/home/ubuntu/FrameworkBenchmarks/installs/py3/lib/python3.3/site-packages/gunicorn-18.0-py3.3.egg/gunicorn/workers/sync.py", line 131, in handle_request
    respiter = self.wsgi(environ, resp.start_response)
  File "/home/ubuntu/FrameworkBenchmarks/installs/py3/lib/python3.3/site-packages/pyramid/router.py", line 251, in __call__
    response = self.invoke_subrequest(request, use_tweens=True)
  File "/home/ubuntu/FrameworkBenchmarks/installs/py3/lib/python3.3/site-packages/pyramid/router.py", line 227, in invoke_subrequest
    response = handle_request(request)
  File "/home/ubuntu/FrameworkBenchmarks/installs/py3/lib/python3.3/site-packages/pyramid/tweens.py", line 21, in excview_tween
    response = handler(request)
  File "/home/ubuntu/FrameworkBenchmarks/installs/py3/lib/python3.3/site-packages/pyramid/router.py", line 161, in handle_request
    response = view_callable(context, request)
  File "/home/ubuntu/FrameworkBenchmarks/installs/py3/lib/python3.3/site-packages/pyramid/config/views.py", line 347, in rendered_view
    result = view(context, request)
  File "/home/ubuntu/FrameworkBenchmarks/installs/py3/lib/python3.3/site-packages/pyramid/config/views.py", line 493, in _requestonly_view
    response = view(request)
  File "/home/ubuntu/FrameworkBenchmarks/pyramid/frameworkbenchmarks/views.py", line 80, in test_5
    for num in [randint(1, 10001) for _ in range(1, queries + 1)]
  File "/home/ubuntu/FrameworkBenchmarks/pyramid/frameworkbenchmarks/views.py", line 80, in <listcomp>
    for num in [randint(1, 10001) for _ in range(1, queries + 1)]
  File "/home/ubuntu/FrameworkBenchmarks/installs/py3/lib/python3.3/site-packages/SQLAlchemy-0.9.0b1-py3.3-linux-x86_64.egg/sqlalchemy/orm/query.py", line 2303, in one
    ret = list(self)
  File "/home/ubuntu/FrameworkBenchmarks/installs/py3/lib/python3.3/site-packages/SQLAlchemy-0.9.0b1-py3.3-linux-x86_64.egg/sqlalchemy/orm/query.py", line 2346, in __iter__
    return self._execute_and_instances(context)
  File "/home/ubuntu/FrameworkBenchmarks/installs/py3/lib/python3.3/site-packages/SQLAlchemy-0.9.0b1-py3.3-linux-x86_64.egg/sqlalchemy/orm/query.py", line 2361, in _execute_and_instances
    result = conn.execute(querycontext.statement, self._params)
  File "/home/ubuntu/FrameworkBenchmarks/installs/py3/lib/python3.3/site-packages/SQLAlchemy-0.9.0b1-py3.3-linux-x86_64.egg/sqlalchemy/engine/base.py", line 664, in execute
    return meth(self, multiparams, params)
  File "/home/ubuntu/FrameworkBenchmarks/installs/py3/lib/python3.3/site-packages/SQLAlchemy-0.9.0b1-py3.3-linux-x86_64.egg/sqlalchemy/sql/elements.py", line 272, in _execute_on_connection
    return connection._execute_clauseelement(self, multiparams, params)
  File "/home/ubuntu/FrameworkBenchmarks/installs/py3/lib/python3.3/site-packages/SQLAlchemy-0.9.0b1-py3.3-linux-x86_64.egg/sqlalchemy/engine/base.py", line 761, in _execute_clauseelement
    compiled_sql, distilled_params
  File "/home/ubuntu/FrameworkBenchmarks/installs/py3/lib/python3.3/site-packages/SQLAlchemy-0.9.0b1-py3.3-linux-x86_64.egg/sqlalchemy/engine/base.py", line 874, in _execute_context
    context)
  File "/home/ubuntu/FrameworkBenchmarks/installs/py3/lib/python3.3/site-packages/SQLAlchemy-0.9.0b1-py3.3-linux-x86_64.egg/sqlalchemy/engine/base.py", line 1023, in _handle_dbapi_exception
    exc_info
  File "/home/ubuntu/FrameworkBenchmarks/installs/py3/lib/python3.3/site-packages/SQLAlchemy-0.9.0b1-py3.3-linux-x86_64.egg/sqlalchemy/util/compat.py", line 174, in raise_from_cause
    reraise(type(exception), exception, tb=exc_tb, cause=exc_value)
  File "/home/ubuntu/FrameworkBenchmarks/installs/py3/lib/python3.3/site-packages/SQLAlchemy-0.9.0b1-py3.3-linux-x86_64.egg/sqlalchemy/util/compat.py", line 167, in reraise
    raise value.with_traceback(tb)
  File "/home/ubuntu/FrameworkBenchmarks/installs/py3/lib/python3.3/site-packages/SQLAlchemy-0.9.0b1-py3.3-linux-x86_64.egg/sqlalchemy/engine/base.py", line 867, in _execute_context
    context)
  File "/home/ubuntu/FrameworkBenchmarks/installs/py3/lib/python3.3/site-packages/SQLAlchemy-0.9.0b1-py3.3-linux-x86_64.egg/sqlalchemy/engine/default.py", line 376, in do_execute
    cursor.execute(statement, parameters)
sqlalchemy.exc.ProgrammingError: (ProgrammingError) relation "World" does not exist
LINE 2: FROM "World" 
             ^
 'SELECT "World".randomnumber AS "World_randomnumber", "World".id AS "World_id" \nFROM "World" \nWHERE "World".id = %(id_1)s' {'id_1': 3926}
2013-12-14 09:24:42 [1532] [ERROR] Error handling request
Traceback (most recent call last):
  File "/home/ubuntu/FrameworkBenchmarks/installs/py3/lib/python3.3/site-packages/SQLAlchemy-0.9.0b1-py3.3-linux-x86_64.egg/sqlalchemy/engine/base.py", line 867, in _execute_context
    context)
  File "/home/ubuntu/FrameworkBenchmarks/installs/py3/lib/python3.3/site-packages/SQLAlchemy-0.9.0b1-py3.3-linux-x86_64.egg/sqlalchemy/engine/default.py", line 376, in do_execute
    cursor.execute(statement, parameters)
psycopg2.InternalError: current transaction is aborted, commands ignored until end of transaction block


The above exception was the direct cause of the following exception:

Traceback (most recent call last):
  File "/home/ubuntu/FrameworkBenchmarks/installs/py3/lib/python3.3/site-packages/gunicorn-18.0-py3.3.egg/gunicorn/workers/sync.py", line 131, in handle_request
    respiter = self.wsgi(environ, resp.start_response)
  File "/home/ubuntu/FrameworkBenchmarks/installs/py3/lib/python3.3/site-packages/pyramid/router.py", line 251, in __call__
    response = self.invoke_subrequest(request, use_tweens=True)
  File "/home/ubuntu/FrameworkBenchmarks/installs/py3/lib/python3.3/site-packages/pyramid/router.py", line 227, in invoke_subrequest
    response = handle_request(request)
  File "/home/ubuntu/FrameworkBenchmarks/installs/py3/lib/python3.3/site-packages/pyramid/tweens.py", line 21, in excview_tween
    response = handler(request)
  File "/home/ubuntu/FrameworkBenchmarks/installs/py3/lib/python3.3/site-packages/pyramid/router.py", line 161, in handle_request
    response = view_callable(context, request)
  File "/home/ubuntu/FrameworkBenchmarks/installs/py3/lib/python3.3/site-packages/pyramid/config/views.py", line 347, in rendered_view
    result = view(context, request)
  File "/home/ubuntu/FrameworkBenchmarks/installs/py3/lib/python3.3/site-packages/pyramid/config/views.py", line 493, in _requestonly_view
    response = view(request)
  File "/home/ubuntu/FrameworkBenchmarks/pyramid/frameworkbenchmarks/views.py", line 80, in test_5
    for num in [randint(1, 10001) for _ in range(1, queries + 1)]
  File "/home/ubuntu/FrameworkBenchmarks/pyramid/frameworkbenchmarks/views.py", line 80, in <listcomp>
    for num in [randint(1, 10001) for _ in range(1, queries + 1)]
  File "/home/ubuntu/FrameworkBenchmarks/installs/py3/lib/python3.3/site-packages/SQLAlchemy-0.9.0b1-py3.3-linux-x86_64.egg/sqlalchemy/orm/query.py", line 2303, in one
    ret = list(self)
  File "/home/ubuntu/FrameworkBenchmarks/installs/py3/lib/python3.3/site-packages/SQLAlchemy-0.9.0b1-py3.3-linux-x86_64.egg/sqlalchemy/orm/query.py", line 2346, in __iter__
    return self._execute_and_instances(context)
  File "/home/ubuntu/FrameworkBenchmarks/installs/py3/lib/python3.3/site-packages/SQLAlchemy-0.9.0b1-py3.3-linux-x86_64.egg/sqlalchemy/orm/query.py", line 2361, in _execute_and_instances
    result = conn.execute(querycontext.statement, self._params)
  File "/home/ubuntu/FrameworkBenchmarks/installs/py3/lib/python3.3/site-packages/SQLAlchemy-0.9.0b1-py3.3-linux-x86_64.egg/sqlalchemy/engine/base.py", line 664, in execute
    return meth(self, multiparams, params)
  File "/home/ubuntu/FrameworkBenchmarks/installs/py3/lib/python3.3/site-packages/SQLAlchemy-0.9.0b1-py3.3-linux-x86_64.egg/sqlalchemy/sql/elements.py", line 272, in _execute_on_connection
    return connection._execute_clauseelement(self, multiparams, params)
  File "/home/ubuntu/FrameworkBenchmarks/installs/py3/lib/python3.3/site-packages/SQLAlchemy-0.9.0b1-py3.3-linux-x86_64.egg/sqlalchemy/engine/base.py", line 761, in _execute_clauseelement
    compiled_sql, distilled_params
  File "/home/ubuntu/FrameworkBenchmarks/installs/py3/lib/python3.3/site-packages/SQLAlchemy-0.9.0b1-py3.3-linux-x86_64.egg/sqlalchemy/engine/base.py", line 874, in _execute_context
    context)
  File "/home/ubuntu/FrameworkBenchmarks/installs/py3/lib/python3.3/site-packages/SQLAlchemy-0.9.0b1-py3.3-linux-x86_64.egg/sqlalchemy/engine/base.py", line 1023, in _handle_dbapi_exception
    exc_info
  File "/home/ubuntu/FrameworkBenchmarks/installs/py3/lib/python3.3/site-packages/SQLAlchemy-0.9.0b1-py3.3-linux-x86_64.egg/sqlalchemy/util/compat.py", line 174, in raise_from_cause
    reraise(type(exception), exception, tb=exc_tb, cause=exc_value)
  File "/home/ubuntu/FrameworkBenchmarks/installs/py3/lib/python3.3/site-packages/SQLAlchemy-0.9.0b1-py3.3-linux-x86_64.egg/sqlalchemy/util/compat.py", line 167, in reraise
    raise value.with_traceback(tb)
  File "/home/ubuntu/FrameworkBenchmarks/installs/py3/lib/python3.3/site-packages/SQLAlchemy-0.9.0b1-py3.3-linux-x86_64.egg/sqlalchemy/engine/base.py", line 867, in _execute_context
    context)
  File "/home/ubuntu/FrameworkBenchmarks/installs/py3/lib/python3.3/site-packages/SQLAlchemy-0.9.0b1-py3.3-linux-x86_64.egg/sqlalchemy/engine/default.py", line 376, in do_execute
    cursor.execute(statement, parameters)
sqlalchemy.exc.InternalError: (InternalError) current transaction is aborted, commands ignored until end of transaction block
 'SELECT "World".randomnumber AS "World_randomnumber", "World".id AS "World_id" \nFROM "World" \nWHERE "World".id = %(id_1)s' {'id_1': 548}
curl: (22) The requested URL returned error: 500
unable to connect to 10.253.40.204:6543 Connection timed out
unable to connect to 10.253.40.204:6543 Connection timed out
unable to connect to 10.253.40.204:6543 Connection timed out
unable to connect to 10.253.40.204:6543 Connection timed out
unable to connect to 10.253.40.204:6543 Connection timed out
unable to connect to 10.253.40.204:6543 Connection timed out
unable to connect to 10.253.40.204:6543 Connection timed out
unable to connect to 10.253.40.204:6543 Connection timed out
unable to connect to 10.253.40.204:6543 Connection timed out
unable to connect to 10.253.40.204:6543 Connection timed out
unable to connect to 10.253.40.204:6543 Connection timed out
unable to connect to 10.253.40.204:6543 Connection timed out
unable to connect to 10.253.40.204:6543 Connection timed out
unable to connect to 10.253.40.204:6543 Connection timed out
2013-12-14 09:40:07 [1529] [INFO] Handling signal: term
2013-12-14 09:40:07 [1537] [INFO] Worker exiting (pid: 1537)
2013-12-14 09:40:07 [1536] [INFO] Worker exiting (pid: 1536)
2013-12-14 09:40:07 [1532] [INFO] Worker exiting (pid: 1532)
2013-12-14 09:40:07 [1533] [INFO] Worker exiting (pid: 1533)
2013-12-14 09:40:07 [1534] [INFO] Worker exiting (pid: 1534)
2013-12-14 09:40:07 [1535] [INFO] Worker exiting (pid: 1535)
2013-12-14 09:40:07 [1529] [INFO] Shutting down: Master
