ERROR:app:Exception on /raw-updates [GET]
Traceback (most recent call last):
  File "/home/tfb/FrameworkBenchmarks/installs/pypy/site-packages/Flask-0.10.1-py2.7.egg/flask/app.py", line 1817, in wsgi_app
    response = self.full_dispatch_request()
  File "/home/tfb/FrameworkBenchmarks/installs/pypy/site-packages/Flask-0.10.1-py2.7.egg/flask/app.py", line 1477, in full_dispatch_request
    rv = self.handle_user_exception(e)
  File "/home/tfb/FrameworkBenchmarks/installs/pypy/site-packages/Flask-0.10.1-py2.7.egg/flask/app.py", line 1381, in handle_user_exception
    reraise(exc_type, exc_value, tb)
  File "/home/tfb/FrameworkBenchmarks/installs/pypy/site-packages/Flask-0.10.1-py2.7.egg/flask/app.py", line 1475, in full_dispatch_request
    rv = self.dispatch_request()
  File "/home/tfb/FrameworkBenchmarks/installs/pypy/site-packages/Flask-0.10.1-py2.7.egg/flask/app.py", line 1461, in dispatch_request
    return self.view_functions[rule.endpoint](**req.view_args)
  File "/home/tfb/FrameworkBenchmarks/flask/app.py", line 152, in raw_updates
    (randomNumber, world['id']))
  File "/home/tfb/FrameworkBenchmarks/installs/pypy/site-packages/SQLAlchemy-0.8.3-py2.7.egg/sqlalchemy/engine/base.py", line 1613, in execute
    connection = self.contextual_connect(close_with_result=True)
  File "/home/tfb/FrameworkBenchmarks/installs/pypy/site-packages/SQLAlchemy-0.8.3-py2.7.egg/sqlalchemy/engine/base.py", line 1661, in contextual_connect
    self.pool.connect(),
  File "/home/tfb/FrameworkBenchmarks/installs/pypy/site-packages/SQLAlchemy-0.8.3-py2.7.egg/sqlalchemy/pool.py", line 272, in connect
    return _ConnectionFairy(self).checkout()
  File "/home/tfb/FrameworkBenchmarks/installs/pypy/site-packages/SQLAlchemy-0.8.3-py2.7.egg/sqlalchemy/pool.py", line 431, in __init__
    rec = self._connection_record = pool._do_get()
  File "/home/tfb/FrameworkBenchmarks/installs/pypy/site-packages/SQLAlchemy-0.8.3-py2.7.egg/sqlalchemy/pool.py", line 780, in _do_get
    (self.size(), self.overflow(), self._timeout))
TimeoutError: QueuePool limit of size 5 overflow 10 reached, connection timed out, timeout 30
ERROR:app:Exception on /raw-updates [GET]
Traceback (most recent call last):
  File "/home/tfb/FrameworkBenchmarks/installs/pypy/site-packages/Flask-0.10.1-py2.7.egg/flask/app.py", line 1817, in wsgi_app
    response = self.full_dispatch_request()
  File "/home/tfb/FrameworkBenchmarks/installs/pypy/site-packages/Flask-0.10.1-py2.7.egg/flask/app.py", line 1477, in full_dispatch_request
    rv = self.handle_user_exception(e)
  File "/home/tfb/FrameworkBenchmarks/installs/pypy/site-packages/Flask-0.10.1-py2.7.egg/flask/app.py", line 1381, in handle_user_exception
    reraise(exc_type, exc_value, tb)
  File "/home/tfb/FrameworkBenchmarks/installs/pypy/site-packages/Flask-0.10.1-py2.7.egg/flask/app.py", line 1475, in full_dispatch_request
    rv = self.dispatch_request()
  File "/home/tfb/FrameworkBenchmarks/installs/pypy/site-packages/Flask-0.10.1-py2.7.egg/flask/app.py", line 1461, in dispatch_request
    return self.view_functions[rule.endpoint](**req.view_args)
  File "/home/tfb/FrameworkBenchmarks/flask/app.py", line 152, in raw_updates
    (randomNumber, world['id']))
  File "/home/tfb/FrameworkBenchmarks/installs/pypy/site-packages/SQLAlchemy-0.8.3-py2.7.egg/sqlalchemy/engine/base.py", line 1613, in execute
    connection = self.contextual_connect(close_with_result=True)
  File "/home/tfb/FrameworkBenchmarks/installs/pypy/site-packages/SQLAlchemy-0.8.3-py2.7.egg/sqlalchemy/engine/base.py", line 1661, in contextual_connect
    self.pool.connect(),
  File "/home/tfb/FrameworkBenchmarks/installs/pypy/site-packages/SQLAlchemy-0.8.3-py2.7.egg/sqlalchemy/pool.py", line 272, in connect
    return _ConnectionFairy(self).checkout()
  File "/home/tfb/FrameworkBenchmarks/installs/pypy/site-packages/SQLAlchemy-0.8.3-py2.7.egg/sqlalchemy/pool.py", line 431, in __init__
    rec = self._connection_record = pool._do_get()
  File "/home/tfb/FrameworkBenchmarks/installs/pypy/site-packages/SQLAlchemy-0.8.3-py2.7.egg/sqlalchemy/pool.py", line 780, in _do_get
    (self.size(), self.overflow(), self._timeout))
TimeoutError: QueuePool limit of size 5 overflow 10 reached, connection timed out, timeout 30
ERROR:app:Exception on /raw-updates [GET]
Traceback (most recent call last):
  File "/home/tfb/FrameworkBenchmarks/installs/pypy/site-packages/Flask-0.10.1-py2.7.egg/flask/app.py", line 1817, in wsgi_app
    response = self.full_dispatch_request()
  File "/home/tfb/FrameworkBenchmarks/installs/pypy/site-packages/Flask-0.10.1-py2.7.egg/flask/app.py", line 1477, in full_dispatch_request
    rv = self.handle_user_exception(e)
  File "/home/tfb/FrameworkBenchmarks/installs/pypy/site-packages/Flask-0.10.1-py2.7.egg/flask/app.py", line 1381, in handle_user_exception
    reraise(exc_type, exc_value, tb)
  File "/home/tfb/FrameworkBenchmarks/installs/pypy/site-packages/Flask-0.10.1-py2.7.egg/flask/app.py", line 1475, in full_dispatch_request
    rv = self.dispatch_request()
  File "/home/tfb/FrameworkBenchmarks/installs/pypy/site-packages/Flask-0.10.1-py2.7.egg/flask/app.py", line 1461, in dispatch_request
    return self.view_functions[rule.endpoint](**req.view_args)
  File "/home/tfb/FrameworkBenchmarks/flask/app.py", line 152, in raw_updates
    (randomNumber, world['id']))
  File "/home/tfb/FrameworkBenchmarks/installs/pypy/site-packages/SQLAlchemy-0.8.3-py2.7.egg/sqlalchemy/engine/base.py", line 1613, in execute
    connection = self.contextual_connect(close_with_result=True)
  File "/home/tfb/FrameworkBenchmarks/installs/pypy/site-packages/SQLAlchemy-0.8.3-py2.7.egg/sqlalchemy/engine/base.py", line 1661, in contextual_connect
    self.pool.connect(),
  File "/home/tfb/FrameworkBenchmarks/installs/pypy/site-packages/SQLAlchemy-0.8.3-py2.7.egg/sqlalchemy/pool.py", line 272, in connect
    return _ConnectionFairy(self).checkout()
  File "/home/tfb/FrameworkBenchmarks/installs/pypy/site-packages/SQLAlchemy-0.8.3-py2.7.egg/sqlalchemy/pool.py", line 431, in __init__
    rec = self._connection_record = pool._do_get()
  File "/home/tfb/FrameworkBenchmarks/installs/pypy/site-packages/SQLAlchemy-0.8.3-py2.7.egg/sqlalchemy/pool.py", line 780, in _do_get
    (self.size(), self.overflow(), self._timeout))
TimeoutError: QueuePool limit of size 5 overflow 10 reached, connection timed out, timeout 30
ERROR:app:Exception on /raw-updates [GET]
Traceback (most recent call last):
  File "/home/tfb/FrameworkBenchmarks/installs/pypy/site-packages/Flask-0.10.1-py2.7.egg/flask/app.py", line 1817, in wsgi_app
    response = self.full_dispatch_request()
  File "/home/tfb/FrameworkBenchmarks/installs/pypy/site-packages/Flask-0.10.1-py2.7.egg/flask/app.py", line 1477, in full_dispatch_request
    rv = self.handle_user_exception(e)
  File "/home/tfb/FrameworkBenchmarks/installs/pypy/site-packages/Flask-0.10.1-py2.7.egg/flask/app.py", line 1381, in handle_user_exception
    reraise(exc_type, exc_value, tb)
  File "/home/tfb/FrameworkBenchmarks/installs/pypy/site-packages/Flask-0.10.1-py2.7.egg/flask/app.py", line 1475, in full_dispatch_request
    rv = self.dispatch_request()
  File "/home/tfb/FrameworkBenchmarks/installs/pypy/site-packages/Flask-0.10.1-py2.7.egg/flask/app.py", line 1461, in dispatch_request
    return self.view_functions[rule.endpoint](**req.view_args)
  File "/home/tfb/FrameworkBenchmarks/flask/app.py", line 152, in raw_updates
    (randomNumber, world['id']))
  File "/home/tfb/FrameworkBenchmarks/installs/pypy/site-packages/SQLAlchemy-0.8.3-py2.7.egg/sqlalchemy/engine/base.py", line 1613, in execute
    connection = self.contextual_connect(close_with_result=True)
  File "/home/tfb/FrameworkBenchmarks/installs/pypy/site-packages/SQLAlchemy-0.8.3-py2.7.egg/sqlalchemy/engine/base.py", line 1661, in contextual_connect
    self.pool.connect(),
  File "/home/tfb/FrameworkBenchmarks/installs/pypy/site-packages/SQLAlchemy-0.8.3-py2.7.egg/sqlalchemy/pool.py", line 272, in connect
    return _ConnectionFairy(self).checkout()
  File "/home/tfb/FrameworkBenchmarks/installs/pypy/site-packages/SQLAlchemy-0.8.3-py2.7.egg/sqlalchemy/pool.py", line 431, in __init__
    rec = self._connection_record = pool._do_get()
  File "/home/tfb/FrameworkBenchmarks/installs/pypy/site-packages/SQLAlchemy-0.8.3-py2.7.egg/sqlalchemy/pool.py", line 780, in _do_get
    (self.size(), self.overflow(), self._timeout))
TimeoutError: QueuePool limit of size 5 overflow 10 reached, connection timed out, timeout 30
ERROR:app:Exception on /raw-updates [GET]
Traceback (most recent call last):
  File "/home/tfb/FrameworkBenchmarks/installs/pypy/site-packages/Flask-0.10.1-py2.7.egg/flask/app.py", line 1817, in wsgi_app
    response = self.full_dispatch_request()
  File "/home/tfb/FrameworkBenchmarks/installs/pypy/site-packages/Flask-0.10.1-py2.7.egg/flask/app.py", line 1477, in full_dispatch_request
    rv = self.handle_user_exception(e)
  File "/home/tfb/FrameworkBenchmarks/installs/pypy/site-packages/Flask-0.10.1-py2.7.egg/flask/app.py", line 1381, in handle_user_exception
    reraise(exc_type, exc_value, tb)
  File "/home/tfb/FrameworkBenchmarks/installs/pypy/site-packages/Flask-0.10.1-py2.7.egg/flask/app.py", line 1475, in full_dispatch_request
    rv = self.dispatch_request()
  File "/home/tfb/FrameworkBenchmarks/installs/pypy/site-packages/Flask-0.10.1-py2.7.egg/flask/app.py", line 1461, in dispatch_request
    return self.view_functions[rule.endpoint](**req.view_args)
  File "/home/tfb/FrameworkBenchmarks/flask/app.py", line 152, in raw_updates
    (randomNumber, world['id']))
  File "/home/tfb/FrameworkBenchmarks/installs/pypy/site-packages/SQLAlchemy-0.8.3-py2.7.egg/sqlalchemy/engine/base.py", line 1613, in execute
    connection = self.contextual_connect(close_with_result=True)
  File "/home/tfb/FrameworkBenchmarks/installs/pypy/site-packages/SQLAlchemy-0.8.3-py2.7.egg/sqlalchemy/engine/base.py", line 1661, in contextual_connect
    self.pool.connect(),
  File "/home/tfb/FrameworkBenchmarks/installs/pypy/site-packages/SQLAlchemy-0.8.3-py2.7.egg/sqlalchemy/pool.py", line 272, in connect
    return _ConnectionFairy(self).checkout()
  File "/home/tfb/FrameworkBenchmarks/installs/pypy/site-packages/SQLAlchemy-0.8.3-py2.7.egg/sqlalchemy/pool.py", line 431, in __init__
    rec = self._connection_record = pool._do_get()
  File "/home/tfb/FrameworkBenchmarks/installs/pypy/site-packages/SQLAlchemy-0.8.3-py2.7.egg/sqlalchemy/pool.py", line 780, in _do_get
    (self.size(), self.overflow(), self._timeout))
TimeoutError: QueuePool limit of size 5 overflow 10 reached, connection timed out, timeout 30
ERROR:app:Exception on /raw-updates [GET]
Traceback (most recent call last):
  File "/home/tfb/FrameworkBenchmarks/installs/pypy/site-packages/Flask-0.10.1-py2.7.egg/flask/app.py", line 1817, in wsgi_app
    response = self.full_dispatch_request()
  File "/home/tfb/FrameworkBenchmarks/installs/pypy/site-packages/Flask-0.10.1-py2.7.egg/flask/app.py", line 1477, in full_dispatch_request
    rv = self.handle_user_exception(e)
  File "/home/tfb/FrameworkBenchmarks/installs/pypy/site-packages/Flask-0.10.1-py2.7.egg/flask/app.py", line 1381, in handle_user_exception
    reraise(exc_type, exc_value, tb)
  File "/home/tfb/FrameworkBenchmarks/installs/pypy/site-packages/Flask-0.10.1-py2.7.egg/flask/app.py", line 1475, in full_dispatch_request
    rv = self.dispatch_request()
  File "/home/tfb/FrameworkBenchmarks/installs/pypy/site-packages/Flask-0.10.1-py2.7.egg/flask/app.py", line 1461, in dispatch_request
    return self.view_functions[rule.endpoint](**req.view_args)
  File "/home/tfb/FrameworkBenchmarks/flask/app.py", line 152, in raw_updates
    (randomNumber, world['id']))
  File "/home/tfb/FrameworkBenchmarks/installs/pypy/site-packages/SQLAlchemy-0.8.3-py2.7.egg/sqlalchemy/engine/base.py", line 1613, in execute
    connection = self.contextual_connect(close_with_result=True)
  File "/home/tfb/FrameworkBenchmarks/installs/pypy/site-packages/SQLAlchemy-0.8.3-py2.7.egg/sqlalchemy/engine/base.py", line 1661, in contextual_connect
    self.pool.connect(),
  File "/home/tfb/FrameworkBenchmarks/installs/pypy/site-packages/SQLAlchemy-0.8.3-py2.7.egg/sqlalchemy/pool.py", line 272, in connect
    return _ConnectionFairy(self).checkout()
  File "/home/tfb/FrameworkBenchmarks/installs/pypy/site-packages/SQLAlchemy-0.8.3-py2.7.egg/sqlalchemy/pool.py", line 431, in __init__
    rec = self._connection_record = pool._do_get()
  File "/home/tfb/FrameworkBenchmarks/installs/pypy/site-packages/SQLAlchemy-0.8.3-py2.7.egg/sqlalchemy/pool.py", line 780, in _do_get
    (self.size(), self.overflow(), self._timeout))
TimeoutError: QueuePool limit of size 5 overflow 10 reached, connection timed out, timeout 30
ERROR:tornado.access:500 GET /raw-updates?queries=2 (172.16.98.98) 30018.13ms
ERROR:tornado.access:500 GET /raw-updates?queries=2 (172.16.98.98) 30023.67ms
ERROR:tornado.access:500 GET /raw-updates?queries=2 (172.16.98.98) 30027.33ms
ERROR:tornado.access:500 GET /raw-updates?queries=2 (172.16.98.98) 30017.30ms
ERROR:tornado.access:500 GET /raw-updates?queries=2 (172.16.98.98) 30026.77ms
ERROR:tornado.access:500 GET /raw-updates?queries=2 (172.16.98.98) 30027.05ms
2013-12-14 16:31:16 [31632] [CRITICAL] WORKER TIMEOUT (pid:31650)
2013-12-14 16:31:16 [31632] [CRITICAL] WORKER TIMEOUT (pid:31651)
2013-12-14 16:31:16 [31632] [CRITICAL] WORKER TIMEOUT (pid:31652)
2013-12-14 16:31:16 [31632] [CRITICAL] WORKER TIMEOUT (pid:31653)
2013-12-14 16:31:16 [31632] [CRITICAL] WORKER TIMEOUT (pid:31654)
2013-12-14 16:31:16 [31632] [CRITICAL] WORKER TIMEOUT (pid:31655)
2013-12-14 16:31:16 [31632] [CRITICAL] WORKER TIMEOUT (pid:31656)
2013-12-14 16:31:16 [31632] [CRITICAL] WORKER TIMEOUT (pid:31666)
2013-12-14 16:31:16 [31632] [CRITICAL] WORKER TIMEOUT (pid:31650)
2013-12-14 16:31:16 [31632] [CRITICAL] WORKER TIMEOUT (pid:31651)
2013-12-14 16:31:16 [31632] [CRITICAL] WORKER TIMEOUT (pid:31652)
2013-12-14 16:31:16 [31632] [CRITICAL] WORKER TIMEOUT (pid:31653)
2013-12-14 16:31:16 [31632] [CRITICAL] WORKER TIMEOUT (pid:31654)
2013-12-14 16:31:16 [31632] [CRITICAL] WORKER TIMEOUT (pid:31655)
2013-12-14 16:31:16 [31632] [CRITICAL] WORKER TIMEOUT (pid:31656)
2013-12-14 16:31:16 [31632] [CRITICAL] WORKER TIMEOUT (pid:31666)
2013-12-14 16:31:16 [31632] [CRITICAL] WORKER TIMEOUT (pid:31644)
2013-12-14 16:31:16 [31632] [CRITICAL] WORKER TIMEOUT (pid:31650)
2013-12-14 16:31:16 [31632] [CRITICAL] WORKER TIMEOUT (pid:31653)
2013-12-14 16:31:16 [31632] [CRITICAL] WORKER TIMEOUT (pid:31654)
2013-12-14 16:31:16 [31632] [CRITICAL] WORKER TIMEOUT (pid:31655)
2013-12-14 16:31:16 [31632] [CRITICAL] WORKER TIMEOUT (pid:31656)
2013-12-14 16:31:16 [31632] [CRITICAL] WORKER TIMEOUT (pid:31666)
2013-12-14 16:31:16 [31632] [CRITICAL] WORKER TIMEOUT (pid:31658)
2013-12-14 16:31:17 [31632] [CRITICAL] WORKER TIMEOUT (pid:31645)
2013-12-14 16:31:17 [31632] [CRITICAL] WORKER TIMEOUT (pid:31646)
2013-12-14 16:31:17 [31632] [CRITICAL] WORKER TIMEOUT (pid:31647)
2013-12-14 16:31:17 [31632] [CRITICAL] WORKER TIMEOUT (pid:31648)
2013-12-14 16:31:17 [31632] [CRITICAL] WORKER TIMEOUT (pid:31659)
2013-12-14 16:31:17 [31632] [CRITICAL] WORKER TIMEOUT (pid:31646)
2013-12-14 16:31:17 [31632] [CRITICAL] WORKER TIMEOUT (pid:31647)
2013-12-14 16:31:17 [31632] [CRITICAL] WORKER TIMEOUT (pid:31648)
2013-12-14 16:31:17 [31632] [CRITICAL] WORKER TIMEOUT (pid:31659)
2013-12-14 16:31:17 [31632] [CRITICAL] WORKER TIMEOUT (pid:31647)
ERROR:app:Exception on /raw-updates [GET]
Traceback (most recent call last):
  File "/home/tfb/FrameworkBenchmarks/installs/pypy/site-packages/Flask-0.10.1-py2.7.egg/flask/app.py", line 1817, in wsgi_app
    response = self.full_dispatch_request()
  File "/home/tfb/FrameworkBenchmarks/installs/pypy/site-packages/Flask-0.10.1-py2.7.egg/flask/app.py", line 1477, in full_dispatch_request
    rv = self.handle_user_exception(e)
  File "/home/tfb/FrameworkBenchmarks/installs/pypy/site-packages/Flask-0.10.1-py2.7.egg/flask/app.py", line 1381, in handle_user_exception
    reraise(exc_type, exc_value, tb)
  File "/home/tfb/FrameworkBenchmarks/installs/pypy/site-packages/Flask-0.10.1-py2.7.egg/flask/app.py", line 1475, in full_dispatch_request
    rv = self.dispatch_request()
  File "/home/tfb/FrameworkBenchmarks/installs/pypy/site-packages/Flask-0.10.1-py2.7.egg/flask/app.py", line 1461, in dispatch_request
    return self.view_functions[rule.endpoint](**req.view_args)
  File "/home/tfb/FrameworkBenchmarks/flask/app.py", line 152, in raw_updates
    (randomNumber, world['id']))
  File "/home/tfb/FrameworkBenchmarks/installs/pypy/site-packages/SQLAlchemy-0.8.3-py2.7.egg/sqlalchemy/engine/base.py", line 1613, in execute
    connection = self.contextual_connect(close_with_result=True)
  File "/home/tfb/FrameworkBenchmarks/installs/pypy/site-packages/SQLAlchemy-0.8.3-py2.7.egg/sqlalchemy/engine/base.py", line 1661, in contextual_connect
    self.pool.connect(),
  File "/home/tfb/FrameworkBenchmarks/installs/pypy/site-packages/SQLAlchemy-0.8.3-py2.7.egg/sqlalchemy/pool.py", line 272, in connect
    return _ConnectionFairy(self).checkout()
  File "/home/tfb/FrameworkBenchmarks/installs/pypy/site-packages/SQLAlchemy-0.8.3-py2.7.egg/sqlalchemy/pool.py", line 431, in __init__
    rec = self._connection_record = pool._do_get()
  File "/home/tfb/FrameworkBenchmarks/installs/pypy/site-packages/SQLAlchemy-0.8.3-py2.7.egg/sqlalchemy/pool.py", line 780, in _do_get
    (self.size(), self.overflow(), self._timeout))
TimeoutError: QueuePool limit of size 5 overflow 10 reached, connection timed out, timeout 30
ERROR:tornado.access:500 GET /raw-updates?queries=2 (172.16.98.98) 30019.11ms
2013-12-14 16:31:18 [31632] [CRITICAL] WORKER TIMEOUT (pid:31643)
2013-12-14 16:31:18 [31632] [CRITICAL] WORKER TIMEOUT (pid:31663)
2013-12-14 16:31:18 [31632] [CRITICAL] WORKER TIMEOUT (pid:31643)
2013-12-14 16:31:18 [31632] [CRITICAL] WORKER TIMEOUT (pid:31663)
ERROR:app:Exception on /raw-updates [GET]
Traceback (most recent call last):
  File "/home/tfb/FrameworkBenchmarks/installs/pypy/site-packages/Flask-0.10.1-py2.7.egg/flask/app.py", line 1817, in wsgi_app
    response = self.full_dispatch_request()
  File "/home/tfb/FrameworkBenchmarks/installs/pypy/site-packages/Flask-0.10.1-py2.7.egg/flask/app.py", line 1477, in full_dispatch_request
    rv = self.handle_user_exception(e)
  File "/home/tfb/FrameworkBenchmarks/installs/pypy/site-packages/Flask-0.10.1-py2.7.egg/flask/app.py", line 1381, in handle_user_exception
    reraise(exc_type, exc_value, tb)
  File "/home/tfb/FrameworkBenchmarks/installs/pypy/site-packages/Flask-0.10.1-py2.7.egg/flask/app.py", line 1475, in full_dispatch_request
    rv = self.dispatch_request()
  File "/home/tfb/FrameworkBenchmarks/installs/pypy/site-packages/Flask-0.10.1-py2.7.egg/flask/app.py", line 1461, in dispatch_request
    return self.view_functions[rule.endpoint](**req.view_args)
  File "/home/tfb/FrameworkBenchmarks/flask/app.py", line 148, in raw_updates
    world = dbraw_engine.execute("SELECT * FROM World WHERE id=%s", (rp(),)).fetchone()
  File "/home/tfb/FrameworkBenchmarks/installs/pypy/site-packages/SQLAlchemy-0.8.3-py2.7.egg/sqlalchemy/engine/base.py", line 1613, in execute
    connection = self.contextual_connect(close_with_result=True)
  File "/home/tfb/FrameworkBenchmarks/installs/pypy/site-packages/SQLAlchemy-0.8.3-py2.7.egg/sqlalchemy/engine/base.py", line 1661, in contextual_connect
    self.pool.connect(),
  File "/home/tfb/FrameworkBenchmarks/installs/pypy/site-packages/SQLAlchemy-0.8.3-py2.7.egg/sqlalchemy/pool.py", line 272, in connect
    return _ConnectionFairy(self).checkout()
  File "/home/tfb/FrameworkBenchmarks/installs/pypy/site-packages/SQLAlchemy-0.8.3-py2.7.egg/sqlalchemy/pool.py", line 431, in __init__
    rec = self._connection_record = pool._do_get()
  File "/home/tfb/FrameworkBenchmarks/installs/pypy/site-packages/SQLAlchemy-0.8.3-py2.7.egg/sqlalchemy/pool.py", line 780, in _do_get
    (self.size(), self.overflow(), self._timeout))
TimeoutError: QueuePool limit of size 5 overflow 10 reached, connection timed out, timeout 30
ERROR:tornado.access:500 GET /raw-updates?queries=2 (172.16.98.98) 30001.82ms
ERROR:app:Exception on /raw-updates [GET]
Traceback (most recent call last):
  File "/home/tfb/FrameworkBenchmarks/installs/pypy/site-packages/Flask-0.10.1-py2.7.egg/flask/app.py", line 1817, in wsgi_app
    response = self.full_dispatch_request()
  File "/home/tfb/FrameworkBenchmarks/installs/pypy/site-packages/Flask-0.10.1-py2.7.egg/flask/app.py", line 1477, in full_dispatch_request
    rv = self.handle_user_exception(e)
  File "/home/tfb/FrameworkBenchmarks/installs/pypy/site-packages/Flask-0.10.1-py2.7.egg/flask/app.py", line 1381, in handle_user_exception
    reraise(exc_type, exc_value, tb)
  File "/home/tfb/FrameworkBenchmarks/installs/pypy/site-packages/Flask-0.10.1-py2.7.egg/flask/app.py", line 1475, in full_dispatch_request
    rv = self.dispatch_request()
  File "/home/tfb/FrameworkBenchmarks/installs/pypy/site-packages/Flask-0.10.1-py2.7.egg/flask/app.py", line 1461, in dispatch_request
    return self.view_functions[rule.endpoint](**req.view_args)
  File "/home/tfb/FrameworkBenchmarks/flask/app.py", line 148, in raw_updates
    world = dbraw_engine.execute("SELECT * FROM World WHERE id=%s", (rp(),)).fetchone()
  File "/home/tfb/FrameworkBenchmarks/installs/pypy/site-packages/SQLAlchemy-0.8.3-py2.7.egg/sqlalchemy/engine/base.py", line 1613, in execute
    connection = self.contextual_connect(close_with_result=True)
  File "/home/tfb/FrameworkBenchmarks/installs/pypy/site-packages/SQLAlchemy-0.8.3-py2.7.egg/sqlalchemy/engine/base.py", line 1661, in contextual_connect
    self.pool.connect(),
  File "/home/tfb/FrameworkBenchmarks/installs/pypy/site-packages/SQLAlchemy-0.8.3-py2.7.egg/sqlalchemy/pool.py", line 272, in connect
    return _ConnectionFairy(self).checkout()
  File "/home/tfb/FrameworkBenchmarks/installs/pypy/site-packages/SQLAlchemy-0.8.3-py2.7.egg/sqlalchemy/pool.py", line 431, in __init__
    rec = self._connection_record = pool._do_get()
  File "/home/tfb/FrameworkBenchmarks/installs/pypy/site-packages/SQLAlchemy-0.8.3-py2.7.egg/sqlalchemy/pool.py", line 780, in _do_get
    (self.size(), self.overflow(), self._timeout))
TimeoutError: QueuePool limit of size 5 overflow 10 reached, connection timed out, timeout 30
ERROR:tornado.access:500 GET /raw-updates?queries=2 (172.16.98.98) 30001.58ms
2013-12-14 16:31:37 [31632] [CRITICAL] WORKER TIMEOUT (pid:31649)
2013-12-14 16:31:37 [31632] [CRITICAL] WORKER TIMEOUT (pid:31665)
2013-12-14 16:31:37 [31632] [CRITICAL] WORKER TIMEOUT (pid:31649)
2013-12-14 16:31:37 [31632] [CRITICAL] WORKER TIMEOUT (pid:31665)
ERROR:app:Exception on /raw-updates [GET]
Traceback (most recent call last):
  File "/home/tfb/FrameworkBenchmarks/installs/pypy/site-packages/Flask-0.10.1-py2.7.egg/flask/app.py", line 1817, in wsgi_app
    response = self.full_dispatch_request()
  File "/home/tfb/FrameworkBenchmarks/installs/pypy/site-packages/Flask-0.10.1-py2.7.egg/flask/app.py", line 1477, in full_dispatch_request
    rv = self.handle_user_exception(e)
  File "/home/tfb/FrameworkBenchmarks/installs/pypy/site-packages/Flask-0.10.1-py2.7.egg/flask/app.py", line 1381, in handle_user_exception
    reraise(exc_type, exc_value, tb)
  File "/home/tfb/FrameworkBenchmarks/installs/pypy/site-packages/Flask-0.10.1-py2.7.egg/flask/app.py", line 1475, in full_dispatch_request
    rv = self.dispatch_request()
  File "/home/tfb/FrameworkBenchmarks/installs/pypy/site-packages/Flask-0.10.1-py2.7.egg/flask/app.py", line 1461, in dispatch_request
    return self.view_functions[rule.endpoint](**req.view_args)
  File "/home/tfb/FrameworkBenchmarks/flask/app.py", line 148, in raw_updates
    world = dbraw_engine.execute("SELECT * FROM World WHERE id=%s", (rp(),)).fetchone()
  File "/home/tfb/FrameworkBenchmarks/installs/pypy/site-packages/SQLAlchemy-0.8.3-py2.7.egg/sqlalchemy/engine/base.py", line 1613, in execute
    connection = self.contextual_connect(close_with_result=True)
  File "/home/tfb/FrameworkBenchmarks/installs/pypy/site-packages/SQLAlchemy-0.8.3-py2.7.egg/sqlalchemy/engine/base.py", line 1661, in contextual_connect
    self.pool.connect(),
  File "/home/tfb/FrameworkBenchmarks/installs/pypy/site-packages/SQLAlchemy-0.8.3-py2.7.egg/sqlalchemy/pool.py", line 272, in connect
    return _ConnectionFairy(self).checkout()
  File "/home/tfb/FrameworkBenchmarks/installs/pypy/site-packages/SQLAlchemy-0.8.3-py2.7.egg/sqlalchemy/pool.py", line 431, in __init__
    rec = self._connection_record = pool._do_get()
  File "/home/tfb/FrameworkBenchmarks/installs/pypy/site-packages/SQLAlchemy-0.8.3-py2.7.egg/sqlalchemy/pool.py", line 780, in _do_get
    (self.size(), self.overflow(), self._timeout))
TimeoutError: QueuePool limit of size 5 overflow 10 reached, connection timed out, timeout 30
ERROR:app:Exception on /raw-updates [GET]
Traceback (most recent call last):
  File "/home/tfb/FrameworkBenchmarks/installs/pypy/site-packages/Flask-0.10.1-py2.7.egg/flask/app.py", line 1817, in wsgi_app
    response = self.full_dispatch_request()
  File "/home/tfb/FrameworkBenchmarks/installs/pypy/site-packages/Flask-0.10.1-py2.7.egg/flask/app.py", line 1477, in full_dispatch_request
    rv = self.handle_user_exception(e)
  File "/home/tfb/FrameworkBenchmarks/installs/pypy/site-packages/Flask-0.10.1-py2.7.egg/flask/app.py", line 1381, in handle_user_exception
    reraise(exc_type, exc_value, tb)
  File "/home/tfb/FrameworkBenchmarks/installs/pypy/site-packages/Flask-0.10.1-py2.7.egg/flask/app.py", line 1475, in full_dispatch_request
    rv = self.dispatch_request()
  File "/home/tfb/FrameworkBenchmarks/installs/pypy/site-packages/Flask-0.10.1-py2.7.egg/flask/app.py", line 1461, in dispatch_request
    return self.view_functions[rule.endpoint](**req.view_args)
  File "/home/tfb/FrameworkBenchmarks/flask/app.py", line 148, in raw_updates
    world = dbraw_engine.execute("SELECT * FROM World WHERE id=%s", (rp(),)).fetchone()
  File "/home/tfb/FrameworkBenchmarks/installs/pypy/site-packages/SQLAlchemy-0.8.3-py2.7.egg/sqlalchemy/engine/base.py", line 1613, in execute
    connection = self.contextual_connect(close_with_result=True)
  File "/home/tfb/FrameworkBenchmarks/installs/pypy/site-packages/SQLAlchemy-0.8.3-py2.7.egg/sqlalchemy/engine/base.py", line 1661, in contextual_connect
    self.pool.connect(),
  File "/home/tfb/FrameworkBenchmarks/installs/pypy/site-packages/SQLAlchemy-0.8.3-py2.7.egg/sqlalchemy/pool.py", line 272, in connect
    return _ConnectionFairy(self).checkout()
  File "/home/tfb/FrameworkBenchmarks/installs/pypy/site-packages/SQLAlchemy-0.8.3-py2.7.egg/sqlalchemy/pool.py", line 431, in __init__
    rec = self._connection_record = pool._do_get()
  File "/home/tfb/FrameworkBenchmarks/installs/pypy/site-packages/SQLAlchemy-0.8.3-py2.7.egg/sqlalchemy/pool.py", line 780, in _do_get
    (self.size(), self.overflow(), self._timeout))
TimeoutError: QueuePool limit of size 5 overflow 10 reached, connection timed out, timeout 30
ERROR:app:Exception on /raw-updates [GET]
Traceback (most recent call last):
  File "/home/tfb/FrameworkBenchmarks/installs/pypy/site-packages/Flask-0.10.1-py2.7.egg/flask/app.py", line 1817, in wsgi_app
    response = self.full_dispatch_request()
  File "/home/tfb/FrameworkBenchmarks/installs/pypy/site-packages/Flask-0.10.1-py2.7.egg/flask/app.py", line 1477, in full_dispatch_request
    rv = self.handle_user_exception(e)
  File "/home/tfb/FrameworkBenchmarks/installs/pypy/site-packages/Flask-0.10.1-py2.7.egg/flask/app.py", line 1381, in handle_user_exception
    reraise(exc_type, exc_value, tb)
  File "/home/tfb/FrameworkBenchmarks/installs/pypy/site-packages/Flask-0.10.1-py2.7.egg/flask/app.py", line 1475, in full_dispatch_request
    rv = self.dispatch_request()
  File "/home/tfb/FrameworkBenchmarks/installs/pypy/site-packages/Flask-0.10.1-py2.7.egg/flask/app.py", line 1461, in dispatch_request
    return self.view_functions[rule.endpoint](**req.view_args)
  File "/home/tfb/FrameworkBenchmarks/flask/app.py", line 148, in raw_updates
    world = dbraw_engine.execute("SELECT * FROM World WHERE id=%s", (rp(),)).fetchone()
  File "/home/tfb/FrameworkBenchmarks/installs/pypy/site-packages/SQLAlchemy-0.8.3-py2.7.egg/sqlalchemy/engine/base.py", line 1613, in execute
    connection = self.contextual_connect(close_with_result=True)
  File "/home/tfb/FrameworkBenchmarks/installs/pypy/site-packages/SQLAlchemy-0.8.3-py2.7.egg/sqlalchemy/engine/base.py", line 1661, in contextual_connect
    self.pool.connect(),
  File "/home/tfb/FrameworkBenchmarks/installs/pypy/site-packages/SQLAlchemy-0.8.3-py2.7.egg/sqlalchemy/pool.py", line 272, in connect
    return _ConnectionFairy(self).checkout()
  File "/home/tfb/FrameworkBenchmarks/installs/pypy/site-packages/SQLAlchemy-0.8.3-py2.7.egg/sqlalchemy/pool.py", line 431, in __init__
    rec = self._connection_record = pool._do_get()
  File "/home/tfb/FrameworkBenchmarks/installs/pypy/site-packages/SQLAlchemy-0.8.3-py2.7.egg/sqlalchemy/pool.py", line 780, in _do_get
    (self.size(), self.overflow(), self._timeout))
TimeoutError: QueuePool limit of size 5 overflow 10 reached, connection timed out, timeout 30
ERROR:tornado.access:500 GET /raw-updates?queries=1 (172.16.98.98) 30001.90ms
ERROR:tornado.access:500 GET /raw-updates?queries=1 (172.16.98.98) 30001.96ms
ERROR:tornado.access:500 GET /raw-updates?queries=1 (172.16.98.98) 30001.95ms
2013-12-14 16:31:38 [31632] [CRITICAL] WORKER TIMEOUT (pid:31660)
2013-12-14 16:31:38 [31632] [CRITICAL] WORKER TIMEOUT (pid:31661)
2013-12-14 16:31:38 [31632] [CRITICAL] WORKER TIMEOUT (pid:31664)
2013-12-14 16:31:38 [31632] [CRITICAL] WORKER TIMEOUT (pid:31660)
2013-12-14 16:31:38 [31632] [CRITICAL] WORKER TIMEOUT (pid:31661)
2013-12-14 16:31:38 [31632] [CRITICAL] WORKER TIMEOUT (pid:31664)
2013-12-14 16:31:46 [31632] [CRITICAL] WORKER TIMEOUT (pid:31704)
2013-12-14 16:31:46 [31632] [CRITICAL] WORKER TIMEOUT (pid:31704)
2013-12-14 16:31:56 [31632] [CRITICAL] WORKER TIMEOUT (pid:31708)
2013-12-14 16:31:56 [31632] [CRITICAL] WORKER TIMEOUT (pid:31709)
2013-12-14 16:31:56 [31632] [CRITICAL] WORKER TIMEOUT (pid:31710)
2013-12-14 16:31:56 [31632] [CRITICAL] WORKER TIMEOUT (pid:31711)
2013-12-14 16:31:56 [31632] [CRITICAL] WORKER TIMEOUT (pid:31713)
2013-12-14 16:31:56 [31632] [CRITICAL] WORKER TIMEOUT (pid:31714)
2013-12-14 16:31:56 [31632] [CRITICAL] WORKER TIMEOUT (pid:31715)
2013-12-14 16:31:56 [31632] [CRITICAL] WORKER TIMEOUT (pid:31716)
2013-12-14 16:31:56 [31632] [CRITICAL] WORKER TIMEOUT (pid:31717)
2013-12-14 16:31:56 [31632] [CRITICAL] WORKER TIMEOUT (pid:31718)
2013-12-14 16:31:56 [31632] [CRITICAL] WORKER TIMEOUT (pid:31719)
2013-12-14 16:31:56 [31632] [CRITICAL] WORKER TIMEOUT (pid:31720)
2013-12-14 16:31:56 [31632] [CRITICAL] WORKER TIMEOUT (pid:31721)
2013-12-14 16:31:56 [31632] [CRITICAL] WORKER TIMEOUT (pid:31708)
2013-12-14 16:31:56 [31632] [CRITICAL] WORKER TIMEOUT (pid:31709)
2013-12-14 16:31:56 [31632] [CRITICAL] WORKER TIMEOUT (pid:31710)
2013-12-14 16:31:56 [31632] [CRITICAL] WORKER TIMEOUT (pid:31711)
2013-12-14 16:31:56 [31632] [CRITICAL] WORKER TIMEOUT (pid:31713)
2013-12-14 16:31:56 [31632] [CRITICAL] WORKER TIMEOUT (pid:31714)
2013-12-14 16:31:56 [31632] [CRITICAL] WORKER TIMEOUT (pid:31715)
2013-12-14 16:31:56 [31632] [CRITICAL] WORKER TIMEOUT (pid:31716)
2013-12-14 16:31:56 [31632] [CRITICAL] WORKER TIMEOUT (pid:31717)
2013-12-14 16:31:56 [31632] [CRITICAL] WORKER TIMEOUT (pid:31718)
2013-12-14 16:31:56 [31632] [CRITICAL] WORKER TIMEOUT (pid:31719)
2013-12-14 16:31:56 [31632] [CRITICAL] WORKER TIMEOUT (pid:31720)
2013-12-14 16:31:56 [31632] [CRITICAL] WORKER TIMEOUT (pid:31721)
2013-12-14 16:31:56 [31632] [CRITICAL] WORKER TIMEOUT (pid:31711)
2013-12-14 16:31:56 [31632] [CRITICAL] WORKER TIMEOUT (pid:31716)
2013-12-14 16:31:56 [31632] [CRITICAL] WORKER TIMEOUT (pid:31718)
2013-12-14 16:31:56 [31632] [CRITICAL] WORKER TIMEOUT (pid:31719)
2013-12-14 16:31:56 [31632] [CRITICAL] WORKER TIMEOUT (pid:31720)
2013-12-14 16:31:56 [31632] [CRITICAL] WORKER TIMEOUT (pid:31721)
ERROR:app:Exception on /raw-updates [GET]
Traceback (most recent call last):
  File "/home/tfb/FrameworkBenchmarks/installs/pypy/site-packages/Flask-0.10.1-py2.7.egg/flask/app.py", line 1817, in wsgi_app
    response = self.full_dispatch_request()
  File "/home/tfb/FrameworkBenchmarks/installs/pypy/site-packages/Flask-0.10.1-py2.7.egg/flask/app.py", line 1477, in full_dispatch_request
    rv = self.handle_user_exception(e)
  File "/home/tfb/FrameworkBenchmarks/installs/pypy/site-packages/Flask-0.10.1-py2.7.egg/flask/app.py", line 1381, in handle_user_exception
    reraise(exc_type, exc_value, tb)
  File "/home/tfb/FrameworkBenchmarks/installs/pypy/site-packages/Flask-0.10.1-py2.7.egg/flask/app.py", line 1475, in full_dispatch_request
    rv = self.dispatch_request()
  File "/home/tfb/FrameworkBenchmarks/installs/pypy/site-packages/Flask-0.10.1-py2.7.egg/flask/app.py", line 1461, in dispatch_request
    return self.view_functions[rule.endpoint](**req.view_args)
  File "/home/tfb/FrameworkBenchmarks/flask/app.py", line 152, in raw_updates
    (randomNumber, world['id']))
  File "/home/tfb/FrameworkBenchmarks/installs/pypy/site-packages/SQLAlchemy-0.8.3-py2.7.egg/sqlalchemy/engine/base.py", line 1613, in execute
    connection = self.contextual_connect(close_with_result=True)
  File "/home/tfb/FrameworkBenchmarks/installs/pypy/site-packages/SQLAlchemy-0.8.3-py2.7.egg/sqlalchemy/engine/base.py", line 1661, in contextual_connect
    self.pool.connect(),
  File "/home/tfb/FrameworkBenchmarks/installs/pypy/site-packages/SQLAlchemy-0.8.3-py2.7.egg/sqlalchemy/pool.py", line 272, in connect
    return _ConnectionFairy(self).checkout()
  File "/home/tfb/FrameworkBenchmarks/installs/pypy/site-packages/SQLAlchemy-0.8.3-py2.7.egg/sqlalchemy/pool.py", line 431, in __init__
    rec = self._connection_record = pool._do_get()
  File "/home/tfb/FrameworkBenchmarks/installs/pypy/site-packages/SQLAlchemy-0.8.3-py2.7.egg/sqlalchemy/pool.py", line 780, in _do_get
    (self.size(), self.overflow(), self._timeout))
TimeoutError: QueuePool limit of size 5 overflow 10 reached, connection timed out, timeout 30
ERROR:app:Exception on /raw-updates [GET]
Traceback (most recent call last):
  File "/home/tfb/FrameworkBenchmarks/installs/pypy/site-packages/Flask-0.10.1-py2.7.egg/flask/app.py", line 1817, in wsgi_app
    response = self.full_dispatch_request()
  File "/home/tfb/FrameworkBenchmarks/installs/pypy/site-packages/Flask-0.10.1-py2.7.egg/flask/app.py", line 1477, in full_dispatch_request
    rv = self.handle_user_exception(e)
  File "/home/tfb/FrameworkBenchmarks/installs/pypy/site-packages/Flask-0.10.1-py2.7.egg/flask/app.py", line 1381, in handle_user_exception
    reraise(exc_type, exc_value, tb)
  File "/home/tfb/FrameworkBenchmarks/installs/pypy/site-packages/Flask-0.10.1-py2.7.egg/flask/app.py", line 1475, in full_dispatch_request
    rv = self.dispatch_request()
  File "/home/tfb/FrameworkBenchmarks/installs/pypy/site-packages/Flask-0.10.1-py2.7.egg/flask/app.py", line 1461, in dispatch_request
    return self.view_functions[rule.endpoint](**req.view_args)
  File "/home/tfb/FrameworkBenchmarks/flask/app.py", line 152, in raw_updates
    (randomNumber, world['id']))
  File "/home/tfb/FrameworkBenchmarks/installs/pypy/site-packages/SQLAlchemy-0.8.3-py2.7.egg/sqlalchemy/engine/base.py", line 1613, in execute
    connection = self.contextual_connect(close_with_result=True)
  File "/home/tfb/FrameworkBenchmarks/installs/pypy/site-packages/SQLAlchemy-0.8.3-py2.7.egg/sqlalchemy/engine/base.py", line 1661, in contextual_connect
    self.pool.connect(),
  File "/home/tfb/FrameworkBenchmarks/installs/pypy/site-packages/SQLAlchemy-0.8.3-py2.7.egg/sqlalchemy/pool.py", line 272, in connect
    return _ConnectionFairy(self).checkout()
  File "/home/tfb/FrameworkBenchmarks/installs/pypy/site-packages/SQLAlchemy-0.8.3-py2.7.egg/sqlalchemy/pool.py", line 431, in __init__
    rec = self._connection_record = pool._do_get()
  File "/home/tfb/FrameworkBenchmarks/installs/pypy/site-packages/SQLAlchemy-0.8.3-py2.7.egg/sqlalchemy/pool.py", line 780, in _do_get
    (self.size(), self.overflow(), self._timeout))
TimeoutError: QueuePool limit of size 5 overflow 10 reached, connection timed out, timeout 30
ERROR:app:Exception on /raw-updates [GET]
Traceback (most recent call last):
  File "/home/tfb/FrameworkBenchmarks/installs/pypy/site-packages/Flask-0.10.1-py2.7.egg/flask/app.py", line 1817, in wsgi_app
    response = self.full_dispatch_request()
  File "/home/tfb/FrameworkBenchmarks/installs/pypy/site-packages/Flask-0.10.1-py2.7.egg/flask/app.py", line 1477, in full_dispatch_request
    rv = self.handle_user_exception(e)
  File "/home/tfb/FrameworkBenchmarks/installs/pypy/site-packages/Flask-0.10.1-py2.7.egg/flask/app.py", line 1381, in handle_user_exception
    reraise(exc_type, exc_value, tb)
  File "/home/tfb/FrameworkBenchmarks/installs/pypy/site-packages/Flask-0.10.1-py2.7.egg/flask/app.py", line 1475, in full_dispatch_request
    rv = self.dispatch_request()
  File "/home/tfb/FrameworkBenchmarks/installs/pypy/site-packages/Flask-0.10.1-py2.7.egg/flask/app.py", line 1461, in dispatch_request
    return self.view_functions[rule.endpoint](**req.view_args)
  File "/home/tfb/FrameworkBenchmarks/flask/app.py", line 152, in raw_updates
    (randomNumber, world['id']))
  File "/home/tfb/FrameworkBenchmarks/installs/pypy/site-packages/SQLAlchemy-0.8.3-py2.7.egg/sqlalchemy/engine/base.py", line 1613, in execute
    connection = self.contextual_connect(close_with_result=True)
  File "/home/tfb/FrameworkBenchmarks/installs/pypy/site-packages/SQLAlchemy-0.8.3-py2.7.egg/sqlalchemy/engine/base.py", line 1661, in contextual_connect
    self.pool.connect(),
  File "/home/tfb/FrameworkBenchmarks/installs/pypy/site-packages/SQLAlchemy-0.8.3-py2.7.egg/sqlalchemy/pool.py", line 272, in connect
    return _ConnectionFairy(self).checkout()
  File "/home/tfb/FrameworkBenchmarks/installs/pypy/site-packages/SQLAlchemy-0.8.3-py2.7.egg/sqlalchemy/pool.py", line 431, in __init__
    rec = self._connection_record = pool._do_get()
  File "/home/tfb/FrameworkBenchmarks/installs/pypy/site-packages/SQLAlchemy-0.8.3-py2.7.egg/sqlalchemy/pool.py", line 780, in _do_get
    (self.size(), self.overflow(), self._timeout))
TimeoutError: QueuePool limit of size 5 overflow 10 reached, connection timed out, timeout 30
ERROR:tornado.access:500 GET /raw-updates?queries=5 (172.16.98.98) 30048.60ms
ERROR:tornado.access:500 GET /raw-updates?queries=5 (172.16.98.98) 30068.29ms
ERROR:tornado.access:500 GET /raw-updates?queries=5 (172.16.98.98) 30063.05ms
2013-12-14 16:31:56 [31632] [CRITICAL] WORKER TIMEOUT (pid:31705)
2013-12-14 16:31:56 [31632] [CRITICAL] WORKER TIMEOUT (pid:31706)
2013-12-14 16:31:56 [31632] [CRITICAL] WORKER TIMEOUT (pid:31707)
ERROR:app:Exception on /raw-updates [GET]
Traceback (most recent call last):
  File "/home/tfb/FrameworkBenchmarks/installs/pypy/site-packages/Flask-0.10.1-py2.7.egg/flask/app.py", line 1817, in wsgi_app
    response = self.full_dispatch_request()
  File "/home/tfb/FrameworkBenchmarks/installs/pypy/site-packages/Flask-0.10.1-py2.7.egg/flask/app.py", line 1477, in full_dispatch_request
    rv = self.handle_user_exception(e)
  File "/home/tfb/FrameworkBenchmarks/installs/pypy/site-packages/Flask-0.10.1-py2.7.egg/flask/app.py", line 1381, in handle_user_exception
    reraise(exc_type, exc_value, tb)
  File "/home/tfb/FrameworkBenchmarks/installs/pypy/site-packages/Flask-0.10.1-py2.7.egg/flask/app.py", line 1475, in full_dispatch_request
    rv = self.dispatch_request()
  File "/home/tfb/FrameworkBenchmarks/installs/pypy/site-packages/Flask-0.10.1-py2.7.egg/flask/app.py", line 1461, in dispatch_request
    return self.view_functions[rule.endpoint](**req.view_args)
  File "/home/tfb/FrameworkBenchmarks/flask/app.py", line 148, in raw_updates
    world = dbraw_engine.execute("SELECT * FROM World WHERE id=%s", (rp(),)).fetchone()
  File "/home/tfb/FrameworkBenchmarks/installs/pypy/site-packages/SQLAlchemy-0.8.3-py2.7.egg/sqlalchemy/engine/base.py", line 1613, in execute
    connection = self.contextual_connect(close_with_result=True)
  File "/home/tfb/FrameworkBenchmarks/installs/pypy/site-packages/SQLAlchemy-0.8.3-py2.7.egg/sqlalchemy/engine/base.py", line 1661, in contextual_connect
    self.pool.connect(),
  File "/home/tfb/FrameworkBenchmarks/installs/pypy/site-packages/SQLAlchemy-0.8.3-py2.7.egg/sqlalchemy/pool.py", line 272, in connect
    return _ConnectionFairy(self).checkout()
  File "/home/tfb/FrameworkBenchmarks/installs/pypy/site-packages/SQLAlchemy-0.8.3-py2.7.egg/sqlalchemy/pool.py", line 431, in __init__
    rec = self._connection_record = pool._do_get()
  File "/home/tfb/FrameworkBenchmarks/installs/pypy/site-packages/SQLAlchemy-0.8.3-py2.7.egg/sqlalchemy/pool.py", line 780, in _do_get
    (self.size(), self.overflow(), self._timeout))
TimeoutError: QueuePool limit of size 5 overflow 10 reached, connection timed out, timeout 30
ERROR:tornado.access:500 GET /raw-updates?queries=5 (172.16.98.98) 30001.72ms
2013-12-14 16:32:07 [31632] [CRITICAL] WORKER TIMEOUT (pid:31662)
2013-12-14 16:32:07 [31632] [CRITICAL] WORKER TIMEOUT (pid:31662)
ERROR:app:Exception on /raw-updates [GET]
Traceback (most recent call last):
  File "/home/tfb/FrameworkBenchmarks/installs/pypy/site-packages/Flask-0.10.1-py2.7.egg/flask/app.py", line 1817, in wsgi_app
    response = self.full_dispatch_request()
  File "/home/tfb/FrameworkBenchmarks/installs/pypy/site-packages/Flask-0.10.1-py2.7.egg/flask/app.py", line 1477, in full_dispatch_request
    rv = self.handle_user_exception(e)
  File "/home/tfb/FrameworkBenchmarks/installs/pypy/site-packages/Flask-0.10.1-py2.7.egg/flask/app.py", line 1381, in handle_user_exception
    reraise(exc_type, exc_value, tb)
  File "/home/tfb/FrameworkBenchmarks/installs/pypy/site-packages/Flask-0.10.1-py2.7.egg/flask/app.py", line 1475, in full_dispatch_request
    rv = self.dispatch_request()
  File "/home/tfb/FrameworkBenchmarks/installs/pypy/site-packages/Flask-0.10.1-py2.7.egg/flask/app.py", line 1461, in dispatch_request
    return self.view_functions[rule.endpoint](**req.view_args)
  File "/home/tfb/FrameworkBenchmarks/flask/app.py", line 148, in raw_updates
    world = dbraw_engine.execute("SELECT * FROM World WHERE id=%s", (rp(),)).fetchone()
  File "/home/tfb/FrameworkBenchmarks/installs/pypy/site-packages/SQLAlchemy-0.8.3-py2.7.egg/sqlalchemy/engine/base.py", line 1613, in execute
    connection = self.contextual_connect(close_with_result=True)
  File "/home/tfb/FrameworkBenchmarks/installs/pypy/site-packages/SQLAlchemy-0.8.3-py2.7.egg/sqlalchemy/engine/base.py", line 1661, in contextual_connect
    self.pool.connect(),
  File "/home/tfb/FrameworkBenchmarks/installs/pypy/site-packages/SQLAlchemy-0.8.3-py2.7.egg/sqlalchemy/pool.py", line 272, in connect
    return _ConnectionFairy(self).checkout()
  File "/home/tfb/FrameworkBenchmarks/installs/pypy/site-packages/SQLAlchemy-0.8.3-py2.7.egg/sqlalchemy/pool.py", line 431, in __init__
    rec = self._connection_record = pool._do_get()
  File "/home/tfb/FrameworkBenchmarks/installs/pypy/site-packages/SQLAlchemy-0.8.3-py2.7.egg/sqlalchemy/pool.py", line 780, in _do_get
    (self.size(), self.overflow(), self._timeout))
TimeoutError: QueuePool limit of size 5 overflow 10 reached, connection timed out, timeout 30
ERROR:tornado.access:500 GET /raw-updates?queries=10 (172.16.98.98) 30001.88ms
2013-12-14 16:32:14 [31632] [CRITICAL] WORKER TIMEOUT (pid:31657)
2013-12-14 16:32:14 [31632] [CRITICAL] WORKER TIMEOUT (pid:31738)
2013-12-14 16:32:14 [31632] [CRITICAL] WORKER TIMEOUT (pid:31739)
2013-12-14 16:32:14 [31632] [CRITICAL] WORKER TIMEOUT (pid:31740)
2013-12-14 16:32:14 [31632] [CRITICAL] WORKER TIMEOUT (pid:31741)
2013-12-14 16:32:14 [31632] [CRITICAL] WORKER TIMEOUT (pid:31742)
2013-12-14 16:32:14 [31632] [CRITICAL] WORKER TIMEOUT (pid:31657)
2013-12-14 16:32:14 [31632] [CRITICAL] WORKER TIMEOUT (pid:31738)
2013-12-14 16:32:14 [31632] [CRITICAL] WORKER TIMEOUT (pid:31739)
2013-12-14 16:32:14 [31632] [CRITICAL] WORKER TIMEOUT (pid:31740)
2013-12-14 16:32:14 [31632] [CRITICAL] WORKER TIMEOUT (pid:31741)
2013-12-14 16:32:14 [31632] [CRITICAL] WORKER TIMEOUT (pid:31742)
2013-12-14 16:32:14 [31632] [CRITICAL] WORKER TIMEOUT (pid:31657)
2013-12-14 16:32:14 [31632] [CRITICAL] WORKER TIMEOUT (pid:31739)
2013-12-14 16:32:14 [31632] [CRITICAL] WORKER TIMEOUT (pid:31740)
2013-12-14 16:32:14 [31632] [CRITICAL] WORKER TIMEOUT (pid:31741)
ERROR:app:Exception on /raw-updates [GET]
Traceback (most recent call last):
  File "/home/tfb/FrameworkBenchmarks/installs/pypy/site-packages/Flask-0.10.1-py2.7.egg/flask/app.py", line 1817, in wsgi_app
    response = self.full_dispatch_request()
  File "/home/tfb/FrameworkBenchmarks/installs/pypy/site-packages/Flask-0.10.1-py2.7.egg/flask/app.py", line 1477, in full_dispatch_request
    rv = self.handle_user_exception(e)
  File "/home/tfb/FrameworkBenchmarks/installs/pypy/site-packages/Flask-0.10.1-py2.7.egg/flask/app.py", line 1381, in handle_user_exception
    reraise(exc_type, exc_value, tb)
  File "/home/tfb/FrameworkBenchmarks/installs/pypy/site-packages/Flask-0.10.1-py2.7.egg/flask/app.py", line 1475, in full_dispatch_request
    rv = self.dispatch_request()
  File "/home/tfb/FrameworkBenchmarks/installs/pypy/site-packages/Flask-0.10.1-py2.7.egg/flask/app.py", line 1461, in dispatch_request
    return self.view_functions[rule.endpoint](**req.view_args)
  File "/home/tfb/FrameworkBenchmarks/flask/app.py", line 152, in raw_updates
    (randomNumber, world['id']))
  File "/home/tfb/FrameworkBenchmarks/installs/pypy/site-packages/SQLAlchemy-0.8.3-py2.7.egg/sqlalchemy/engine/base.py", line 1613, in execute
    connection = self.contextual_connect(close_with_result=True)
  File "/home/tfb/FrameworkBenchmarks/installs/pypy/site-packages/SQLAlchemy-0.8.3-py2.7.egg/sqlalchemy/engine/base.py", line 1661, in contextual_connect
    self.pool.connect(),
  File "/home/tfb/FrameworkBenchmarks/installs/pypy/site-packages/SQLAlchemy-0.8.3-py2.7.egg/sqlalchemy/pool.py", line 272, in connect
    return _ConnectionFairy(self).checkout()
  File "/home/tfb/FrameworkBenchmarks/installs/pypy/site-packages/SQLAlchemy-0.8.3-py2.7.egg/sqlalchemy/pool.py", line 431, in __init__
    rec = self._connection_record = pool._do_get()
  File "/home/tfb/FrameworkBenchmarks/installs/pypy/site-packages/SQLAlchemy-0.8.3-py2.7.egg/sqlalchemy/pool.py", line 780, in _do_get
    (self.size(), self.overflow(), self._timeout))
TimeoutError: QueuePool limit of size 5 overflow 10 reached, connection timed out, timeout 30
ERROR:tornado.access:500 GET /raw-updates?queries=10 (172.16.98.98) 30034.04ms
2013-12-14 16:32:17 [31632] [CRITICAL] WORKER TIMEOUT (pid:31748)
2013-12-14 16:32:17 [31632] [CRITICAL] WORKER TIMEOUT (pid:31748)
2013-12-14 16:32:31 [31632] [CRITICAL] WORKER TIMEOUT (pid:31751)
2013-12-14 16:32:31 [31632] [CRITICAL] WORKER TIMEOUT (pid:31752)
2013-12-14 16:32:31 [31632] [CRITICAL] WORKER TIMEOUT (pid:31753)
2013-12-14 16:32:31 [31632] [CRITICAL] WORKER TIMEOUT (pid:31755)
2013-12-14 16:32:31 [31632] [CRITICAL] WORKER TIMEOUT (pid:31756)
2013-12-14 16:32:31 [31632] [CRITICAL] WORKER TIMEOUT (pid:31751)
2013-12-14 16:32:31 [31632] [CRITICAL] WORKER TIMEOUT (pid:31752)
2013-12-14 16:32:31 [31632] [CRITICAL] WORKER TIMEOUT (pid:31753)
2013-12-14 16:32:31 [31632] [CRITICAL] WORKER TIMEOUT (pid:31755)
2013-12-14 16:32:31 [31632] [CRITICAL] WORKER TIMEOUT (pid:31756)
ERROR:app:Exception on /raw-updates [GET]
Traceback (most recent call last):
  File "/home/tfb/FrameworkBenchmarks/installs/pypy/site-packages/Flask-0.10.1-py2.7.egg/flask/app.py", line 1817, in wsgi_app
    response = self.full_dispatch_request()
  File "/home/tfb/FrameworkBenchmarks/installs/pypy/site-packages/Flask-0.10.1-py2.7.egg/flask/app.py", line 1477, in full_dispatch_request
    rv = self.handle_user_exception(e)
  File "/home/tfb/FrameworkBenchmarks/installs/pypy/site-packages/Flask-0.10.1-py2.7.egg/flask/app.py", line 1381, in handle_user_exception
    reraise(exc_type, exc_value, tb)
  File "/home/tfb/FrameworkBenchmarks/installs/pypy/site-packages/Flask-0.10.1-py2.7.egg/flask/app.py", line 1475, in full_dispatch_request
    rv = self.dispatch_request()
  File "/home/tfb/FrameworkBenchmarks/installs/pypy/site-packages/Flask-0.10.1-py2.7.egg/flask/app.py", line 1461, in dispatch_request
    return self.view_functions[rule.endpoint](**req.view_args)
  File "/home/tfb/FrameworkBenchmarks/flask/app.py", line 152, in raw_updates
    (randomNumber, world['id']))
  File "/home/tfb/FrameworkBenchmarks/installs/pypy/site-packages/SQLAlchemy-0.8.3-py2.7.egg/sqlalchemy/engine/base.py", line 1613, in execute
    connection = self.contextual_connect(close_with_result=True)
  File "/home/tfb/FrameworkBenchmarks/installs/pypy/site-packages/SQLAlchemy-0.8.3-py2.7.egg/sqlalchemy/engine/base.py", line 1661, in contextual_connect
    self.pool.connect(),
  File "/home/tfb/FrameworkBenchmarks/installs/pypy/site-packages/SQLAlchemy-0.8.3-py2.7.egg/sqlalchemy/pool.py", line 272, in connect
    return _ConnectionFairy(self).checkout()
  File "/home/tfb/FrameworkBenchmarks/installs/pypy/site-packages/SQLAlchemy-0.8.3-py2.7.egg/sqlalchemy/pool.py", line 431, in __init__
    rec = self._connection_record = pool._do_get()
  File "/home/tfb/FrameworkBenchmarks/installs/pypy/site-packages/SQLAlchemy-0.8.3-py2.7.egg/sqlalchemy/pool.py", line 780, in _do_get
    (self.size(), self.overflow(), self._timeout))
TimeoutError: QueuePool limit of size 5 overflow 10 reached, connection timed out, timeout 30
ERROR:app:Exception on /raw-updates [GET]
Traceback (most recent call last):
  File "/home/tfb/FrameworkBenchmarks/installs/pypy/site-packages/Flask-0.10.1-py2.7.egg/flask/app.py", line 1817, in wsgi_app
    response = self.full_dispatch_request()
  File "/home/tfb/FrameworkBenchmarks/installs/pypy/site-packages/Flask-0.10.1-py2.7.egg/flask/app.py", line 1477, in full_dispatch_request
    rv = self.handle_user_exception(e)
  File "/home/tfb/FrameworkBenchmarks/installs/pypy/site-packages/Flask-0.10.1-py2.7.egg/flask/app.py", line 1381, in handle_user_exception
    reraise(exc_type, exc_value, tb)
  File "/home/tfb/FrameworkBenchmarks/installs/pypy/site-packages/Flask-0.10.1-py2.7.egg/flask/app.py", line 1475, in full_dispatch_request
    rv = self.dispatch_request()
  File "/home/tfb/FrameworkBenchmarks/installs/pypy/site-packages/Flask-0.10.1-py2.7.egg/flask/app.py", line 1461, in dispatch_request
    return self.view_functions[rule.endpoint](**req.view_args)
  File "/home/tfb/FrameworkBenchmarks/flask/app.py", line 152, in raw_updates
    (randomNumber, world['id']))
  File "/home/tfb/FrameworkBenchmarks/installs/pypy/site-packages/SQLAlchemy-0.8.3-py2.7.egg/sqlalchemy/engine/base.py", line 1613, in execute
    connection = self.contextual_connect(close_with_result=True)
  File "/home/tfb/FrameworkBenchmarks/installs/pypy/site-packages/SQLAlchemy-0.8.3-py2.7.egg/sqlalchemy/engine/base.py", line 1661, in contextual_connect
    self.pool.connect(),
  File "/home/tfb/FrameworkBenchmarks/installs/pypy/site-packages/SQLAlchemy-0.8.3-py2.7.egg/sqlalchemy/pool.py", line 272, in connect
    return _ConnectionFairy(self).checkout()
  File "/home/tfb/FrameworkBenchmarks/installs/pypy/site-packages/SQLAlchemy-0.8.3-py2.7.egg/sqlalchemy/pool.py", line 431, in __init__
    rec = self._connection_record = pool._do_get()
  File "/home/tfb/FrameworkBenchmarks/installs/pypy/site-packages/SQLAlchemy-0.8.3-py2.7.egg/sqlalchemy/pool.py", line 780, in _do_get
    (self.size(), self.overflow(), self._timeout))
TimeoutError: QueuePool limit of size 5 overflow 10 reached, connection timed out, timeout 30
ERROR:app:Exception on /raw-updates [GET]
Traceback (most recent call last):
  File "/home/tfb/FrameworkBenchmarks/installs/pypy/site-packages/Flask-0.10.1-py2.7.egg/flask/app.py", line 1817, in wsgi_app
    response = self.full_dispatch_request()
  File "/home/tfb/FrameworkBenchmarks/installs/pypy/site-packages/Flask-0.10.1-py2.7.egg/flask/app.py", line 1477, in full_dispatch_request
    rv = self.handle_user_exception(e)
  File "/home/tfb/FrameworkBenchmarks/installs/pypy/site-packages/Flask-0.10.1-py2.7.egg/flask/app.py", line 1381, in handle_user_exception
    reraise(exc_type, exc_value, tb)
  File "/home/tfb/FrameworkBenchmarks/installs/pypy/site-packages/Flask-0.10.1-py2.7.egg/flask/app.py", line 1475, in full_dispatch_request
    rv = self.dispatch_request()
  File "/home/tfb/FrameworkBenchmarks/installs/pypy/site-packages/Flask-0.10.1-py2.7.egg/flask/app.py", line 1461, in dispatch_request
    return self.view_functions[rule.endpoint](**req.view_args)
  File "/home/tfb/FrameworkBenchmarks/flask/app.py", line 152, in raw_updates
    (randomNumber, world['id']))
  File "/home/tfb/FrameworkBenchmarks/installs/pypy/site-packages/SQLAlchemy-0.8.3-py2.7.egg/sqlalchemy/engine/base.py", line 1613, in execute
    connection = self.contextual_connect(close_with_result=True)
  File "/home/tfb/FrameworkBenchmarks/installs/pypy/site-packages/SQLAlchemy-0.8.3-py2.7.egg/sqlalchemy/engine/base.py", line 1661, in contextual_connect
    self.pool.connect(),
  File "/home/tfb/FrameworkBenchmarks/installs/pypy/site-packages/SQLAlchemy-0.8.3-py2.7.egg/sqlalchemy/pool.py", line 272, in connect
    return _ConnectionFairy(self).checkout()
  File "/home/tfb/FrameworkBenchmarks/installs/pypy/site-packages/SQLAlchemy-0.8.3-py2.7.egg/sqlalchemy/pool.py", line 431, in __init__
    rec = self._connection_record = pool._do_get()
  File "/home/tfb/FrameworkBenchmarks/installs/pypy/site-packages/SQLAlchemy-0.8.3-py2.7.egg/sqlalchemy/pool.py", line 780, in _do_get
    (self.size(), self.overflow(), self._timeout))
TimeoutError: QueuePool limit of size 5 overflow 10 reached, connection timed out, timeout 30
ERROR:app:Exception on /raw-updates [GET]
Traceback (most recent call last):
  File "/home/tfb/FrameworkBenchmarks/installs/pypy/site-packages/Flask-0.10.1-py2.7.egg/flask/app.py", line 1817, in wsgi_app
    response = self.full_dispatch_request()
  File "/home/tfb/FrameworkBenchmarks/installs/pypy/site-packages/Flask-0.10.1-py2.7.egg/flask/app.py", line 1477, in full_dispatch_request
    rv = self.handle_user_exception(e)
  File "/home/tfb/FrameworkBenchmarks/installs/pypy/site-packages/Flask-0.10.1-py2.7.egg/flask/app.py", line 1381, in handle_user_exception
    reraise(exc_type, exc_value, tb)
  File "/home/tfb/FrameworkBenchmarks/installs/pypy/site-packages/Flask-0.10.1-py2.7.egg/flask/app.py", line 1475, in full_dispatch_request
    rv = self.dispatch_request()
  File "/home/tfb/FrameworkBenchmarks/installs/pypy/site-packages/Flask-0.10.1-py2.7.egg/flask/app.py", line 1461, in dispatch_request
    return self.view_functions[rule.endpoint](**req.view_args)
  File "/home/tfb/FrameworkBenchmarks/flask/app.py", line 152, in raw_updates
    (randomNumber, world['id']))
  File "/home/tfb/FrameworkBenchmarks/installs/pypy/site-packages/SQLAlchemy-0.8.3-py2.7.egg/sqlalchemy/engine/base.py", line 1613, in execute
    connection = self.contextual_connect(close_with_result=True)
  File "/home/tfb/FrameworkBenchmarks/installs/pypy/site-packages/SQLAlchemy-0.8.3-py2.7.egg/sqlalchemy/engine/base.py", line 1661, in contextual_connect
    self.pool.connect(),
  File "/home/tfb/FrameworkBenchmarks/installs/pypy/site-packages/SQLAlchemy-0.8.3-py2.7.egg/sqlalchemy/pool.py", line 272, in connect
    return _ConnectionFairy(self).checkout()
  File "/home/tfb/FrameworkBenchmarks/installs/pypy/site-packages/SQLAlchemy-0.8.3-py2.7.egg/sqlalchemy/pool.py", line 431, in __init__
    rec = self._connection_record = pool._do_get()
  File "/home/tfb/FrameworkBenchmarks/installs/pypy/site-packages/SQLAlchemy-0.8.3-py2.7.egg/sqlalchemy/pool.py", line 780, in _do_get
    (self.size(), self.overflow(), self._timeout))
TimeoutError: QueuePool limit of size 5 overflow 10 reached, connection timed out, timeout 30
ERROR:app:Exception on /raw-updates [GET]
Traceback (most recent call last):
  File "/home/tfb/FrameworkBenchmarks/installs/pypy/site-packages/Flask-0.10.1-py2.7.egg/flask/app.py", line 1817, in wsgi_app
    response = self.full_dispatch_request()
  File "/home/tfb/FrameworkBenchmarks/installs/pypy/site-packages/Flask-0.10.1-py2.7.egg/flask/app.py", line 1477, in full_dispatch_request
    rv = self.handle_user_exception(e)
  File "/home/tfb/FrameworkBenchmarks/installs/pypy/site-packages/Flask-0.10.1-py2.7.egg/flask/app.py", line 1381, in handle_user_exception
    reraise(exc_type, exc_value, tb)
  File "/home/tfb/FrameworkBenchmarks/installs/pypy/site-packages/Flask-0.10.1-py2.7.egg/flask/app.py", line 1475, in full_dispatch_request
    rv = self.dispatch_request()
  File "/home/tfb/FrameworkBenchmarks/installs/pypy/site-packages/Flask-0.10.1-py2.7.egg/flask/app.py", line 1461, in dispatch_request
    return self.view_functions[rule.endpoint](**req.view_args)
  File "/home/tfb/FrameworkBenchmarks/flask/app.py", line 152, in raw_updates
    (randomNumber, world['id']))
  File "/home/tfb/FrameworkBenchmarks/installs/pypy/site-packages/SQLAlchemy-0.8.3-py2.7.egg/sqlalchemy/engine/base.py", line 1613, in execute
    connection = self.contextual_connect(close_with_result=True)
  File "/home/tfb/FrameworkBenchmarks/installs/pypy/site-packages/SQLAlchemy-0.8.3-py2.7.egg/sqlalchemy/engine/base.py", line 1661, in contextual_connect
    self.pool.connect(),
  File "/home/tfb/FrameworkBenchmarks/installs/pypy/site-packages/SQLAlchemy-0.8.3-py2.7.egg/sqlalchemy/pool.py", line 272, in connect
    return _ConnectionFairy(self).checkout()
  File "/home/tfb/FrameworkBenchmarks/installs/pypy/site-packages/SQLAlchemy-0.8.3-py2.7.egg/sqlalchemy/pool.py", line 431, in __init__
    rec = self._connection_record = pool._do_get()
  File "/home/tfb/FrameworkBenchmarks/installs/pypy/site-packages/SQLAlchemy-0.8.3-py2.7.egg/sqlalchemy/pool.py", line 780, in _do_get
    (self.size(), self.overflow(), self._timeout))
TimeoutError: QueuePool limit of size 5 overflow 10 reached, connection timed out, timeout 30
ERROR:app:Exception on /raw-updates [GET]
Traceback (most recent call last):
  File "/home/tfb/FrameworkBenchmarks/installs/pypy/site-packages/Flask-0.10.1-py2.7.egg/flask/app.py", line 1817, in wsgi_app
    response = self.full_dispatch_request()
  File "/home/tfb/FrameworkBenchmarks/installs/pypy/site-packages/Flask-0.10.1-py2.7.egg/flask/app.py", line 1477, in full_dispatch_request
    rv = self.handle_user_exception(e)
  File "/home/tfb/FrameworkBenchmarks/installs/pypy/site-packages/Flask-0.10.1-py2.7.egg/flask/app.py", line 1381, in handle_user_exception
    reraise(exc_type, exc_value, tb)
  File "/home/tfb/FrameworkBenchmarks/installs/pypy/site-packages/Flask-0.10.1-py2.7.egg/flask/app.py", line 1475, in full_dispatch_request
    rv = self.dispatch_request()
  File "/home/tfb/FrameworkBenchmarks/installs/pypy/site-packages/Flask-0.10.1-py2.7.egg/flask/app.py", line 1461, in dispatch_request
    return self.view_functions[rule.endpoint](**req.view_args)
  File "/home/tfb/FrameworkBenchmarks/flask/app.py", line 152, in raw_updates
    (randomNumber, world['id']))
  File "/home/tfb/FrameworkBenchmarks/installs/pypy/site-packages/SQLAlchemy-0.8.3-py2.7.egg/sqlalchemy/engine/base.py", line 1613, in execute
    connection = self.contextual_connect(close_with_result=True)
  File "/home/tfb/FrameworkBenchmarks/installs/pypy/site-packages/SQLAlchemy-0.8.3-py2.7.egg/sqlalchemy/engine/base.py", line 1661, in contextual_connect
    self.pool.connect(),
  File "/home/tfb/FrameworkBenchmarks/installs/pypy/site-packages/SQLAlchemy-0.8.3-py2.7.egg/sqlalchemy/pool.py", line 272, in connect
    return _ConnectionFairy(self).checkout()
  File "/home/tfb/FrameworkBenchmarks/installs/pypy/site-packages/SQLAlchemy-0.8.3-py2.7.egg/sqlalchemy/pool.py", line 431, in __init__
    rec = self._connection_record = pool._do_get()
  File "/home/tfb/FrameworkBenchmarks/installs/pypy/site-packages/SQLAlchemy-0.8.3-py2.7.egg/sqlalchemy/pool.py", line 780, in _do_get
    (self.size(), self.overflow(), self._timeout))
TimeoutError: QueuePool limit of size 5 overflow 10 reached, connection timed out, timeout 30
ERROR:app:Exception on /raw-updates [GET]
Traceback (most recent call last):
  File "/home/tfb/FrameworkBenchmarks/installs/pypy/site-packages/Flask-0.10.1-py2.7.egg/flask/app.py", line 1817, in wsgi_app
    response = self.full_dispatch_request()
  File "/home/tfb/FrameworkBenchmarks/installs/pypy/site-packages/Flask-0.10.1-py2.7.egg/flask/app.py", line 1477, in full_dispatch_request
    rv = self.handle_user_exception(e)
  File "/home/tfb/FrameworkBenchmarks/installs/pypy/site-packages/Flask-0.10.1-py2.7.egg/flask/app.py", line 1381, in handle_user_exception
    reraise(exc_type, exc_value, tb)
  File "/home/tfb/FrameworkBenchmarks/installs/pypy/site-packages/Flask-0.10.1-py2.7.egg/flask/app.py", line 1475, in full_dispatch_request
    rv = self.dispatch_request()
  File "/home/tfb/FrameworkBenchmarks/installs/pypy/site-packages/Flask-0.10.1-py2.7.egg/flask/app.py", line 1461, in dispatch_request
    return self.view_functions[rule.endpoint](**req.view_args)
  File "/home/tfb/FrameworkBenchmarks/flask/app.py", line 152, in raw_updates
    (randomNumber, world['id']))
  File "/home/tfb/FrameworkBenchmarks/installs/pypy/site-packages/SQLAlchemy-0.8.3-py2.7.egg/sqlalchemy/engine/base.py", line 1613, in execute
    connection = self.contextual_connect(close_with_result=True)
  File "/home/tfb/FrameworkBenchmarks/installs/pypy/site-packages/SQLAlchemy-0.8.3-py2.7.egg/sqlalchemy/engine/base.py", line 1661, in contextual_connect
    self.pool.connect(),
  File "/home/tfb/FrameworkBenchmarks/installs/pypy/site-packages/SQLAlchemy-0.8.3-py2.7.egg/sqlalchemy/pool.py", line 272, in connect
    return _ConnectionFairy(self).checkout()
  File "/home/tfb/FrameworkBenchmarks/installs/pypy/site-packages/SQLAlchemy-0.8.3-py2.7.egg/sqlalchemy/pool.py", line 431, in __init__
    rec = self._connection_record = pool._do_get()
  File "/home/tfb/FrameworkBenchmarks/installs/pypy/site-packages/SQLAlchemy-0.8.3-py2.7.egg/sqlalchemy/pool.py", line 780, in _do_get
    (self.size(), self.overflow(), self._timeout))
TimeoutError: QueuePool limit of size 5 overflow 10 reached, connection timed out, timeout 30
ERROR:app:Exception on /raw-updates [GET]
Traceback (most recent call last):
  File "/home/tfb/FrameworkBenchmarks/installs/pypy/site-packages/Flask-0.10.1-py2.7.egg/flask/app.py", line 1817, in wsgi_app
    response = self.full_dispatch_request()
  File "/home/tfb/FrameworkBenchmarks/installs/pypy/site-packages/Flask-0.10.1-py2.7.egg/flask/app.py", line 1477, in full_dispatch_request
    rv = self.handle_user_exception(e)
  File "/home/tfb/FrameworkBenchmarks/installs/pypy/site-packages/Flask-0.10.1-py2.7.egg/flask/app.py", line 1381, in handle_user_exception
    reraise(exc_type, exc_value, tb)
  File "/home/tfb/FrameworkBenchmarks/installs/pypy/site-packages/Flask-0.10.1-py2.7.egg/flask/app.py", line 1475, in full_dispatch_request
    rv = self.dispatch_request()
  File "/home/tfb/FrameworkBenchmarks/installs/pypy/site-packages/Flask-0.10.1-py2.7.egg/flask/app.py", line 1461, in dispatch_request
    return self.view_functions[rule.endpoint](**req.view_args)
  File "/home/tfb/FrameworkBenchmarks/flask/app.py", line 152, in raw_updates
    (randomNumber, world['id']))
  File "/home/tfb/FrameworkBenchmarks/installs/pypy/site-packages/SQLAlchemy-0.8.3-py2.7.egg/sqlalchemy/engine/base.py", line 1613, in execute
    connection = self.contextual_connect(close_with_result=True)
  File "/home/tfb/FrameworkBenchmarks/installs/pypy/site-packages/SQLAlchemy-0.8.3-py2.7.egg/sqlalchemy/engine/base.py", line 1661, in contextual_connect
    self.pool.connect(),
  File "/home/tfb/FrameworkBenchmarks/installs/pypy/site-packages/SQLAlchemy-0.8.3-py2.7.egg/sqlalchemy/pool.py", line 272, in connect
    return _ConnectionFairy(self).checkout()
  File "/home/tfb/FrameworkBenchmarks/installs/pypy/site-packages/SQLAlchemy-0.8.3-py2.7.egg/sqlalchemy/pool.py", line 431, in __init__
    rec = self._connection_record = pool._do_get()
  File "/home/tfb/FrameworkBenchmarks/installs/pypy/site-packages/SQLAlchemy-0.8.3-py2.7.egg/sqlalchemy/pool.py", line 780, in _do_get
    (self.size(), self.overflow(), self._timeout))
TimeoutError: QueuePool limit of size 5 overflow 10 reached, connection timed out, timeout 30
ERROR:app:Exception on /raw-updates [GET]
Traceback (most recent call last):
  File "/home/tfb/FrameworkBenchmarks/installs/pypy/site-packages/Flask-0.10.1-py2.7.egg/flask/app.py", line 1817, in wsgi_app
    response = self.full_dispatch_request()
  File "/home/tfb/FrameworkBenchmarks/installs/pypy/site-packages/Flask-0.10.1-py2.7.egg/flask/app.py", line 1477, in full_dispatch_request
    rv = self.handle_user_exception(e)
  File "/home/tfb/FrameworkBenchmarks/installs/pypy/site-packages/Flask-0.10.1-py2.7.egg/flask/app.py", line 1381, in handle_user_exception
    reraise(exc_type, exc_value, tb)
  File "/home/tfb/FrameworkBenchmarks/installs/pypy/site-packages/Flask-0.10.1-py2.7.egg/flask/app.py", line 1475, in full_dispatch_request
    rv = self.dispatch_request()
  File "/home/tfb/FrameworkBenchmarks/installs/pypy/site-packages/Flask-0.10.1-py2.7.egg/flask/app.py", line 1461, in dispatch_request
    return self.view_functions[rule.endpoint](**req.view_args)
  File "/home/tfb/FrameworkBenchmarks/flask/app.py", line 152, in raw_updates
    (randomNumber, world['id']))
  File "/home/tfb/FrameworkBenchmarks/installs/pypy/site-packages/SQLAlchemy-0.8.3-py2.7.egg/sqlalchemy/engine/base.py", line 1613, in execute
    connection = self.contextual_connect(close_with_result=True)
  File "/home/tfb/FrameworkBenchmarks/installs/pypy/site-packages/SQLAlchemy-0.8.3-py2.7.egg/sqlalchemy/engine/base.py", line 1661, in contextual_connect
    self.pool.connect(),
  File "/home/tfb/FrameworkBenchmarks/installs/pypy/site-packages/SQLAlchemy-0.8.3-py2.7.egg/sqlalchemy/pool.py", line 272, in connect
    return _ConnectionFairy(self).checkout()
  File "/home/tfb/FrameworkBenchmarks/installs/pypy/site-packages/SQLAlchemy-0.8.3-py2.7.egg/sqlalchemy/pool.py", line 431, in __init__
    rec = self._connection_record = pool._do_get()
  File "/home/tfb/FrameworkBenchmarks/installs/pypy/site-packages/SQLAlchemy-0.8.3-py2.7.egg/sqlalchemy/pool.py", line 780, in _do_get
    (self.size(), self.overflow(), self._timeout))
TimeoutError: QueuePool limit of size 5 overflow 10 reached, connection timed out, timeout 30
ERROR:app:Exception on /raw-updates [GET]
Traceback (most recent call last):
  File "/home/tfb/FrameworkBenchmarks/installs/pypy/site-packages/Flask-0.10.1-py2.7.egg/flask/app.py", line 1817, in wsgi_app
    response = self.full_dispatch_request()
  File "/home/tfb/FrameworkBenchmarks/installs/pypy/site-packages/Flask-0.10.1-py2.7.egg/flask/app.py", line 1477, in full_dispatch_request
    rv = self.handle_user_exception(e)
  File "/home/tfb/FrameworkBenchmarks/installs/pypy/site-packages/Flask-0.10.1-py2.7.egg/flask/app.py", line 1381, in handle_user_exception
    reraise(exc_type, exc_value, tb)
  File "/home/tfb/FrameworkBenchmarks/installs/pypy/site-packages/Flask-0.10.1-py2.7.egg/flask/app.py", line 1475, in full_dispatch_request
    rv = self.dispatch_request()
  File "/home/tfb/FrameworkBenchmarks/installs/pypy/site-packages/Flask-0.10.1-py2.7.egg/flask/app.py", line 1461, in dispatch_request
    return self.view_functions[rule.endpoint](**req.view_args)
  File "/home/tfb/FrameworkBenchmarks/flask/app.py", line 152, in raw_updates
    (randomNumber, world['id']))
  File "/home/tfb/FrameworkBenchmarks/installs/pypy/site-packages/SQLAlchemy-0.8.3-py2.7.egg/sqlalchemy/engine/base.py", line 1613, in execute
    connection = self.contextual_connect(close_with_result=True)
  File "/home/tfb/FrameworkBenchmarks/installs/pypy/site-packages/SQLAlchemy-0.8.3-py2.7.egg/sqlalchemy/engine/base.py", line 1661, in contextual_connect
    self.pool.connect(),
  File "/home/tfb/FrameworkBenchmarks/installs/pypy/site-packages/SQLAlchemy-0.8.3-py2.7.egg/sqlalchemy/pool.py", line 272, in connect
    return _ConnectionFairy(self).checkout()
  File "/home/tfb/FrameworkBenchmarks/installs/pypy/site-packages/SQLAlchemy-0.8.3-py2.7.egg/sqlalchemy/pool.py", line 431, in __init__
    rec = self._connection_record = pool._do_get()
  File "/home/tfb/FrameworkBenchmarks/installs/pypy/site-packages/SQLAlchemy-0.8.3-py2.7.egg/sqlalchemy/pool.py", line 780, in _do_get
    (self.size(), self.overflow(), self._timeout))
TimeoutError: QueuePool limit of size 5 overflow 10 reached, connection timed out, timeout 30
ERROR:tornado.access:500 GET /raw-updates?queries=15 (172.16.98.98) 30113.62ms
ERROR:tornado.access:500 GET /raw-updates?queries=15 (172.16.98.98) 30130.02ms
ERROR:tornado.access:500 GET /raw-updates?queries=15 (172.16.98.98) 30138.16ms
ERROR:tornado.access:500 GET /raw-updates?queries=15 (172.16.98.98) 30140.35ms
ERROR:tornado.access:500 GET /raw-updates?queries=15 (172.16.98.98) 30135.98ms
ERROR:tornado.access:500 GET /raw-updates?queries=15 (172.16.98.98) 30135.31ms
ERROR:tornado.access:500 GET /raw-updates?queries=15 (172.16.98.98) 30135.56ms
ERROR:tornado.access:500 GET /raw-updates?queries=15 (172.16.98.98) 30134.89ms
ERROR:tornado.access:500 GET /raw-updates?queries=15 (172.16.98.98) 30148.67ms
ERROR:tornado.access:500 GET /raw-updates?queries=15 (172.16.98.98) 30139.78ms
2013-12-14 16:32:33 [31632] [CRITICAL] WORKER TIMEOUT (pid:31750)
2013-12-14 16:32:33 [31632] [CRITICAL] WORKER TIMEOUT (pid:31754)
2013-12-14 16:32:33 [31632] [CRITICAL] WORKER TIMEOUT (pid:31758)
2013-12-14 16:32:33 [31632] [CRITICAL] WORKER TIMEOUT (pid:31759)
2013-12-14 16:32:33 [31632] [CRITICAL] WORKER TIMEOUT (pid:31760)
2013-12-14 16:32:33 [31632] [CRITICAL] WORKER TIMEOUT (pid:31762)
2013-12-14 16:32:33 [31632] [CRITICAL] WORKER TIMEOUT (pid:31763)
2013-12-14 16:32:33 [31632] [CRITICAL] WORKER TIMEOUT (pid:31750)
2013-12-14 16:32:33 [31632] [CRITICAL] WORKER TIMEOUT (pid:31754)
2013-12-14 16:32:33 [31632] [CRITICAL] WORKER TIMEOUT (pid:31758)
2013-12-14 16:32:33 [31632] [CRITICAL] WORKER TIMEOUT (pid:31759)
2013-12-14 16:32:33 [31632] [CRITICAL] WORKER TIMEOUT (pid:31760)
2013-12-14 16:32:33 [31632] [CRITICAL] WORKER TIMEOUT (pid:31762)
2013-12-14 16:32:33 [31632] [CRITICAL] WORKER TIMEOUT (pid:31763)
2013-12-14 16:32:33 [31632] [CRITICAL] WORKER TIMEOUT (pid:31750)
2013-12-14 16:32:33 [31632] [CRITICAL] WORKER TIMEOUT (pid:31758)
2013-12-14 16:32:33 [31632] [CRITICAL] WORKER TIMEOUT (pid:31759)
2013-12-14 16:32:33 [31632] [CRITICAL] WORKER TIMEOUT (pid:31760)
2013-12-14 16:32:33 [31632] [CRITICAL] WORKER TIMEOUT (pid:31763)
ERROR:tornado.application:Uncaught exception, closing connection.
Traceback (most recent call last):
  File "/home/tfb/FrameworkBenchmarks/installs/pypy/site-packages/tornado-3.1-py2.7.egg/tornado/iostream.py", line 341, in wrapper
    callback(*args)
  File "/home/tfb/FrameworkBenchmarks/installs/pypy/site-packages/tornado-3.1-py2.7.egg/tornado/stack_context.py", line 331, in wrapped
    raise_exc_info(exc)
  File "/home/tfb/FrameworkBenchmarks/installs/pypy/site-packages/tornado-3.1-py2.7.egg/tornado/stack_context.py", line 302, in wrapped
    ret = fn(*args, **kwargs)
TypeError: exceptions must be old-style classes or derived from BaseException, not NoneType
ERROR:tornado.application:Uncaught exception, closing connection.
Traceback (most recent call last):
  File "/home/tfb/FrameworkBenchmarks/installs/pypy/site-packages/tornado-3.1-py2.7.egg/tornado/iostream.py", line 341, in wrapper
    callback(*args)
  File "/home/tfb/FrameworkBenchmarks/installs/pypy/site-packages/tornado-3.1-py2.7.egg/tornado/stack_context.py", line 331, in wrapped
    raise_exc_info(exc)
  File "/home/tfb/FrameworkBenchmarks/installs/pypy/site-packages/tornado-3.1-py2.7.egg/tornado/stack_context.py", line 302, in wrapped
    ret = fn(*args, **kwargs)
TypeError: exceptions must be old-style classes or derived from BaseException, not NoneType
ERROR:tornado.application:Exception in callback <_functools.partial object at 0x00007ffd23359440>
Traceback (most recent call last):
  File "/home/tfb/FrameworkBenchmarks/installs/pypy/site-packages/tornado-3.1-py2.7.egg/tornado/ioloop.py", line 458, in _run_callback
    callback()
  File "/home/tfb/FrameworkBenchmarks/installs/pypy/lib_pypy/_functools.py", line 22, in __call__
    return self.func(*(self.args + fargs), **fkeywords)
  File "/home/tfb/FrameworkBenchmarks/installs/pypy/site-packages/tornado-3.1-py2.7.egg/tornado/stack_context.py", line 331, in wrapped
    raise_exc_info(exc)
  File "/home/tfb/FrameworkBenchmarks/installs/pypy/site-packages/tornado-3.1-py2.7.egg/tornado/stack_context.py", line 302, in wrapped
    ret = fn(*args, **kwargs)
  File "/home/tfb/FrameworkBenchmarks/installs/pypy/site-packages/tornado-3.1-py2.7.egg/tornado/iostream.py", line 341, in wrapper
    callback(*args)
  File "/home/tfb/FrameworkBenchmarks/installs/pypy/site-packages/tornado-3.1-py2.7.egg/tornado/stack_context.py", line 331, in wrapped
    raise_exc_info(exc)
  File "/home/tfb/FrameworkBenchmarks/installs/pypy/site-packages/tornado-3.1-py2.7.egg/tornado/stack_context.py", line 302, in wrapped
    ret = fn(*args, **kwargs)
TypeError: exceptions must be old-style classes or derived from BaseException, not NoneType
ERROR:tornado.application:Exception in callback <_functools.partial object at 0x00007ffd233591d8>
Traceback (most recent call last):
  File "/home/tfb/FrameworkBenchmarks/installs/pypy/site-packages/tornado-3.1-py2.7.egg/tornado/ioloop.py", line 458, in _run_callback
    callback()
  File "/home/tfb/FrameworkBenchmarks/installs/pypy/lib_pypy/_functools.py", line 22, in __call__
    return self.func(*(self.args + fargs), **fkeywords)
  File "/home/tfb/FrameworkBenchmarks/installs/pypy/site-packages/tornado-3.1-py2.7.egg/tornado/stack_context.py", line 331, in wrapped
    raise_exc_info(exc)
  File "/home/tfb/FrameworkBenchmarks/installs/pypy/site-packages/tornado-3.1-py2.7.egg/tornado/stack_context.py", line 302, in wrapped
    ret = fn(*args, **kwargs)
  File "/home/tfb/FrameworkBenchmarks/installs/pypy/site-packages/tornado-3.1-py2.7.egg/tornado/iostream.py", line 341, in wrapper
    callback(*args)
  File "/home/tfb/FrameworkBenchmarks/installs/pypy/site-packages/tornado-3.1-py2.7.egg/tornado/stack_context.py", line 331, in wrapped
    raise_exc_info(exc)
  File "/home/tfb/FrameworkBenchmarks/installs/pypy/site-packages/tornado-3.1-py2.7.egg/tornado/stack_context.py", line 302, in wrapped
    ret = fn(*args, **kwargs)
TypeError: exceptions must be old-style classes or derived from BaseException, not NoneType
ERROR:tornado.application:Uncaught exception, closing connection.
Traceback (most recent call last):
  File "/home/tfb/FrameworkBenchmarks/installs/pypy/site-packages/tornado-3.1-py2.7.egg/tornado/iostream.py", line 341, in wrapper
    callback(*args)
  File "/home/tfb/FrameworkBenchmarks/installs/pypy/site-packages/tornado-3.1-py2.7.egg/tornado/stack_context.py", line 331, in wrapped
    raise_exc_info(exc)
  File "/home/tfb/FrameworkBenchmarks/installs/pypy/site-packages/tornado-3.1-py2.7.egg/tornado/stack_context.py", line 302, in wrapped
    ret = fn(*args, **kwargs)
TypeError: exceptions must be old-style classes or derived from BaseException, not NoneType
ERROR:tornado.application:Exception in callback <_functools.partial object at 0x00007ffd23359c58>
Traceback (most recent call last):
  File "/home/tfb/FrameworkBenchmarks/installs/pypy/site-packages/tornado-3.1-py2.7.egg/tornado/ioloop.py", line 458, in _run_callback
    callback()
  File "/home/tfb/FrameworkBenchmarks/installs/pypy/lib_pypy/_functools.py", line 22, in __call__
    return self.func(*(self.args + fargs), **fkeywords)
  File "/home/tfb/FrameworkBenchmarks/installs/pypy/site-packages/tornado-3.1-py2.7.egg/tornado/stack_context.py", line 331, in wrapped
    raise_exc_info(exc)
  File "/home/tfb/FrameworkBenchmarks/installs/pypy/site-packages/tornado-3.1-py2.7.egg/tornado/stack_context.py", line 302, in wrapped
    ret = fn(*args, **kwargs)
  File "/home/tfb/FrameworkBenchmarks/installs/pypy/site-packages/tornado-3.1-py2.7.egg/tornado/iostream.py", line 341, in wrapper
    callback(*args)
  File "/home/tfb/FrameworkBenchmarks/installs/pypy/site-packages/tornado-3.1-py2.7.egg/tornado/stack_context.py", line 331, in wrapped
    raise_exc_info(exc)
  File "/home/tfb/FrameworkBenchmarks/installs/pypy/site-packages/tornado-3.1-py2.7.egg/tornado/stack_context.py", line 302, in wrapped
    ret = fn(*args, **kwargs)
TypeError: exceptions must be old-style classes or derived from BaseException, not NoneType
ERROR:tornado.application:Exception in callback <_functools.partial object at 0x00007ffd23359520>
Traceback (most recent call last):
  File "/home/tfb/FrameworkBenchmarks/installs/pypy/site-packages/tornado-3.1-py2.7.egg/tornado/ioloop.py", line 458, in _run_callback
    callback()
  File "/home/tfb/FrameworkBenchmarks/installs/pypy/lib_pypy/_functools.py", line 22, in __call__
    return self.func(*(self.args + fargs), **fkeywords)
  File "/home/tfb/FrameworkBenchmarks/installs/pypy/site-packages/tornado-3.1-py2.7.egg/tornado/stack_context.py", line 331, in wrapped
    raise_exc_info(exc)
  File "/home/tfb/FrameworkBenchmarks/installs/pypy/site-packages/tornado-3.1-py2.7.egg/tornado/stack_context.py", line 302, in wrapped
    ret = fn(*args, **kwargs)
  File "/home/tfb/FrameworkBenchmarks/installs/pypy/site-packages/tornado-3.1-py2.7.egg/tornado/iostream.py", line 341, in wrapper
    callback(*args)
  File "/home/tfb/FrameworkBenchmarks/installs/pypy/site-packages/tornado-3.1-py2.7.egg/tornado/stack_context.py", line 331, in wrapped
    raise_exc_info(exc)
  File "/home/tfb/FrameworkBenchmarks/installs/pypy/site-packages/tornado-3.1-py2.7.egg/tornado/stack_context.py", line 302, in wrapped
    ret = fn(*args, **kwargs)
TypeError: exceptions must be old-style classes or derived from BaseException, not NoneType
ERROR:tornado.application:Uncaught exception, closing connection.
Traceback (most recent call last):
  File "/home/tfb/FrameworkBenchmarks/installs/pypy/site-packages/tornado-3.1-py2.7.egg/tornado/iostream.py", line 341, in wrapper
    callback(*args)
  File "/home/tfb/FrameworkBenchmarks/installs/pypy/site-packages/tornado-3.1-py2.7.egg/tornado/stack_context.py", line 331, in wrapped
    raise_exc_info(exc)
  File "/home/tfb/FrameworkBenchmarks/installs/pypy/site-packages/tornado-3.1-py2.7.egg/tornado/stack_context.py", line 302, in wrapped
    ret = fn(*args, **kwargs)
TypeError: exceptions must be old-style classes or derived from BaseException, not NoneType
ERROR:tornado.application:Uncaught exception, closing connection.
Traceback (most recent call last):
  File "/home/tfb/FrameworkBenchmarks/installs/pypy/site-packages/tornado-3.1-py2.7.egg/tornado/iostream.py", line 341, in wrapper
    callback(*args)
  File "/home/tfb/FrameworkBenchmarks/installs/pypy/site-packages/tornado-3.1-py2.7.egg/tornado/stack_context.py", line 331, in wrapped
    raise_exc_info(exc)
  File "/home/tfb/FrameworkBenchmarks/installs/pypy/site-packages/tornado-3.1-py2.7.egg/tornado/stack_context.py", line 302, in wrapped
    ret = fn(*args, **kwargs)
TypeError: exceptions must be old-style classes or derived from BaseException, not NoneType
ERROR:tornado.application:Exception in callback <_functools.partial object at 0x00007ffd23358d08>
Traceback (most recent call last):
  File "/home/tfb/FrameworkBenchmarks/installs/pypy/site-packages/tornado-3.1-py2.7.egg/tornado/ioloop.py", line 458, in _run_callback
    callback()
  File "/home/tfb/FrameworkBenchmarks/installs/pypy/lib_pypy/_functools.py", line 22, in __call__
    return self.func(*(self.args + fargs), **fkeywords)
  File "/home/tfb/FrameworkBenchmarks/installs/pypy/site-packages/tornado-3.1-py2.7.egg/tornado/stack_context.py", line 331, in wrapped
    raise_exc_info(exc)
  File "/home/tfb/FrameworkBenchmarks/installs/pypy/site-packages/tornado-3.1-py2.7.egg/tornado/stack_context.py", line 302, in wrapped
    ret = fn(*args, **kwargs)
  File "/home/tfb/FrameworkBenchmarks/installs/pypy/site-packages/tornado-3.1-py2.7.egg/tornado/iostream.py", line 341, in wrapper
    callback(*args)
  File "/home/tfb/FrameworkBenchmarks/installs/pypy/site-packages/tornado-3.1-py2.7.egg/tornado/stack_context.py", line 331, in wrapped
    raise_exc_info(exc)
  File "/home/tfb/FrameworkBenchmarks/installs/pypy/site-packages/tornado-3.1-py2.7.egg/tornado/stack_context.py", line 302, in wrapped
    ret = fn(*args, **kwargs)
TypeError: exceptions must be old-style classes or derived from BaseException, not NoneType
ERROR:tornado.application:Exception in callback <_functools.partial object at 0x00007ffd23359be8>
Traceback (most recent call last):
  File "/home/tfb/FrameworkBenchmarks/installs/pypy/site-packages/tornado-3.1-py2.7.egg/tornado/ioloop.py", line 458, in _run_callback
    callback()
  File "/home/tfb/FrameworkBenchmarks/installs/pypy/lib_pypy/_functools.py", line 22, in __call__
    return self.func(*(self.args + fargs), **fkeywords)
  File "/home/tfb/FrameworkBenchmarks/installs/pypy/site-packages/tornado-3.1-py2.7.egg/tornado/stack_context.py", line 331, in wrapped
    raise_exc_info(exc)
  File "/home/tfb/FrameworkBenchmarks/installs/pypy/site-packages/tornado-3.1-py2.7.egg/tornado/stack_context.py", line 302, in wrapped
    ret = fn(*args, **kwargs)
  File "/home/tfb/FrameworkBenchmarks/installs/pypy/site-packages/tornado-3.1-py2.7.egg/tornado/iostream.py", line 341, in wrapper
    callback(*args)
  File "/home/tfb/FrameworkBenchmarks/installs/pypy/site-packages/tornado-3.1-py2.7.egg/tornado/stack_context.py", line 331, in wrapped
    raise_exc_info(exc)
  File "/home/tfb/FrameworkBenchmarks/installs/pypy/site-packages/tornado-3.1-py2.7.egg/tornado/stack_context.py", line 302, in wrapped
    ret = fn(*args, **kwargs)
TypeError: exceptions must be old-style classes or derived from BaseException, not NoneType
ERROR:tornado.application:Uncaught exception, closing connection.
Traceback (most recent call last):
  File "/home/tfb/FrameworkBenchmarks/installs/pypy/site-packages/tornado-3.1-py2.7.egg/tornado/iostream.py", line 341, in wrapper
    callback(*args)
  File "/home/tfb/FrameworkBenchmarks/installs/pypy/site-packages/tornado-3.1-py2.7.egg/tornado/stack_context.py", line 331, in wrapped
    raise_exc_info(exc)
  File "/home/tfb/FrameworkBenchmarks/installs/pypy/site-packages/tornado-3.1-py2.7.egg/tornado/stack_context.py", line 302, in wrapped
    ret = fn(*args, **kwargs)
TypeError: exceptions must be old-style classes or derived from BaseException, not NoneType
ERROR:tornado.application:Exception in callback <_functools.partial object at 0x00007ffd23380ec8>
Traceback (most recent call last):
  File "/home/tfb/FrameworkBenchmarks/installs/pypy/site-packages/tornado-3.1-py2.7.egg/tornado/ioloop.py", line 458, in _run_callback
    callback()
  File "/home/tfb/FrameworkBenchmarks/installs/pypy/lib_pypy/_functools.py", line 22, in __call__
    return self.func(*(self.args + fargs), **fkeywords)
  File "/home/tfb/FrameworkBenchmarks/installs/pypy/site-packages/tornado-3.1-py2.7.egg/tornado/stack_context.py", line 331, in wrapped
    raise_exc_info(exc)
  File "/home/tfb/FrameworkBenchmarks/installs/pypy/site-packages/tornado-3.1-py2.7.egg/tornado/stack_context.py", line 302, in wrapped
    ret = fn(*args, **kwargs)
  File "/home/tfb/FrameworkBenchmarks/installs/pypy/site-packages/tornado-3.1-py2.7.egg/tornado/iostream.py", line 341, in wrapper
    callback(*args)
  File "/home/tfb/FrameworkBenchmarks/installs/pypy/site-packages/tornado-3.1-py2.7.egg/tornado/stack_context.py", line 331, in wrapped
    raise_exc_info(exc)
  File "/home/tfb/FrameworkBenchmarks/installs/pypy/site-packages/tornado-3.1-py2.7.egg/tornado/stack_context.py", line 302, in wrapped
    ret = fn(*args, **kwargs)
TypeError: exceptions must be old-style classes or derived from BaseException, not NoneType
ERROR:tornado.application:Uncaught exception, closing connection.
Traceback (most recent call last):
  File "/home/tfb/FrameworkBenchmarks/installs/pypy/site-packages/tornado-3.1-py2.7.egg/tornado/iostream.py", line 341, in wrapper
    callback(*args)
  File "/home/tfb/FrameworkBenchmarks/installs/pypy/site-packages/tornado-3.1-py2.7.egg/tornado/stack_context.py", line 331, in wrapped
    raise_exc_info(exc)
  File "/home/tfb/FrameworkBenchmarks/installs/pypy/site-packages/tornado-3.1-py2.7.egg/tornado/stack_context.py", line 302, in wrapped
    ret = fn(*args, **kwargs)
TypeError: exceptions must be old-style classes or derived from BaseException, not NoneType
ERROR:tornado.application:Exception in callback <_functools.partial object at 0x00007ffd23380bf0>
Traceback (most recent call last):
  File "/home/tfb/FrameworkBenchmarks/installs/pypy/site-packages/tornado-3.1-py2.7.egg/tornado/ioloop.py", line 458, in _run_callback
    callback()
  File "/home/tfb/FrameworkBenchmarks/installs/pypy/lib_pypy/_functools.py", line 22, in __call__
    return self.func(*(self.args + fargs), **fkeywords)
  File "/home/tfb/FrameworkBenchmarks/installs/pypy/site-packages/tornado-3.1-py2.7.egg/tornado/stack_context.py", line 331, in wrapped
    raise_exc_info(exc)
  File "/home/tfb/FrameworkBenchmarks/installs/pypy/site-packages/tornado-3.1-py2.7.egg/tornado/stack_context.py", line 302, in wrapped
    ret = fn(*args, **kwargs)
  File "/home/tfb/FrameworkBenchmarks/installs/pypy/site-packages/tornado-3.1-py2.7.egg/tornado/iostream.py", line 341, in wrapper
    callback(*args)
  File "/home/tfb/FrameworkBenchmarks/installs/pypy/site-packages/tornado-3.1-py2.7.egg/tornado/stack_context.py", line 331, in wrapped
    raise_exc_info(exc)
  File "/home/tfb/FrameworkBenchmarks/installs/pypy/site-packages/tornado-3.1-py2.7.egg/tornado/stack_context.py", line 302, in wrapped
    ret = fn(*args, **kwargs)
TypeError: exceptions must be old-style classes or derived from BaseException, not NoneType
ERROR:tornado.application:Uncaught exception, closing connection.
Traceback (most recent call last):
  File "/home/tfb/FrameworkBenchmarks/installs/pypy/site-packages/tornado-3.1-py2.7.egg/tornado/iostream.py", line 341, in wrapper
    callback(*args)
  File "/home/tfb/FrameworkBenchmarks/installs/pypy/site-packages/tornado-3.1-py2.7.egg/tornado/stack_context.py", line 331, in wrapped
    raise_exc_info(exc)
  File "/home/tfb/FrameworkBenchmarks/installs/pypy/site-packages/tornado-3.1-py2.7.egg/tornado/stack_context.py", line 302, in wrapped
    ret = fn(*args, **kwargs)
TypeError: exceptions must be old-style classes or derived from BaseException, not NoneType
ERROR:tornado.application:Uncaught exception, closing connection.
Traceback (most recent call last):
  File "/home/tfb/FrameworkBenchmarks/installs/pypy/site-packages/tornado-3.1-py2.7.egg/tornado/iostream.py", line 341, in wrapper
    callback(*args)
  File "/home/tfb/FrameworkBenchmarks/installs/pypy/site-packages/tornado-3.1-py2.7.egg/tornado/stack_context.py", line 331, in wrapped
    raise_exc_info(exc)
  File "/home/tfb/FrameworkBenchmarks/installs/pypy/site-packages/tornado-3.1-py2.7.egg/tornado/stack_context.py", line 302, in wrapped
    ret = fn(*args, **kwargs)
TypeError: exceptions must be old-style classes or derived from BaseException, not NoneType
ERROR:tornado.application:Uncaught exception, closing connection.
Traceback (most recent call last):
  File "/home/tfb/FrameworkBenchmarks/installs/pypy/site-packages/tornado-3.1-py2.7.egg/tornado/iostream.py", line 341, in wrapper
    callback(*args)
  File "/home/tfb/FrameworkBenchmarks/installs/pypy/site-packages/tornado-3.1-py2.7.egg/tornado/stack_context.py", line 331, in wrapped
    raise_exc_info(exc)
  File "/home/tfb/FrameworkBenchmarks/installs/pypy/site-packages/tornado-3.1-py2.7.egg/tornado/stack_context.py", line 302, in wrapped
    ret = fn(*args, **kwargs)
TypeError: exceptions must be old-style classes or derived from BaseException, not NoneType
ERROR:tornado.application:Exception in callback <_functools.partial object at 0x00007ffd23380c98>
Traceback (most recent call last):
  File "/home/tfb/FrameworkBenchmarks/installs/pypy/site-packages/tornado-3.1-py2.7.egg/tornado/ioloop.py", line 458, in _run_callback
    callback()
  File "/home/tfb/FrameworkBenchmarks/installs/pypy/lib_pypy/_functools.py", line 22, in __call__
    return self.func(*(self.args + fargs), **fkeywords)
  File "/home/tfb/FrameworkBenchmarks/installs/pypy/site-packages/tornado-3.1-py2.7.egg/tornado/stack_context.py", line 331, in wrapped
    raise_exc_info(exc)
  File "/home/tfb/FrameworkBenchmarks/installs/pypy/site-packages/tornado-3.1-py2.7.egg/tornado/stack_context.py", line 302, in wrapped
    ret = fn(*args, **kwargs)
  File "/home/tfb/FrameworkBenchmarks/installs/pypy/site-packages/tornado-3.1-py2.7.egg/tornado/iostream.py", line 341, in wrapper
    callback(*args)
  File "/home/tfb/FrameworkBenchmarks/installs/pypy/site-packages/tornado-3.1-py2.7.egg/tornado/stack_context.py", line 331, in wrapped
    raise_exc_info(exc)
  File "/home/tfb/FrameworkBenchmarks/installs/pypy/site-packages/tornado-3.1-py2.7.egg/tornado/stack_context.py", line 302, in wrapped
    ret = fn(*args, **kwargs)
TypeError: exceptions must be old-style classes or derived from BaseException, not NoneType
ERROR:tornado.application:Exception in callback <_functools.partial object at 0x00007ffd20a4dda8>
Traceback (most recent call last):
  File "/home/tfb/FrameworkBenchmarks/installs/pypy/site-packages/tornado-3.1-py2.7.egg/tornado/ioloop.py", line 458, in _run_callback
    callback()
  File "/home/tfb/FrameworkBenchmarks/installs/pypy/lib_pypy/_functools.py", line 22, in __call__
    return self.func(*(self.args + fargs), **fkeywords)
  File "/home/tfb/FrameworkBenchmarks/installs/pypy/site-packages/tornado-3.1-py2.7.egg/tornado/stack_context.py", line 331, in wrapped
    raise_exc_info(exc)
  File "/home/tfb/FrameworkBenchmarks/installs/pypy/site-packages/tornado-3.1-py2.7.egg/tornado/stack_context.py", line 302, in wrapped
    ret = fn(*args, **kwargs)
  File "/home/tfb/FrameworkBenchmarks/installs/pypy/site-packages/tornado-3.1-py2.7.egg/tornado/iostream.py", line 341, in wrapper
    callback(*args)
  File "/home/tfb/FrameworkBenchmarks/installs/pypy/site-packages/tornado-3.1-py2.7.egg/tornado/stack_context.py", line 331, in wrapped
    raise_exc_info(exc)
  File "/home/tfb/FrameworkBenchmarks/installs/pypy/site-packages/tornado-3.1-py2.7.egg/tornado/stack_context.py", line 302, in wrapped
    ret = fn(*args, **kwargs)
TypeError: exceptions must be old-style classes or derived from BaseException, not NoneType
ERROR:tornado.application:Exception in callback <_functools.partial object at 0x00007ffd23359590>
Traceback (most recent call last):
  File "/home/tfb/FrameworkBenchmarks/installs/pypy/site-packages/tornado-3.1-py2.7.egg/tornado/ioloop.py", line 458, in _run_callback
    callback()
  File "/home/tfb/FrameworkBenchmarks/installs/pypy/lib_pypy/_functools.py", line 22, in __call__
    return self.func(*(self.args + fargs), **fkeywords)
  File "/home/tfb/FrameworkBenchmarks/installs/pypy/site-packages/tornado-3.1-py2.7.egg/tornado/stack_context.py", line 331, in wrapped
    raise_exc_info(exc)
  File "/home/tfb/FrameworkBenchmarks/installs/pypy/site-packages/tornado-3.1-py2.7.egg/tornado/stack_context.py", line 302, in wrapped
    ret = fn(*args, **kwargs)
  File "/home/tfb/FrameworkBenchmarks/installs/pypy/site-packages/tornado-3.1-py2.7.egg/tornado/iostream.py", line 341, in wrapper
    callback(*args)
  File "/home/tfb/FrameworkBenchmarks/installs/pypy/site-packages/tornado-3.1-py2.7.egg/tornado/stack_context.py", line 331, in wrapped
    raise_exc_info(exc)
  File "/home/tfb/FrameworkBenchmarks/installs/pypy/site-packages/tornado-3.1-py2.7.egg/tornado/stack_context.py", line 302, in wrapped
    ret = fn(*args, **kwargs)
TypeError: exceptions must be old-style classes or derived from BaseException, not NoneType
debug: OperationError:
debug:  operror-type: SystemExit
debug:  operror-value: 0
ERROR:tornado.application:Uncaught exception, closing connection.
Traceback (most recent call last):
  File "/home/tfb/FrameworkBenchmarks/installs/pypy/site-packages/tornado-3.1-py2.7.egg/tornado/iostream.py", line 341, in wrapper
    callback(*args)
  File "/home/tfb/FrameworkBenchmarks/installs/pypy/site-packages/tornado-3.1-py2.7.egg/tornado/stack_context.py", line 331, in wrapped
    raise_exc_info(exc)
  File "/home/tfb/FrameworkBenchmarks/installs/pypy/site-packages/tornado-3.1-py2.7.egg/tornado/stack_context.py", line 302, in wrapped
    ret = fn(*args, **kwargs)
TypeError: exceptions must be old-style classes or derived from BaseException, not NoneType
ERROR:tornado.application:Uncaught exception, closing connection.
Traceback (most recent call last):
  File "/home/tfb/FrameworkBenchmarks/installs/pypy/site-packages/tornado-3.1-py2.7.egg/tornado/iostream.py", line 341, in wrapper
    callback(*args)
  File "/home/tfb/FrameworkBenchmarks/installs/pypy/site-packages/tornado-3.1-py2.7.egg/tornado/stack_context.py", line 331, in wrapped
    raise_exc_info(exc)
  File "/home/tfb/FrameworkBenchmarks/installs/pypy/site-packages/tornado-3.1-py2.7.egg/tornado/stack_context.py", line 302, in wrapped
    ret = fn(*args, **kwargs)
TypeError: exceptions must be old-style classes or derived from BaseException, not NoneType
ERROR:tornado.application:Uncaught exception, closing connection.
Traceback (most recent call last):
  File "/home/tfb/FrameworkBenchmarks/installs/pypy/site-packages/tornado-3.1-py2.7.egg/tornado/iostream.py", line 341, in wrapper
    callback(*args)
  File "/home/tfb/FrameworkBenchmarks/installs/pypy/site-packages/tornado-3.1-py2.7.egg/tornado/stack_context.py", line 331, in wrapped
    raise_exc_info(exc)
  File "/home/tfb/FrameworkBenchmarks/installs/pypy/site-packages/tornado-3.1-py2.7.egg/tornado/stack_context.py", line 302, in wrapped
    ret = fn(*args, **kwargs)
TypeError: exceptions must be old-style classes or derived from BaseException, not NoneType
ERROR:tornado.application:Exception in callback <_functools.partial object at 0x00007ffd23380f00>
Traceback (most recent call last):
  File "/home/tfb/FrameworkBenchmarks/installs/pypy/site-packages/tornado-3.1-py2.7.egg/tornado/ioloop.py", line 458, in _run_callback
    callback()
  File "/home/tfb/FrameworkBenchmarks/installs/pypy/lib_pypy/_functools.py", line 22, in __call__
    return self.func(*(self.args + fargs), **fkeywords)
  File "/home/tfb/FrameworkBenchmarks/installs/pypy/site-packages/tornado-3.1-py2.7.egg/tornado/stack_context.py", line 331, in wrapped
    raise_exc_info(exc)
  File "/home/tfb/FrameworkBenchmarks/installs/pypy/site-packages/tornado-3.1-py2.7.egg/tornado/stack_context.py", line 302, in wrapped
    ret = fn(*args, **kwargs)
  File "/home/tfb/FrameworkBenchmarks/installs/pypy/site-packages/tornado-3.1-py2.7.egg/tornado/iostream.py", line 341, in wrapper
    callback(*args)
  File "/home/tfb/FrameworkBenchmarks/installs/pypy/site-packages/tornado-3.1-py2.7.egg/tornado/stack_context.py", line 331, in wrapped
    raise_exc_info(exc)
  File "/home/tfb/FrameworkBenchmarks/installs/pypy/site-packages/tornado-3.1-py2.7.egg/tornado/stack_context.py", line 302, in wrapped
    ret = fn(*args, **kwargs)
TypeError: exceptions must be old-style classes or derived from BaseException, not NoneType
ERROR:tornado.application:Exception in callback <_functools.partial object at 0x00007ffd23359c20>
Traceback (most recent call last):
  File "/home/tfb/FrameworkBenchmarks/installs/pypy/site-packages/tornado-3.1-py2.7.egg/tornado/ioloop.py", line 458, in _run_callback
    callback()
  File "/home/tfb/FrameworkBenchmarks/installs/pypy/lib_pypy/_functools.py", line 22, in __call__
    return self.func(*(self.args + fargs), **fkeywords)
  File "/home/tfb/FrameworkBenchmarks/installs/pypy/site-packages/tornado-3.1-py2.7.egg/tornado/stack_context.py", line 331, in wrapped
    raise_exc_info(exc)
  File "/home/tfb/FrameworkBenchmarks/installs/pypy/site-packages/tornado-3.1-py2.7.egg/tornado/stack_context.py", line 302, in wrapped
    ret = fn(*args, **kwargs)
  File "/home/tfb/FrameworkBenchmarks/installs/pypy/site-packages/tornado-3.1-py2.7.egg/tornado/iostream.py", line 341, in wrapper
    callback(*args)
  File "/home/tfb/FrameworkBenchmarks/installs/pypy/site-packages/tornado-3.1-py2.7.egg/tornado/stack_context.py", line 331, in wrapped
    raise_exc_info(exc)
  File "/home/tfb/FrameworkBenchmarks/installs/pypy/site-packages/tornado-3.1-py2.7.egg/tornado/stack_context.py", line 302, in wrapped
    ret = fn(*args, **kwargs)
TypeError: exceptions must be old-style classes or derived from BaseException, not NoneType
ERROR:tornado.application:Uncaught exception, closing connection.
Traceback (most recent call last):
  File "/home/tfb/FrameworkBenchmarks/installs/pypy/site-packages/tornado-3.1-py2.7.egg/tornado/iostream.py", line 341, in wrapper
    callback(*args)
  File "/home/tfb/FrameworkBenchmarks/installs/pypy/site-packages/tornado-3.1-py2.7.egg/tornado/stack_context.py", line 331, in wrapped
    raise_exc_info(exc)
  File "/home/tfb/FrameworkBenchmarks/installs/pypy/site-packages/tornado-3.1-py2.7.egg/tornado/stack_context.py", line 302, in wrapped
    ret = fn(*args, **kwargs)
TypeError: exceptions must be old-style classes or derived from BaseException, not NoneType
ERROR:tornado.application:Exception in callback <_functools.partial object at 0x00007ffd23380d78>
Traceback (most recent call last):
  File "/home/tfb/FrameworkBenchmarks/installs/pypy/site-packages/tornado-3.1-py2.7.egg/tornado/ioloop.py", line 458, in _run_callback
    callback()
  File "/home/tfb/FrameworkBenchmarks/installs/pypy/lib_pypy/_functools.py", line 22, in __call__
    return self.func(*(self.args + fargs), **fkeywords)
  File "/home/tfb/FrameworkBenchmarks/installs/pypy/site-packages/tornado-3.1-py2.7.egg/tornado/stack_context.py", line 331, in wrapped
    raise_exc_info(exc)
  File "/home/tfb/FrameworkBenchmarks/installs/pypy/site-packages/tornado-3.1-py2.7.egg/tornado/stack_context.py", line 302, in wrapped
    ret = fn(*args, **kwargs)
  File "/home/tfb/FrameworkBenchmarks/installs/pypy/site-packages/tornado-3.1-py2.7.egg/tornado/iostream.py", line 341, in wrapper
    callback(*args)
  File "/home/tfb/FrameworkBenchmarks/installs/pypy/site-packages/tornado-3.1-py2.7.egg/tornado/stack_context.py", line 331, in wrapped
    raise_exc_info(exc)
  File "/home/tfb/FrameworkBenchmarks/installs/pypy/site-packages/tornado-3.1-py2.7.egg/tornado/stack_context.py", line 302, in wrapped
    ret = fn(*args, **kwargs)
TypeError: exceptions must be old-style classes or derived from BaseException, not NoneType
debug: OperationError:
debug:  operror-type: SystemExit
debug:  operror-value: 0
ERROR:tornado.application:Uncaught exception, closing connection.
Traceback (most recent call last):
  File "/home/tfb/FrameworkBenchmarks/installs/pypy/site-packages/tornado-3.1-py2.7.egg/tornado/iostream.py", line 341, in wrapper
    callback(*args)
  File "/home/tfb/FrameworkBenchmarks/installs/pypy/site-packages/tornado-3.1-py2.7.egg/tornado/stack_context.py", line 331, in wrapped
    raise_exc_info(exc)
  File "/home/tfb/FrameworkBenchmarks/installs/pypy/site-packages/tornado-3.1-py2.7.egg/tornado/stack_context.py", line 302, in wrapped
    ret = fn(*args, **kwargs)
TypeError: exceptions must be old-style classes or derived from BaseException, not NoneType
ERROR:tornado.application:Exception in callback <_functools.partial object at 0x00007ffd20a4dde0>
Traceback (most recent call last):
  File "/home/tfb/FrameworkBenchmarks/installs/pypy/site-packages/tornado-3.1-py2.7.egg/tornado/ioloop.py", line 458, in _run_callback
    callback()
  File "/home/tfb/FrameworkBenchmarks/installs/pypy/lib_pypy/_functools.py", line 22, in __call__
    return self.func(*(self.args + fargs), **fkeywords)
  File "/home/tfb/FrameworkBenchmarks/installs/pypy/site-packages/tornado-3.1-py2.7.egg/tornado/stack_context.py", line 331, in wrapped
    raise_exc_info(exc)
  File "/home/tfb/FrameworkBenchmarks/installs/pypy/site-packages/tornado-3.1-py2.7.egg/tornado/stack_context.py", line 302, in wrapped
    ret = fn(*args, **kwargs)
  File "/home/tfb/FrameworkBenchmarks/installs/pypy/site-packages/tornado-3.1-py2.7.egg/tornado/iostream.py", line 341, in wrapper
    callback(*args)
  File "/home/tfb/FrameworkBenchmarks/installs/pypy/site-packages/tornado-3.1-py2.7.egg/tornado/stack_context.py", line 331, in wrapped
    raise_exc_info(exc)
  File "/home/tfb/FrameworkBenchmarks/installs/pypy/site-packages/tornado-3.1-py2.7.egg/tornado/stack_context.py", line 302, in wrapped
    ret = fn(*args, **kwargs)
TypeError: exceptions must be old-style classes or derived from BaseException, not NoneType
ERROR:tornado.application:Uncaught exception, closing connection.
Traceback (most recent call last):
  File "/home/tfb/FrameworkBenchmarks/installs/pypy/site-packages/tornado-3.1-py2.7.egg/tornado/iostream.py", line 341, in wrapper
    callback(*args)
  File "/home/tfb/FrameworkBenchmarks/installs/pypy/site-packages/tornado-3.1-py2.7.egg/tornado/stack_context.py", line 331, in wrapped
    raise_exc_info(exc)
  File "/home/tfb/FrameworkBenchmarks/installs/pypy/site-packages/tornado-3.1-py2.7.egg/tornado/stack_context.py", line 302, in wrapped
    ret = fn(*args, **kwargs)
TypeError: exceptions must be old-style classes or derived from BaseException, not NoneType
ERROR:tornado.application:Uncaught exception, closing connection.
Traceback (most recent call last):
  File "/home/tfb/FrameworkBenchmarks/installs/pypy/site-packages/tornado-3.1-py2.7.egg/tornado/iostream.py", line 341, in wrapper
    callback(*args)
  File "/home/tfb/FrameworkBenchmarks/installs/pypy/site-packages/tornado-3.1-py2.7.egg/tornado/stack_context.py", line 331, in wrapped
    raise_exc_info(exc)
  File "/home/tfb/FrameworkBenchmarks/installs/pypy/site-packages/tornado-3.1-py2.7.egg/tornado/stack_context.py", line 302, in wrapped
    ret = fn(*args, **kwargs)
TypeError: exceptions must be old-style classes or derived from BaseException, not NoneType
ERROR:tornado.application:Uncaught exception, closing connection.
Traceback (most recent call last):
  File "/home/tfb/FrameworkBenchmarks/installs/pypy/site-packages/tornado-3.1-py2.7.egg/tornado/iostream.py", line 341, in wrapper
    callback(*args)
  File "/home/tfb/FrameworkBenchmarks/installs/pypy/site-packages/tornado-3.1-py2.7.egg/tornado/stack_context.py", line 331, in wrapped
    raise_exc_info(exc)
  File "/home/tfb/FrameworkBenchmarks/installs/pypy/site-packages/tornado-3.1-py2.7.egg/tornado/stack_context.py", line 302, in wrapped
    ret = fn(*args, **kwargs)
TypeError: exceptions must be old-style classes or derived from BaseException, not NoneType
ERROR:tornado.application:Exception in callback <_functools.partial object at 0x00007ffd23380f38>
Traceback (most recent call last):
  File "/home/tfb/FrameworkBenchmarks/installs/pypy/site-packages/tornado-3.1-py2.7.egg/tornado/ioloop.py", line 458, in _run_callback
    callback()
  File "/home/tfb/FrameworkBenchmarks/installs/pypy/lib_pypy/_functools.py", line 22, in __call__
    return self.func(*(self.args + fargs), **fkeywords)
  File "/home/tfb/FrameworkBenchmarks/installs/pypy/site-packages/tornado-3.1-py2.7.egg/tornado/stack_context.py", line 331, in wrapped
    raise_exc_info(exc)
  File "/home/tfb/FrameworkBenchmarks/installs/pypy/site-packages/tornado-3.1-py2.7.egg/tornado/stack_context.py", line 302, in wrapped
    ret = fn(*args, **kwargs)
  File "/home/tfb/FrameworkBenchmarks/installs/pypy/site-packages/tornado-3.1-py2.7.egg/tornado/iostream.py", line 341, in wrapper
    callback(*args)
  File "/home/tfb/FrameworkBenchmarks/installs/pypy/site-packages/tornado-3.1-py2.7.egg/tornado/stack_context.py", line 331, in wrapped
    raise_exc_info(exc)
  File "/home/tfb/FrameworkBenchmarks/installs/pypy/site-packages/tornado-3.1-py2.7.egg/tornado/stack_context.py", line 302, in wrapped
    ret = fn(*args, **kwargs)
TypeError: exceptions must be old-style classes or derived from BaseException, not NoneType
ERROR:tornado.application:Exception in callback <_functools.partial object at 0x00007ffd23359c58>
Traceback (most recent call last):
  File "/home/tfb/FrameworkBenchmarks/installs/pypy/site-packages/tornado-3.1-py2.7.egg/tornado/ioloop.py", line 458, in _run_callback
    callback()
  File "/home/tfb/FrameworkBenchmarks/installs/pypy/lib_pypy/_functools.py", line 22, in __call__
    return self.func(*(self.args + fargs), **fkeywords)
  File "/home/tfb/FrameworkBenchmarks/installs/pypy/site-packages/tornado-3.1-py2.7.egg/tornado/stack_context.py", line 331, in wrapped
    raise_exc_info(exc)
  File "/home/tfb/FrameworkBenchmarks/installs/pypy/site-packages/tornado-3.1-py2.7.egg/tornado/stack_context.py", line 302, in wrapped
    ret = fn(*args, **kwargs)
  File "/home/tfb/FrameworkBenchmarks/installs/pypy/site-packages/tornado-3.1-py2.7.egg/tornado/iostream.py", line 341, in wrapper
    callback(*args)
  File "/home/tfb/FrameworkBenchmarks/installs/pypy/site-packages/tornado-3.1-py2.7.egg/tornado/stack_context.py", line 331, in wrapped
    raise_exc_info(exc)
  File "/home/tfb/FrameworkBenchmarks/installs/pypy/site-packages/tornado-3.1-py2.7.egg/tornado/stack_context.py", line 302, in wrapped
    ret = fn(*args, **kwargs)
TypeError: exceptions must be old-style classes or derived from BaseException, not NoneType
ERROR:tornado.application:Exception in callback <_functools.partial object at 0x00007ffd23380d40>
Traceback (most recent call last):
  File "/home/tfb/FrameworkBenchmarks/installs/pypy/site-packages/tornado-3.1-py2.7.egg/tornado/ioloop.py", line 458, in _run_callback
    callback()
  File "/home/tfb/FrameworkBenchmarks/installs/pypy/lib_pypy/_functools.py", line 22, in __call__
    return self.func(*(self.args + fargs), **fkeywords)
  File "/home/tfb/FrameworkBenchmarks/installs/pypy/site-packages/tornado-3.1-py2.7.egg/tornado/stack_context.py", line 331, in wrapped
    raise_exc_info(exc)
  File "/home/tfb/FrameworkBenchmarks/installs/pypy/site-packages/tornado-3.1-py2.7.egg/tornado/stack_context.py", line 302, in wrapped
    ret = fn(*args, **kwargs)
  File "/home/tfb/FrameworkBenchmarks/installs/pypy/site-packages/tornado-3.1-py2.7.egg/tornado/iostream.py", line 341, in wrapper
    callback(*args)
  File "/home/tfb/FrameworkBenchmarks/installs/pypy/site-packages/tornado-3.1-py2.7.egg/tornado/stack_context.py", line 331, in wrapped
    raise_exc_info(exc)
  File "/home/tfb/FrameworkBenchmarks/installs/pypy/site-packages/tornado-3.1-py2.7.egg/tornado/stack_context.py", line 302, in wrapped
    ret = fn(*args, **kwargs)
TypeError: exceptions must be old-style classes or derived from BaseException, not NoneType
ERROR:tornado.application:Uncaught exception, closing connection.
Traceback (most recent call last):
  File "/home/tfb/FrameworkBenchmarks/installs/pypy/site-packages/tornado-3.1-py2.7.egg/tornado/iostream.py", line 341, in wrapper
    callback(*args)
  File "/home/tfb/FrameworkBenchmarks/installs/pypy/site-packages/tornado-3.1-py2.7.egg/tornado/stack_context.py", line 331, in wrapped
    raise_exc_info(exc)
  File "/home/tfb/FrameworkBenchmarks/installs/pypy/site-packages/tornado-3.1-py2.7.egg/tornado/stack_context.py", line 302, in wrapped
    ret = fn(*args, **kwargs)
TypeError: exceptions must be old-style classes or derived from BaseException, not NoneType
ERROR:tornado.application:Uncaught exception, closing connection.
Traceback (most recent call last):
  File "/home/tfb/FrameworkBenchmarks/installs/pypy/site-packages/tornado-3.1-py2.7.egg/tornado/iostream.py", line 341, in wrapper
    callback(*args)
  File "/home/tfb/FrameworkBenchmarks/installs/pypy/site-packages/tornado-3.1-py2.7.egg/tornado/stack_context.py", line 331, in wrapped
    raise_exc_info(exc)
  File "/home/tfb/FrameworkBenchmarks/installs/pypy/site-packages/tornado-3.1-py2.7.egg/tornado/stack_context.py", line 302, in wrapped
    ret = fn(*args, **kwargs)
TypeError: exceptions must be old-style classes or derived from BaseException, not NoneType
